[2015-10-30 05:21:07,013: WARNING/MainProcess] worker@alpha005 ready.
[2015-10-30 05:50:23,545: WARNING/Worker-3] /cluster/home/mmunso01/envs/nidaba/lib/python2.7/site-packages/scipy/ndimage/interpolation.py:549: UserWarning: From scipy 0.13.0, the output shape of zoom() is calculated with round() instead of int() - for these inputs the size of the returned array has changed.
  "the returned array has changed.", UserWarning)
[2015-10-30 05:50:40,744: WARNING/Worker-12] /cluster/home/mmunso01/envs/nidaba/lib/python2.7/site-packages/scipy/ndimage/interpolation.py:549: UserWarning: From scipy 0.13.0, the output shape of zoom() is calculated with round() instead of int() - for these inputs the size of the returned array has changed.
  "the returned array has changed.", UserWarning)
[2015-10-30 05:51:49,900: WARNING/Worker-26] /cluster/home/mmunso01/envs/nidaba/lib/python2.7/site-packages/scipy/ndimage/interpolation.py:549: UserWarning: From scipy 0.13.0, the output shape of zoom() is calculated with round() instead of int() - for these inputs the size of the returned array has changed.
  "the returned array has changed.", UserWarning)
[2015-10-30 05:54:30,885: WARNING/Worker-27] /cluster/home/mmunso01/envs/nidaba/lib/python2.7/site-packages/scipy/ndimage/interpolation.py:549: UserWarning: From scipy 0.13.0, the output shape of zoom() is calculated with round() instead of int() - for these inputs the size of the returned array has changed.
  "the returned array has changed.", UserWarning)
[2015-10-30 05:55:01,084: WARNING/Worker-18] /cluster/home/mmunso01/envs/nidaba/lib/python2.7/site-packages/scipy/ndimage/interpolation.py:549: UserWarning: From scipy 0.13.0, the output shape of zoom() is calculated with round() instead of int() - for these inputs the size of the returned array has changed.
  "the returned array has changed.", UserWarning)
[2015-10-30 05:58:35,645: WARNING/Worker-38] /cluster/home/mmunso01/envs/nidaba/lib/python2.7/site-packages/scipy/ndimage/interpolation.py:549: UserWarning: From scipy 0.13.0, the output shape of zoom() is calculated with round() instead of int() - for these inputs the size of the returned array has changed.
  "the returned array has changed.", UserWarning)
[2015-10-30 05:58:36,444: WARNING/Worker-5] /cluster/home/mmunso01/envs/nidaba/lib/python2.7/site-packages/scipy/ndimage/interpolation.py:549: UserWarning: From scipy 0.13.0, the output shape of zoom() is calculated with round() instead of int() - for these inputs the size of the returned array has changed.
  "the returned array has changed.", UserWarning)
[2015-10-30 05:58:58,255: WARNING/Worker-1] /cluster/home/mmunso01/envs/nidaba/lib/python2.7/site-packages/scipy/ndimage/interpolation.py:549: UserWarning: From scipy 0.13.0, the output shape of zoom() is calculated with round() instead of int() - for these inputs the size of the returned array has changed.
  "the returned array has changed.", UserWarning)
[2015-10-30 05:59:02,605: WARNING/Worker-11] /cluster/home/mmunso01/envs/nidaba/lib/python2.7/site-packages/scipy/ndimage/interpolation.py:549: UserWarning: From scipy 0.13.0, the output shape of zoom() is calculated with round() instead of int() - for these inputs the size of the returned array has changed.
  "the returned array has changed.", UserWarning)
[2015-10-30 05:59:09,019: WARNING/Worker-6] /cluster/home/mmunso01/envs/nidaba/lib/python2.7/site-packages/scipy/ndimage/interpolation.py:549: UserWarning: From scipy 0.13.0, the output shape of zoom() is calculated with round() instead of int() - for these inputs the size of the returned array has changed.
  "the returned array has changed.", UserWarning)
[2015-10-30 05:59:11,144: WARNING/Worker-29] /cluster/home/mmunso01/envs/nidaba/lib/python2.7/site-packages/scipy/ndimage/interpolation.py:549: UserWarning: From scipy 0.13.0, the output shape of zoom() is calculated with round() instead of int() - for these inputs the size of the returned array has changed.
  "the returned array has changed.", UserWarning)
[2015-10-30 05:59:14,195: WARNING/Worker-8] /cluster/home/mmunso01/envs/nidaba/lib/python2.7/site-packages/scipy/ndimage/interpolation.py:549: UserWarning: From scipy 0.13.0, the output shape of zoom() is calculated with round() instead of int() - for these inputs the size of the returned array has changed.
  "the returned array has changed.", UserWarning)
[2015-10-30 05:59:14,536: WARNING/Worker-4] /cluster/home/mmunso01/envs/nidaba/lib/python2.7/site-packages/scipy/ndimage/interpolation.py:549: UserWarning: From scipy 0.13.0, the output shape of zoom() is calculated with round() instead of int() - for these inputs the size of the returned array has changed.
  "the returned array has changed.", UserWarning)
[2015-10-30 05:59:15,064: WARNING/Worker-24] /cluster/home/mmunso01/envs/nidaba/lib/python2.7/site-packages/scipy/ndimage/interpolation.py:549: UserWarning: From scipy 0.13.0, the output shape of zoom() is calculated with round() instead of int() - for these inputs the size of the returned array has changed.
  "the returned array has changed.", UserWarning)
[2015-10-30 05:59:15,525: WARNING/Worker-37] /cluster/home/mmunso01/envs/nidaba/lib/python2.7/site-packages/scipy/ndimage/interpolation.py:549: UserWarning: From scipy 0.13.0, the output shape of zoom() is calculated with round() instead of int() - for these inputs the size of the returned array has changed.
  "the returned array has changed.", UserWarning)
[2015-10-30 05:59:17,175: WARNING/Worker-2] /cluster/home/mmunso01/envs/nidaba/lib/python2.7/site-packages/scipy/ndimage/interpolation.py:549: UserWarning: From scipy 0.13.0, the output shape of zoom() is calculated with round() instead of int() - for these inputs the size of the returned array has changed.
  "the returned array has changed.", UserWarning)
[2015-10-30 05:59:19,047: WARNING/Worker-16] /cluster/home/mmunso01/envs/nidaba/lib/python2.7/site-packages/scipy/ndimage/interpolation.py:549: UserWarning: From scipy 0.13.0, the output shape of zoom() is calculated with round() instead of int() - for these inputs the size of the returned array has changed.
  "the returned array has changed.", UserWarning)
[2015-10-30 05:59:24,515: WARNING/Worker-35] /cluster/home/mmunso01/envs/nidaba/lib/python2.7/site-packages/scipy/ndimage/interpolation.py:549: UserWarning: From scipy 0.13.0, the output shape of zoom() is calculated with round() instead of int() - for these inputs the size of the returned array has changed.
  "the returned array has changed.", UserWarning)
[2015-10-30 05:59:29,195: WARNING/Worker-13] /cluster/home/mmunso01/envs/nidaba/lib/python2.7/site-packages/scipy/ndimage/interpolation.py:549: UserWarning: From scipy 0.13.0, the output shape of zoom() is calculated with round() instead of int() - for these inputs the size of the returned array has changed.
  "the returned array has changed.", UserWarning)
[2015-10-30 05:59:34,906: WARNING/Worker-30] /cluster/home/mmunso01/envs/nidaba/lib/python2.7/site-packages/scipy/ndimage/interpolation.py:549: UserWarning: From scipy 0.13.0, the output shape of zoom() is calculated with round() instead of int() - for these inputs the size of the returned array has changed.
  "the returned array has changed.", UserWarning)
[2015-10-30 05:59:35,354: WARNING/Worker-36] /cluster/home/mmunso01/envs/nidaba/lib/python2.7/site-packages/scipy/ndimage/interpolation.py:549: UserWarning: From scipy 0.13.0, the output shape of zoom() is calculated with round() instead of int() - for these inputs the size of the returned array has changed.
  "the returned array has changed.", UserWarning)
[2015-10-30 05:59:36,974: WARNING/Worker-15] /cluster/home/mmunso01/envs/nidaba/lib/python2.7/site-packages/scipy/ndimage/interpolation.py:549: UserWarning: From scipy 0.13.0, the output shape of zoom() is calculated with round() instead of int() - for these inputs the size of the returned array has changed.
  "the returned array has changed.", UserWarning)
[2015-10-30 05:59:39,634: WARNING/Worker-19] /cluster/home/mmunso01/envs/nidaba/lib/python2.7/site-packages/scipy/ndimage/interpolation.py:549: UserWarning: From scipy 0.13.0, the output shape of zoom() is calculated with round() instead of int() - for these inputs the size of the returned array has changed.
  "the returned array has changed.", UserWarning)
[2015-10-30 05:59:40,152: WARNING/Worker-34] /cluster/home/mmunso01/envs/nidaba/lib/python2.7/site-packages/scipy/ndimage/interpolation.py:549: UserWarning: From scipy 0.13.0, the output shape of zoom() is calculated with round() instead of int() - for these inputs the size of the returned array has changed.
  "the returned array has changed.", UserWarning)
[2015-10-30 05:59:40,575: WARNING/Worker-32] /cluster/home/mmunso01/envs/nidaba/lib/python2.7/site-packages/scipy/ndimage/interpolation.py:549: UserWarning: From scipy 0.13.0, the output shape of zoom() is calculated with round() instead of int() - for these inputs the size of the returned array has changed.
  "the returned array has changed.", UserWarning)
[2015-10-30 05:59:43,648: WARNING/Worker-28] /cluster/home/mmunso01/envs/nidaba/lib/python2.7/site-packages/scipy/ndimage/interpolation.py:549: UserWarning: From scipy 0.13.0, the output shape of zoom() is calculated with round() instead of int() - for these inputs the size of the returned array has changed.
  "the returned array has changed.", UserWarning)
[2015-10-30 05:59:46,778: WARNING/Worker-17] /cluster/home/mmunso01/envs/nidaba/lib/python2.7/site-packages/scipy/ndimage/interpolation.py:549: UserWarning: From scipy 0.13.0, the output shape of zoom() is calculated with round() instead of int() - for these inputs the size of the returned array has changed.
  "the returned array has changed.", UserWarning)
[2015-10-30 05:59:54,590: WARNING/Worker-39] /cluster/home/mmunso01/envs/nidaba/lib/python2.7/site-packages/scipy/ndimage/interpolation.py:549: UserWarning: From scipy 0.13.0, the output shape of zoom() is calculated with round() instead of int() - for these inputs the size of the returned array has changed.
  "the returned array has changed.", UserWarning)
[2015-10-30 05:59:54,683: WARNING/Worker-22] /cluster/home/mmunso01/envs/nidaba/lib/python2.7/site-packages/scipy/ndimage/interpolation.py:549: UserWarning: From scipy 0.13.0, the output shape of zoom() is calculated with round() instead of int() - for these inputs the size of the returned array has changed.
  "the returned array has changed.", UserWarning)
[2015-10-30 05:59:56,056: WARNING/Worker-14] /cluster/home/mmunso01/envs/nidaba/lib/python2.7/site-packages/scipy/ndimage/interpolation.py:549: UserWarning: From scipy 0.13.0, the output shape of zoom() is calculated with round() instead of int() - for these inputs the size of the returned array has changed.
  "the returned array has changed.", UserWarning)
[2015-10-30 06:00:01,154: WARNING/Worker-23] /cluster/home/mmunso01/envs/nidaba/lib/python2.7/site-packages/scipy/ndimage/interpolation.py:549: UserWarning: From scipy 0.13.0, the output shape of zoom() is calculated with round() instead of int() - for these inputs the size of the returned array has changed.
  "the returned array has changed.", UserWarning)
[2015-10-30 06:00:04,754: WARNING/Worker-33] /cluster/home/mmunso01/envs/nidaba/lib/python2.7/site-packages/scipy/ndimage/interpolation.py:549: UserWarning: From scipy 0.13.0, the output shape of zoom() is calculated with round() instead of int() - for these inputs the size of the returned array has changed.
  "the returned array has changed.", UserWarning)
[2015-10-30 06:00:05,665: WARNING/Worker-7] /cluster/home/mmunso01/envs/nidaba/lib/python2.7/site-packages/scipy/ndimage/interpolation.py:549: UserWarning: From scipy 0.13.0, the output shape of zoom() is calculated with round() instead of int() - for these inputs the size of the returned array has changed.
  "the returned array has changed.", UserWarning)
[2015-10-30 06:00:15,919: WARNING/Worker-9] /cluster/home/mmunso01/envs/nidaba/lib/python2.7/site-packages/scipy/ndimage/interpolation.py:549: UserWarning: From scipy 0.13.0, the output shape of zoom() is calculated with round() instead of int() - for these inputs the size of the returned array has changed.
  "the returned array has changed.", UserWarning)
[2015-10-30 06:00:50,164: WARNING/Worker-20] /cluster/home/mmunso01/envs/nidaba/lib/python2.7/site-packages/scipy/ndimage/interpolation.py:549: UserWarning: From scipy 0.13.0, the output shape of zoom() is calculated with round() instead of int() - for these inputs the size of the returned array has changed.
  "the returned array has changed.", UserWarning)
[2015-10-30 06:00:56,805: WARNING/Worker-21] /cluster/home/mmunso01/envs/nidaba/lib/python2.7/site-packages/scipy/ndimage/interpolation.py:549: UserWarning: From scipy 0.13.0, the output shape of zoom() is calculated with round() instead of int() - for these inputs the size of the returned array has changed.
  "the returned array has changed.", UserWarning)
[2015-10-30 06:01:00,624: WARNING/Worker-10] /cluster/home/mmunso01/envs/nidaba/lib/python2.7/site-packages/scipy/ndimage/interpolation.py:549: UserWarning: From scipy 0.13.0, the output shape of zoom() is calculated with round() instead of int() - for these inputs the size of the returned array has changed.
  "the returned array has changed.", UserWarning)
[2015-10-30 06:01:02,285: WARNING/Worker-40] /cluster/home/mmunso01/envs/nidaba/lib/python2.7/site-packages/scipy/ndimage/interpolation.py:549: UserWarning: From scipy 0.13.0, the output shape of zoom() is calculated with round() instead of int() - for these inputs the size of the returned array has changed.
  "the returned array has changed.", UserWarning)
[2015-10-30 06:01:18,085: WARNING/Worker-31] /cluster/home/mmunso01/envs/nidaba/lib/python2.7/site-packages/scipy/ndimage/interpolation.py:549: UserWarning: From scipy 0.13.0, the output shape of zoom() is calculated with round() instead of int() - for these inputs the size of the returned array has changed.
  "the returned array has changed.", UserWarning)
[2015-10-30 06:01:34,685: WARNING/Worker-25] /cluster/home/mmunso01/envs/nidaba/lib/python2.7/site-packages/scipy/ndimage/interpolation.py:549: UserWarning: From scipy 0.13.0, the output shape of zoom() is calculated with round() instead of int() - for these inputs the size of the returned array has changed.
  "the returned array has changed.", UserWarning)
[2015-10-30 06:15:34,695: WARNING/Worker-7] /cluster/home/mmunso01/envs/nidaba/lib/python2.7/site-packages/kraken/binarization.py:38: RuntimeWarning: invalid value encountered in true_divide
  image /= np.amax(image)
[2015-10-30 06:15:48,345: WARNING/Worker-7] /cluster/home/mmunso01/envs/nidaba/lib/python2.7/site-packages/kraken/binarization.py:56: RuntimeWarning: invalid value encountered in greater
  v = (v > 0.3*np.amax(v))
[2015-10-30 06:15:50,934: ERROR/Worker-7] nidaba.binarize.nlbin[890b4d45-8116-4a35-8328-276e095bf744]: cannot do a non-empty take from an empty axes.
[2015-10-30 06:15:56,024: ERROR/MainProcess] Task nidaba.binarize.nlbin[890b4d45-8116-4a35-8328-276e095bf744] raised unexpected: IndexError('cannot do a non-empty take from an empty axes.',)
Traceback (most recent call last):
  File "/cluster/home/mmunso01/envs/nidaba/lib/python2.7/site-packages/celery/app/trace.py", line 240, in trace_task
    R = retval = fun(*args, **kwargs)
  File "/cluster/home/mmunso01/envs/nidaba/lib/python2.7/site-packages/nidaba/tasks/helper.py", line 89, in __call__
    ret = super(NidabaTask, self).__call__(*args, **nkwargs)
  File "/cluster/home/mmunso01/envs/nidaba/lib/python2.7/site-packages/celery/app/trace.py", line 438, in __protected_call__
    return self.run(*args, **kwargs)
  File "/cluster/home/mmunso01/envs/nidaba/lib/python2.7/site-packages/nidaba/plugins/kraken.py", line 225, in nlbin
    perc, range, low, high)
  File "/cluster/home/mmunso01/envs/nidaba/lib/python2.7/site-packages/nidaba/plugins/kraken.py", line 253, in kraken_nlbin
    high).save(output_path)
  File "/cluster/home/mmunso01/envs/nidaba/lib/python2.7/site-packages/kraken/binarization.py", line 60, in nlbin
    lo = np.percentile(est.ravel(), low)
  File "/cluster/home/mmunso01/envs/nidaba/lib/python2.7/site-packages/numpy/lib/function_base.py", line 3268, in percentile
    interpolation=interpolation)
  File "/cluster/home/mmunso01/envs/nidaba/lib/python2.7/site-packages/numpy/lib/function_base.py", line 2997, in _ureduce
    r = func(a, **kwargs)
  File "/cluster/home/mmunso01/envs/nidaba/lib/python2.7/site-packages/numpy/lib/function_base.py", line 3385, in _percentile
    x1 = take(ap, indices_below, axis=axis) * weights_below
  File "/cluster/home/mmunso01/envs/nidaba/lib/python2.7/site-packages/numpy/core/fromnumeric.py", line 124, in take
    return take(indices, axis, out, mode)
IndexError: cannot do a non-empty take from an empty axes.
[2015-10-30 06:49:50,017: ERROR/Worker-8] nidaba.segmentation.tesseract[43d993b0-567b-471d-b8df-a1e33b25a842]: Tesseract killed by signal: 11
[2015-10-30 06:49:50,727: ERROR/MainProcess] Task nidaba.segmentation.tesseract[43d993b0-567b-471d-b8df-a1e33b25a842] raised unexpected: NidabaTesseractException(u'Tesseract killed by signal: 11',)
Traceback (most recent call last):
  File "/cluster/home/mmunso01/envs/nidaba/lib/python2.7/site-packages/celery/app/trace.py", line 240, in trace_task
    R = retval = fun(*args, **kwargs)
  File "/cluster/home/mmunso01/envs/nidaba/lib/python2.7/site-packages/nidaba/tasks/helper.py", line 89, in __call__
    ret = super(NidabaTask, self).__call__(*args, **nkwargs)
  File "/cluster/home/mmunso01/envs/nidaba/lib/python2.7/site-packages/celery/app/trace.py", line 438, in __protected_call__
    return self.run(*args, **kwargs)
  File "/cluster/home/mmunso01/envs/nidaba/lib/python2.7/site-packages/nidaba/plugins/tesseract.py", line 251, in segmentation_tesseract
    raise NidabaTesseractException('Tesseract killed by signal: {0}'.format(os.WTERMSIG(status)))
NidabaTesseractException: Tesseract killed by signal: 11
[2015-10-30 06:50:24,967: ERROR/Worker-19] nidaba.segmentation.tesseract[d100bbda-7ea2-4987-a337-121dacbbdf90]: Tesseract killed by signal: 11
[2015-10-30 06:50:33,768: ERROR/MainProcess] Task nidaba.segmentation.tesseract[d100bbda-7ea2-4987-a337-121dacbbdf90] raised unexpected: NidabaTesseractException(u'Tesseract killed by signal: 11',)
Traceback (most recent call last):
  File "/cluster/home/mmunso01/envs/nidaba/lib/python2.7/site-packages/celery/app/trace.py", line 240, in trace_task
    R = retval = fun(*args, **kwargs)
  File "/cluster/home/mmunso01/envs/nidaba/lib/python2.7/site-packages/nidaba/tasks/helper.py", line 89, in __call__
    ret = super(NidabaTask, self).__call__(*args, **nkwargs)
  File "/cluster/home/mmunso01/envs/nidaba/lib/python2.7/site-packages/celery/app/trace.py", line 438, in __protected_call__
    return self.run(*args, **kwargs)
  File "/cluster/home/mmunso01/envs/nidaba/lib/python2.7/site-packages/nidaba/plugins/tesseract.py", line 251, in segmentation_tesseract
    raise NidabaTesseractException('Tesseract killed by signal: {0}'.format(os.WTERMSIG(status)))
NidabaTesseractException: Tesseract killed by signal: 11
[2015-10-30 07:07:08,925: WARNING/Worker-25] /cluster/home/mmunso01/envs/nidaba/lib/python2.7/site-packages/kraken/rpred.py:91: RuntimeWarning: invalid value encountered in true_divide
  temp = temp*1.0/np.amax(temp)
[2015-10-30 07:07:26,385: WARNING/Worker-5] /cluster/home/mmunso01/envs/nidaba/lib/python2.7/site-packages/kraken/rpred.py:91: RuntimeWarning: invalid value encountered in true_divide
  temp = temp*1.0/np.amax(temp)
[2015-10-30 07:08:25,852: ERROR/Worker-3] nidaba.segmentation.tesseract[fa70ac4a-fbed-42ef-aa67-033c24beafa1]: Tesseract killed by signal: 11
[2015-10-30 07:08:27,644: ERROR/Worker-4] nidaba.segmentation.tesseract[9997f812-8f65-4373-9ed3-a32c64d840f7]: Tesseract killed by signal: 11
[2015-10-30 07:08:34,109: ERROR/MainProcess] Task nidaba.segmentation.tesseract[fa70ac4a-fbed-42ef-aa67-033c24beafa1] raised unexpected: NidabaTesseractException(u'Tesseract killed by signal: 11',)
Traceback (most recent call last):
  File "/cluster/home/mmunso01/envs/nidaba/lib/python2.7/site-packages/celery/app/trace.py", line 240, in trace_task
    R = retval = fun(*args, **kwargs)
  File "/cluster/home/mmunso01/envs/nidaba/lib/python2.7/site-packages/nidaba/tasks/helper.py", line 89, in __call__
    ret = super(NidabaTask, self).__call__(*args, **nkwargs)
  File "/cluster/home/mmunso01/envs/nidaba/lib/python2.7/site-packages/celery/app/trace.py", line 438, in __protected_call__
    return self.run(*args, **kwargs)
  File "/cluster/home/mmunso01/envs/nidaba/lib/python2.7/site-packages/nidaba/plugins/tesseract.py", line 251, in segmentation_tesseract
    raise NidabaTesseractException('Tesseract killed by signal: {0}'.format(os.WTERMSIG(status)))
NidabaTesseractException: Tesseract killed by signal: 11
[2015-10-30 07:08:35,650: ERROR/MainProcess] Task nidaba.segmentation.tesseract[9997f812-8f65-4373-9ed3-a32c64d840f7] raised unexpected: NidabaTesseractException(u'Tesseract killed by signal: 11',)
Traceback (most recent call last):
  File "/cluster/home/mmunso01/envs/nidaba/lib/python2.7/site-packages/celery/app/trace.py", line 240, in trace_task
    R = retval = fun(*args, **kwargs)
  File "/cluster/home/mmunso01/envs/nidaba/lib/python2.7/site-packages/nidaba/tasks/helper.py", line 89, in __call__
    ret = super(NidabaTask, self).__call__(*args, **nkwargs)
  File "/cluster/home/mmunso01/envs/nidaba/lib/python2.7/site-packages/celery/app/trace.py", line 438, in __protected_call__
    return self.run(*args, **kwargs)
  File "/cluster/home/mmunso01/envs/nidaba/lib/python2.7/site-packages/nidaba/plugins/tesseract.py", line 251, in segmentation_tesseract
    raise NidabaTesseractException('Tesseract killed by signal: {0}'.format(os.WTERMSIG(status)))
NidabaTesseractException: Tesseract killed by signal: 11
[2015-10-30 07:09:16,912: ERROR/Worker-29] nidaba.segmentation.tesseract[8b87e1c7-5444-4867-959e-a7e106f200d5]: Tesseract killed by signal: 11
[2015-10-30 07:09:24,645: WARNING/Worker-20] /cluster/home/mmunso01/envs/nidaba/lib/python2.7/site-packages/kraken/rpred.py:91: RuntimeWarning: invalid value encountered in true_divide
  temp = temp*1.0/np.amax(temp)
[2015-10-30 07:09:25,053: WARNING/Worker-12] /cluster/home/mmunso01/envs/nidaba/lib/python2.7/site-packages/kraken/rpred.py:91: RuntimeWarning: invalid value encountered in true_divide
  temp = temp*1.0/np.amax(temp)
[2015-10-30 07:09:25,057: WARNING/Worker-12] /cluster/home/mmunso01/envs/nidaba/lib/python2.7/site-packages/kraken/lib/lstm.py:48: RuntimeWarning: invalid value encountered in true_divide
  line = line * 1.0/np.amax(line)
[2015-10-30 07:09:25,088: ERROR/Worker-12] nidaba.ocr.kraken[45932f0a-ca2a-4c56-a1c1-a5c50ab897b2]: 
[2015-10-30 07:09:26,682: ERROR/MainProcess] Task nidaba.ocr.kraken[45932f0a-ca2a-4c56-a1c1-a5c50ab897b2] raised unexpected: AssertionError()
Traceback (most recent call last):
  File "/cluster/home/mmunso01/envs/nidaba/lib/python2.7/site-packages/celery/app/trace.py", line 240, in trace_task
    R = retval = fun(*args, **kwargs)
  File "/cluster/home/mmunso01/envs/nidaba/lib/python2.7/site-packages/nidaba/tasks/helper.py", line 89, in __call__
    ret = super(NidabaTask, self).__call__(*args, **nkwargs)
  File "/cluster/home/mmunso01/envs/nidaba/lib/python2.7/site-packages/celery/app/trace.py", line 438, in __protected_call__
    return self.run(*args, **kwargs)
  File "/cluster/home/mmunso01/envs/nidaba/lib/python2.7/site-packages/nidaba/plugins/kraken.py", line 155, in ocr_kraken
    for rec in rpred.rpred(rnn, img, [(int(x[0]), int(x[1]), int(x[2]), int(x[3])) for x in lines]):
  File "/cluster/home/mmunso01/envs/nidaba/lib/python2.7/site-packages/kraken/rpred.py", line 134, in rpred
    pred = network.predictString(line)
  File "/cluster/home/mmunso01/envs/nidaba/lib/python2.7/site-packages/kraken/lib/lstm.py", line 281, in predictString
    cs = self.predictSequence(xs)
  File "/cluster/home/mmunso01/envs/nidaba/lib/python2.7/site-packages/kraken/lib/lstm.py", line 273, in predictSequence
    self.outputs = np.array(self.lstm.forward(xs))
  File "/cluster/home/mmunso01/envs/nidaba/lib/python2.7/site-packages/kraken/lib/lstm.py", line 229, in forward
    xs = net.forward(xs)
  File "/cluster/home/mmunso01/envs/nidaba/lib/python2.7/site-packages/kraken/lib/lstm.py", line 244, in forward
    outputs = [net.forward(xs) for net in self.nets]
  File "/cluster/home/mmunso01/envs/nidaba/lib/python2.7/site-packages/kraken/lib/lstm.py", line 216, in forward
    assert not np.isnan(self.output[:n]).any()
AssertionError
[2015-10-30 07:09:38,515: ERROR/MainProcess] Task nidaba.segmentation.tesseract[8b87e1c7-5444-4867-959e-a7e106f200d5] raised unexpected: NidabaTesseractException(u'Tesseract killed by signal: 11',)
Traceback (most recent call last):
  File "/cluster/home/mmunso01/envs/nidaba/lib/python2.7/site-packages/celery/app/trace.py", line 240, in trace_task
    R = retval = fun(*args, **kwargs)
  File "/cluster/home/mmunso01/envs/nidaba/lib/python2.7/site-packages/nidaba/tasks/helper.py", line 89, in __call__
    ret = super(NidabaTask, self).__call__(*args, **nkwargs)
  File "/cluster/home/mmunso01/envs/nidaba/lib/python2.7/site-packages/celery/app/trace.py", line 438, in __protected_call__
    return self.run(*args, **kwargs)
  File "/cluster/home/mmunso01/envs/nidaba/lib/python2.7/site-packages/nidaba/plugins/tesseract.py", line 251, in segmentation_tesseract
    raise NidabaTesseractException('Tesseract killed by signal: {0}'.format(os.WTERMSIG(status)))
NidabaTesseractException: Tesseract killed by signal: 11
[2015-10-30 07:10:14,763: ERROR/Worker-11] nidaba.ocr.kraken[ae98745f-67e4-46bb-972f-301473f3d0c5]: index 5000 is out of bounds for axis 0 with size 5000
[2015-10-30 07:10:22,664: WARNING/Worker-17] /cluster/home/mmunso01/envs/nidaba/lib/python2.7/site-packages/kraken/rpred.py:91: RuntimeWarning: invalid value encountered in true_divide
  temp = temp*1.0/np.amax(temp)
[2015-10-30 07:10:24,241: ERROR/MainProcess] Task nidaba.ocr.kraken[ae98745f-67e4-46bb-972f-301473f3d0c5] raised unexpected: IndexError('index 5000 is out of bounds for axis 0 with size 5000',)
Traceback (most recent call last):
  File "/cluster/home/mmunso01/envs/nidaba/lib/python2.7/site-packages/celery/app/trace.py", line 240, in trace_task
    R = retval = fun(*args, **kwargs)
  File "/cluster/home/mmunso01/envs/nidaba/lib/python2.7/site-packages/nidaba/tasks/helper.py", line 89, in __call__
    ret = super(NidabaTask, self).__call__(*args, **nkwargs)
  File "/cluster/home/mmunso01/envs/nidaba/lib/python2.7/site-packages/celery/app/trace.py", line 438, in __protected_call__
    return self.run(*args, **kwargs)
  File "/cluster/home/mmunso01/envs/nidaba/lib/python2.7/site-packages/nidaba/plugins/kraken.py", line 155, in ocr_kraken
    for rec in rpred.rpred(rnn, img, [(int(x[0]), int(x[1]), int(x[2]), int(x[3])) for x in lines]):
  File "/cluster/home/mmunso01/envs/nidaba/lib/python2.7/site-packages/kraken/rpred.py", line 134, in rpred
    pred = network.predictString(line)
  File "/cluster/home/mmunso01/envs/nidaba/lib/python2.7/site-packages/kraken/lib/lstm.py", line 281, in predictString
    cs = self.predictSequence(xs)
  File "/cluster/home/mmunso01/envs/nidaba/lib/python2.7/site-packages/kraken/lib/lstm.py", line 273, in predictSequence
    self.outputs = np.array(self.lstm.forward(xs))
  File "/cluster/home/mmunso01/envs/nidaba/lib/python2.7/site-packages/kraken/lib/lstm.py", line 229, in forward
    xs = net.forward(xs)
  File "/cluster/home/mmunso01/envs/nidaba/lib/python2.7/site-packages/kraken/lib/lstm.py", line 244, in forward
    outputs = [net.forward(xs) for net in self.nets]
  File "/cluster/home/mmunso01/envs/nidaba/lib/python2.7/site-packages/kraken/lib/lstm.py", line 196, in forward
    self.source[t,0] = 1
IndexError: index 5000 is out of bounds for axis 0 with size 5000
[2015-10-30 07:10:36,901: WARNING/Worker-16] /cluster/home/mmunso01/envs/nidaba/lib/python2.7/site-packages/kraken/rpred.py:91: RuntimeWarning: invalid value encountered in true_divide
  temp = temp*1.0/np.amax(temp)
[2015-10-30 07:11:03,342: ERROR/Worker-35] nidaba.ocr.kraken[3013593f-100a-484b-8760-2fdb27a65dd7]: index 5000 is out of bounds for axis 0 with size 5000
[2015-10-30 07:11:08,956: ERROR/MainProcess] Task nidaba.ocr.kraken[3013593f-100a-484b-8760-2fdb27a65dd7] raised unexpected: IndexError('index 5000 is out of bounds for axis 0 with size 5000',)
Traceback (most recent call last):
  File "/cluster/home/mmunso01/envs/nidaba/lib/python2.7/site-packages/celery/app/trace.py", line 240, in trace_task
    R = retval = fun(*args, **kwargs)
  File "/cluster/home/mmunso01/envs/nidaba/lib/python2.7/site-packages/nidaba/tasks/helper.py", line 89, in __call__
    ret = super(NidabaTask, self).__call__(*args, **nkwargs)
  File "/cluster/home/mmunso01/envs/nidaba/lib/python2.7/site-packages/celery/app/trace.py", line 438, in __protected_call__
    return self.run(*args, **kwargs)
  File "/cluster/home/mmunso01/envs/nidaba/lib/python2.7/site-packages/nidaba/plugins/kraken.py", line 155, in ocr_kraken
    for rec in rpred.rpred(rnn, img, [(int(x[0]), int(x[1]), int(x[2]), int(x[3])) for x in lines]):
  File "/cluster/home/mmunso01/envs/nidaba/lib/python2.7/site-packages/kraken/rpred.py", line 134, in rpred
    pred = network.predictString(line)
  File "/cluster/home/mmunso01/envs/nidaba/lib/python2.7/site-packages/kraken/lib/lstm.py", line 281, in predictString
    cs = self.predictSequence(xs)
  File "/cluster/home/mmunso01/envs/nidaba/lib/python2.7/site-packages/kraken/lib/lstm.py", line 273, in predictSequence
    self.outputs = np.array(self.lstm.forward(xs))
  File "/cluster/home/mmunso01/envs/nidaba/lib/python2.7/site-packages/kraken/lib/lstm.py", line 229, in forward
    xs = net.forward(xs)
  File "/cluster/home/mmunso01/envs/nidaba/lib/python2.7/site-packages/kraken/lib/lstm.py", line 244, in forward
    outputs = [net.forward(xs) for net in self.nets]
  File "/cluster/home/mmunso01/envs/nidaba/lib/python2.7/site-packages/kraken/lib/lstm.py", line 196, in forward
    self.source[t,0] = 1
IndexError: index 5000 is out of bounds for axis 0 with size 5000
[2015-10-30 07:11:14,027: WARNING/Worker-2] /cluster/home/mmunso01/envs/nidaba/lib/python2.7/site-packages/kraken/rpred.py:91: RuntimeWarning: invalid value encountered in true_divide
  temp = temp*1.0/np.amax(temp)
[2015-10-30 07:11:42,884: WARNING/Worker-3] /cluster/home/mmunso01/envs/nidaba/lib/python2.7/site-packages/kraken/rpred.py:91: RuntimeWarning: invalid value encountered in true_divide
  temp = temp*1.0/np.amax(temp)
[2015-10-30 07:11:42,964: WARNING/Worker-20] /cluster/home/mmunso01/envs/nidaba/lib/python2.7/site-packages/kraken/lib/lstm.py:48: RuntimeWarning: invalid value encountered in true_divide
  line = line * 1.0/np.amax(line)
[2015-10-30 07:11:43,005: ERROR/Worker-20] nidaba.ocr.kraken[0430fcc2-5c8b-4166-9fe6-12afeaa69919]: 
[2015-10-30 07:11:53,382: ERROR/Worker-12] nidaba.ocr.kraken[d896931f-dfc1-4fcf-adc9-96a1ab3f86f6]: float division by zero
[2015-10-30 07:11:58,944: WARNING/Worker-19] /cluster/home/mmunso01/envs/nidaba/lib/python2.7/site-packages/kraken/rpred.py:91: RuntimeWarning: invalid value encountered in true_divide
  temp = temp*1.0/np.amax(temp)
[2015-10-30 07:12:03,501: ERROR/MainProcess] Task nidaba.ocr.kraken[d896931f-dfc1-4fcf-adc9-96a1ab3f86f6] raised unexpected: ZeroDivisionError('float division by zero',)
Traceback (most recent call last):
  File "/cluster/home/mmunso01/envs/nidaba/lib/python2.7/site-packages/celery/app/trace.py", line 240, in trace_task
    R = retval = fun(*args, **kwargs)
  File "/cluster/home/mmunso01/envs/nidaba/lib/python2.7/site-packages/nidaba/tasks/helper.py", line 89, in __call__
    ret = super(NidabaTask, self).__call__(*args, **nkwargs)
  File "/cluster/home/mmunso01/envs/nidaba/lib/python2.7/site-packages/celery/app/trace.py", line 438, in __protected_call__
    return self.run(*args, **kwargs)
  File "/cluster/home/mmunso01/envs/nidaba/lib/python2.7/site-packages/nidaba/plugins/kraken.py", line 155, in ocr_kraken
    for rec in rpred.rpred(rnn, img, [(int(x[0]), int(x[1]), int(x[2]), int(x[3])) for x in lines]):
  File "/cluster/home/mmunso01/envs/nidaba/lib/python2.7/site-packages/kraken/rpred.py", line 127, in rpred
    box = dewarp(lnorm, box)
  File "/cluster/home/mmunso01/envs/nidaba/lib/python2.7/site-packages/kraken/rpred.py", line 93, in dewarp
    line = normalizer.normalize(line, cval=np.amax(line))
  File "/cluster/home/mmunso01/envs/nidaba/lib/python2.7/site-packages/kraken/lib/lineest.py", line 60, in normalize
    dtype=dtype, cval=cval)
  File "/cluster/home/mmunso01/envs/nidaba/lib/python2.7/site-packages/kraken/lib/lineest.py", line 13, in scale_to_h
    scale = target_height*1.0/h
ZeroDivisionError: float division by zero
[2015-10-30 07:12:27,005: WARNING/Worker-10] /cluster/home/mmunso01/envs/nidaba/lib/python2.7/site-packages/kraken/rpred.py:91: RuntimeWarning: invalid value encountered in true_divide
  temp = temp*1.0/np.amax(temp)
[2015-10-30 07:12:28,255: ERROR/Worker-10] nidaba.ocr.kraken[06d237ef-4ea8-4b1b-9c68-f229d50f7c1c]: float division by zero
[2015-10-30 07:12:37,466: ERROR/MainProcess] Task nidaba.ocr.kraken[06d237ef-4ea8-4b1b-9c68-f229d50f7c1c] raised unexpected: ZeroDivisionError('float division by zero',)
Traceback (most recent call last):
  File "/cluster/home/mmunso01/envs/nidaba/lib/python2.7/site-packages/celery/app/trace.py", line 240, in trace_task
    R = retval = fun(*args, **kwargs)
  File "/cluster/home/mmunso01/envs/nidaba/lib/python2.7/site-packages/nidaba/tasks/helper.py", line 89, in __call__
    ret = super(NidabaTask, self).__call__(*args, **nkwargs)
  File "/cluster/home/mmunso01/envs/nidaba/lib/python2.7/site-packages/celery/app/trace.py", line 438, in __protected_call__
    return self.run(*args, **kwargs)
  File "/cluster/home/mmunso01/envs/nidaba/lib/python2.7/site-packages/nidaba/plugins/kraken.py", line 155, in ocr_kraken
    for rec in rpred.rpred(rnn, img, [(int(x[0]), int(x[1]), int(x[2]), int(x[3])) for x in lines]):
  File "/cluster/home/mmunso01/envs/nidaba/lib/python2.7/site-packages/kraken/rpred.py", line 127, in rpred
    box = dewarp(lnorm, box)
  File "/cluster/home/mmunso01/envs/nidaba/lib/python2.7/site-packages/kraken/rpred.py", line 93, in dewarp
    line = normalizer.normalize(line, cval=np.amax(line))
  File "/cluster/home/mmunso01/envs/nidaba/lib/python2.7/site-packages/kraken/lib/lineest.py", line 60, in normalize
    dtype=dtype, cval=cval)
  File "/cluster/home/mmunso01/envs/nidaba/lib/python2.7/site-packages/kraken/lib/lineest.py", line 13, in scale_to_h
    scale = target_height*1.0/h
ZeroDivisionError: float division by zero
[2015-10-30 07:12:53,957: ERROR/MainProcess] Task nidaba.ocr.kraken[0430fcc2-5c8b-4166-9fe6-12afeaa69919] raised unexpected: AssertionError()
Traceback (most recent call last):
  File "/cluster/home/mmunso01/envs/nidaba/lib/python2.7/site-packages/celery/app/trace.py", line 240, in trace_task
    R = retval = fun(*args, **kwargs)
  File "/cluster/home/mmunso01/envs/nidaba/lib/python2.7/site-packages/nidaba/tasks/helper.py", line 89, in __call__
    ret = super(NidabaTask, self).__call__(*args, **nkwargs)
  File "/cluster/home/mmunso01/envs/nidaba/lib/python2.7/site-packages/celery/app/trace.py", line 438, in __protected_call__
    return self.run(*args, **kwargs)
  File "/cluster/home/mmunso01/envs/nidaba/lib/python2.7/site-packages/nidaba/plugins/kraken.py", line 155, in ocr_kraken
    for rec in rpred.rpred(rnn, img, [(int(x[0]), int(x[1]), int(x[2]), int(x[3])) for x in lines]):
  File "/cluster/home/mmunso01/envs/nidaba/lib/python2.7/site-packages/kraken/rpred.py", line 134, in rpred
    pred = network.predictString(line)
  File "/cluster/home/mmunso01/envs/nidaba/lib/python2.7/site-packages/kraken/lib/lstm.py", line 281, in predictString
    cs = self.predictSequence(xs)
  File "/cluster/home/mmunso01/envs/nidaba/lib/python2.7/site-packages/kraken/lib/lstm.py", line 273, in predictSequence
    self.outputs = np.array(self.lstm.forward(xs))
  File "/cluster/home/mmunso01/envs/nidaba/lib/python2.7/site-packages/kraken/lib/lstm.py", line 229, in forward
    xs = net.forward(xs)
  File "/cluster/home/mmunso01/envs/nidaba/lib/python2.7/site-packages/kraken/lib/lstm.py", line 244, in forward
    outputs = [net.forward(xs) for net in self.nets]
  File "/cluster/home/mmunso01/envs/nidaba/lib/python2.7/site-packages/kraken/lib/lstm.py", line 216, in forward
    assert not np.isnan(self.output[:n]).any()
AssertionError
[2015-10-30 07:13:04,574: WARNING/Worker-37] /cluster/home/mmunso01/envs/nidaba/lib/python2.7/site-packages/kraken/rpred.py:91: RuntimeWarning: invalid value encountered in true_divide
  temp = temp*1.0/np.amax(temp)
[2015-10-30 07:13:04,585: WARNING/Worker-37] /cluster/home/mmunso01/envs/nidaba/lib/python2.7/site-packages/kraken/lib/lstm.py:48: RuntimeWarning: invalid value encountered in true_divide
  line = line * 1.0/np.amax(line)
[2015-10-30 07:13:04,626: ERROR/Worker-37] nidaba.ocr.kraken[86c2a105-a5c3-42cb-a3b7-9d815e977259]: 
[2015-10-30 07:13:26,014: ERROR/MainProcess] Task nidaba.ocr.kraken[86c2a105-a5c3-42cb-a3b7-9d815e977259] raised unexpected: AssertionError()
Traceback (most recent call last):
  File "/cluster/home/mmunso01/envs/nidaba/lib/python2.7/site-packages/celery/app/trace.py", line 240, in trace_task
    R = retval = fun(*args, **kwargs)
  File "/cluster/home/mmunso01/envs/nidaba/lib/python2.7/site-packages/nidaba/tasks/helper.py", line 89, in __call__
    ret = super(NidabaTask, self).__call__(*args, **nkwargs)
  File "/cluster/home/mmunso01/envs/nidaba/lib/python2.7/site-packages/celery/app/trace.py", line 438, in __protected_call__
    return self.run(*args, **kwargs)
  File "/cluster/home/mmunso01/envs/nidaba/lib/python2.7/site-packages/nidaba/plugins/kraken.py", line 155, in ocr_kraken
    for rec in rpred.rpred(rnn, img, [(int(x[0]), int(x[1]), int(x[2]), int(x[3])) for x in lines]):
  File "/cluster/home/mmunso01/envs/nidaba/lib/python2.7/site-packages/kraken/rpred.py", line 134, in rpred
    pred = network.predictString(line)
  File "/cluster/home/mmunso01/envs/nidaba/lib/python2.7/site-packages/kraken/lib/lstm.py", line 281, in predictString
    cs = self.predictSequence(xs)
  File "/cluster/home/mmunso01/envs/nidaba/lib/python2.7/site-packages/kraken/lib/lstm.py", line 273, in predictSequence
    self.outputs = np.array(self.lstm.forward(xs))
  File "/cluster/home/mmunso01/envs/nidaba/lib/python2.7/site-packages/kraken/lib/lstm.py", line 229, in forward
    xs = net.forward(xs)
  File "/cluster/home/mmunso01/envs/nidaba/lib/python2.7/site-packages/kraken/lib/lstm.py", line 244, in forward
    outputs = [net.forward(xs) for net in self.nets]
  File "/cluster/home/mmunso01/envs/nidaba/lib/python2.7/site-packages/kraken/lib/lstm.py", line 216, in forward
    assert not np.isnan(self.output[:n]).any()
AssertionError
[2015-10-30 07:13:41,742: WARNING/Worker-23] /cluster/home/mmunso01/envs/nidaba/lib/python2.7/site-packages/kraken/rpred.py:91: RuntimeWarning: invalid value encountered in true_divide
  temp = temp*1.0/np.amax(temp)
[2015-10-30 07:13:56,534: WARNING/Worker-1] /cluster/home/mmunso01/envs/nidaba/lib/python2.7/site-packages/kraken/rpred.py:91: RuntimeWarning: invalid value encountered in true_divide
  temp = temp*1.0/np.amax(temp)
[2015-10-30 07:13:56,544: WARNING/Worker-1] /cluster/home/mmunso01/envs/nidaba/lib/python2.7/site-packages/kraken/lib/lstm.py:48: RuntimeWarning: invalid value encountered in true_divide
  line = line * 1.0/np.amax(line)
[2015-10-30 07:13:56,561: ERROR/Worker-1] nidaba.ocr.kraken[1ad42feb-7339-47cc-a8c3-2aeca82ebc21]: 
[2015-10-30 07:14:07,196: ERROR/MainProcess] Task nidaba.ocr.kraken[1ad42feb-7339-47cc-a8c3-2aeca82ebc21] raised unexpected: AssertionError()
Traceback (most recent call last):
  File "/cluster/home/mmunso01/envs/nidaba/lib/python2.7/site-packages/celery/app/trace.py", line 240, in trace_task
    R = retval = fun(*args, **kwargs)
  File "/cluster/home/mmunso01/envs/nidaba/lib/python2.7/site-packages/nidaba/tasks/helper.py", line 89, in __call__
    ret = super(NidabaTask, self).__call__(*args, **nkwargs)
  File "/cluster/home/mmunso01/envs/nidaba/lib/python2.7/site-packages/celery/app/trace.py", line 438, in __protected_call__
    return self.run(*args, **kwargs)
  File "/cluster/home/mmunso01/envs/nidaba/lib/python2.7/site-packages/nidaba/plugins/kraken.py", line 155, in ocr_kraken
    for rec in rpred.rpred(rnn, img, [(int(x[0]), int(x[1]), int(x[2]), int(x[3])) for x in lines]):
  File "/cluster/home/mmunso01/envs/nidaba/lib/python2.7/site-packages/kraken/rpred.py", line 134, in rpred
    pred = network.predictString(line)
  File "/cluster/home/mmunso01/envs/nidaba/lib/python2.7/site-packages/kraken/lib/lstm.py", line 281, in predictString
    cs = self.predictSequence(xs)
  File "/cluster/home/mmunso01/envs/nidaba/lib/python2.7/site-packages/kraken/lib/lstm.py", line 273, in predictSequence
    self.outputs = np.array(self.lstm.forward(xs))
  File "/cluster/home/mmunso01/envs/nidaba/lib/python2.7/site-packages/kraken/lib/lstm.py", line 229, in forward
    xs = net.forward(xs)
  File "/cluster/home/mmunso01/envs/nidaba/lib/python2.7/site-packages/kraken/lib/lstm.py", line 244, in forward
    outputs = [net.forward(xs) for net in self.nets]
  File "/cluster/home/mmunso01/envs/nidaba/lib/python2.7/site-packages/kraken/lib/lstm.py", line 216, in forward
    assert not np.isnan(self.output[:n]).any()
AssertionError
[2015-10-30 07:14:12,506: WARNING/Worker-16] /cluster/home/mmunso01/envs/nidaba/lib/python2.7/site-packages/kraken/lib/lstm.py:48: RuntimeWarning: invalid value encountered in true_divide
  line = line * 1.0/np.amax(line)
[2015-10-30 07:14:12,540: ERROR/Worker-16] nidaba.ocr.kraken[e9280249-cea1-449c-b782-ae520812d252]: 
[2015-10-30 07:14:30,992: WARNING/Worker-4] /cluster/home/mmunso01/envs/nidaba/lib/python2.7/site-packages/kraken/rpred.py:91: RuntimeWarning: invalid value encountered in true_divide
  temp = temp*1.0/np.amax(temp)
[2015-10-30 07:14:30,995: WARNING/Worker-4] /cluster/home/mmunso01/envs/nidaba/lib/python2.7/site-packages/kraken/lib/lstm.py:48: RuntimeWarning: invalid value encountered in true_divide
  line = line * 1.0/np.amax(line)
[2015-10-30 07:14:31,023: ERROR/Worker-4] nidaba.ocr.kraken[43925eb5-f5f0-48af-b6c3-79fe2a7376de]: 
[2015-10-30 07:14:32,256: ERROR/Worker-39] nidaba.ocr.kraken[4e10b5cb-7e37-49a3-9d61-5501a24a3da0]: float division by zero
[2015-10-30 07:14:33,633: ERROR/MainProcess] Task nidaba.ocr.kraken[4e10b5cb-7e37-49a3-9d61-5501a24a3da0] raised unexpected: ZeroDivisionError('float division by zero',)
Traceback (most recent call last):
  File "/cluster/home/mmunso01/envs/nidaba/lib/python2.7/site-packages/celery/app/trace.py", line 240, in trace_task
    R = retval = fun(*args, **kwargs)
  File "/cluster/home/mmunso01/envs/nidaba/lib/python2.7/site-packages/nidaba/tasks/helper.py", line 89, in __call__
    ret = super(NidabaTask, self).__call__(*args, **nkwargs)
  File "/cluster/home/mmunso01/envs/nidaba/lib/python2.7/site-packages/celery/app/trace.py", line 438, in __protected_call__
    return self.run(*args, **kwargs)
  File "/cluster/home/mmunso01/envs/nidaba/lib/python2.7/site-packages/nidaba/plugins/kraken.py", line 155, in ocr_kraken
    for rec in rpred.rpred(rnn, img, [(int(x[0]), int(x[1]), int(x[2]), int(x[3])) for x in lines]):
  File "/cluster/home/mmunso01/envs/nidaba/lib/python2.7/site-packages/kraken/rpred.py", line 127, in rpred
    box = dewarp(lnorm, box)
  File "/cluster/home/mmunso01/envs/nidaba/lib/python2.7/site-packages/kraken/rpred.py", line 93, in dewarp
    line = normalizer.normalize(line, cval=np.amax(line))
  File "/cluster/home/mmunso01/envs/nidaba/lib/python2.7/site-packages/kraken/lib/lineest.py", line 60, in normalize
    dtype=dtype, cval=cval)
  File "/cluster/home/mmunso01/envs/nidaba/lib/python2.7/site-packages/kraken/lib/lineest.py", line 13, in scale_to_h
    scale = target_height*1.0/h
ZeroDivisionError: float division by zero
[2015-10-30 07:14:36,091: ERROR/MainProcess] Task nidaba.ocr.kraken[e9280249-cea1-449c-b782-ae520812d252] raised unexpected: AssertionError()
Traceback (most recent call last):
  File "/cluster/home/mmunso01/envs/nidaba/lib/python2.7/site-packages/celery/app/trace.py", line 240, in trace_task
    R = retval = fun(*args, **kwargs)
  File "/cluster/home/mmunso01/envs/nidaba/lib/python2.7/site-packages/nidaba/tasks/helper.py", line 89, in __call__
    ret = super(NidabaTask, self).__call__(*args, **nkwargs)
  File "/cluster/home/mmunso01/envs/nidaba/lib/python2.7/site-packages/celery/app/trace.py", line 438, in __protected_call__
    return self.run(*args, **kwargs)
  File "/cluster/home/mmunso01/envs/nidaba/lib/python2.7/site-packages/nidaba/plugins/kraken.py", line 155, in ocr_kraken
    for rec in rpred.rpred(rnn, img, [(int(x[0]), int(x[1]), int(x[2]), int(x[3])) for x in lines]):
  File "/cluster/home/mmunso01/envs/nidaba/lib/python2.7/site-packages/kraken/rpred.py", line 134, in rpred
    pred = network.predictString(line)
  File "/cluster/home/mmunso01/envs/nidaba/lib/python2.7/site-packages/kraken/lib/lstm.py", line 281, in predictString
    cs = self.predictSequence(xs)
  File "/cluster/home/mmunso01/envs/nidaba/lib/python2.7/site-packages/kraken/lib/lstm.py", line 273, in predictSequence
    self.outputs = np.array(self.lstm.forward(xs))
  File "/cluster/home/mmunso01/envs/nidaba/lib/python2.7/site-packages/kraken/lib/lstm.py", line 229, in forward
    xs = net.forward(xs)
  File "/cluster/home/mmunso01/envs/nidaba/lib/python2.7/site-packages/kraken/lib/lstm.py", line 244, in forward
    outputs = [net.forward(xs) for net in self.nets]
  File "/cluster/home/mmunso01/envs/nidaba/lib/python2.7/site-packages/kraken/lib/lstm.py", line 216, in forward
    assert not np.isnan(self.output[:n]).any()
AssertionError
[2015-10-30 07:14:38,338: ERROR/MainProcess] Task nidaba.ocr.kraken[43925eb5-f5f0-48af-b6c3-79fe2a7376de] raised unexpected: AssertionError()
Traceback (most recent call last):
  File "/cluster/home/mmunso01/envs/nidaba/lib/python2.7/site-packages/celery/app/trace.py", line 240, in trace_task
    R = retval = fun(*args, **kwargs)
  File "/cluster/home/mmunso01/envs/nidaba/lib/python2.7/site-packages/nidaba/tasks/helper.py", line 89, in __call__
    ret = super(NidabaTask, self).__call__(*args, **nkwargs)
  File "/cluster/home/mmunso01/envs/nidaba/lib/python2.7/site-packages/celery/app/trace.py", line 438, in __protected_call__
    return self.run(*args, **kwargs)
  File "/cluster/home/mmunso01/envs/nidaba/lib/python2.7/site-packages/nidaba/plugins/kraken.py", line 155, in ocr_kraken
    for rec in rpred.rpred(rnn, img, [(int(x[0]), int(x[1]), int(x[2]), int(x[3])) for x in lines]):
  File "/cluster/home/mmunso01/envs/nidaba/lib/python2.7/site-packages/kraken/rpred.py", line 134, in rpred
    pred = network.predictString(line)
  File "/cluster/home/mmunso01/envs/nidaba/lib/python2.7/site-packages/kraken/lib/lstm.py", line 281, in predictString
    cs = self.predictSequence(xs)
  File "/cluster/home/mmunso01/envs/nidaba/lib/python2.7/site-packages/kraken/lib/lstm.py", line 273, in predictSequence
    self.outputs = np.array(self.lstm.forward(xs))
  File "/cluster/home/mmunso01/envs/nidaba/lib/python2.7/site-packages/kraken/lib/lstm.py", line 229, in forward
    xs = net.forward(xs)
  File "/cluster/home/mmunso01/envs/nidaba/lib/python2.7/site-packages/kraken/lib/lstm.py", line 244, in forward
    outputs = [net.forward(xs) for net in self.nets]
  File "/cluster/home/mmunso01/envs/nidaba/lib/python2.7/site-packages/kraken/lib/lstm.py", line 216, in forward
    assert not np.isnan(self.output[:n]).any()
AssertionError
[2015-10-30 07:15:05,856: WARNING/Worker-11] /cluster/home/mmunso01/envs/nidaba/lib/python2.7/site-packages/kraken/rpred.py:91: RuntimeWarning: invalid value encountered in true_divide
  temp = temp*1.0/np.amax(temp)
[2015-10-30 07:15:05,866: WARNING/Worker-11] /cluster/home/mmunso01/envs/nidaba/lib/python2.7/site-packages/kraken/lib/lstm.py:48: RuntimeWarning: invalid value encountered in true_divide
  line = line * 1.0/np.amax(line)
[2015-10-30 07:15:05,903: ERROR/Worker-11] nidaba.ocr.kraken[d16e568d-7942-40b8-950a-a146a9c8ea03]: 
[2015-10-30 07:15:08,056: ERROR/MainProcess] Task nidaba.ocr.kraken[d16e568d-7942-40b8-950a-a146a9c8ea03] raised unexpected: AssertionError()
Traceback (most recent call last):
  File "/cluster/home/mmunso01/envs/nidaba/lib/python2.7/site-packages/celery/app/trace.py", line 240, in trace_task
    R = retval = fun(*args, **kwargs)
  File "/cluster/home/mmunso01/envs/nidaba/lib/python2.7/site-packages/nidaba/tasks/helper.py", line 89, in __call__
    ret = super(NidabaTask, self).__call__(*args, **nkwargs)
  File "/cluster/home/mmunso01/envs/nidaba/lib/python2.7/site-packages/celery/app/trace.py", line 438, in __protected_call__
    return self.run(*args, **kwargs)
  File "/cluster/home/mmunso01/envs/nidaba/lib/python2.7/site-packages/nidaba/plugins/kraken.py", line 155, in ocr_kraken
    for rec in rpred.rpred(rnn, img, [(int(x[0]), int(x[1]), int(x[2]), int(x[3])) for x in lines]):
  File "/cluster/home/mmunso01/envs/nidaba/lib/python2.7/site-packages/kraken/rpred.py", line 134, in rpred
    pred = network.predictString(line)
  File "/cluster/home/mmunso01/envs/nidaba/lib/python2.7/site-packages/kraken/lib/lstm.py", line 281, in predictString
    cs = self.predictSequence(xs)
  File "/cluster/home/mmunso01/envs/nidaba/lib/python2.7/site-packages/kraken/lib/lstm.py", line 273, in predictSequence
    self.outputs = np.array(self.lstm.forward(xs))
  File "/cluster/home/mmunso01/envs/nidaba/lib/python2.7/site-packages/kraken/lib/lstm.py", line 229, in forward
    xs = net.forward(xs)
  File "/cluster/home/mmunso01/envs/nidaba/lib/python2.7/site-packages/kraken/lib/lstm.py", line 244, in forward
    outputs = [net.forward(xs) for net in self.nets]
  File "/cluster/home/mmunso01/envs/nidaba/lib/python2.7/site-packages/kraken/lib/lstm.py", line 216, in forward
    assert not np.isnan(self.output[:n]).any()
AssertionError
[2015-10-30 07:15:51,764: WARNING/Worker-28] /cluster/home/mmunso01/envs/nidaba/lib/python2.7/site-packages/kraken/rpred.py:91: RuntimeWarning: invalid value encountered in true_divide
  temp = temp*1.0/np.amax(temp)
[2015-10-30 07:16:03,932: ERROR/Worker-15] nidaba.ocr.kraken[8236f539-9e0f-4ca2-98c3-19316054a9eb]: float division by zero
[2015-10-30 07:16:05,425: WARNING/Worker-19] /cluster/home/mmunso01/envs/nidaba/lib/python2.7/site-packages/kraken/lib/lstm.py:48: RuntimeWarning: invalid value encountered in true_divide
  line = line * 1.0/np.amax(line)
[2015-10-30 07:16:05,462: ERROR/Worker-19] nidaba.ocr.kraken[11c70ded-d8f7-4c41-9070-12b18dff14bf]: 
[2015-10-30 07:16:08,220: ERROR/Worker-6] nidaba.ocr.kraken[29da8c1d-74ca-47ca-85b3-e144aad5dcd7]: float division by zero
[2015-10-30 07:16:09,723: ERROR/MainProcess] Task nidaba.ocr.kraken[29da8c1d-74ca-47ca-85b3-e144aad5dcd7] raised unexpected: ZeroDivisionError('float division by zero',)
Traceback (most recent call last):
  File "/cluster/home/mmunso01/envs/nidaba/lib/python2.7/site-packages/celery/app/trace.py", line 240, in trace_task
    R = retval = fun(*args, **kwargs)
  File "/cluster/home/mmunso01/envs/nidaba/lib/python2.7/site-packages/nidaba/tasks/helper.py", line 89, in __call__
    ret = super(NidabaTask, self).__call__(*args, **nkwargs)
  File "/cluster/home/mmunso01/envs/nidaba/lib/python2.7/site-packages/celery/app/trace.py", line 438, in __protected_call__
    return self.run(*args, **kwargs)
  File "/cluster/home/mmunso01/envs/nidaba/lib/python2.7/site-packages/nidaba/plugins/kraken.py", line 155, in ocr_kraken
    for rec in rpred.rpred(rnn, img, [(int(x[0]), int(x[1]), int(x[2]), int(x[3])) for x in lines]):
  File "/cluster/home/mmunso01/envs/nidaba/lib/python2.7/site-packages/kraken/rpred.py", line 127, in rpred
    box = dewarp(lnorm, box)
  File "/cluster/home/mmunso01/envs/nidaba/lib/python2.7/site-packages/kraken/rpred.py", line 93, in dewarp
    line = normalizer.normalize(line, cval=np.amax(line))
  File "/cluster/home/mmunso01/envs/nidaba/lib/python2.7/site-packages/kraken/lib/lineest.py", line 60, in normalize
    dtype=dtype, cval=cval)
  File "/cluster/home/mmunso01/envs/nidaba/lib/python2.7/site-packages/kraken/lib/lineest.py", line 13, in scale_to_h
    scale = target_height*1.0/h
ZeroDivisionError: float division by zero
[2015-10-30 07:16:14,796: WARNING/Worker-29] /cluster/home/mmunso01/envs/nidaba/lib/python2.7/site-packages/kraken/rpred.py:91: RuntimeWarning: invalid value encountered in true_divide
  temp = temp*1.0/np.amax(temp)
[2015-10-30 07:16:19,770: ERROR/MainProcess] Task nidaba.ocr.kraken[11c70ded-d8f7-4c41-9070-12b18dff14bf] raised unexpected: AssertionError()
Traceback (most recent call last):
  File "/cluster/home/mmunso01/envs/nidaba/lib/python2.7/site-packages/celery/app/trace.py", line 240, in trace_task
    R = retval = fun(*args, **kwargs)
  File "/cluster/home/mmunso01/envs/nidaba/lib/python2.7/site-packages/nidaba/tasks/helper.py", line 89, in __call__
    ret = super(NidabaTask, self).__call__(*args, **nkwargs)
  File "/cluster/home/mmunso01/envs/nidaba/lib/python2.7/site-packages/celery/app/trace.py", line 438, in __protected_call__
    return self.run(*args, **kwargs)
  File "/cluster/home/mmunso01/envs/nidaba/lib/python2.7/site-packages/nidaba/plugins/kraken.py", line 155, in ocr_kraken
    for rec in rpred.rpred(rnn, img, [(int(x[0]), int(x[1]), int(x[2]), int(x[3])) for x in lines]):
  File "/cluster/home/mmunso01/envs/nidaba/lib/python2.7/site-packages/kraken/rpred.py", line 134, in rpred
    pred = network.predictString(line)
  File "/cluster/home/mmunso01/envs/nidaba/lib/python2.7/site-packages/kraken/lib/lstm.py", line 281, in predictString
    cs = self.predictSequence(xs)
  File "/cluster/home/mmunso01/envs/nidaba/lib/python2.7/site-packages/kraken/lib/lstm.py", line 273, in predictSequence
    self.outputs = np.array(self.lstm.forward(xs))
  File "/cluster/home/mmunso01/envs/nidaba/lib/python2.7/site-packages/kraken/lib/lstm.py", line 229, in forward
    xs = net.forward(xs)
  File "/cluster/home/mmunso01/envs/nidaba/lib/python2.7/site-packages/kraken/lib/lstm.py", line 244, in forward
    outputs = [net.forward(xs) for net in self.nets]
  File "/cluster/home/mmunso01/envs/nidaba/lib/python2.7/site-packages/kraken/lib/lstm.py", line 216, in forward
    assert not np.isnan(self.output[:n]).any()
AssertionError
[2015-10-30 07:16:22,020: ERROR/Worker-21] nidaba.ocr.kraken[e2b1c3cc-429f-46a2-981d-936a83998605]: float division by zero
[2015-10-30 07:16:27,888: ERROR/MainProcess] Task nidaba.ocr.kraken[8236f539-9e0f-4ca2-98c3-19316054a9eb] raised unexpected: ZeroDivisionError('float division by zero',)
Traceback (most recent call last):
  File "/cluster/home/mmunso01/envs/nidaba/lib/python2.7/site-packages/celery/app/trace.py", line 240, in trace_task
    R = retval = fun(*args, **kwargs)
  File "/cluster/home/mmunso01/envs/nidaba/lib/python2.7/site-packages/nidaba/tasks/helper.py", line 89, in __call__
    ret = super(NidabaTask, self).__call__(*args, **nkwargs)
  File "/cluster/home/mmunso01/envs/nidaba/lib/python2.7/site-packages/celery/app/trace.py", line 438, in __protected_call__
    return self.run(*args, **kwargs)
  File "/cluster/home/mmunso01/envs/nidaba/lib/python2.7/site-packages/nidaba/plugins/kraken.py", line 155, in ocr_kraken
    for rec in rpred.rpred(rnn, img, [(int(x[0]), int(x[1]), int(x[2]), int(x[3])) for x in lines]):
  File "/cluster/home/mmunso01/envs/nidaba/lib/python2.7/site-packages/kraken/rpred.py", line 127, in rpred
    box = dewarp(lnorm, box)
  File "/cluster/home/mmunso01/envs/nidaba/lib/python2.7/site-packages/kraken/rpred.py", line 93, in dewarp
    line = normalizer.normalize(line, cval=np.amax(line))
  File "/cluster/home/mmunso01/envs/nidaba/lib/python2.7/site-packages/kraken/lib/lineest.py", line 60, in normalize
    dtype=dtype, cval=cval)
  File "/cluster/home/mmunso01/envs/nidaba/lib/python2.7/site-packages/kraken/lib/lineest.py", line 13, in scale_to_h
    scale = target_height*1.0/h
ZeroDivisionError: float division by zero
[2015-10-30 07:16:28,223: ERROR/MainProcess] Task nidaba.ocr.kraken[e2b1c3cc-429f-46a2-981d-936a83998605] raised unexpected: ZeroDivisionError('float division by zero',)
Traceback (most recent call last):
  File "/cluster/home/mmunso01/envs/nidaba/lib/python2.7/site-packages/celery/app/trace.py", line 240, in trace_task
    R = retval = fun(*args, **kwargs)
  File "/cluster/home/mmunso01/envs/nidaba/lib/python2.7/site-packages/nidaba/tasks/helper.py", line 89, in __call__
    ret = super(NidabaTask, self).__call__(*args, **nkwargs)
  File "/cluster/home/mmunso01/envs/nidaba/lib/python2.7/site-packages/celery/app/trace.py", line 438, in __protected_call__
    return self.run(*args, **kwargs)
  File "/cluster/home/mmunso01/envs/nidaba/lib/python2.7/site-packages/nidaba/plugins/kraken.py", line 155, in ocr_kraken
    for rec in rpred.rpred(rnn, img, [(int(x[0]), int(x[1]), int(x[2]), int(x[3])) for x in lines]):
  File "/cluster/home/mmunso01/envs/nidaba/lib/python2.7/site-packages/kraken/rpred.py", line 127, in rpred
    box = dewarp(lnorm, box)
  File "/cluster/home/mmunso01/envs/nidaba/lib/python2.7/site-packages/kraken/rpred.py", line 93, in dewarp
    line = normalizer.normalize(line, cval=np.amax(line))
  File "/cluster/home/mmunso01/envs/nidaba/lib/python2.7/site-packages/kraken/lib/lineest.py", line 60, in normalize
    dtype=dtype, cval=cval)
  File "/cluster/home/mmunso01/envs/nidaba/lib/python2.7/site-packages/kraken/lib/lineest.py", line 13, in scale_to_h
    scale = target_height*1.0/h
ZeroDivisionError: float division by zero
[2015-10-30 07:16:39,534: WARNING/Worker-9] /cluster/home/mmunso01/envs/nidaba/lib/python2.7/site-packages/kraken/rpred.py:91: RuntimeWarning: invalid value encountered in true_divide
  temp = temp*1.0/np.amax(temp)
[2015-10-30 07:17:13,642: ERROR/Worker-20] nidaba.ocr.kraken[c0b97049-8624-4895-93bd-97b10e8778f2]: 
[2015-10-30 07:17:45,351: ERROR/MainProcess] Task nidaba.ocr.kraken[c0b97049-8624-4895-93bd-97b10e8778f2] raised unexpected: AssertionError()
Traceback (most recent call last):
  File "/cluster/home/mmunso01/envs/nidaba/lib/python2.7/site-packages/celery/app/trace.py", line 240, in trace_task
    R = retval = fun(*args, **kwargs)
  File "/cluster/home/mmunso01/envs/nidaba/lib/python2.7/site-packages/nidaba/tasks/helper.py", line 89, in __call__
    ret = super(NidabaTask, self).__call__(*args, **nkwargs)
  File "/cluster/home/mmunso01/envs/nidaba/lib/python2.7/site-packages/celery/app/trace.py", line 438, in __protected_call__
    return self.run(*args, **kwargs)
  File "/cluster/home/mmunso01/envs/nidaba/lib/python2.7/site-packages/nidaba/plugins/kraken.py", line 155, in ocr_kraken
    for rec in rpred.rpred(rnn, img, [(int(x[0]), int(x[1]), int(x[2]), int(x[3])) for x in lines]):
  File "/cluster/home/mmunso01/envs/nidaba/lib/python2.7/site-packages/kraken/rpred.py", line 134, in rpred
    pred = network.predictString(line)
  File "/cluster/home/mmunso01/envs/nidaba/lib/python2.7/site-packages/kraken/lib/lstm.py", line 281, in predictString
    cs = self.predictSequence(xs)
  File "/cluster/home/mmunso01/envs/nidaba/lib/python2.7/site-packages/kraken/lib/lstm.py", line 273, in predictSequence
    self.outputs = np.array(self.lstm.forward(xs))
  File "/cluster/home/mmunso01/envs/nidaba/lib/python2.7/site-packages/kraken/lib/lstm.py", line 229, in forward
    xs = net.forward(xs)
  File "/cluster/home/mmunso01/envs/nidaba/lib/python2.7/site-packages/kraken/lib/lstm.py", line 244, in forward
    outputs = [net.forward(xs) for net in self.nets]
  File "/cluster/home/mmunso01/envs/nidaba/lib/python2.7/site-packages/kraken/lib/lstm.py", line 216, in forward
    assert not np.isnan(self.output[:n]).any()
AssertionError
[2015-10-30 07:18:05,573: WARNING/Worker-22] /cluster/home/mmunso01/envs/nidaba/lib/python2.7/site-packages/kraken/rpred.py:91: RuntimeWarning: invalid value encountered in true_divide
  temp = temp*1.0/np.amax(temp)
[2015-10-30 07:18:05,577: WARNING/Worker-22] /cluster/home/mmunso01/envs/nidaba/lib/python2.7/site-packages/kraken/lib/lstm.py:48: RuntimeWarning: invalid value encountered in true_divide
  line = line * 1.0/np.amax(line)
[2015-10-30 07:18:05,653: ERROR/Worker-22] nidaba.ocr.kraken[c494f316-6577-4c0c-a5ba-17b7d4a3606c]: 
[2015-10-30 07:18:06,647: ERROR/MainProcess] Task nidaba.ocr.kraken[c494f316-6577-4c0c-a5ba-17b7d4a3606c] raised unexpected: AssertionError()
Traceback (most recent call last):
  File "/cluster/home/mmunso01/envs/nidaba/lib/python2.7/site-packages/celery/app/trace.py", line 240, in trace_task
    R = retval = fun(*args, **kwargs)
  File "/cluster/home/mmunso01/envs/nidaba/lib/python2.7/site-packages/nidaba/tasks/helper.py", line 89, in __call__
    ret = super(NidabaTask, self).__call__(*args, **nkwargs)
  File "/cluster/home/mmunso01/envs/nidaba/lib/python2.7/site-packages/celery/app/trace.py", line 438, in __protected_call__
    return self.run(*args, **kwargs)
  File "/cluster/home/mmunso01/envs/nidaba/lib/python2.7/site-packages/nidaba/plugins/kraken.py", line 155, in ocr_kraken
    for rec in rpred.rpred(rnn, img, [(int(x[0]), int(x[1]), int(x[2]), int(x[3])) for x in lines]):
  File "/cluster/home/mmunso01/envs/nidaba/lib/python2.7/site-packages/kraken/rpred.py", line 134, in rpred
    pred = network.predictString(line)
  File "/cluster/home/mmunso01/envs/nidaba/lib/python2.7/site-packages/kraken/lib/lstm.py", line 281, in predictString
    cs = self.predictSequence(xs)
  File "/cluster/home/mmunso01/envs/nidaba/lib/python2.7/site-packages/kraken/lib/lstm.py", line 273, in predictSequence
    self.outputs = np.array(self.lstm.forward(xs))
  File "/cluster/home/mmunso01/envs/nidaba/lib/python2.7/site-packages/kraken/lib/lstm.py", line 229, in forward
    xs = net.forward(xs)
  File "/cluster/home/mmunso01/envs/nidaba/lib/python2.7/site-packages/kraken/lib/lstm.py", line 244, in forward
    outputs = [net.forward(xs) for net in self.nets]
  File "/cluster/home/mmunso01/envs/nidaba/lib/python2.7/site-packages/kraken/lib/lstm.py", line 216, in forward
    assert not np.isnan(self.output[:n]).any()
AssertionError
[2015-10-30 07:18:12,355: WARNING/Worker-2] /cluster/home/mmunso01/envs/nidaba/lib/python2.7/site-packages/kraken/lib/lstm.py:48: RuntimeWarning: invalid value encountered in true_divide
  line = line * 1.0/np.amax(line)
[2015-10-30 07:18:12,383: ERROR/Worker-2] nidaba.ocr.kraken[39542623-c8d6-4062-a3cf-306b3ca68c91]: 
[2015-10-30 07:18:17,856: ERROR/MainProcess] Task nidaba.ocr.kraken[39542623-c8d6-4062-a3cf-306b3ca68c91] raised unexpected: AssertionError()
Traceback (most recent call last):
  File "/cluster/home/mmunso01/envs/nidaba/lib/python2.7/site-packages/celery/app/trace.py", line 240, in trace_task
    R = retval = fun(*args, **kwargs)
  File "/cluster/home/mmunso01/envs/nidaba/lib/python2.7/site-packages/nidaba/tasks/helper.py", line 89, in __call__
    ret = super(NidabaTask, self).__call__(*args, **nkwargs)
  File "/cluster/home/mmunso01/envs/nidaba/lib/python2.7/site-packages/celery/app/trace.py", line 438, in __protected_call__
    return self.run(*args, **kwargs)
  File "/cluster/home/mmunso01/envs/nidaba/lib/python2.7/site-packages/nidaba/plugins/kraken.py", line 155, in ocr_kraken
    for rec in rpred.rpred(rnn, img, [(int(x[0]), int(x[1]), int(x[2]), int(x[3])) for x in lines]):
  File "/cluster/home/mmunso01/envs/nidaba/lib/python2.7/site-packages/kraken/rpred.py", line 134, in rpred
    pred = network.predictString(line)
  File "/cluster/home/mmunso01/envs/nidaba/lib/python2.7/site-packages/kraken/lib/lstm.py", line 281, in predictString
    cs = self.predictSequence(xs)
  File "/cluster/home/mmunso01/envs/nidaba/lib/python2.7/site-packages/kraken/lib/lstm.py", line 273, in predictSequence
    self.outputs = np.array(self.lstm.forward(xs))
  File "/cluster/home/mmunso01/envs/nidaba/lib/python2.7/site-packages/kraken/lib/lstm.py", line 229, in forward
    xs = net.forward(xs)
  File "/cluster/home/mmunso01/envs/nidaba/lib/python2.7/site-packages/kraken/lib/lstm.py", line 244, in forward
    outputs = [net.forward(xs) for net in self.nets]
  File "/cluster/home/mmunso01/envs/nidaba/lib/python2.7/site-packages/kraken/lib/lstm.py", line 216, in forward
    assert not np.isnan(self.output[:n]).any()
AssertionError
[2015-10-30 07:20:08,902: WARNING/Worker-21] /cluster/home/mmunso01/envs/nidaba/lib/python2.7/site-packages/kraken/rpred.py:91: RuntimeWarning: invalid value encountered in true_divide
  temp = temp*1.0/np.amax(temp)
[2015-10-30 07:21:02,905: WARNING/Worker-8] /cluster/home/mmunso01/envs/nidaba/lib/python2.7/site-packages/kraken/rpred.py:91: RuntimeWarning: invalid value encountered in true_divide
  temp = temp*1.0/np.amax(temp)
[2015-10-30 07:21:02,908: WARNING/Worker-8] /cluster/home/mmunso01/envs/nidaba/lib/python2.7/site-packages/kraken/lib/lstm.py:48: RuntimeWarning: invalid value encountered in true_divide
  line = line * 1.0/np.amax(line)
[2015-10-30 07:21:02,965: ERROR/Worker-8] nidaba.ocr.kraken[93402838-cfa5-4a18-8ea2-e24691e276d6]: 
[2015-10-30 07:21:07,514: ERROR/MainProcess] Task nidaba.ocr.kraken[93402838-cfa5-4a18-8ea2-e24691e276d6] raised unexpected: AssertionError()
Traceback (most recent call last):
  File "/cluster/home/mmunso01/envs/nidaba/lib/python2.7/site-packages/celery/app/trace.py", line 240, in trace_task
    R = retval = fun(*args, **kwargs)
  File "/cluster/home/mmunso01/envs/nidaba/lib/python2.7/site-packages/nidaba/tasks/helper.py", line 89, in __call__
    ret = super(NidabaTask, self).__call__(*args, **nkwargs)
  File "/cluster/home/mmunso01/envs/nidaba/lib/python2.7/site-packages/celery/app/trace.py", line 438, in __protected_call__
    return self.run(*args, **kwargs)
  File "/cluster/home/mmunso01/envs/nidaba/lib/python2.7/site-packages/nidaba/plugins/kraken.py", line 155, in ocr_kraken
    for rec in rpred.rpred(rnn, img, [(int(x[0]), int(x[1]), int(x[2]), int(x[3])) for x in lines]):
  File "/cluster/home/mmunso01/envs/nidaba/lib/python2.7/site-packages/kraken/rpred.py", line 134, in rpred
    pred = network.predictString(line)
  File "/cluster/home/mmunso01/envs/nidaba/lib/python2.7/site-packages/kraken/lib/lstm.py", line 281, in predictString
    cs = self.predictSequence(xs)
  File "/cluster/home/mmunso01/envs/nidaba/lib/python2.7/site-packages/kraken/lib/lstm.py", line 273, in predictSequence
    self.outputs = np.array(self.lstm.forward(xs))
  File "/cluster/home/mmunso01/envs/nidaba/lib/python2.7/site-packages/kraken/lib/lstm.py", line 229, in forward
    xs = net.forward(xs)
  File "/cluster/home/mmunso01/envs/nidaba/lib/python2.7/site-packages/kraken/lib/lstm.py", line 244, in forward
    outputs = [net.forward(xs) for net in self.nets]
  File "/cluster/home/mmunso01/envs/nidaba/lib/python2.7/site-packages/kraken/lib/lstm.py", line 216, in forward
    assert not np.isnan(self.output[:n]).any()
AssertionError
[2015-10-30 07:22:21,198: ERROR/Worker-11] nidaba.ocr.kraken[b024574d-64d3-47bb-b843-6b09a91f6626]: float division by zero
[2015-10-30 07:22:46,835: ERROR/Worker-17] nidaba.ocr.kraken[06f3d328-b288-4bd5-b5a8-0cb2c89c5bdb]: float division by zero
[2015-10-30 07:22:47,597: ERROR/MainProcess] Task nidaba.ocr.kraken[06f3d328-b288-4bd5-b5a8-0cb2c89c5bdb] raised unexpected: ZeroDivisionError('float division by zero',)
Traceback (most recent call last):
  File "/cluster/home/mmunso01/envs/nidaba/lib/python2.7/site-packages/celery/app/trace.py", line 240, in trace_task
    R = retval = fun(*args, **kwargs)
  File "/cluster/home/mmunso01/envs/nidaba/lib/python2.7/site-packages/nidaba/tasks/helper.py", line 89, in __call__
    ret = super(NidabaTask, self).__call__(*args, **nkwargs)
  File "/cluster/home/mmunso01/envs/nidaba/lib/python2.7/site-packages/celery/app/trace.py", line 438, in __protected_call__
    return self.run(*args, **kwargs)
  File "/cluster/home/mmunso01/envs/nidaba/lib/python2.7/site-packages/nidaba/plugins/kraken.py", line 155, in ocr_kraken
    for rec in rpred.rpred(rnn, img, [(int(x[0]), int(x[1]), int(x[2]), int(x[3])) for x in lines]):
  File "/cluster/home/mmunso01/envs/nidaba/lib/python2.7/site-packages/kraken/rpred.py", line 127, in rpred
    box = dewarp(lnorm, box)
  File "/cluster/home/mmunso01/envs/nidaba/lib/python2.7/site-packages/kraken/rpred.py", line 93, in dewarp
    line = normalizer.normalize(line, cval=np.amax(line))
  File "/cluster/home/mmunso01/envs/nidaba/lib/python2.7/site-packages/kraken/lib/lineest.py", line 60, in normalize
    dtype=dtype, cval=cval)
  File "/cluster/home/mmunso01/envs/nidaba/lib/python2.7/site-packages/kraken/lib/lineest.py", line 13, in scale_to_h
    scale = target_height*1.0/h
ZeroDivisionError: float division by zero
[2015-10-30 07:22:58,631: ERROR/MainProcess] Task nidaba.ocr.kraken[b024574d-64d3-47bb-b843-6b09a91f6626] raised unexpected: ZeroDivisionError('float division by zero',)
Traceback (most recent call last):
  File "/cluster/home/mmunso01/envs/nidaba/lib/python2.7/site-packages/celery/app/trace.py", line 240, in trace_task
    R = retval = fun(*args, **kwargs)
  File "/cluster/home/mmunso01/envs/nidaba/lib/python2.7/site-packages/nidaba/tasks/helper.py", line 89, in __call__
    ret = super(NidabaTask, self).__call__(*args, **nkwargs)
  File "/cluster/home/mmunso01/envs/nidaba/lib/python2.7/site-packages/celery/app/trace.py", line 438, in __protected_call__
    return self.run(*args, **kwargs)
  File "/cluster/home/mmunso01/envs/nidaba/lib/python2.7/site-packages/nidaba/plugins/kraken.py", line 155, in ocr_kraken
    for rec in rpred.rpred(rnn, img, [(int(x[0]), int(x[1]), int(x[2]), int(x[3])) for x in lines]):
  File "/cluster/home/mmunso01/envs/nidaba/lib/python2.7/site-packages/kraken/rpred.py", line 127, in rpred
    box = dewarp(lnorm, box)
  File "/cluster/home/mmunso01/envs/nidaba/lib/python2.7/site-packages/kraken/rpred.py", line 93, in dewarp
    line = normalizer.normalize(line, cval=np.amax(line))
  File "/cluster/home/mmunso01/envs/nidaba/lib/python2.7/site-packages/kraken/lib/lineest.py", line 60, in normalize
    dtype=dtype, cval=cval)
  File "/cluster/home/mmunso01/envs/nidaba/lib/python2.7/site-packages/kraken/lib/lineest.py", line 13, in scale_to_h
    scale = target_height*1.0/h
ZeroDivisionError: float division by zero
[2015-10-30 07:23:07,488: ERROR/Worker-37] nidaba.ocr.kraken[aef67e37-ad65-4edf-9609-8191b292d8e4]: 
[2015-10-30 07:23:07,884: WARNING/Worker-24] /cluster/home/mmunso01/envs/nidaba/lib/python2.7/site-packages/kraken/rpred.py:91: RuntimeWarning: invalid value encountered in true_divide
  temp = temp*1.0/np.amax(temp)
[2015-10-30 07:23:07,895: WARNING/Worker-24] /cluster/home/mmunso01/envs/nidaba/lib/python2.7/site-packages/kraken/lib/lstm.py:48: RuntimeWarning: invalid value encountered in true_divide
  line = line * 1.0/np.amax(line)
[2015-10-30 07:23:07,924: ERROR/Worker-24] nidaba.ocr.kraken[cbe2bbac-254f-4971-8427-18a37d83de51]: 
[2015-10-30 07:23:13,801: ERROR/MainProcess] Task nidaba.ocr.kraken[aef67e37-ad65-4edf-9609-8191b292d8e4] raised unexpected: AssertionError()
Traceback (most recent call last):
  File "/cluster/home/mmunso01/envs/nidaba/lib/python2.7/site-packages/celery/app/trace.py", line 240, in trace_task
    R = retval = fun(*args, **kwargs)
  File "/cluster/home/mmunso01/envs/nidaba/lib/python2.7/site-packages/nidaba/tasks/helper.py", line 89, in __call__
    ret = super(NidabaTask, self).__call__(*args, **nkwargs)
  File "/cluster/home/mmunso01/envs/nidaba/lib/python2.7/site-packages/celery/app/trace.py", line 438, in __protected_call__
    return self.run(*args, **kwargs)
  File "/cluster/home/mmunso01/envs/nidaba/lib/python2.7/site-packages/nidaba/plugins/kraken.py", line 155, in ocr_kraken
    for rec in rpred.rpred(rnn, img, [(int(x[0]), int(x[1]), int(x[2]), int(x[3])) for x in lines]):
  File "/cluster/home/mmunso01/envs/nidaba/lib/python2.7/site-packages/kraken/rpred.py", line 134, in rpred
    pred = network.predictString(line)
  File "/cluster/home/mmunso01/envs/nidaba/lib/python2.7/site-packages/kraken/lib/lstm.py", line 281, in predictString
    cs = self.predictSequence(xs)
  File "/cluster/home/mmunso01/envs/nidaba/lib/python2.7/site-packages/kraken/lib/lstm.py", line 273, in predictSequence
    self.outputs = np.array(self.lstm.forward(xs))
  File "/cluster/home/mmunso01/envs/nidaba/lib/python2.7/site-packages/kraken/lib/lstm.py", line 229, in forward
    xs = net.forward(xs)
  File "/cluster/home/mmunso01/envs/nidaba/lib/python2.7/site-packages/kraken/lib/lstm.py", line 244, in forward
    outputs = [net.forward(xs) for net in self.nets]
  File "/cluster/home/mmunso01/envs/nidaba/lib/python2.7/site-packages/kraken/lib/lstm.py", line 216, in forward
    assert not np.isnan(self.output[:n]).any()
AssertionError
[2015-10-30 07:23:17,232: ERROR/MainProcess] Task nidaba.ocr.kraken[cbe2bbac-254f-4971-8427-18a37d83de51] raised unexpected: AssertionError()
Traceback (most recent call last):
  File "/cluster/home/mmunso01/envs/nidaba/lib/python2.7/site-packages/celery/app/trace.py", line 240, in trace_task
    R = retval = fun(*args, **kwargs)
  File "/cluster/home/mmunso01/envs/nidaba/lib/python2.7/site-packages/nidaba/tasks/helper.py", line 89, in __call__
    ret = super(NidabaTask, self).__call__(*args, **nkwargs)
  File "/cluster/home/mmunso01/envs/nidaba/lib/python2.7/site-packages/celery/app/trace.py", line 438, in __protected_call__
    return self.run(*args, **kwargs)
  File "/cluster/home/mmunso01/envs/nidaba/lib/python2.7/site-packages/nidaba/plugins/kraken.py", line 155, in ocr_kraken
    for rec in rpred.rpred(rnn, img, [(int(x[0]), int(x[1]), int(x[2]), int(x[3])) for x in lines]):
  File "/cluster/home/mmunso01/envs/nidaba/lib/python2.7/site-packages/kraken/rpred.py", line 134, in rpred
    pred = network.predictString(line)
  File "/cluster/home/mmunso01/envs/nidaba/lib/python2.7/site-packages/kraken/lib/lstm.py", line 281, in predictString
    cs = self.predictSequence(xs)
  File "/cluster/home/mmunso01/envs/nidaba/lib/python2.7/site-packages/kraken/lib/lstm.py", line 273, in predictSequence
    self.outputs = np.array(self.lstm.forward(xs))
  File "/cluster/home/mmunso01/envs/nidaba/lib/python2.7/site-packages/kraken/lib/lstm.py", line 229, in forward
    xs = net.forward(xs)
  File "/cluster/home/mmunso01/envs/nidaba/lib/python2.7/site-packages/kraken/lib/lstm.py", line 244, in forward
    outputs = [net.forward(xs) for net in self.nets]
  File "/cluster/home/mmunso01/envs/nidaba/lib/python2.7/site-packages/kraken/lib/lstm.py", line 216, in forward
    assert not np.isnan(self.output[:n]).any()
AssertionError
[2015-10-30 07:23:54,836: WARNING/Worker-10] /cluster/home/mmunso01/envs/nidaba/lib/python2.7/site-packages/kraken/lib/lstm.py:48: RuntimeWarning: invalid value encountered in true_divide
  line = line * 1.0/np.amax(line)
[2015-10-30 07:23:54,867: ERROR/Worker-10] nidaba.ocr.kraken[31cd58ce-0fd2-40d7-b578-71b6502fd223]: 
[2015-10-30 07:23:57,240: ERROR/MainProcess] Task nidaba.ocr.kraken[31cd58ce-0fd2-40d7-b578-71b6502fd223] raised unexpected: AssertionError()
Traceback (most recent call last):
  File "/cluster/home/mmunso01/envs/nidaba/lib/python2.7/site-packages/celery/app/trace.py", line 240, in trace_task
    R = retval = fun(*args, **kwargs)
  File "/cluster/home/mmunso01/envs/nidaba/lib/python2.7/site-packages/nidaba/tasks/helper.py", line 89, in __call__
    ret = super(NidabaTask, self).__call__(*args, **nkwargs)
  File "/cluster/home/mmunso01/envs/nidaba/lib/python2.7/site-packages/celery/app/trace.py", line 438, in __protected_call__
    return self.run(*args, **kwargs)
  File "/cluster/home/mmunso01/envs/nidaba/lib/python2.7/site-packages/nidaba/plugins/kraken.py", line 155, in ocr_kraken
    for rec in rpred.rpred(rnn, img, [(int(x[0]), int(x[1]), int(x[2]), int(x[3])) for x in lines]):
  File "/cluster/home/mmunso01/envs/nidaba/lib/python2.7/site-packages/kraken/rpred.py", line 134, in rpred
    pred = network.predictString(line)
  File "/cluster/home/mmunso01/envs/nidaba/lib/python2.7/site-packages/kraken/lib/lstm.py", line 281, in predictString
    cs = self.predictSequence(xs)
  File "/cluster/home/mmunso01/envs/nidaba/lib/python2.7/site-packages/kraken/lib/lstm.py", line 273, in predictSequence
    self.outputs = np.array(self.lstm.forward(xs))
  File "/cluster/home/mmunso01/envs/nidaba/lib/python2.7/site-packages/kraken/lib/lstm.py", line 229, in forward
    xs = net.forward(xs)
  File "/cluster/home/mmunso01/envs/nidaba/lib/python2.7/site-packages/kraken/lib/lstm.py", line 244, in forward
    outputs = [net.forward(xs) for net in self.nets]
  File "/cluster/home/mmunso01/envs/nidaba/lib/python2.7/site-packages/kraken/lib/lstm.py", line 216, in forward
    assert not np.isnan(self.output[:n]).any()
AssertionError
[2015-10-30 07:24:04,009: ERROR/Worker-12] nidaba.ocr.kraken[10d0e48e-7225-4474-b06a-2535b59f338b]: float division by zero
[2015-10-30 07:24:34,379: ERROR/MainProcess] Task nidaba.ocr.kraken[10d0e48e-7225-4474-b06a-2535b59f338b] raised unexpected: ZeroDivisionError('float division by zero',)
Traceback (most recent call last):
  File "/cluster/home/mmunso01/envs/nidaba/lib/python2.7/site-packages/celery/app/trace.py", line 240, in trace_task
    R = retval = fun(*args, **kwargs)
  File "/cluster/home/mmunso01/envs/nidaba/lib/python2.7/site-packages/nidaba/tasks/helper.py", line 89, in __call__
    ret = super(NidabaTask, self).__call__(*args, **nkwargs)
  File "/cluster/home/mmunso01/envs/nidaba/lib/python2.7/site-packages/celery/app/trace.py", line 438, in __protected_call__
    return self.run(*args, **kwargs)
  File "/cluster/home/mmunso01/envs/nidaba/lib/python2.7/site-packages/nidaba/plugins/kraken.py", line 155, in ocr_kraken
    for rec in rpred.rpred(rnn, img, [(int(x[0]), int(x[1]), int(x[2]), int(x[3])) for x in lines]):
  File "/cluster/home/mmunso01/envs/nidaba/lib/python2.7/site-packages/kraken/rpred.py", line 127, in rpred
    box = dewarp(lnorm, box)
  File "/cluster/home/mmunso01/envs/nidaba/lib/python2.7/site-packages/kraken/rpred.py", line 93, in dewarp
    line = normalizer.normalize(line, cval=np.amax(line))
  File "/cluster/home/mmunso01/envs/nidaba/lib/python2.7/site-packages/kraken/lib/lineest.py", line 60, in normalize
    dtype=dtype, cval=cval)
  File "/cluster/home/mmunso01/envs/nidaba/lib/python2.7/site-packages/kraken/lib/lineest.py", line 13, in scale_to_h
    scale = target_height*1.0/h
ZeroDivisionError: float division by zero
[2015-10-30 07:24:50,532: ERROR/Worker-24] nidaba.ocr.kraken[ba331a66-5356-47d1-8239-fb8d4a089661]: 
[2015-10-30 07:24:52,860: ERROR/MainProcess] Task nidaba.ocr.kraken[ba331a66-5356-47d1-8239-fb8d4a089661] raised unexpected: AssertionError()
Traceback (most recent call last):
  File "/cluster/home/mmunso01/envs/nidaba/lib/python2.7/site-packages/celery/app/trace.py", line 240, in trace_task
    R = retval = fun(*args, **kwargs)
  File "/cluster/home/mmunso01/envs/nidaba/lib/python2.7/site-packages/nidaba/tasks/helper.py", line 89, in __call__
    ret = super(NidabaTask, self).__call__(*args, **nkwargs)
  File "/cluster/home/mmunso01/envs/nidaba/lib/python2.7/site-packages/celery/app/trace.py", line 438, in __protected_call__
    return self.run(*args, **kwargs)
  File "/cluster/home/mmunso01/envs/nidaba/lib/python2.7/site-packages/nidaba/plugins/kraken.py", line 155, in ocr_kraken
    for rec in rpred.rpred(rnn, img, [(int(x[0]), int(x[1]), int(x[2]), int(x[3])) for x in lines]):
  File "/cluster/home/mmunso01/envs/nidaba/lib/python2.7/site-packages/kraken/rpred.py", line 134, in rpred
    pred = network.predictString(line)
  File "/cluster/home/mmunso01/envs/nidaba/lib/python2.7/site-packages/kraken/lib/lstm.py", line 281, in predictString
    cs = self.predictSequence(xs)
  File "/cluster/home/mmunso01/envs/nidaba/lib/python2.7/site-packages/kraken/lib/lstm.py", line 273, in predictSequence
    self.outputs = np.array(self.lstm.forward(xs))
  File "/cluster/home/mmunso01/envs/nidaba/lib/python2.7/site-packages/kraken/lib/lstm.py", line 229, in forward
    xs = net.forward(xs)
  File "/cluster/home/mmunso01/envs/nidaba/lib/python2.7/site-packages/kraken/lib/lstm.py", line 244, in forward
    outputs = [net.forward(xs) for net in self.nets]
  File "/cluster/home/mmunso01/envs/nidaba/lib/python2.7/site-packages/kraken/lib/lstm.py", line 216, in forward
    assert not np.isnan(self.output[:n]).any()
AssertionError
[2015-10-30 07:25:57,495: ERROR/Worker-26] nidaba.ocr.kraken[c87e736b-296f-4605-bad1-ec0e5da1c863]: index 5000 is out of bounds for axis 0 with size 5000
[2015-10-30 07:25:58,326: ERROR/MainProcess] Task nidaba.ocr.kraken[c87e736b-296f-4605-bad1-ec0e5da1c863] raised unexpected: IndexError('index 5000 is out of bounds for axis 0 with size 5000',)
Traceback (most recent call last):
  File "/cluster/home/mmunso01/envs/nidaba/lib/python2.7/site-packages/celery/app/trace.py", line 240, in trace_task
    R = retval = fun(*args, **kwargs)
  File "/cluster/home/mmunso01/envs/nidaba/lib/python2.7/site-packages/nidaba/tasks/helper.py", line 89, in __call__
    ret = super(NidabaTask, self).__call__(*args, **nkwargs)
  File "/cluster/home/mmunso01/envs/nidaba/lib/python2.7/site-packages/celery/app/trace.py", line 438, in __protected_call__
    return self.run(*args, **kwargs)
  File "/cluster/home/mmunso01/envs/nidaba/lib/python2.7/site-packages/nidaba/plugins/kraken.py", line 155, in ocr_kraken
    for rec in rpred.rpred(rnn, img, [(int(x[0]), int(x[1]), int(x[2]), int(x[3])) for x in lines]):
  File "/cluster/home/mmunso01/envs/nidaba/lib/python2.7/site-packages/kraken/rpred.py", line 134, in rpred
    pred = network.predictString(line)
  File "/cluster/home/mmunso01/envs/nidaba/lib/python2.7/site-packages/kraken/lib/lstm.py", line 281, in predictString
    cs = self.predictSequence(xs)
  File "/cluster/home/mmunso01/envs/nidaba/lib/python2.7/site-packages/kraken/lib/lstm.py", line 273, in predictSequence
    self.outputs = np.array(self.lstm.forward(xs))
  File "/cluster/home/mmunso01/envs/nidaba/lib/python2.7/site-packages/kraken/lib/lstm.py", line 229, in forward
    xs = net.forward(xs)
  File "/cluster/home/mmunso01/envs/nidaba/lib/python2.7/site-packages/kraken/lib/lstm.py", line 244, in forward
    outputs = [net.forward(xs) for net in self.nets]
  File "/cluster/home/mmunso01/envs/nidaba/lib/python2.7/site-packages/kraken/lib/lstm.py", line 196, in forward
    self.source[t,0] = 1
IndexError: index 5000 is out of bounds for axis 0 with size 5000
[2015-10-30 07:26:01,048: WARNING/Worker-23] /cluster/home/mmunso01/envs/nidaba/lib/python2.7/site-packages/kraken/lib/lstm.py:48: RuntimeWarning: invalid value encountered in true_divide
  line = line * 1.0/np.amax(line)
[2015-10-30 07:26:01,269: ERROR/Worker-23] nidaba.ocr.kraken[0346862f-3550-4858-b006-1f2f6ad76623]: 
[2015-10-30 07:26:06,246: ERROR/MainProcess] Task nidaba.ocr.kraken[0346862f-3550-4858-b006-1f2f6ad76623] raised unexpected: AssertionError()
Traceback (most recent call last):
  File "/cluster/home/mmunso01/envs/nidaba/lib/python2.7/site-packages/celery/app/trace.py", line 240, in trace_task
    R = retval = fun(*args, **kwargs)
  File "/cluster/home/mmunso01/envs/nidaba/lib/python2.7/site-packages/nidaba/tasks/helper.py", line 89, in __call__
    ret = super(NidabaTask, self).__call__(*args, **nkwargs)
  File "/cluster/home/mmunso01/envs/nidaba/lib/python2.7/site-packages/celery/app/trace.py", line 438, in __protected_call__
    return self.run(*args, **kwargs)
  File "/cluster/home/mmunso01/envs/nidaba/lib/python2.7/site-packages/nidaba/plugins/kraken.py", line 155, in ocr_kraken
    for rec in rpred.rpred(rnn, img, [(int(x[0]), int(x[1]), int(x[2]), int(x[3])) for x in lines]):
  File "/cluster/home/mmunso01/envs/nidaba/lib/python2.7/site-packages/kraken/rpred.py", line 134, in rpred
    pred = network.predictString(line)
  File "/cluster/home/mmunso01/envs/nidaba/lib/python2.7/site-packages/kraken/lib/lstm.py", line 281, in predictString
    cs = self.predictSequence(xs)
  File "/cluster/home/mmunso01/envs/nidaba/lib/python2.7/site-packages/kraken/lib/lstm.py", line 273, in predictSequence
    self.outputs = np.array(self.lstm.forward(xs))
  File "/cluster/home/mmunso01/envs/nidaba/lib/python2.7/site-packages/kraken/lib/lstm.py", line 229, in forward
    xs = net.forward(xs)
  File "/cluster/home/mmunso01/envs/nidaba/lib/python2.7/site-packages/kraken/lib/lstm.py", line 244, in forward
    outputs = [net.forward(xs) for net in self.nets]
  File "/cluster/home/mmunso01/envs/nidaba/lib/python2.7/site-packages/kraken/lib/lstm.py", line 216, in forward
    assert not np.isnan(self.output[:n]).any()
AssertionError
[2015-10-30 07:26:34,160: ERROR/Worker-2] nidaba.ocr.kraken[b753cb30-9c82-48a3-8b1f-a5e7c3ef6515]: 
[2015-10-30 07:26:38,176: ERROR/MainProcess] Task nidaba.ocr.kraken[b753cb30-9c82-48a3-8b1f-a5e7c3ef6515] raised unexpected: AssertionError()
Traceback (most recent call last):
  File "/cluster/home/mmunso01/envs/nidaba/lib/python2.7/site-packages/celery/app/trace.py", line 240, in trace_task
    R = retval = fun(*args, **kwargs)
  File "/cluster/home/mmunso01/envs/nidaba/lib/python2.7/site-packages/nidaba/tasks/helper.py", line 89, in __call__
    ret = super(NidabaTask, self).__call__(*args, **nkwargs)
  File "/cluster/home/mmunso01/envs/nidaba/lib/python2.7/site-packages/celery/app/trace.py", line 438, in __protected_call__
    return self.run(*args, **kwargs)
  File "/cluster/home/mmunso01/envs/nidaba/lib/python2.7/site-packages/nidaba/plugins/kraken.py", line 155, in ocr_kraken
    for rec in rpred.rpred(rnn, img, [(int(x[0]), int(x[1]), int(x[2]), int(x[3])) for x in lines]):
  File "/cluster/home/mmunso01/envs/nidaba/lib/python2.7/site-packages/kraken/rpred.py", line 134, in rpred
    pred = network.predictString(line)
  File "/cluster/home/mmunso01/envs/nidaba/lib/python2.7/site-packages/kraken/lib/lstm.py", line 281, in predictString
    cs = self.predictSequence(xs)
  File "/cluster/home/mmunso01/envs/nidaba/lib/python2.7/site-packages/kraken/lib/lstm.py", line 273, in predictSequence
    self.outputs = np.array(self.lstm.forward(xs))
  File "/cluster/home/mmunso01/envs/nidaba/lib/python2.7/site-packages/kraken/lib/lstm.py", line 229, in forward
    xs = net.forward(xs)
  File "/cluster/home/mmunso01/envs/nidaba/lib/python2.7/site-packages/kraken/lib/lstm.py", line 244, in forward
    outputs = [net.forward(xs) for net in self.nets]
  File "/cluster/home/mmunso01/envs/nidaba/lib/python2.7/site-packages/kraken/lib/lstm.py", line 216, in forward
    assert not np.isnan(self.output[:n]).any()
AssertionError
[2015-10-30 07:27:48,771: WARNING/Worker-30] /cluster/home/mmunso01/envs/nidaba/lib/python2.7/site-packages/kraken/rpred.py:91: RuntimeWarning: invalid value encountered in true_divide
  temp = temp*1.0/np.amax(temp)
[2015-10-30 07:27:48,783: WARNING/Worker-30] /cluster/home/mmunso01/envs/nidaba/lib/python2.7/site-packages/kraken/lib/lstm.py:48: RuntimeWarning: invalid value encountered in true_divide
  line = line * 1.0/np.amax(line)
[2015-10-30 07:27:48,801: ERROR/Worker-30] nidaba.ocr.kraken[ef1fb4b2-2f73-4e51-baf8-4ffa1d58937c]: 
[2015-10-30 07:27:49,967: ERROR/MainProcess] Task nidaba.ocr.kraken[ef1fb4b2-2f73-4e51-baf8-4ffa1d58937c] raised unexpected: AssertionError()
Traceback (most recent call last):
  File "/cluster/home/mmunso01/envs/nidaba/lib/python2.7/site-packages/celery/app/trace.py", line 240, in trace_task
    R = retval = fun(*args, **kwargs)
  File "/cluster/home/mmunso01/envs/nidaba/lib/python2.7/site-packages/nidaba/tasks/helper.py", line 89, in __call__
    ret = super(NidabaTask, self).__call__(*args, **nkwargs)
  File "/cluster/home/mmunso01/envs/nidaba/lib/python2.7/site-packages/celery/app/trace.py", line 438, in __protected_call__
    return self.run(*args, **kwargs)
  File "/cluster/home/mmunso01/envs/nidaba/lib/python2.7/site-packages/nidaba/plugins/kraken.py", line 155, in ocr_kraken
    for rec in rpred.rpred(rnn, img, [(int(x[0]), int(x[1]), int(x[2]), int(x[3])) for x in lines]):
  File "/cluster/home/mmunso01/envs/nidaba/lib/python2.7/site-packages/kraken/rpred.py", line 134, in rpred
    pred = network.predictString(line)
  File "/cluster/home/mmunso01/envs/nidaba/lib/python2.7/site-packages/kraken/lib/lstm.py", line 281, in predictString
    cs = self.predictSequence(xs)
  File "/cluster/home/mmunso01/envs/nidaba/lib/python2.7/site-packages/kraken/lib/lstm.py", line 273, in predictSequence
    self.outputs = np.array(self.lstm.forward(xs))
  File "/cluster/home/mmunso01/envs/nidaba/lib/python2.7/site-packages/kraken/lib/lstm.py", line 229, in forward
    xs = net.forward(xs)
  File "/cluster/home/mmunso01/envs/nidaba/lib/python2.7/site-packages/kraken/lib/lstm.py", line 244, in forward
    outputs = [net.forward(xs) for net in self.nets]
  File "/cluster/home/mmunso01/envs/nidaba/lib/python2.7/site-packages/kraken/lib/lstm.py", line 216, in forward
    assert not np.isnan(self.output[:n]).any()
AssertionError
[2015-10-30 07:28:33,004: WARNING/Worker-33] /cluster/home/mmunso01/envs/nidaba/lib/python2.7/site-packages/kraken/rpred.py:91: RuntimeWarning: invalid value encountered in true_divide
  temp = temp*1.0/np.amax(temp)
[2015-10-30 07:29:06,882: WARNING/Worker-32] /cluster/home/mmunso01/envs/nidaba/lib/python2.7/site-packages/kraken/rpred.py:91: RuntimeWarning: invalid value encountered in true_divide
  temp = temp*1.0/np.amax(temp)
[2015-10-30 07:29:16,891: ERROR/Worker-20] nidaba.ocr.kraken[08c5da09-cd51-4692-9895-f5421a0d13e9]: float division by zero
[2015-10-30 07:29:18,650: ERROR/MainProcess] Task nidaba.ocr.kraken[08c5da09-cd51-4692-9895-f5421a0d13e9] raised unexpected: ZeroDivisionError('float division by zero',)
Traceback (most recent call last):
  File "/cluster/home/mmunso01/envs/nidaba/lib/python2.7/site-packages/celery/app/trace.py", line 240, in trace_task
    R = retval = fun(*args, **kwargs)
  File "/cluster/home/mmunso01/envs/nidaba/lib/python2.7/site-packages/nidaba/tasks/helper.py", line 89, in __call__
    ret = super(NidabaTask, self).__call__(*args, **nkwargs)
  File "/cluster/home/mmunso01/envs/nidaba/lib/python2.7/site-packages/celery/app/trace.py", line 438, in __protected_call__
    return self.run(*args, **kwargs)
  File "/cluster/home/mmunso01/envs/nidaba/lib/python2.7/site-packages/nidaba/plugins/kraken.py", line 155, in ocr_kraken
    for rec in rpred.rpred(rnn, img, [(int(x[0]), int(x[1]), int(x[2]), int(x[3])) for x in lines]):
  File "/cluster/home/mmunso01/envs/nidaba/lib/python2.7/site-packages/kraken/rpred.py", line 127, in rpred
    box = dewarp(lnorm, box)
  File "/cluster/home/mmunso01/envs/nidaba/lib/python2.7/site-packages/kraken/rpred.py", line 93, in dewarp
    line = normalizer.normalize(line, cval=np.amax(line))
  File "/cluster/home/mmunso01/envs/nidaba/lib/python2.7/site-packages/kraken/lib/lineest.py", line 60, in normalize
    dtype=dtype, cval=cval)
  File "/cluster/home/mmunso01/envs/nidaba/lib/python2.7/site-packages/kraken/lib/lineest.py", line 13, in scale_to_h
    scale = target_height*1.0/h
ZeroDivisionError: float division by zero
[2015-10-30 07:30:17,233: ERROR/Worker-21] nidaba.ocr.kraken[dc27e961-05b5-47ff-bfef-5ce76d259ef7]: float division by zero
[2015-10-30 07:30:18,380: ERROR/MainProcess] Task nidaba.ocr.kraken[dc27e961-05b5-47ff-bfef-5ce76d259ef7] raised unexpected: ZeroDivisionError('float division by zero',)
Traceback (most recent call last):
  File "/cluster/home/mmunso01/envs/nidaba/lib/python2.7/site-packages/celery/app/trace.py", line 240, in trace_task
    R = retval = fun(*args, **kwargs)
  File "/cluster/home/mmunso01/envs/nidaba/lib/python2.7/site-packages/nidaba/tasks/helper.py", line 89, in __call__
    ret = super(NidabaTask, self).__call__(*args, **nkwargs)
  File "/cluster/home/mmunso01/envs/nidaba/lib/python2.7/site-packages/celery/app/trace.py", line 438, in __protected_call__
    return self.run(*args, **kwargs)
  File "/cluster/home/mmunso01/envs/nidaba/lib/python2.7/site-packages/nidaba/plugins/kraken.py", line 155, in ocr_kraken
    for rec in rpred.rpred(rnn, img, [(int(x[0]), int(x[1]), int(x[2]), int(x[3])) for x in lines]):
  File "/cluster/home/mmunso01/envs/nidaba/lib/python2.7/site-packages/kraken/rpred.py", line 127, in rpred
    box = dewarp(lnorm, box)
  File "/cluster/home/mmunso01/envs/nidaba/lib/python2.7/site-packages/kraken/rpred.py", line 93, in dewarp
    line = normalizer.normalize(line, cval=np.amax(line))
  File "/cluster/home/mmunso01/envs/nidaba/lib/python2.7/site-packages/kraken/lib/lineest.py", line 60, in normalize
    dtype=dtype, cval=cval)
  File "/cluster/home/mmunso01/envs/nidaba/lib/python2.7/site-packages/kraken/lib/lineest.py", line 13, in scale_to_h
    scale = target_height*1.0/h
ZeroDivisionError: float division by zero
[2015-10-30 07:30:54,358: ERROR/Worker-8] nidaba.ocr.kraken[054efab5-c540-4393-a842-2ca1a31c50bc]: index 5000 is out of bounds for axis 0 with size 5000
[2015-10-30 07:30:55,620: ERROR/MainProcess] Task nidaba.ocr.kraken[054efab5-c540-4393-a842-2ca1a31c50bc] raised unexpected: IndexError('index 5000 is out of bounds for axis 0 with size 5000',)
Traceback (most recent call last):
  File "/cluster/home/mmunso01/envs/nidaba/lib/python2.7/site-packages/celery/app/trace.py", line 240, in trace_task
    R = retval = fun(*args, **kwargs)
  File "/cluster/home/mmunso01/envs/nidaba/lib/python2.7/site-packages/nidaba/tasks/helper.py", line 89, in __call__
    ret = super(NidabaTask, self).__call__(*args, **nkwargs)
  File "/cluster/home/mmunso01/envs/nidaba/lib/python2.7/site-packages/celery/app/trace.py", line 438, in __protected_call__
    return self.run(*args, **kwargs)
  File "/cluster/home/mmunso01/envs/nidaba/lib/python2.7/site-packages/nidaba/plugins/kraken.py", line 155, in ocr_kraken
    for rec in rpred.rpred(rnn, img, [(int(x[0]), int(x[1]), int(x[2]), int(x[3])) for x in lines]):
  File "/cluster/home/mmunso01/envs/nidaba/lib/python2.7/site-packages/kraken/rpred.py", line 134, in rpred
    pred = network.predictString(line)
  File "/cluster/home/mmunso01/envs/nidaba/lib/python2.7/site-packages/kraken/lib/lstm.py", line 281, in predictString
    cs = self.predictSequence(xs)
  File "/cluster/home/mmunso01/envs/nidaba/lib/python2.7/site-packages/kraken/lib/lstm.py", line 273, in predictSequence
    self.outputs = np.array(self.lstm.forward(xs))
  File "/cluster/home/mmunso01/envs/nidaba/lib/python2.7/site-packages/kraken/lib/lstm.py", line 229, in forward
    xs = net.forward(xs)
  File "/cluster/home/mmunso01/envs/nidaba/lib/python2.7/site-packages/kraken/lib/lstm.py", line 244, in forward
    outputs = [net.forward(xs) for net in self.nets]
  File "/cluster/home/mmunso01/envs/nidaba/lib/python2.7/site-packages/kraken/lib/lstm.py", line 196, in forward
    self.source[t,0] = 1
IndexError: index 5000 is out of bounds for axis 0 with size 5000
[2015-10-30 07:39:10,333: ERROR/Worker-38] nidaba.ocr.kraken[67d0d451-d52d-43c7-b22c-c37a2f182535]: index 5000 is out of bounds for axis 0 with size 5000
[2015-10-30 07:40:06,143: ERROR/MainProcess] Task nidaba.ocr.kraken[67d0d451-d52d-43c7-b22c-c37a2f182535] raised unexpected: IndexError('index 5000 is out of bounds for axis 0 with size 5000',)
Traceback (most recent call last):
  File "/cluster/home/mmunso01/envs/nidaba/lib/python2.7/site-packages/celery/app/trace.py", line 240, in trace_task
    R = retval = fun(*args, **kwargs)
  File "/cluster/home/mmunso01/envs/nidaba/lib/python2.7/site-packages/nidaba/tasks/helper.py", line 89, in __call__
    ret = super(NidabaTask, self).__call__(*args, **nkwargs)
  File "/cluster/home/mmunso01/envs/nidaba/lib/python2.7/site-packages/celery/app/trace.py", line 438, in __protected_call__
    return self.run(*args, **kwargs)
  File "/cluster/home/mmunso01/envs/nidaba/lib/python2.7/site-packages/nidaba/plugins/kraken.py", line 155, in ocr_kraken
    for rec in rpred.rpred(rnn, img, [(int(x[0]), int(x[1]), int(x[2]), int(x[3])) for x in lines]):
  File "/cluster/home/mmunso01/envs/nidaba/lib/python2.7/site-packages/kraken/rpred.py", line 134, in rpred
    pred = network.predictString(line)
  File "/cluster/home/mmunso01/envs/nidaba/lib/python2.7/site-packages/kraken/lib/lstm.py", line 281, in predictString
    cs = self.predictSequence(xs)
  File "/cluster/home/mmunso01/envs/nidaba/lib/python2.7/site-packages/kraken/lib/lstm.py", line 273, in predictSequence
    self.outputs = np.array(self.lstm.forward(xs))
  File "/cluster/home/mmunso01/envs/nidaba/lib/python2.7/site-packages/kraken/lib/lstm.py", line 229, in forward
    xs = net.forward(xs)
  File "/cluster/home/mmunso01/envs/nidaba/lib/python2.7/site-packages/kraken/lib/lstm.py", line 244, in forward
    outputs = [net.forward(xs) for net in self.nets]
  File "/cluster/home/mmunso01/envs/nidaba/lib/python2.7/site-packages/kraken/lib/lstm.py", line 196, in forward
    self.source[t,0] = 1
IndexError: index 5000 is out of bounds for axis 0 with size 5000
[2015-10-30 07:41:30,263: ERROR/Worker-32] nidaba.ocr.kraken[f0836e46-ebe2-4f9f-ae35-f7ead9502687]: index 5000 is out of bounds for axis 0 with size 5000
[2015-10-30 07:41:36,434: ERROR/MainProcess] Task nidaba.ocr.kraken[f0836e46-ebe2-4f9f-ae35-f7ead9502687] raised unexpected: IndexError('index 5000 is out of bounds for axis 0 with size 5000',)
Traceback (most recent call last):
  File "/cluster/home/mmunso01/envs/nidaba/lib/python2.7/site-packages/celery/app/trace.py", line 240, in trace_task
    R = retval = fun(*args, **kwargs)
  File "/cluster/home/mmunso01/envs/nidaba/lib/python2.7/site-packages/nidaba/tasks/helper.py", line 89, in __call__
    ret = super(NidabaTask, self).__call__(*args, **nkwargs)
  File "/cluster/home/mmunso01/envs/nidaba/lib/python2.7/site-packages/celery/app/trace.py", line 438, in __protected_call__
    return self.run(*args, **kwargs)
  File "/cluster/home/mmunso01/envs/nidaba/lib/python2.7/site-packages/nidaba/plugins/kraken.py", line 155, in ocr_kraken
    for rec in rpred.rpred(rnn, img, [(int(x[0]), int(x[1]), int(x[2]), int(x[3])) for x in lines]):
  File "/cluster/home/mmunso01/envs/nidaba/lib/python2.7/site-packages/kraken/rpred.py", line 134, in rpred
    pred = network.predictString(line)
  File "/cluster/home/mmunso01/envs/nidaba/lib/python2.7/site-packages/kraken/lib/lstm.py", line 281, in predictString
    cs = self.predictSequence(xs)
  File "/cluster/home/mmunso01/envs/nidaba/lib/python2.7/site-packages/kraken/lib/lstm.py", line 273, in predictSequence
    self.outputs = np.array(self.lstm.forward(xs))
  File "/cluster/home/mmunso01/envs/nidaba/lib/python2.7/site-packages/kraken/lib/lstm.py", line 229, in forward
    xs = net.forward(xs)
  File "/cluster/home/mmunso01/envs/nidaba/lib/python2.7/site-packages/kraken/lib/lstm.py", line 244, in forward
    outputs = [net.forward(xs) for net in self.nets]
  File "/cluster/home/mmunso01/envs/nidaba/lib/python2.7/site-packages/kraken/lib/lstm.py", line 196, in forward
    self.source[t,0] = 1
IndexError: index 5000 is out of bounds for axis 0 with size 5000
[2015-10-30 07:43:27,799: ERROR/Worker-23] nidaba.ocr.kraken[0a7716f6-ee6a-4611-9688-6e2997b6f965]: index 5000 is out of bounds for axis 0 with size 5000
[2015-10-30 07:43:32,220: ERROR/MainProcess] Task nidaba.ocr.kraken[0a7716f6-ee6a-4611-9688-6e2997b6f965] raised unexpected: IndexError('index 5000 is out of bounds for axis 0 with size 5000',)
Traceback (most recent call last):
  File "/cluster/home/mmunso01/envs/nidaba/lib/python2.7/site-packages/celery/app/trace.py", line 240, in trace_task
    R = retval = fun(*args, **kwargs)
  File "/cluster/home/mmunso01/envs/nidaba/lib/python2.7/site-packages/nidaba/tasks/helper.py", line 89, in __call__
    ret = super(NidabaTask, self).__call__(*args, **nkwargs)
  File "/cluster/home/mmunso01/envs/nidaba/lib/python2.7/site-packages/celery/app/trace.py", line 438, in __protected_call__
    return self.run(*args, **kwargs)
  File "/cluster/home/mmunso01/envs/nidaba/lib/python2.7/site-packages/nidaba/plugins/kraken.py", line 155, in ocr_kraken
    for rec in rpred.rpred(rnn, img, [(int(x[0]), int(x[1]), int(x[2]), int(x[3])) for x in lines]):
  File "/cluster/home/mmunso01/envs/nidaba/lib/python2.7/site-packages/kraken/rpred.py", line 134, in rpred
    pred = network.predictString(line)
  File "/cluster/home/mmunso01/envs/nidaba/lib/python2.7/site-packages/kraken/lib/lstm.py", line 281, in predictString
    cs = self.predictSequence(xs)
  File "/cluster/home/mmunso01/envs/nidaba/lib/python2.7/site-packages/kraken/lib/lstm.py", line 273, in predictSequence
    self.outputs = np.array(self.lstm.forward(xs))
  File "/cluster/home/mmunso01/envs/nidaba/lib/python2.7/site-packages/kraken/lib/lstm.py", line 229, in forward
    xs = net.forward(xs)
  File "/cluster/home/mmunso01/envs/nidaba/lib/python2.7/site-packages/kraken/lib/lstm.py", line 244, in forward
    outputs = [net.forward(xs) for net in self.nets]
  File "/cluster/home/mmunso01/envs/nidaba/lib/python2.7/site-packages/kraken/lib/lstm.py", line 196, in forward
    self.source[t,0] = 1
IndexError: index 5000 is out of bounds for axis 0 with size 5000
[2015-10-30 07:51:37,710: ERROR/Worker-4] nidaba.ocr.kraken[82302456-936b-43b0-90e3-cb41b5adf3b6]: index 5000 is out of bounds for axis 0 with size 5000
[2015-10-30 07:51:38,626: ERROR/MainProcess] Task nidaba.ocr.kraken[82302456-936b-43b0-90e3-cb41b5adf3b6] raised unexpected: IndexError('index 5000 is out of bounds for axis 0 with size 5000',)
Traceback (most recent call last):
  File "/cluster/home/mmunso01/envs/nidaba/lib/python2.7/site-packages/celery/app/trace.py", line 240, in trace_task
    R = retval = fun(*args, **kwargs)
  File "/cluster/home/mmunso01/envs/nidaba/lib/python2.7/site-packages/nidaba/tasks/helper.py", line 89, in __call__
    ret = super(NidabaTask, self).__call__(*args, **nkwargs)
  File "/cluster/home/mmunso01/envs/nidaba/lib/python2.7/site-packages/celery/app/trace.py", line 438, in __protected_call__
    return self.run(*args, **kwargs)
  File "/cluster/home/mmunso01/envs/nidaba/lib/python2.7/site-packages/nidaba/plugins/kraken.py", line 155, in ocr_kraken
    for rec in rpred.rpred(rnn, img, [(int(x[0]), int(x[1]), int(x[2]), int(x[3])) for x in lines]):
  File "/cluster/home/mmunso01/envs/nidaba/lib/python2.7/site-packages/kraken/rpred.py", line 134, in rpred
    pred = network.predictString(line)
  File "/cluster/home/mmunso01/envs/nidaba/lib/python2.7/site-packages/kraken/lib/lstm.py", line 281, in predictString
    cs = self.predictSequence(xs)
  File "/cluster/home/mmunso01/envs/nidaba/lib/python2.7/site-packages/kraken/lib/lstm.py", line 273, in predictSequence
    self.outputs = np.array(self.lstm.forward(xs))
  File "/cluster/home/mmunso01/envs/nidaba/lib/python2.7/site-packages/kraken/lib/lstm.py", line 229, in forward
    xs = net.forward(xs)
  File "/cluster/home/mmunso01/envs/nidaba/lib/python2.7/site-packages/kraken/lib/lstm.py", line 244, in forward
    outputs = [net.forward(xs) for net in self.nets]
  File "/cluster/home/mmunso01/envs/nidaba/lib/python2.7/site-packages/kraken/lib/lstm.py", line 196, in forward
    self.source[t,0] = 1
IndexError: index 5000 is out of bounds for axis 0 with size 5000
[2015-10-30 07:51:43,036: ERROR/Worker-31] nidaba.ocr.kraken[9ab730c3-1266-45fd-a70d-1ea8715ede3f]: index 5000 is out of bounds for axis 0 with size 5000
[2015-10-30 07:51:46,219: ERROR/MainProcess] Task nidaba.ocr.kraken[9ab730c3-1266-45fd-a70d-1ea8715ede3f] raised unexpected: IndexError('index 5000 is out of bounds for axis 0 with size 5000',)
Traceback (most recent call last):
  File "/cluster/home/mmunso01/envs/nidaba/lib/python2.7/site-packages/celery/app/trace.py", line 240, in trace_task
    R = retval = fun(*args, **kwargs)
  File "/cluster/home/mmunso01/envs/nidaba/lib/python2.7/site-packages/nidaba/tasks/helper.py", line 89, in __call__
    ret = super(NidabaTask, self).__call__(*args, **nkwargs)
  File "/cluster/home/mmunso01/envs/nidaba/lib/python2.7/site-packages/celery/app/trace.py", line 438, in __protected_call__
    return self.run(*args, **kwargs)
  File "/cluster/home/mmunso01/envs/nidaba/lib/python2.7/site-packages/nidaba/plugins/kraken.py", line 155, in ocr_kraken
    for rec in rpred.rpred(rnn, img, [(int(x[0]), int(x[1]), int(x[2]), int(x[3])) for x in lines]):
  File "/cluster/home/mmunso01/envs/nidaba/lib/python2.7/site-packages/kraken/rpred.py", line 134, in rpred
    pred = network.predictString(line)
  File "/cluster/home/mmunso01/envs/nidaba/lib/python2.7/site-packages/kraken/lib/lstm.py", line 281, in predictString
    cs = self.predictSequence(xs)
  File "/cluster/home/mmunso01/envs/nidaba/lib/python2.7/site-packages/kraken/lib/lstm.py", line 273, in predictSequence
    self.outputs = np.array(self.lstm.forward(xs))
  File "/cluster/home/mmunso01/envs/nidaba/lib/python2.7/site-packages/kraken/lib/lstm.py", line 229, in forward
    xs = net.forward(xs)
  File "/cluster/home/mmunso01/envs/nidaba/lib/python2.7/site-packages/kraken/lib/lstm.py", line 244, in forward
    outputs = [net.forward(xs) for net in self.nets]
  File "/cluster/home/mmunso01/envs/nidaba/lib/python2.7/site-packages/kraken/lib/lstm.py", line 196, in forward
    self.source[t,0] = 1
IndexError: index 5000 is out of bounds for axis 0 with size 5000
[2015-10-30 07:52:56,387: ERROR/Worker-36] nidaba.ocr.kraken[6c5c91f7-0990-405e-b174-47435c0e0acf]: index 5000 is out of bounds for axis 0 with size 5000
[2015-10-30 07:53:07,594: ERROR/MainProcess] Task nidaba.ocr.kraken[6c5c91f7-0990-405e-b174-47435c0e0acf] raised unexpected: IndexError('index 5000 is out of bounds for axis 0 with size 5000',)
Traceback (most recent call last):
  File "/cluster/home/mmunso01/envs/nidaba/lib/python2.7/site-packages/celery/app/trace.py", line 240, in trace_task
    R = retval = fun(*args, **kwargs)
  File "/cluster/home/mmunso01/envs/nidaba/lib/python2.7/site-packages/nidaba/tasks/helper.py", line 89, in __call__
    ret = super(NidabaTask, self).__call__(*args, **nkwargs)
  File "/cluster/home/mmunso01/envs/nidaba/lib/python2.7/site-packages/celery/app/trace.py", line 438, in __protected_call__
    return self.run(*args, **kwargs)
  File "/cluster/home/mmunso01/envs/nidaba/lib/python2.7/site-packages/nidaba/plugins/kraken.py", line 155, in ocr_kraken
    for rec in rpred.rpred(rnn, img, [(int(x[0]), int(x[1]), int(x[2]), int(x[3])) for x in lines]):
  File "/cluster/home/mmunso01/envs/nidaba/lib/python2.7/site-packages/kraken/rpred.py", line 134, in rpred
    pred = network.predictString(line)
  File "/cluster/home/mmunso01/envs/nidaba/lib/python2.7/site-packages/kraken/lib/lstm.py", line 281, in predictString
    cs = self.predictSequence(xs)
  File "/cluster/home/mmunso01/envs/nidaba/lib/python2.7/site-packages/kraken/lib/lstm.py", line 273, in predictSequence
    self.outputs = np.array(self.lstm.forward(xs))
  File "/cluster/home/mmunso01/envs/nidaba/lib/python2.7/site-packages/kraken/lib/lstm.py", line 229, in forward
    xs = net.forward(xs)
  File "/cluster/home/mmunso01/envs/nidaba/lib/python2.7/site-packages/kraken/lib/lstm.py", line 244, in forward
    outputs = [net.forward(xs) for net in self.nets]
  File "/cluster/home/mmunso01/envs/nidaba/lib/python2.7/site-packages/kraken/lib/lstm.py", line 196, in forward
    self.source[t,0] = 1
IndexError: index 5000 is out of bounds for axis 0 with size 5000
[2015-10-30 07:54:00,416: ERROR/Worker-36] nidaba.ocr.kraken[4e347541-1e27-493d-b095-da2fe007903d]: index 5000 is out of bounds for axis 0 with size 5000
[2015-10-30 07:54:03,084: ERROR/MainProcess] Task nidaba.ocr.kraken[4e347541-1e27-493d-b095-da2fe007903d] raised unexpected: IndexError('index 5000 is out of bounds for axis 0 with size 5000',)
Traceback (most recent call last):
  File "/cluster/home/mmunso01/envs/nidaba/lib/python2.7/site-packages/celery/app/trace.py", line 240, in trace_task
    R = retval = fun(*args, **kwargs)
  File "/cluster/home/mmunso01/envs/nidaba/lib/python2.7/site-packages/nidaba/tasks/helper.py", line 89, in __call__
    ret = super(NidabaTask, self).__call__(*args, **nkwargs)
  File "/cluster/home/mmunso01/envs/nidaba/lib/python2.7/site-packages/celery/app/trace.py", line 438, in __protected_call__
    return self.run(*args, **kwargs)
  File "/cluster/home/mmunso01/envs/nidaba/lib/python2.7/site-packages/nidaba/plugins/kraken.py", line 155, in ocr_kraken
    for rec in rpred.rpred(rnn, img, [(int(x[0]), int(x[1]), int(x[2]), int(x[3])) for x in lines]):
  File "/cluster/home/mmunso01/envs/nidaba/lib/python2.7/site-packages/kraken/rpred.py", line 134, in rpred
    pred = network.predictString(line)
  File "/cluster/home/mmunso01/envs/nidaba/lib/python2.7/site-packages/kraken/lib/lstm.py", line 281, in predictString
    cs = self.predictSequence(xs)
  File "/cluster/home/mmunso01/envs/nidaba/lib/python2.7/site-packages/kraken/lib/lstm.py", line 273, in predictSequence
    self.outputs = np.array(self.lstm.forward(xs))
  File "/cluster/home/mmunso01/envs/nidaba/lib/python2.7/site-packages/kraken/lib/lstm.py", line 229, in forward
    xs = net.forward(xs)
  File "/cluster/home/mmunso01/envs/nidaba/lib/python2.7/site-packages/kraken/lib/lstm.py", line 244, in forward
    outputs = [net.forward(xs) for net in self.nets]
  File "/cluster/home/mmunso01/envs/nidaba/lib/python2.7/site-packages/kraken/lib/lstm.py", line 196, in forward
    self.source[t,0] = 1
IndexError: index 5000 is out of bounds for axis 0 with size 5000
[2015-10-30 07:54:10,426: ERROR/Worker-38] nidaba.ocr.kraken[93f5f615-47bf-449f-bbad-0fe2398ea535]: index 5000 is out of bounds for axis 0 with size 5000
[2015-10-30 07:54:18,610: ERROR/MainProcess] Task nidaba.ocr.kraken[93f5f615-47bf-449f-bbad-0fe2398ea535] raised unexpected: IndexError('index 5000 is out of bounds for axis 0 with size 5000',)
Traceback (most recent call last):
  File "/cluster/home/mmunso01/envs/nidaba/lib/python2.7/site-packages/celery/app/trace.py", line 240, in trace_task
    R = retval = fun(*args, **kwargs)
  File "/cluster/home/mmunso01/envs/nidaba/lib/python2.7/site-packages/nidaba/tasks/helper.py", line 89, in __call__
    ret = super(NidabaTask, self).__call__(*args, **nkwargs)
  File "/cluster/home/mmunso01/envs/nidaba/lib/python2.7/site-packages/celery/app/trace.py", line 438, in __protected_call__
    return self.run(*args, **kwargs)
  File "/cluster/home/mmunso01/envs/nidaba/lib/python2.7/site-packages/nidaba/plugins/kraken.py", line 155, in ocr_kraken
    for rec in rpred.rpred(rnn, img, [(int(x[0]), int(x[1]), int(x[2]), int(x[3])) for x in lines]):
  File "/cluster/home/mmunso01/envs/nidaba/lib/python2.7/site-packages/kraken/rpred.py", line 134, in rpred
    pred = network.predictString(line)
  File "/cluster/home/mmunso01/envs/nidaba/lib/python2.7/site-packages/kraken/lib/lstm.py", line 281, in predictString
    cs = self.predictSequence(xs)
  File "/cluster/home/mmunso01/envs/nidaba/lib/python2.7/site-packages/kraken/lib/lstm.py", line 273, in predictSequence
    self.outputs = np.array(self.lstm.forward(xs))
  File "/cluster/home/mmunso01/envs/nidaba/lib/python2.7/site-packages/kraken/lib/lstm.py", line 229, in forward
    xs = net.forward(xs)
  File "/cluster/home/mmunso01/envs/nidaba/lib/python2.7/site-packages/kraken/lib/lstm.py", line 244, in forward
    outputs = [net.forward(xs) for net in self.nets]
  File "/cluster/home/mmunso01/envs/nidaba/lib/python2.7/site-packages/kraken/lib/lstm.py", line 196, in forward
    self.source[t,0] = 1
IndexError: index 5000 is out of bounds for axis 0 with size 5000
[2015-10-30 07:54:33,226: ERROR/Worker-9] nidaba.ocr.kraken[dc4bf205-fe5a-41b8-a21c-ad73c7672f53]: index 5000 is out of bounds for axis 0 with size 5000
[2015-10-30 07:54:49,357: ERROR/MainProcess] Task nidaba.ocr.kraken[dc4bf205-fe5a-41b8-a21c-ad73c7672f53] raised unexpected: IndexError('index 5000 is out of bounds for axis 0 with size 5000',)
Traceback (most recent call last):
  File "/cluster/home/mmunso01/envs/nidaba/lib/python2.7/site-packages/celery/app/trace.py", line 240, in trace_task
    R = retval = fun(*args, **kwargs)
  File "/cluster/home/mmunso01/envs/nidaba/lib/python2.7/site-packages/nidaba/tasks/helper.py", line 89, in __call__
    ret = super(NidabaTask, self).__call__(*args, **nkwargs)
  File "/cluster/home/mmunso01/envs/nidaba/lib/python2.7/site-packages/celery/app/trace.py", line 438, in __protected_call__
    return self.run(*args, **kwargs)
  File "/cluster/home/mmunso01/envs/nidaba/lib/python2.7/site-packages/nidaba/plugins/kraken.py", line 155, in ocr_kraken
    for rec in rpred.rpred(rnn, img, [(int(x[0]), int(x[1]), int(x[2]), int(x[3])) for x in lines]):
  File "/cluster/home/mmunso01/envs/nidaba/lib/python2.7/site-packages/kraken/rpred.py", line 134, in rpred
    pred = network.predictString(line)
  File "/cluster/home/mmunso01/envs/nidaba/lib/python2.7/site-packages/kraken/lib/lstm.py", line 281, in predictString
    cs = self.predictSequence(xs)
  File "/cluster/home/mmunso01/envs/nidaba/lib/python2.7/site-packages/kraken/lib/lstm.py", line 273, in predictSequence
    self.outputs = np.array(self.lstm.forward(xs))
  File "/cluster/home/mmunso01/envs/nidaba/lib/python2.7/site-packages/kraken/lib/lstm.py", line 229, in forward
    xs = net.forward(xs)
  File "/cluster/home/mmunso01/envs/nidaba/lib/python2.7/site-packages/kraken/lib/lstm.py", line 244, in forward
    outputs = [net.forward(xs) for net in self.nets]
  File "/cluster/home/mmunso01/envs/nidaba/lib/python2.7/site-packages/kraken/lib/lstm.py", line 196, in forward
    self.source[t,0] = 1
IndexError: index 5000 is out of bounds for axis 0 with size 5000
[2015-10-30 20:36:54,059: WARNING/MainProcess] consumer: Connection to broker lost. Trying to re-establish the connection...
Traceback (most recent call last):
  File "/cluster/home/mmunso01/envs/nidaba/lib/python2.7/site-packages/celery/worker/consumer.py", line 278, in start
    blueprint.start(self)
  File "/cluster/home/mmunso01/envs/nidaba/lib/python2.7/site-packages/celery/bootsteps.py", line 123, in start
    step.start(parent)
  File "/cluster/home/mmunso01/envs/nidaba/lib/python2.7/site-packages/celery/worker/consumer.py", line 821, in start
    c.loop(*c.loop_args())
  File "/cluster/home/mmunso01/envs/nidaba/lib/python2.7/site-packages/celery/worker/loops.py", line 76, in asynloop
    next(loop)
  File "/cluster/home/mmunso01/envs/nidaba/lib/python2.7/site-packages/kombu/async/hub.py", line 267, in create_loop
    tick_callback()
  File "/cluster/home/mmunso01/envs/nidaba/lib/python2.7/site-packages/kombu/transport/redis.py", line 947, in on_poll_start
    cycle_poll_start()
  File "/cluster/home/mmunso01/envs/nidaba/lib/python2.7/site-packages/kombu/transport/redis.py", line 301, in on_poll_start
    self._register_BRPOP(channel)
  File "/cluster/home/mmunso01/envs/nidaba/lib/python2.7/site-packages/kombu/transport/redis.py", line 284, in _register_BRPOP
    self._register(*ident)
  File "/cluster/home/mmunso01/envs/nidaba/lib/python2.7/site-packages/kombu/transport/redis.py", line 269, in _register
    client.connection.connect()
  File "/cluster/home/mmunso01/envs/nidaba/lib/python2.7/site-packages/redis/connection.py", line 436, in connect
    raise ConnectionError(self._error_message(e))
ConnectionError: Error 111 connecting to 127.0.0.1:6379. Connection refused.
[2015-10-30 20:36:54,080: ERROR/MainProcess] consumer: Cannot connect to redis://127.0.0.1:6379//: Error 111 connecting to 127.0.0.1:6379. Connection refused..
Trying again in 2.00 seconds...

[2015-10-30 20:36:56,087: ERROR/MainProcess] consumer: Cannot connect to redis://127.0.0.1:6379//: Error 111 connecting to 127.0.0.1:6379. Connection refused..
Trying again in 4.00 seconds...

[2015-10-30 20:37:00,092: ERROR/MainProcess] consumer: Cannot connect to redis://127.0.0.1:6379//: Error 111 connecting to 127.0.0.1:6379. Connection refused..
Trying again in 6.00 seconds...

[2015-10-30 20:37:06,100: ERROR/MainProcess] consumer: Cannot connect to redis://127.0.0.1:6379//: Error 111 connecting to 127.0.0.1:6379. Connection refused..
Trying again in 8.00 seconds...

[2015-10-30 20:37:14,111: ERROR/MainProcess] consumer: Cannot connect to redis://127.0.0.1:6379//: Error 111 connecting to 127.0.0.1:6379. Connection refused..
Trying again in 10.00 seconds...

[2015-10-30 20:37:24,123: ERROR/MainProcess] consumer: Cannot connect to redis://127.0.0.1:6379//: Error 111 connecting to 127.0.0.1:6379. Connection refused..
Trying again in 12.00 seconds...

[2015-10-30 20:37:36,137: ERROR/MainProcess] consumer: Cannot connect to redis://127.0.0.1:6379//: Error 111 connecting to 127.0.0.1:6379. Connection refused..
Trying again in 14.00 seconds...

[2015-10-30 20:37:50,154: ERROR/MainProcess] consumer: Cannot connect to redis://127.0.0.1:6379//: Error 111 connecting to 127.0.0.1:6379. Connection refused..
Trying again in 16.00 seconds...

[2015-10-30 20:38:06,173: ERROR/MainProcess] consumer: Cannot connect to redis://127.0.0.1:6379//: Error 111 connecting to 127.0.0.1:6379. Connection refused..
Trying again in 18.00 seconds...

[2015-10-30 20:38:24,194: ERROR/MainProcess] consumer: Cannot connect to redis://127.0.0.1:6379//: Error 111 connecting to 127.0.0.1:6379. Connection refused..
Trying again in 20.00 seconds...

[2015-10-30 20:38:44,217: ERROR/MainProcess] consumer: Cannot connect to redis://127.0.0.1:6379//: Error 111 connecting to 127.0.0.1:6379. Connection refused..
Trying again in 22.00 seconds...

[2015-10-30 20:39:06,249: ERROR/MainProcess] consumer: Cannot connect to redis://127.0.0.1:6379//: Error 111 connecting to 127.0.0.1:6379. Connection refused..
Trying again in 24.00 seconds...

[2015-10-30 20:39:30,288: ERROR/MainProcess] consumer: Cannot connect to redis://127.0.0.1:6379//: Error 111 connecting to 127.0.0.1:6379. Connection refused..
Trying again in 26.00 seconds...

[2015-10-30 20:39:56,318: ERROR/MainProcess] consumer: Cannot connect to redis://127.0.0.1:6379//: Error 111 connecting to 127.0.0.1:6379. Connection refused..
Trying again in 28.00 seconds...

[2015-10-30 20:40:24,350: ERROR/MainProcess] consumer: Cannot connect to redis://127.0.0.1:6379//: Error 111 connecting to 127.0.0.1:6379. Connection refused..
Trying again in 30.00 seconds...

[2015-10-30 20:40:54,386: ERROR/MainProcess] consumer: Cannot connect to redis://127.0.0.1:6379//: Error 111 connecting to 127.0.0.1:6379. Connection refused..
Trying again in 32.00 seconds...

[2015-10-30 20:41:26,424: ERROR/MainProcess] consumer: Cannot connect to redis://127.0.0.1:6379//: Error 111 connecting to 127.0.0.1:6379. Connection refused..
Trying again in 32.00 seconds...

[2015-10-30 20:41:58,461: ERROR/MainProcess] consumer: Cannot connect to redis://127.0.0.1:6379//: Error 111 connecting to 127.0.0.1:6379. Connection refused..
Trying again in 32.00 seconds...

[2015-10-30 20:42:30,499: ERROR/MainProcess] consumer: Cannot connect to redis://127.0.0.1:6379//: Error 111 connecting to 127.0.0.1:6379. Connection refused..
Trying again in 32.00 seconds...

[2015-10-30 20:43:02,537: ERROR/MainProcess] consumer: Cannot connect to redis://127.0.0.1:6379//: Error 111 connecting to 127.0.0.1:6379. Connection refused..
Trying again in 32.00 seconds...

[2015-10-30 20:43:34,578: ERROR/MainProcess] consumer: Cannot connect to redis://127.0.0.1:6379//: Error 111 connecting to 127.0.0.1:6379. Connection refused..
Trying again in 32.00 seconds...

[2015-10-30 20:44:06,618: ERROR/MainProcess] consumer: Cannot connect to redis://127.0.0.1:6379//: Error 111 connecting to 127.0.0.1:6379. Connection refused..
Trying again in 32.00 seconds...

[2015-10-30 20:44:38,656: ERROR/MainProcess] consumer: Cannot connect to redis://127.0.0.1:6379//: Error 111 connecting to 127.0.0.1:6379. Connection refused..
Trying again in 32.00 seconds...

[2015-10-30 20:45:10,696: ERROR/MainProcess] consumer: Cannot connect to redis://127.0.0.1:6379//: Error 111 connecting to 127.0.0.1:6379. Connection refused..
Trying again in 32.00 seconds...

[2015-10-30 20:45:42,735: ERROR/MainProcess] consumer: Cannot connect to redis://127.0.0.1:6379//: Error 111 connecting to 127.0.0.1:6379. Connection refused..
Trying again in 32.00 seconds...

[2015-10-30 20:46:14,774: ERROR/MainProcess] consumer: Cannot connect to redis://127.0.0.1:6379//: Error 111 connecting to 127.0.0.1:6379. Connection refused..
Trying again in 32.00 seconds...

[2015-10-30 20:46:46,811: ERROR/MainProcess] consumer: Cannot connect to redis://127.0.0.1:6379//: Error 111 connecting to 127.0.0.1:6379. Connection refused..
Trying again in 32.00 seconds...

[2015-10-30 20:47:18,850: ERROR/MainProcess] consumer: Cannot connect to redis://127.0.0.1:6379//: Error 111 connecting to 127.0.0.1:6379. Connection refused..
Trying again in 32.00 seconds...

[2015-10-30 20:47:50,888: ERROR/MainProcess] consumer: Cannot connect to redis://127.0.0.1:6379//: Error 111 connecting to 127.0.0.1:6379. Connection refused..
Trying again in 32.00 seconds...

[2015-10-30 20:48:22,927: ERROR/MainProcess] consumer: Cannot connect to redis://127.0.0.1:6379//: Error 111 connecting to 127.0.0.1:6379. Connection refused..
Trying again in 32.00 seconds...

[2015-10-30 20:48:54,965: ERROR/MainProcess] consumer: Cannot connect to redis://127.0.0.1:6379//: Error 111 connecting to 127.0.0.1:6379. Connection refused..
Trying again in 32.00 seconds...

[2015-10-30 20:49:27,002: ERROR/MainProcess] consumer: Cannot connect to redis://127.0.0.1:6379//: Error 111 connecting to 127.0.0.1:6379. Connection refused..
Trying again in 32.00 seconds...

[2015-10-30 20:49:59,038: ERROR/MainProcess] consumer: Cannot connect to redis://127.0.0.1:6379//: Error 111 connecting to 127.0.0.1:6379. Connection refused..
Trying again in 32.00 seconds...

[2015-10-30 20:50:31,075: ERROR/MainProcess] consumer: Cannot connect to redis://127.0.0.1:6379//: Error 111 connecting to 127.0.0.1:6379. Connection refused..
Trying again in 32.00 seconds...

[2015-10-30 20:51:03,111: ERROR/MainProcess] consumer: Cannot connect to redis://127.0.0.1:6379//: Error 111 connecting to 127.0.0.1:6379. Connection refused..
Trying again in 32.00 seconds...

[2015-10-30 20:51:35,149: ERROR/MainProcess] consumer: Cannot connect to redis://127.0.0.1:6379//: Error 111 connecting to 127.0.0.1:6379. Connection refused..
Trying again in 32.00 seconds...

[2015-10-30 20:52:07,185: ERROR/MainProcess] consumer: Cannot connect to redis://127.0.0.1:6379//: Error 111 connecting to 127.0.0.1:6379. Connection refused..
Trying again in 32.00 seconds...

[2015-10-30 20:52:39,223: ERROR/MainProcess] consumer: Cannot connect to redis://127.0.0.1:6379//: Error 111 connecting to 127.0.0.1:6379. Connection refused..
Trying again in 32.00 seconds...

[2015-10-30 20:53:11,260: ERROR/MainProcess] consumer: Cannot connect to redis://127.0.0.1:6379//: Error 111 connecting to 127.0.0.1:6379. Connection refused..
Trying again in 32.00 seconds...

[2015-10-30 20:53:43,297: ERROR/MainProcess] consumer: Cannot connect to redis://127.0.0.1:6379//: Error 111 connecting to 127.0.0.1:6379. Connection refused..
Trying again in 32.00 seconds...

[2015-10-30 20:54:15,334: ERROR/MainProcess] consumer: Cannot connect to redis://127.0.0.1:6379//: Error 111 connecting to 127.0.0.1:6379. Connection refused..
Trying again in 32.00 seconds...

[2015-10-30 20:54:47,372: ERROR/MainProcess] consumer: Cannot connect to redis://127.0.0.1:6379//: Error 111 connecting to 127.0.0.1:6379. Connection refused..
Trying again in 32.00 seconds...

[2015-10-30 20:55:19,410: ERROR/MainProcess] consumer: Cannot connect to redis://127.0.0.1:6379//: Error 111 connecting to 127.0.0.1:6379. Connection refused..
Trying again in 32.00 seconds...

[2015-10-30 20:55:51,447: ERROR/MainProcess] consumer: Cannot connect to redis://127.0.0.1:6379//: Error 111 connecting to 127.0.0.1:6379. Connection refused..
Trying again in 32.00 seconds...

[2015-10-30 20:56:23,484: ERROR/MainProcess] consumer: Cannot connect to redis://127.0.0.1:6379//: Error 111 connecting to 127.0.0.1:6379. Connection refused..
Trying again in 32.00 seconds...

[2015-10-30 20:56:55,522: ERROR/MainProcess] consumer: Cannot connect to redis://127.0.0.1:6379//: Error 111 connecting to 127.0.0.1:6379. Connection refused..
Trying again in 32.00 seconds...

[2015-10-30 20:57:27,560: ERROR/MainProcess] consumer: Cannot connect to redis://127.0.0.1:6379//: Error 111 connecting to 127.0.0.1:6379. Connection refused..
Trying again in 32.00 seconds...

[2015-10-30 20:57:59,600: ERROR/MainProcess] consumer: Cannot connect to redis://127.0.0.1:6379//: Error 111 connecting to 127.0.0.1:6379. Connection refused..
Trying again in 32.00 seconds...

[2015-10-30 20:58:31,638: ERROR/MainProcess] consumer: Cannot connect to redis://127.0.0.1:6379//: Error 111 connecting to 127.0.0.1:6379. Connection refused..
Trying again in 32.00 seconds...

[2015-10-30 20:59:03,676: ERROR/MainProcess] consumer: Cannot connect to redis://127.0.0.1:6379//: Error 111 connecting to 127.0.0.1:6379. Connection refused..
Trying again in 32.00 seconds...

[2015-10-30 20:59:35,722: ERROR/MainProcess] consumer: Cannot connect to redis://127.0.0.1:6379//: Error 111 connecting to 127.0.0.1:6379. Connection refused..
Trying again in 32.00 seconds...

[2015-10-30 21:00:07,760: ERROR/MainProcess] consumer: Cannot connect to redis://127.0.0.1:6379//: Error 111 connecting to 127.0.0.1:6379. Connection refused..
Trying again in 32.00 seconds...

[2015-10-30 21:00:39,799: ERROR/MainProcess] consumer: Cannot connect to redis://127.0.0.1:6379//: Error 111 connecting to 127.0.0.1:6379. Connection refused..
Trying again in 32.00 seconds...

[2015-10-30 21:01:11,837: ERROR/MainProcess] consumer: Cannot connect to redis://127.0.0.1:6379//: Error 111 connecting to 127.0.0.1:6379. Connection refused..
Trying again in 32.00 seconds...

[2015-10-30 21:01:43,878: ERROR/MainProcess] consumer: Cannot connect to redis://127.0.0.1:6379//: Error 111 connecting to 127.0.0.1:6379. Connection refused..
Trying again in 32.00 seconds...

[2015-10-30 21:02:15,917: ERROR/MainProcess] consumer: Cannot connect to redis://127.0.0.1:6379//: Error 111 connecting to 127.0.0.1:6379. Connection refused..
Trying again in 32.00 seconds...

[2015-10-30 21:02:47,955: ERROR/MainProcess] consumer: Cannot connect to redis://127.0.0.1:6379//: Error 111 connecting to 127.0.0.1:6379. Connection refused..
Trying again in 32.00 seconds...

[2015-10-30 21:03:19,993: ERROR/MainProcess] consumer: Cannot connect to redis://127.0.0.1:6379//: Error 111 connecting to 127.0.0.1:6379. Connection refused..
Trying again in 32.00 seconds...

[2015-10-30 21:03:52,028: ERROR/MainProcess] consumer: Cannot connect to redis://127.0.0.1:6379//: Error 111 connecting to 127.0.0.1:6379. Connection refused..
Trying again in 32.00 seconds...

[2015-10-30 21:04:24,065: ERROR/MainProcess] consumer: Cannot connect to redis://127.0.0.1:6379//: Error 111 connecting to 127.0.0.1:6379. Connection refused..
Trying again in 32.00 seconds...

[2015-10-30 21:04:56,101: ERROR/MainProcess] consumer: Cannot connect to redis://127.0.0.1:6379//: Error 111 connecting to 127.0.0.1:6379. Connection refused..
Trying again in 32.00 seconds...

[2015-10-30 21:05:28,138: ERROR/MainProcess] consumer: Cannot connect to redis://127.0.0.1:6379//: Error 111 connecting to 127.0.0.1:6379. Connection refused..
Trying again in 32.00 seconds...

[2015-10-30 21:06:00,176: ERROR/MainProcess] consumer: Cannot connect to redis://127.0.0.1:6379//: Error 111 connecting to 127.0.0.1:6379. Connection refused..
Trying again in 32.00 seconds...

[2015-10-30 21:06:32,213: ERROR/MainProcess] consumer: Cannot connect to redis://127.0.0.1:6379//: Error 111 connecting to 127.0.0.1:6379. Connection refused..
Trying again in 32.00 seconds...

[2015-10-30 21:07:04,250: ERROR/MainProcess] consumer: Cannot connect to redis://127.0.0.1:6379//: Error 111 connecting to 127.0.0.1:6379. Connection refused..
Trying again in 32.00 seconds...

[2015-10-30 21:07:36,287: ERROR/MainProcess] consumer: Cannot connect to redis://127.0.0.1:6379//: Error 111 connecting to 127.0.0.1:6379. Connection refused..
Trying again in 32.00 seconds...

[2015-10-30 21:08:08,324: ERROR/MainProcess] consumer: Cannot connect to redis://127.0.0.1:6379//: Error 111 connecting to 127.0.0.1:6379. Connection refused..
Trying again in 32.00 seconds...

[2015-10-30 21:08:40,362: ERROR/MainProcess] consumer: Cannot connect to redis://127.0.0.1:6379//: Error 111 connecting to 127.0.0.1:6379. Connection refused..
Trying again in 32.00 seconds...

[2015-10-30 21:09:12,399: ERROR/MainProcess] consumer: Cannot connect to redis://127.0.0.1:6379//: Error 111 connecting to 127.0.0.1:6379. Connection refused..
Trying again in 32.00 seconds...

[2015-10-30 21:09:44,436: ERROR/MainProcess] consumer: Cannot connect to redis://127.0.0.1:6379//: Error 111 connecting to 127.0.0.1:6379. Connection refused..
Trying again in 32.00 seconds...

[2015-10-30 21:10:16,474: ERROR/MainProcess] consumer: Cannot connect to redis://127.0.0.1:6379//: Error 111 connecting to 127.0.0.1:6379. Connection refused..
Trying again in 32.00 seconds...

