[2015-10-30 05:21:04,382: WARNING/MainProcess] worker@omega007 ready.
[2015-10-30 05:56:46,546: ERROR/Worker-30] nidaba.segmentation.tesseract[f38e5e52-196e-4fcc-9e0d-e8dfdefb4592]: Tesseract killed by signal: 11
[2015-10-30 05:57:03,540: ERROR/Worker-8] nidaba.segmentation.tesseract[e596ab85-f757-4a59-99b2-0a9cd4273535]: Tesseract killed by signal: 11
[2015-10-30 05:57:10,308: ERROR/MainProcess] Task nidaba.segmentation.tesseract[f38e5e52-196e-4fcc-9e0d-e8dfdefb4592] raised unexpected: NidabaTesseractException(u'Tesseract killed by signal: 11',)
Traceback (most recent call last):
  File "/cluster/home/mmunso01/envs/nidaba/lib/python2.7/site-packages/celery/app/trace.py", line 240, in trace_task
    R = retval = fun(*args, **kwargs)
  File "/cluster/home/mmunso01/envs/nidaba/lib/python2.7/site-packages/nidaba/tasks/helper.py", line 89, in __call__
    ret = super(NidabaTask, self).__call__(*args, **nkwargs)
  File "/cluster/home/mmunso01/envs/nidaba/lib/python2.7/site-packages/celery/app/trace.py", line 438, in __protected_call__
    return self.run(*args, **kwargs)
  File "/cluster/home/mmunso01/envs/nidaba/lib/python2.7/site-packages/nidaba/plugins/tesseract.py", line 251, in segmentation_tesseract
    raise NidabaTesseractException('Tesseract killed by signal: {0}'.format(os.WTERMSIG(status)))
NidabaTesseractException: Tesseract killed by signal: 11
[2015-10-30 05:57:17,065: ERROR/MainProcess] Task nidaba.segmentation.tesseract[e596ab85-f757-4a59-99b2-0a9cd4273535] raised unexpected: NidabaTesseractException(u'Tesseract killed by signal: 11',)
Traceback (most recent call last):
  File "/cluster/home/mmunso01/envs/nidaba/lib/python2.7/site-packages/celery/app/trace.py", line 240, in trace_task
    R = retval = fun(*args, **kwargs)
  File "/cluster/home/mmunso01/envs/nidaba/lib/python2.7/site-packages/nidaba/tasks/helper.py", line 89, in __call__
    ret = super(NidabaTask, self).__call__(*args, **nkwargs)
  File "/cluster/home/mmunso01/envs/nidaba/lib/python2.7/site-packages/celery/app/trace.py", line 438, in __protected_call__
    return self.run(*args, **kwargs)
  File "/cluster/home/mmunso01/envs/nidaba/lib/python2.7/site-packages/nidaba/plugins/tesseract.py", line 251, in segmentation_tesseract
    raise NidabaTesseractException('Tesseract killed by signal: {0}'.format(os.WTERMSIG(status)))
NidabaTesseractException: Tesseract killed by signal: 11
[2015-10-30 06:09:13,290: ERROR/Worker-8] nidaba.segmentation.tesseract[3f72eb0f-f9cd-434d-9435-295588b070ac]: Tesseract killed by signal: 11
[2015-10-30 06:09:15,590: ERROR/MainProcess] Task nidaba.segmentation.tesseract[3f72eb0f-f9cd-434d-9435-295588b070ac] raised unexpected: NidabaTesseractException(u'Tesseract killed by signal: 11',)
Traceback (most recent call last):
  File "/cluster/home/mmunso01/envs/nidaba/lib/python2.7/site-packages/celery/app/trace.py", line 240, in trace_task
    R = retval = fun(*args, **kwargs)
  File "/cluster/home/mmunso01/envs/nidaba/lib/python2.7/site-packages/nidaba/tasks/helper.py", line 89, in __call__
    ret = super(NidabaTask, self).__call__(*args, **nkwargs)
  File "/cluster/home/mmunso01/envs/nidaba/lib/python2.7/site-packages/celery/app/trace.py", line 438, in __protected_call__
    return self.run(*args, **kwargs)
  File "/cluster/home/mmunso01/envs/nidaba/lib/python2.7/site-packages/nidaba/plugins/tesseract.py", line 251, in segmentation_tesseract
    raise NidabaTesseractException('Tesseract killed by signal: {0}'.format(os.WTERMSIG(status)))
NidabaTesseractException: Tesseract killed by signal: 11
[2015-10-30 06:09:59,332: ERROR/Worker-27] nidaba.segmentation.tesseract[1a43f32e-173b-4930-b92f-1da9f4006009]: Tesseract killed by signal: 11
[2015-10-30 06:10:00,879: ERROR/MainProcess] Task nidaba.segmentation.tesseract[1a43f32e-173b-4930-b92f-1da9f4006009] raised unexpected: NidabaTesseractException(u'Tesseract killed by signal: 11',)
Traceback (most recent call last):
  File "/cluster/home/mmunso01/envs/nidaba/lib/python2.7/site-packages/celery/app/trace.py", line 240, in trace_task
    R = retval = fun(*args, **kwargs)
  File "/cluster/home/mmunso01/envs/nidaba/lib/python2.7/site-packages/nidaba/tasks/helper.py", line 89, in __call__
    ret = super(NidabaTask, self).__call__(*args, **nkwargs)
  File "/cluster/home/mmunso01/envs/nidaba/lib/python2.7/site-packages/celery/app/trace.py", line 438, in __protected_call__
    return self.run(*args, **kwargs)
  File "/cluster/home/mmunso01/envs/nidaba/lib/python2.7/site-packages/nidaba/plugins/tesseract.py", line 251, in segmentation_tesseract
    raise NidabaTesseractException('Tesseract killed by signal: {0}'.format(os.WTERMSIG(status)))
NidabaTesseractException: Tesseract killed by signal: 11
[2015-10-30 06:19:02,088: ERROR/Worker-6] nidaba.ocr.kraken[9f9c0b8e-a4c2-4d87-aeb0-fd1101d50fa5]: index 5000 is out of bounds for axis 0 with size 5000
[2015-10-30 06:19:03,565: ERROR/MainProcess] Task nidaba.ocr.kraken[9f9c0b8e-a4c2-4d87-aeb0-fd1101d50fa5] raised unexpected: IndexError('index 5000 is out of bounds for axis 0 with size 5000',)
Traceback (most recent call last):
  File "/cluster/home/mmunso01/envs/nidaba/lib/python2.7/site-packages/celery/app/trace.py", line 240, in trace_task
    R = retval = fun(*args, **kwargs)
  File "/cluster/home/mmunso01/envs/nidaba/lib/python2.7/site-packages/nidaba/tasks/helper.py", line 89, in __call__
    ret = super(NidabaTask, self).__call__(*args, **nkwargs)
  File "/cluster/home/mmunso01/envs/nidaba/lib/python2.7/site-packages/celery/app/trace.py", line 438, in __protected_call__
    return self.run(*args, **kwargs)
  File "/cluster/home/mmunso01/envs/nidaba/lib/python2.7/site-packages/nidaba/plugins/kraken.py", line 155, in ocr_kraken
    for rec in rpred.rpred(rnn, img, [(int(x[0]), int(x[1]), int(x[2]), int(x[3])) for x in lines]):
  File "/cluster/home/mmunso01/envs/nidaba/lib/python2.7/site-packages/kraken/rpred.py", line 134, in rpred
    pred = network.predictString(line)
  File "/cluster/home/mmunso01/envs/nidaba/lib/python2.7/site-packages/kraken/lib/lstm.py", line 281, in predictString
    cs = self.predictSequence(xs)
  File "/cluster/home/mmunso01/envs/nidaba/lib/python2.7/site-packages/kraken/lib/lstm.py", line 273, in predictSequence
    self.outputs = np.array(self.lstm.forward(xs))
  File "/cluster/home/mmunso01/envs/nidaba/lib/python2.7/site-packages/kraken/lib/lstm.py", line 229, in forward
    xs = net.forward(xs)
  File "/cluster/home/mmunso01/envs/nidaba/lib/python2.7/site-packages/kraken/lib/lstm.py", line 244, in forward
    outputs = [net.forward(xs) for net in self.nets]
  File "/cluster/home/mmunso01/envs/nidaba/lib/python2.7/site-packages/kraken/lib/lstm.py", line 196, in forward
    self.source[t,0] = 1
IndexError: index 5000 is out of bounds for axis 0 with size 5000
[2015-10-30 06:48:59,863: ERROR/Worker-37] nidaba.ocr.kraken[cc39f02b-9d4b-4885-9a32-8eac1f82c6e1]: index 5000 is out of bounds for axis 0 with size 5000
[2015-10-30 06:49:03,096: ERROR/MainProcess] Task nidaba.ocr.kraken[cc39f02b-9d4b-4885-9a32-8eac1f82c6e1] raised unexpected: IndexError('index 5000 is out of bounds for axis 0 with size 5000',)
Traceback (most recent call last):
  File "/cluster/home/mmunso01/envs/nidaba/lib/python2.7/site-packages/celery/app/trace.py", line 240, in trace_task
    R = retval = fun(*args, **kwargs)
  File "/cluster/home/mmunso01/envs/nidaba/lib/python2.7/site-packages/nidaba/tasks/helper.py", line 89, in __call__
    ret = super(NidabaTask, self).__call__(*args, **nkwargs)
  File "/cluster/home/mmunso01/envs/nidaba/lib/python2.7/site-packages/celery/app/trace.py", line 438, in __protected_call__
    return self.run(*args, **kwargs)
  File "/cluster/home/mmunso01/envs/nidaba/lib/python2.7/site-packages/nidaba/plugins/kraken.py", line 155, in ocr_kraken
    for rec in rpred.rpred(rnn, img, [(int(x[0]), int(x[1]), int(x[2]), int(x[3])) for x in lines]):
  File "/cluster/home/mmunso01/envs/nidaba/lib/python2.7/site-packages/kraken/rpred.py", line 134, in rpred
    pred = network.predictString(line)
  File "/cluster/home/mmunso01/envs/nidaba/lib/python2.7/site-packages/kraken/lib/lstm.py", line 281, in predictString
    cs = self.predictSequence(xs)
  File "/cluster/home/mmunso01/envs/nidaba/lib/python2.7/site-packages/kraken/lib/lstm.py", line 273, in predictSequence
    self.outputs = np.array(self.lstm.forward(xs))
  File "/cluster/home/mmunso01/envs/nidaba/lib/python2.7/site-packages/kraken/lib/lstm.py", line 229, in forward
    xs = net.forward(xs)
  File "/cluster/home/mmunso01/envs/nidaba/lib/python2.7/site-packages/kraken/lib/lstm.py", line 244, in forward
    outputs = [net.forward(xs) for net in self.nets]
  File "/cluster/home/mmunso01/envs/nidaba/lib/python2.7/site-packages/kraken/lib/lstm.py", line 196, in forward
    self.source[t,0] = 1
IndexError: index 5000 is out of bounds for axis 0 with size 5000
[2015-10-30 06:50:01,966: ERROR/Worker-11] nidaba.ocr.kraken[05a9395c-a05a-447d-9d1c-da1b6a8add96]: index 5000 is out of bounds for axis 0 with size 5000
[2015-10-30 06:50:03,724: ERROR/MainProcess] Task nidaba.ocr.kraken[05a9395c-a05a-447d-9d1c-da1b6a8add96] raised unexpected: IndexError('index 5000 is out of bounds for axis 0 with size 5000',)
Traceback (most recent call last):
  File "/cluster/home/mmunso01/envs/nidaba/lib/python2.7/site-packages/celery/app/trace.py", line 240, in trace_task
    R = retval = fun(*args, **kwargs)
  File "/cluster/home/mmunso01/envs/nidaba/lib/python2.7/site-packages/nidaba/tasks/helper.py", line 89, in __call__
    ret = super(NidabaTask, self).__call__(*args, **nkwargs)
  File "/cluster/home/mmunso01/envs/nidaba/lib/python2.7/site-packages/celery/app/trace.py", line 438, in __protected_call__
    return self.run(*args, **kwargs)
  File "/cluster/home/mmunso01/envs/nidaba/lib/python2.7/site-packages/nidaba/plugins/kraken.py", line 155, in ocr_kraken
    for rec in rpred.rpred(rnn, img, [(int(x[0]), int(x[1]), int(x[2]), int(x[3])) for x in lines]):
  File "/cluster/home/mmunso01/envs/nidaba/lib/python2.7/site-packages/kraken/rpred.py", line 134, in rpred
    pred = network.predictString(line)
  File "/cluster/home/mmunso01/envs/nidaba/lib/python2.7/site-packages/kraken/lib/lstm.py", line 281, in predictString
    cs = self.predictSequence(xs)
  File "/cluster/home/mmunso01/envs/nidaba/lib/python2.7/site-packages/kraken/lib/lstm.py", line 273, in predictSequence
    self.outputs = np.array(self.lstm.forward(xs))
  File "/cluster/home/mmunso01/envs/nidaba/lib/python2.7/site-packages/kraken/lib/lstm.py", line 229, in forward
    xs = net.forward(xs)
  File "/cluster/home/mmunso01/envs/nidaba/lib/python2.7/site-packages/kraken/lib/lstm.py", line 244, in forward
    outputs = [net.forward(xs) for net in self.nets]
  File "/cluster/home/mmunso01/envs/nidaba/lib/python2.7/site-packages/kraken/lib/lstm.py", line 196, in forward
    self.source[t,0] = 1
IndexError: index 5000 is out of bounds for axis 0 with size 5000
[2015-10-30 06:50:12,471: ERROR/Worker-32] nidaba.ocr.kraken[c8bb5e58-eb5f-4d1b-befa-8ca71ebd3d3b]: index 5000 is out of bounds for axis 0 with size 5000
[2015-10-30 06:50:13,834: ERROR/MainProcess] Task nidaba.ocr.kraken[c8bb5e58-eb5f-4d1b-befa-8ca71ebd3d3b] raised unexpected: IndexError('index 5000 is out of bounds for axis 0 with size 5000',)
Traceback (most recent call last):
  File "/cluster/home/mmunso01/envs/nidaba/lib/python2.7/site-packages/celery/app/trace.py", line 240, in trace_task
    R = retval = fun(*args, **kwargs)
  File "/cluster/home/mmunso01/envs/nidaba/lib/python2.7/site-packages/nidaba/tasks/helper.py", line 89, in __call__
    ret = super(NidabaTask, self).__call__(*args, **nkwargs)
  File "/cluster/home/mmunso01/envs/nidaba/lib/python2.7/site-packages/celery/app/trace.py", line 438, in __protected_call__
    return self.run(*args, **kwargs)
  File "/cluster/home/mmunso01/envs/nidaba/lib/python2.7/site-packages/nidaba/plugins/kraken.py", line 155, in ocr_kraken
    for rec in rpred.rpred(rnn, img, [(int(x[0]), int(x[1]), int(x[2]), int(x[3])) for x in lines]):
  File "/cluster/home/mmunso01/envs/nidaba/lib/python2.7/site-packages/kraken/rpred.py", line 134, in rpred
    pred = network.predictString(line)
  File "/cluster/home/mmunso01/envs/nidaba/lib/python2.7/site-packages/kraken/lib/lstm.py", line 281, in predictString
    cs = self.predictSequence(xs)
  File "/cluster/home/mmunso01/envs/nidaba/lib/python2.7/site-packages/kraken/lib/lstm.py", line 273, in predictSequence
    self.outputs = np.array(self.lstm.forward(xs))
  File "/cluster/home/mmunso01/envs/nidaba/lib/python2.7/site-packages/kraken/lib/lstm.py", line 229, in forward
    xs = net.forward(xs)
  File "/cluster/home/mmunso01/envs/nidaba/lib/python2.7/site-packages/kraken/lib/lstm.py", line 244, in forward
    outputs = [net.forward(xs) for net in self.nets]
  File "/cluster/home/mmunso01/envs/nidaba/lib/python2.7/site-packages/kraken/lib/lstm.py", line 196, in forward
    self.source[t,0] = 1
IndexError: index 5000 is out of bounds for axis 0 with size 5000
[2015-10-30 06:50:38,032: ERROR/Worker-12] nidaba.ocr.kraken[1148a8f4-241f-4333-b868-c98d3d6953b8]: index 5000 is out of bounds for axis 0 with size 5000
[2015-10-30 06:50:44,645: ERROR/MainProcess] Task nidaba.ocr.kraken[1148a8f4-241f-4333-b868-c98d3d6953b8] raised unexpected: IndexError('index 5000 is out of bounds for axis 0 with size 5000',)
Traceback (most recent call last):
  File "/cluster/home/mmunso01/envs/nidaba/lib/python2.7/site-packages/celery/app/trace.py", line 240, in trace_task
    R = retval = fun(*args, **kwargs)
  File "/cluster/home/mmunso01/envs/nidaba/lib/python2.7/site-packages/nidaba/tasks/helper.py", line 89, in __call__
    ret = super(NidabaTask, self).__call__(*args, **nkwargs)
  File "/cluster/home/mmunso01/envs/nidaba/lib/python2.7/site-packages/celery/app/trace.py", line 438, in __protected_call__
    return self.run(*args, **kwargs)
  File "/cluster/home/mmunso01/envs/nidaba/lib/python2.7/site-packages/nidaba/plugins/kraken.py", line 155, in ocr_kraken
    for rec in rpred.rpred(rnn, img, [(int(x[0]), int(x[1]), int(x[2]), int(x[3])) for x in lines]):
  File "/cluster/home/mmunso01/envs/nidaba/lib/python2.7/site-packages/kraken/rpred.py", line 134, in rpred
    pred = network.predictString(line)
  File "/cluster/home/mmunso01/envs/nidaba/lib/python2.7/site-packages/kraken/lib/lstm.py", line 281, in predictString
    cs = self.predictSequence(xs)
  File "/cluster/home/mmunso01/envs/nidaba/lib/python2.7/site-packages/kraken/lib/lstm.py", line 273, in predictSequence
    self.outputs = np.array(self.lstm.forward(xs))
  File "/cluster/home/mmunso01/envs/nidaba/lib/python2.7/site-packages/kraken/lib/lstm.py", line 229, in forward
    xs = net.forward(xs)
  File "/cluster/home/mmunso01/envs/nidaba/lib/python2.7/site-packages/kraken/lib/lstm.py", line 244, in forward
    outputs = [net.forward(xs) for net in self.nets]
  File "/cluster/home/mmunso01/envs/nidaba/lib/python2.7/site-packages/kraken/lib/lstm.py", line 196, in forward
    self.source[t,0] = 1
IndexError: index 5000 is out of bounds for axis 0 with size 5000
[2015-10-30 06:50:54,612: ERROR/Worker-24] nidaba.ocr.kraken[66212ac1-a4db-41e0-bcee-3d4ca81c48fd]: index 5000 is out of bounds for axis 0 with size 5000
[2015-10-30 06:50:57,786: ERROR/MainProcess] Task nidaba.ocr.kraken[66212ac1-a4db-41e0-bcee-3d4ca81c48fd] raised unexpected: IndexError('index 5000 is out of bounds for axis 0 with size 5000',)
Traceback (most recent call last):
  File "/cluster/home/mmunso01/envs/nidaba/lib/python2.7/site-packages/celery/app/trace.py", line 240, in trace_task
    R = retval = fun(*args, **kwargs)
  File "/cluster/home/mmunso01/envs/nidaba/lib/python2.7/site-packages/nidaba/tasks/helper.py", line 89, in __call__
    ret = super(NidabaTask, self).__call__(*args, **nkwargs)
  File "/cluster/home/mmunso01/envs/nidaba/lib/python2.7/site-packages/celery/app/trace.py", line 438, in __protected_call__
    return self.run(*args, **kwargs)
  File "/cluster/home/mmunso01/envs/nidaba/lib/python2.7/site-packages/nidaba/plugins/kraken.py", line 155, in ocr_kraken
    for rec in rpred.rpred(rnn, img, [(int(x[0]), int(x[1]), int(x[2]), int(x[3])) for x in lines]):
  File "/cluster/home/mmunso01/envs/nidaba/lib/python2.7/site-packages/kraken/rpred.py", line 134, in rpred
    pred = network.predictString(line)
  File "/cluster/home/mmunso01/envs/nidaba/lib/python2.7/site-packages/kraken/lib/lstm.py", line 281, in predictString
    cs = self.predictSequence(xs)
  File "/cluster/home/mmunso01/envs/nidaba/lib/python2.7/site-packages/kraken/lib/lstm.py", line 273, in predictSequence
    self.outputs = np.array(self.lstm.forward(xs))
  File "/cluster/home/mmunso01/envs/nidaba/lib/python2.7/site-packages/kraken/lib/lstm.py", line 229, in forward
    xs = net.forward(xs)
  File "/cluster/home/mmunso01/envs/nidaba/lib/python2.7/site-packages/kraken/lib/lstm.py", line 244, in forward
    outputs = [net.forward(xs) for net in self.nets]
  File "/cluster/home/mmunso01/envs/nidaba/lib/python2.7/site-packages/kraken/lib/lstm.py", line 196, in forward
    self.source[t,0] = 1
IndexError: index 5000 is out of bounds for axis 0 with size 5000
[2015-10-30 06:51:08,972: ERROR/Worker-9] nidaba.ocr.kraken[7a34fbf4-871a-4b47-ac68-0f1c20029034]: index 5000 is out of bounds for axis 0 with size 5000
[2015-10-30 06:51:13,675: ERROR/MainProcess] Task nidaba.ocr.kraken[7a34fbf4-871a-4b47-ac68-0f1c20029034] raised unexpected: IndexError('index 5000 is out of bounds for axis 0 with size 5000',)
Traceback (most recent call last):
  File "/cluster/home/mmunso01/envs/nidaba/lib/python2.7/site-packages/celery/app/trace.py", line 240, in trace_task
    R = retval = fun(*args, **kwargs)
  File "/cluster/home/mmunso01/envs/nidaba/lib/python2.7/site-packages/nidaba/tasks/helper.py", line 89, in __call__
    ret = super(NidabaTask, self).__call__(*args, **nkwargs)
  File "/cluster/home/mmunso01/envs/nidaba/lib/python2.7/site-packages/celery/app/trace.py", line 438, in __protected_call__
    return self.run(*args, **kwargs)
  File "/cluster/home/mmunso01/envs/nidaba/lib/python2.7/site-packages/nidaba/plugins/kraken.py", line 155, in ocr_kraken
    for rec in rpred.rpred(rnn, img, [(int(x[0]), int(x[1]), int(x[2]), int(x[3])) for x in lines]):
  File "/cluster/home/mmunso01/envs/nidaba/lib/python2.7/site-packages/kraken/rpred.py", line 134, in rpred
    pred = network.predictString(line)
  File "/cluster/home/mmunso01/envs/nidaba/lib/python2.7/site-packages/kraken/lib/lstm.py", line 281, in predictString
    cs = self.predictSequence(xs)
  File "/cluster/home/mmunso01/envs/nidaba/lib/python2.7/site-packages/kraken/lib/lstm.py", line 273, in predictSequence
    self.outputs = np.array(self.lstm.forward(xs))
  File "/cluster/home/mmunso01/envs/nidaba/lib/python2.7/site-packages/kraken/lib/lstm.py", line 229, in forward
    xs = net.forward(xs)
  File "/cluster/home/mmunso01/envs/nidaba/lib/python2.7/site-packages/kraken/lib/lstm.py", line 244, in forward
    outputs = [net.forward(xs) for net in self.nets]
  File "/cluster/home/mmunso01/envs/nidaba/lib/python2.7/site-packages/kraken/lib/lstm.py", line 196, in forward
    self.source[t,0] = 1
IndexError: index 5000 is out of bounds for axis 0 with size 5000
[2015-10-30 06:52:08,685: ERROR/Worker-35] nidaba.ocr.kraken[bcea63d5-8847-4896-b50f-2a8235fae810]: index 5000 is out of bounds for axis 0 with size 5000
[2015-10-30 06:52:09,996: ERROR/MainProcess] Task nidaba.ocr.kraken[bcea63d5-8847-4896-b50f-2a8235fae810] raised unexpected: IndexError('index 5000 is out of bounds for axis 0 with size 5000',)
Traceback (most recent call last):
  File "/cluster/home/mmunso01/envs/nidaba/lib/python2.7/site-packages/celery/app/trace.py", line 240, in trace_task
    R = retval = fun(*args, **kwargs)
  File "/cluster/home/mmunso01/envs/nidaba/lib/python2.7/site-packages/nidaba/tasks/helper.py", line 89, in __call__
    ret = super(NidabaTask, self).__call__(*args, **nkwargs)
  File "/cluster/home/mmunso01/envs/nidaba/lib/python2.7/site-packages/celery/app/trace.py", line 438, in __protected_call__
    return self.run(*args, **kwargs)
  File "/cluster/home/mmunso01/envs/nidaba/lib/python2.7/site-packages/nidaba/plugins/kraken.py", line 155, in ocr_kraken
    for rec in rpred.rpred(rnn, img, [(int(x[0]), int(x[1]), int(x[2]), int(x[3])) for x in lines]):
  File "/cluster/home/mmunso01/envs/nidaba/lib/python2.7/site-packages/kraken/rpred.py", line 134, in rpred
    pred = network.predictString(line)
  File "/cluster/home/mmunso01/envs/nidaba/lib/python2.7/site-packages/kraken/lib/lstm.py", line 281, in predictString
    cs = self.predictSequence(xs)
  File "/cluster/home/mmunso01/envs/nidaba/lib/python2.7/site-packages/kraken/lib/lstm.py", line 273, in predictSequence
    self.outputs = np.array(self.lstm.forward(xs))
  File "/cluster/home/mmunso01/envs/nidaba/lib/python2.7/site-packages/kraken/lib/lstm.py", line 229, in forward
    xs = net.forward(xs)
  File "/cluster/home/mmunso01/envs/nidaba/lib/python2.7/site-packages/kraken/lib/lstm.py", line 244, in forward
    outputs = [net.forward(xs) for net in self.nets]
  File "/cluster/home/mmunso01/envs/nidaba/lib/python2.7/site-packages/kraken/lib/lstm.py", line 196, in forward
    self.source[t,0] = 1
IndexError: index 5000 is out of bounds for axis 0 with size 5000
[2015-10-30 06:52:15,612: ERROR/Worker-6] nidaba.ocr.kraken[f0a412c9-66cf-471a-a994-34f306a9efdd]: index 5000 is out of bounds for axis 0 with size 5000
[2015-10-30 06:52:18,808: ERROR/MainProcess] Task nidaba.ocr.kraken[f0a412c9-66cf-471a-a994-34f306a9efdd] raised unexpected: IndexError('index 5000 is out of bounds for axis 0 with size 5000',)
Traceback (most recent call last):
  File "/cluster/home/mmunso01/envs/nidaba/lib/python2.7/site-packages/celery/app/trace.py", line 240, in trace_task
    R = retval = fun(*args, **kwargs)
  File "/cluster/home/mmunso01/envs/nidaba/lib/python2.7/site-packages/nidaba/tasks/helper.py", line 89, in __call__
    ret = super(NidabaTask, self).__call__(*args, **nkwargs)
  File "/cluster/home/mmunso01/envs/nidaba/lib/python2.7/site-packages/celery/app/trace.py", line 438, in __protected_call__
    return self.run(*args, **kwargs)
  File "/cluster/home/mmunso01/envs/nidaba/lib/python2.7/site-packages/nidaba/plugins/kraken.py", line 155, in ocr_kraken
    for rec in rpred.rpred(rnn, img, [(int(x[0]), int(x[1]), int(x[2]), int(x[3])) for x in lines]):
  File "/cluster/home/mmunso01/envs/nidaba/lib/python2.7/site-packages/kraken/rpred.py", line 134, in rpred
    pred = network.predictString(line)
  File "/cluster/home/mmunso01/envs/nidaba/lib/python2.7/site-packages/kraken/lib/lstm.py", line 281, in predictString
    cs = self.predictSequence(xs)
  File "/cluster/home/mmunso01/envs/nidaba/lib/python2.7/site-packages/kraken/lib/lstm.py", line 273, in predictSequence
    self.outputs = np.array(self.lstm.forward(xs))
  File "/cluster/home/mmunso01/envs/nidaba/lib/python2.7/site-packages/kraken/lib/lstm.py", line 229, in forward
    xs = net.forward(xs)
  File "/cluster/home/mmunso01/envs/nidaba/lib/python2.7/site-packages/kraken/lib/lstm.py", line 244, in forward
    outputs = [net.forward(xs) for net in self.nets]
  File "/cluster/home/mmunso01/envs/nidaba/lib/python2.7/site-packages/kraken/lib/lstm.py", line 196, in forward
    self.source[t,0] = 1
IndexError: index 5000 is out of bounds for axis 0 with size 5000
[2015-10-30 06:52:56,001: ERROR/Worker-2] nidaba.ocr.kraken[f0e7beed-1661-4516-8c0b-75914cc3dad3]: float division by zero
[2015-10-30 06:52:57,119: ERROR/MainProcess] Task nidaba.ocr.kraken[f0e7beed-1661-4516-8c0b-75914cc3dad3] raised unexpected: ZeroDivisionError('float division by zero',)
Traceback (most recent call last):
  File "/cluster/home/mmunso01/envs/nidaba/lib/python2.7/site-packages/celery/app/trace.py", line 240, in trace_task
    R = retval = fun(*args, **kwargs)
  File "/cluster/home/mmunso01/envs/nidaba/lib/python2.7/site-packages/nidaba/tasks/helper.py", line 89, in __call__
    ret = super(NidabaTask, self).__call__(*args, **nkwargs)
  File "/cluster/home/mmunso01/envs/nidaba/lib/python2.7/site-packages/celery/app/trace.py", line 438, in __protected_call__
    return self.run(*args, **kwargs)
  File "/cluster/home/mmunso01/envs/nidaba/lib/python2.7/site-packages/nidaba/plugins/kraken.py", line 155, in ocr_kraken
    for rec in rpred.rpred(rnn, img, [(int(x[0]), int(x[1]), int(x[2]), int(x[3])) for x in lines]):
  File "/cluster/home/mmunso01/envs/nidaba/lib/python2.7/site-packages/kraken/rpred.py", line 127, in rpred
    box = dewarp(lnorm, box)
  File "/cluster/home/mmunso01/envs/nidaba/lib/python2.7/site-packages/kraken/rpred.py", line 93, in dewarp
    line = normalizer.normalize(line, cval=np.amax(line))
  File "/cluster/home/mmunso01/envs/nidaba/lib/python2.7/site-packages/kraken/lib/lineest.py", line 60, in normalize
    dtype=dtype, cval=cval)
  File "/cluster/home/mmunso01/envs/nidaba/lib/python2.7/site-packages/kraken/lib/lineest.py", line 13, in scale_to_h
    scale = target_height*1.0/h
ZeroDivisionError: float division by zero
[2015-10-30 06:53:44,784: ERROR/Worker-4] nidaba.ocr.kraken[bf9b1756-6c79-4b08-9876-f7ac09d42edd]: index 5000 is out of bounds for axis 0 with size 5000
[2015-10-30 06:53:45,885: ERROR/MainProcess] Task nidaba.ocr.kraken[bf9b1756-6c79-4b08-9876-f7ac09d42edd] raised unexpected: IndexError('index 5000 is out of bounds for axis 0 with size 5000',)
Traceback (most recent call last):
  File "/cluster/home/mmunso01/envs/nidaba/lib/python2.7/site-packages/celery/app/trace.py", line 240, in trace_task
    R = retval = fun(*args, **kwargs)
  File "/cluster/home/mmunso01/envs/nidaba/lib/python2.7/site-packages/nidaba/tasks/helper.py", line 89, in __call__
    ret = super(NidabaTask, self).__call__(*args, **nkwargs)
  File "/cluster/home/mmunso01/envs/nidaba/lib/python2.7/site-packages/celery/app/trace.py", line 438, in __protected_call__
    return self.run(*args, **kwargs)
  File "/cluster/home/mmunso01/envs/nidaba/lib/python2.7/site-packages/nidaba/plugins/kraken.py", line 155, in ocr_kraken
    for rec in rpred.rpred(rnn, img, [(int(x[0]), int(x[1]), int(x[2]), int(x[3])) for x in lines]):
  File "/cluster/home/mmunso01/envs/nidaba/lib/python2.7/site-packages/kraken/rpred.py", line 134, in rpred
    pred = network.predictString(line)
  File "/cluster/home/mmunso01/envs/nidaba/lib/python2.7/site-packages/kraken/lib/lstm.py", line 281, in predictString
    cs = self.predictSequence(xs)
  File "/cluster/home/mmunso01/envs/nidaba/lib/python2.7/site-packages/kraken/lib/lstm.py", line 273, in predictSequence
    self.outputs = np.array(self.lstm.forward(xs))
  File "/cluster/home/mmunso01/envs/nidaba/lib/python2.7/site-packages/kraken/lib/lstm.py", line 229, in forward
    xs = net.forward(xs)
  File "/cluster/home/mmunso01/envs/nidaba/lib/python2.7/site-packages/kraken/lib/lstm.py", line 244, in forward
    outputs = [net.forward(xs) for net in self.nets]
  File "/cluster/home/mmunso01/envs/nidaba/lib/python2.7/site-packages/kraken/lib/lstm.py", line 196, in forward
    self.source[t,0] = 1
IndexError: index 5000 is out of bounds for axis 0 with size 5000
[2015-10-30 06:55:02,626: ERROR/Worker-20] nidaba.ocr.kraken[897739e6-9946-45f9-905a-ef04f4bf3cf1]: index 5000 is out of bounds for axis 0 with size 5000
[2015-10-30 06:55:03,474: ERROR/MainProcess] Task nidaba.ocr.kraken[897739e6-9946-45f9-905a-ef04f4bf3cf1] raised unexpected: IndexError('index 5000 is out of bounds for axis 0 with size 5000',)
Traceback (most recent call last):
  File "/cluster/home/mmunso01/envs/nidaba/lib/python2.7/site-packages/celery/app/trace.py", line 240, in trace_task
    R = retval = fun(*args, **kwargs)
  File "/cluster/home/mmunso01/envs/nidaba/lib/python2.7/site-packages/nidaba/tasks/helper.py", line 89, in __call__
    ret = super(NidabaTask, self).__call__(*args, **nkwargs)
  File "/cluster/home/mmunso01/envs/nidaba/lib/python2.7/site-packages/celery/app/trace.py", line 438, in __protected_call__
    return self.run(*args, **kwargs)
  File "/cluster/home/mmunso01/envs/nidaba/lib/python2.7/site-packages/nidaba/plugins/kraken.py", line 155, in ocr_kraken
    for rec in rpred.rpred(rnn, img, [(int(x[0]), int(x[1]), int(x[2]), int(x[3])) for x in lines]):
  File "/cluster/home/mmunso01/envs/nidaba/lib/python2.7/site-packages/kraken/rpred.py", line 134, in rpred
    pred = network.predictString(line)
  File "/cluster/home/mmunso01/envs/nidaba/lib/python2.7/site-packages/kraken/lib/lstm.py", line 281, in predictString
    cs = self.predictSequence(xs)
  File "/cluster/home/mmunso01/envs/nidaba/lib/python2.7/site-packages/kraken/lib/lstm.py", line 273, in predictSequence
    self.outputs = np.array(self.lstm.forward(xs))
  File "/cluster/home/mmunso01/envs/nidaba/lib/python2.7/site-packages/kraken/lib/lstm.py", line 229, in forward
    xs = net.forward(xs)
  File "/cluster/home/mmunso01/envs/nidaba/lib/python2.7/site-packages/kraken/lib/lstm.py", line 244, in forward
    outputs = [net.forward(xs) for net in self.nets]
  File "/cluster/home/mmunso01/envs/nidaba/lib/python2.7/site-packages/kraken/lib/lstm.py", line 196, in forward
    self.source[t,0] = 1
IndexError: index 5000 is out of bounds for axis 0 with size 5000
[2015-10-30 06:55:50,214: ERROR/Worker-33] nidaba.ocr.kraken[cc543717-b380-4d64-abbb-96181a4e9529]: index 5000 is out of bounds for axis 0 with size 5000
[2015-10-30 06:55:50,604: ERROR/MainProcess] Task nidaba.ocr.kraken[cc543717-b380-4d64-abbb-96181a4e9529] raised unexpected: IndexError('index 5000 is out of bounds for axis 0 with size 5000',)
Traceback (most recent call last):
  File "/cluster/home/mmunso01/envs/nidaba/lib/python2.7/site-packages/celery/app/trace.py", line 240, in trace_task
    R = retval = fun(*args, **kwargs)
  File "/cluster/home/mmunso01/envs/nidaba/lib/python2.7/site-packages/nidaba/tasks/helper.py", line 89, in __call__
    ret = super(NidabaTask, self).__call__(*args, **nkwargs)
  File "/cluster/home/mmunso01/envs/nidaba/lib/python2.7/site-packages/celery/app/trace.py", line 438, in __protected_call__
    return self.run(*args, **kwargs)
  File "/cluster/home/mmunso01/envs/nidaba/lib/python2.7/site-packages/nidaba/plugins/kraken.py", line 155, in ocr_kraken
    for rec in rpred.rpred(rnn, img, [(int(x[0]), int(x[1]), int(x[2]), int(x[3])) for x in lines]):
  File "/cluster/home/mmunso01/envs/nidaba/lib/python2.7/site-packages/kraken/rpred.py", line 134, in rpred
    pred = network.predictString(line)
  File "/cluster/home/mmunso01/envs/nidaba/lib/python2.7/site-packages/kraken/lib/lstm.py", line 281, in predictString
    cs = self.predictSequence(xs)
  File "/cluster/home/mmunso01/envs/nidaba/lib/python2.7/site-packages/kraken/lib/lstm.py", line 273, in predictSequence
    self.outputs = np.array(self.lstm.forward(xs))
  File "/cluster/home/mmunso01/envs/nidaba/lib/python2.7/site-packages/kraken/lib/lstm.py", line 229, in forward
    xs = net.forward(xs)
  File "/cluster/home/mmunso01/envs/nidaba/lib/python2.7/site-packages/kraken/lib/lstm.py", line 244, in forward
    outputs = [net.forward(xs) for net in self.nets]
  File "/cluster/home/mmunso01/envs/nidaba/lib/python2.7/site-packages/kraken/lib/lstm.py", line 196, in forward
    self.source[t,0] = 1
IndexError: index 5000 is out of bounds for axis 0 with size 5000
[2015-10-30 06:56:08,842: ERROR/Worker-33] nidaba.ocr.kraken[1c9adf4c-48d4-483d-b07d-c30fcaede4ae]: index 5000 is out of bounds for axis 0 with size 5000
[2015-10-30 06:56:09,156: ERROR/MainProcess] Task nidaba.ocr.kraken[1c9adf4c-48d4-483d-b07d-c30fcaede4ae] raised unexpected: IndexError('index 5000 is out of bounds for axis 0 with size 5000',)
Traceback (most recent call last):
  File "/cluster/home/mmunso01/envs/nidaba/lib/python2.7/site-packages/celery/app/trace.py", line 240, in trace_task
    R = retval = fun(*args, **kwargs)
  File "/cluster/home/mmunso01/envs/nidaba/lib/python2.7/site-packages/nidaba/tasks/helper.py", line 89, in __call__
    ret = super(NidabaTask, self).__call__(*args, **nkwargs)
  File "/cluster/home/mmunso01/envs/nidaba/lib/python2.7/site-packages/celery/app/trace.py", line 438, in __protected_call__
    return self.run(*args, **kwargs)
  File "/cluster/home/mmunso01/envs/nidaba/lib/python2.7/site-packages/nidaba/plugins/kraken.py", line 155, in ocr_kraken
    for rec in rpred.rpred(rnn, img, [(int(x[0]), int(x[1]), int(x[2]), int(x[3])) for x in lines]):
  File "/cluster/home/mmunso01/envs/nidaba/lib/python2.7/site-packages/kraken/rpred.py", line 134, in rpred
    pred = network.predictString(line)
  File "/cluster/home/mmunso01/envs/nidaba/lib/python2.7/site-packages/kraken/lib/lstm.py", line 281, in predictString
    cs = self.predictSequence(xs)
  File "/cluster/home/mmunso01/envs/nidaba/lib/python2.7/site-packages/kraken/lib/lstm.py", line 273, in predictSequence
    self.outputs = np.array(self.lstm.forward(xs))
  File "/cluster/home/mmunso01/envs/nidaba/lib/python2.7/site-packages/kraken/lib/lstm.py", line 229, in forward
    xs = net.forward(xs)
  File "/cluster/home/mmunso01/envs/nidaba/lib/python2.7/site-packages/kraken/lib/lstm.py", line 244, in forward
    outputs = [net.forward(xs) for net in self.nets]
  File "/cluster/home/mmunso01/envs/nidaba/lib/python2.7/site-packages/kraken/lib/lstm.py", line 196, in forward
    self.source[t,0] = 1
IndexError: index 5000 is out of bounds for axis 0 with size 5000
