[2015-10-30 05:21:05,692: WARNING/MainProcess] worker@alpha005 ready.
[2015-10-30 05:34:48,367: WARNING/Worker-10] /cluster/home/mmunso01/envs/nidaba/lib/python2.7/site-packages/scipy/ndimage/interpolation.py:549: UserWarning: From scipy 0.13.0, the output shape of zoom() is calculated with round() instead of int() - for these inputs the size of the returned array has changed.
  "the returned array has changed.", UserWarning)
[2015-10-30 05:42:29,478: WARNING/Worker-23] /cluster/home/mmunso01/envs/nidaba/lib/python2.7/site-packages/scipy/ndimage/interpolation.py:549: UserWarning: From scipy 0.13.0, the output shape of zoom() is calculated with round() instead of int() - for these inputs the size of the returned array has changed.
  "the returned array has changed.", UserWarning)
[2015-10-30 05:42:46,189: WARNING/Worker-4] /cluster/home/mmunso01/envs/nidaba/lib/python2.7/site-packages/scipy/ndimage/interpolation.py:549: UserWarning: From scipy 0.13.0, the output shape of zoom() is calculated with round() instead of int() - for these inputs the size of the returned array has changed.
  "the returned array has changed.", UserWarning)
[2015-10-30 05:58:32,504: WARNING/Worker-16] /cluster/home/mmunso01/envs/nidaba/lib/python2.7/site-packages/scipy/ndimage/interpolation.py:549: UserWarning: From scipy 0.13.0, the output shape of zoom() is calculated with round() instead of int() - for these inputs the size of the returned array has changed.
  "the returned array has changed.", UserWarning)
[2015-10-30 05:58:33,729: WARNING/Worker-24] /cluster/home/mmunso01/envs/nidaba/lib/python2.7/site-packages/scipy/ndimage/interpolation.py:549: UserWarning: From scipy 0.13.0, the output shape of zoom() is calculated with round() instead of int() - for these inputs the size of the returned array has changed.
  "the returned array has changed.", UserWarning)
[2015-10-30 05:58:36,735: WARNING/Worker-40] /cluster/home/mmunso01/envs/nidaba/lib/python2.7/site-packages/scipy/ndimage/interpolation.py:549: UserWarning: From scipy 0.13.0, the output shape of zoom() is calculated with round() instead of int() - for these inputs the size of the returned array has changed.
  "the returned array has changed.", UserWarning)
[2015-10-30 05:58:37,374: WARNING/Worker-34] /cluster/home/mmunso01/envs/nidaba/lib/python2.7/site-packages/scipy/ndimage/interpolation.py:549: UserWarning: From scipy 0.13.0, the output shape of zoom() is calculated with round() instead of int() - for these inputs the size of the returned array has changed.
  "the returned array has changed.", UserWarning)
[2015-10-30 05:58:40,055: WARNING/Worker-7] /cluster/home/mmunso01/envs/nidaba/lib/python2.7/site-packages/scipy/ndimage/interpolation.py:549: UserWarning: From scipy 0.13.0, the output shape of zoom() is calculated with round() instead of int() - for these inputs the size of the returned array has changed.
  "the returned array has changed.", UserWarning)
[2015-10-30 05:58:41,622: WARNING/Worker-17] /cluster/home/mmunso01/envs/nidaba/lib/python2.7/site-packages/scipy/ndimage/interpolation.py:549: UserWarning: From scipy 0.13.0, the output shape of zoom() is calculated with round() instead of int() - for these inputs the size of the returned array has changed.
  "the returned array has changed.", UserWarning)
[2015-10-30 05:58:42,614: WARNING/Worker-27] /cluster/home/mmunso01/envs/nidaba/lib/python2.7/site-packages/scipy/ndimage/interpolation.py:549: UserWarning: From scipy 0.13.0, the output shape of zoom() is calculated with round() instead of int() - for these inputs the size of the returned array has changed.
  "the returned array has changed.", UserWarning)
[2015-10-30 05:58:44,488: WARNING/Worker-12] /cluster/home/mmunso01/envs/nidaba/lib/python2.7/site-packages/scipy/ndimage/interpolation.py:549: UserWarning: From scipy 0.13.0, the output shape of zoom() is calculated with round() instead of int() - for these inputs the size of the returned array has changed.
  "the returned array has changed.", UserWarning)
[2015-10-30 05:58:44,844: WARNING/Worker-25] /cluster/home/mmunso01/envs/nidaba/lib/python2.7/site-packages/scipy/ndimage/interpolation.py:549: UserWarning: From scipy 0.13.0, the output shape of zoom() is calculated with round() instead of int() - for these inputs the size of the returned array has changed.
  "the returned array has changed.", UserWarning)
[2015-10-30 05:58:46,784: WARNING/Worker-29] /cluster/home/mmunso01/envs/nidaba/lib/python2.7/site-packages/scipy/ndimage/interpolation.py:549: UserWarning: From scipy 0.13.0, the output shape of zoom() is calculated with round() instead of int() - for these inputs the size of the returned array has changed.
  "the returned array has changed.", UserWarning)
[2015-10-30 05:58:48,564: WARNING/Worker-35] /cluster/home/mmunso01/envs/nidaba/lib/python2.7/site-packages/scipy/ndimage/interpolation.py:549: UserWarning: From scipy 0.13.0, the output shape of zoom() is calculated with round() instead of int() - for these inputs the size of the returned array has changed.
  "the returned array has changed.", UserWarning)
[2015-10-30 05:58:51,954: WARNING/Worker-6] /cluster/home/mmunso01/envs/nidaba/lib/python2.7/site-packages/scipy/ndimage/interpolation.py:549: UserWarning: From scipy 0.13.0, the output shape of zoom() is calculated with round() instead of int() - for these inputs the size of the returned array has changed.
  "the returned array has changed.", UserWarning)
[2015-10-30 05:58:52,314: WARNING/Worker-13] /cluster/home/mmunso01/envs/nidaba/lib/python2.7/site-packages/scipy/ndimage/interpolation.py:549: UserWarning: From scipy 0.13.0, the output shape of zoom() is calculated with round() instead of int() - for these inputs the size of the returned array has changed.
  "the returned array has changed.", UserWarning)
[2015-10-30 05:58:53,676: WARNING/Worker-21] /cluster/home/mmunso01/envs/nidaba/lib/python2.7/site-packages/scipy/ndimage/interpolation.py:549: UserWarning: From scipy 0.13.0, the output shape of zoom() is calculated with round() instead of int() - for these inputs the size of the returned array has changed.
  "the returned array has changed.", UserWarning)
[2015-10-30 05:58:54,014: WARNING/Worker-26] /cluster/home/mmunso01/envs/nidaba/lib/python2.7/site-packages/scipy/ndimage/interpolation.py:549: UserWarning: From scipy 0.13.0, the output shape of zoom() is calculated with round() instead of int() - for these inputs the size of the returned array has changed.
  "the returned array has changed.", UserWarning)
[2015-10-30 05:58:55,224: WARNING/Worker-33] /cluster/home/mmunso01/envs/nidaba/lib/python2.7/site-packages/scipy/ndimage/interpolation.py:549: UserWarning: From scipy 0.13.0, the output shape of zoom() is calculated with round() instead of int() - for these inputs the size of the returned array has changed.
  "the returned array has changed.", UserWarning)
[2015-10-30 05:58:57,184: WARNING/Worker-5] /cluster/home/mmunso01/envs/nidaba/lib/python2.7/site-packages/scipy/ndimage/interpolation.py:549: UserWarning: From scipy 0.13.0, the output shape of zoom() is calculated with round() instead of int() - for these inputs the size of the returned array has changed.
  "the returned array has changed.", UserWarning)
[2015-10-30 05:58:58,493: WARNING/Worker-32] /cluster/home/mmunso01/envs/nidaba/lib/python2.7/site-packages/scipy/ndimage/interpolation.py:549: UserWarning: From scipy 0.13.0, the output shape of zoom() is calculated with round() instead of int() - for these inputs the size of the returned array has changed.
  "the returned array has changed.", UserWarning)
[2015-10-30 05:58:59,154: WARNING/Worker-19] /cluster/home/mmunso01/envs/nidaba/lib/python2.7/site-packages/scipy/ndimage/interpolation.py:549: UserWarning: From scipy 0.13.0, the output shape of zoom() is calculated with round() instead of int() - for these inputs the size of the returned array has changed.
  "the returned array has changed.", UserWarning)
[2015-10-30 05:58:59,666: WARNING/Worker-11] /cluster/home/mmunso01/envs/nidaba/lib/python2.7/site-packages/scipy/ndimage/interpolation.py:549: UserWarning: From scipy 0.13.0, the output shape of zoom() is calculated with round() instead of int() - for these inputs the size of the returned array has changed.
  "the returned array has changed.", UserWarning)
[2015-10-30 05:59:00,439: WARNING/Worker-39] /cluster/home/mmunso01/envs/nidaba/lib/python2.7/site-packages/scipy/ndimage/interpolation.py:549: UserWarning: From scipy 0.13.0, the output shape of zoom() is calculated with round() instead of int() - for these inputs the size of the returned array has changed.
  "the returned array has changed.", UserWarning)
[2015-10-30 05:59:01,284: WARNING/Worker-9] /cluster/home/mmunso01/envs/nidaba/lib/python2.7/site-packages/scipy/ndimage/interpolation.py:549: UserWarning: From scipy 0.13.0, the output shape of zoom() is calculated with round() instead of int() - for these inputs the size of the returned array has changed.
  "the returned array has changed.", UserWarning)
[2015-10-30 05:59:03,044: WARNING/Worker-14] /cluster/home/mmunso01/envs/nidaba/lib/python2.7/site-packages/scipy/ndimage/interpolation.py:549: UserWarning: From scipy 0.13.0, the output shape of zoom() is calculated with round() instead of int() - for these inputs the size of the returned array has changed.
  "the returned array has changed.", UserWarning)
[2015-10-30 05:59:03,554: WARNING/Worker-22] /cluster/home/mmunso01/envs/nidaba/lib/python2.7/site-packages/scipy/ndimage/interpolation.py:549: UserWarning: From scipy 0.13.0, the output shape of zoom() is calculated with round() instead of int() - for these inputs the size of the returned array has changed.
  "the returned array has changed.", UserWarning)
[2015-10-30 05:59:03,754: WARNING/Worker-36] /cluster/home/mmunso01/envs/nidaba/lib/python2.7/site-packages/scipy/ndimage/interpolation.py:549: UserWarning: From scipy 0.13.0, the output shape of zoom() is calculated with round() instead of int() - for these inputs the size of the returned array has changed.
  "the returned array has changed.", UserWarning)
[2015-10-30 05:59:08,074: WARNING/Worker-8] /cluster/home/mmunso01/envs/nidaba/lib/python2.7/site-packages/scipy/ndimage/interpolation.py:549: UserWarning: From scipy 0.13.0, the output shape of zoom() is calculated with round() instead of int() - for these inputs the size of the returned array has changed.
  "the returned array has changed.", UserWarning)
[2015-10-30 05:59:10,354: WARNING/Worker-2] /cluster/home/mmunso01/envs/nidaba/lib/python2.7/site-packages/scipy/ndimage/interpolation.py:549: UserWarning: From scipy 0.13.0, the output shape of zoom() is calculated with round() instead of int() - for these inputs the size of the returned array has changed.
  "the returned array has changed.", UserWarning)
[2015-10-30 05:59:11,645: WARNING/Worker-20] /cluster/home/mmunso01/envs/nidaba/lib/python2.7/site-packages/scipy/ndimage/interpolation.py:549: UserWarning: From scipy 0.13.0, the output shape of zoom() is calculated with round() instead of int() - for these inputs the size of the returned array has changed.
  "the returned array has changed.", UserWarning)
[2015-10-30 05:59:12,104: WARNING/Worker-30] /cluster/home/mmunso01/envs/nidaba/lib/python2.7/site-packages/scipy/ndimage/interpolation.py:549: UserWarning: From scipy 0.13.0, the output shape of zoom() is calculated with round() instead of int() - for these inputs the size of the returned array has changed.
  "the returned array has changed.", UserWarning)
[2015-10-30 05:59:20,424: WARNING/Worker-1] /cluster/home/mmunso01/envs/nidaba/lib/python2.7/site-packages/scipy/ndimage/interpolation.py:549: UserWarning: From scipy 0.13.0, the output shape of zoom() is calculated with round() instead of int() - for these inputs the size of the returned array has changed.
  "the returned array has changed.", UserWarning)
[2015-10-30 05:59:20,994: WARNING/Worker-38] /cluster/home/mmunso01/envs/nidaba/lib/python2.7/site-packages/scipy/ndimage/interpolation.py:549: UserWarning: From scipy 0.13.0, the output shape of zoom() is calculated with round() instead of int() - for these inputs the size of the returned array has changed.
  "the returned array has changed.", UserWarning)
[2015-10-30 05:59:30,835: WARNING/Worker-3] /cluster/home/mmunso01/envs/nidaba/lib/python2.7/site-packages/scipy/ndimage/interpolation.py:549: UserWarning: From scipy 0.13.0, the output shape of zoom() is calculated with round() instead of int() - for these inputs the size of the returned array has changed.
  "the returned array has changed.", UserWarning)
[2015-10-30 05:59:44,081: WARNING/Worker-28] /cluster/home/mmunso01/envs/nidaba/lib/python2.7/site-packages/scipy/ndimage/interpolation.py:549: UserWarning: From scipy 0.13.0, the output shape of zoom() is calculated with round() instead of int() - for these inputs the size of the returned array has changed.
  "the returned array has changed.", UserWarning)
[2015-10-30 05:59:47,641: WARNING/Worker-18] /cluster/home/mmunso01/envs/nidaba/lib/python2.7/site-packages/scipy/ndimage/interpolation.py:549: UserWarning: From scipy 0.13.0, the output shape of zoom() is calculated with round() instead of int() - for these inputs the size of the returned array has changed.
  "the returned array has changed.", UserWarning)
[2015-10-30 05:59:51,734: WARNING/Worker-15] /cluster/home/mmunso01/envs/nidaba/lib/python2.7/site-packages/scipy/ndimage/interpolation.py:549: UserWarning: From scipy 0.13.0, the output shape of zoom() is calculated with round() instead of int() - for these inputs the size of the returned array has changed.
  "the returned array has changed.", UserWarning)
[2015-10-30 05:59:59,312: WARNING/Worker-31] /cluster/home/mmunso01/envs/nidaba/lib/python2.7/site-packages/scipy/ndimage/interpolation.py:549: UserWarning: From scipy 0.13.0, the output shape of zoom() is calculated with round() instead of int() - for these inputs the size of the returned array has changed.
  "the returned array has changed.", UserWarning)
[2015-10-30 06:04:24,295: WARNING/Worker-37] /cluster/home/mmunso01/envs/nidaba/lib/python2.7/site-packages/scipy/ndimage/interpolation.py:549: UserWarning: From scipy 0.13.0, the output shape of zoom() is calculated with round() instead of int() - for these inputs the size of the returned array has changed.
  "the returned array has changed.", UserWarning)
[2015-10-30 06:35:44,445: WARNING/Worker-22] /cluster/home/mmunso01/envs/nidaba/lib/python2.7/site-packages/kraken/binarization.py:64: RuntimeWarning: divide by zero encountered in true_divide
  flat /= (hi-lo)
[2015-10-30 06:35:44,446: WARNING/Worker-22] /cluster/home/mmunso01/envs/nidaba/lib/python2.7/site-packages/kraken/binarization.py:64: RuntimeWarning: invalid value encountered in true_divide
  flat /= (hi-lo)
[2015-10-30 06:35:44,571: WARNING/Worker-22] /cluster/home/mmunso01/envs/nidaba/lib/python2.7/site-packages/kraken/binarization.py:66: RuntimeWarning: invalid value encountered in greater
  bin = np.array(255*(flat > threshold), 'B')
[2015-10-30 06:39:45,252: ERROR/Worker-23] nidaba.segmentation.tesseract[970ed4a8-ab89-4de3-bbd0-1c449347188a]: Tesseract killed by signal: 11
[2015-10-30 06:40:33,002: ERROR/MainProcess] Task nidaba.segmentation.tesseract[970ed4a8-ab89-4de3-bbd0-1c449347188a] raised unexpected: NidabaTesseractException(u'Tesseract killed by signal: 11',)
Traceback (most recent call last):
  File "/cluster/home/mmunso01/envs/nidaba/lib/python2.7/site-packages/celery/app/trace.py", line 240, in trace_task
    R = retval = fun(*args, **kwargs)
  File "/cluster/home/mmunso01/envs/nidaba/lib/python2.7/site-packages/nidaba/tasks/helper.py", line 89, in __call__
    ret = super(NidabaTask, self).__call__(*args, **nkwargs)
  File "/cluster/home/mmunso01/envs/nidaba/lib/python2.7/site-packages/celery/app/trace.py", line 438, in __protected_call__
    return self.run(*args, **kwargs)
  File "/cluster/home/mmunso01/envs/nidaba/lib/python2.7/site-packages/nidaba/plugins/tesseract.py", line 251, in segmentation_tesseract
    raise NidabaTesseractException('Tesseract killed by signal: {0}'.format(os.WTERMSIG(status)))
NidabaTesseractException: Tesseract killed by signal: 11
[2015-10-30 06:50:25,811: ERROR/Worker-10] nidaba.segmentation.tesseract[c50e157e-0fbb-4fd1-b1c6-090cf387f0d1]: Tesseract killed by signal: 11
[2015-10-30 06:50:34,061: ERROR/Worker-7] nidaba.segmentation.tesseract[d28dd873-c109-48fa-af05-451a40b15132]: Tesseract killed by signal: 11
[2015-10-30 06:50:34,894: ERROR/MainProcess] Task nidaba.segmentation.tesseract[d28dd873-c109-48fa-af05-451a40b15132] raised unexpected: NidabaTesseractException(u'Tesseract killed by signal: 11',)
Traceback (most recent call last):
  File "/cluster/home/mmunso01/envs/nidaba/lib/python2.7/site-packages/celery/app/trace.py", line 240, in trace_task
    R = retval = fun(*args, **kwargs)
  File "/cluster/home/mmunso01/envs/nidaba/lib/python2.7/site-packages/nidaba/tasks/helper.py", line 89, in __call__
    ret = super(NidabaTask, self).__call__(*args, **nkwargs)
  File "/cluster/home/mmunso01/envs/nidaba/lib/python2.7/site-packages/celery/app/trace.py", line 438, in __protected_call__
    return self.run(*args, **kwargs)
  File "/cluster/home/mmunso01/envs/nidaba/lib/python2.7/site-packages/nidaba/plugins/tesseract.py", line 251, in segmentation_tesseract
    raise NidabaTesseractException('Tesseract killed by signal: {0}'.format(os.WTERMSIG(status)))
NidabaTesseractException: Tesseract killed by signal: 11
[2015-10-30 06:50:36,257: ERROR/MainProcess] Task nidaba.segmentation.tesseract[c50e157e-0fbb-4fd1-b1c6-090cf387f0d1] raised unexpected: NidabaTesseractException(u'Tesseract killed by signal: 11',)
Traceback (most recent call last):
  File "/cluster/home/mmunso01/envs/nidaba/lib/python2.7/site-packages/celery/app/trace.py", line 240, in trace_task
    R = retval = fun(*args, **kwargs)
  File "/cluster/home/mmunso01/envs/nidaba/lib/python2.7/site-packages/nidaba/tasks/helper.py", line 89, in __call__
    ret = super(NidabaTask, self).__call__(*args, **nkwargs)
  File "/cluster/home/mmunso01/envs/nidaba/lib/python2.7/site-packages/celery/app/trace.py", line 438, in __protected_call__
    return self.run(*args, **kwargs)
  File "/cluster/home/mmunso01/envs/nidaba/lib/python2.7/site-packages/nidaba/plugins/tesseract.py", line 251, in segmentation_tesseract
    raise NidabaTesseractException('Tesseract killed by signal: {0}'.format(os.WTERMSIG(status)))
NidabaTesseractException: Tesseract killed by signal: 11
[2015-10-30 06:50:46,175: ERROR/Worker-21] nidaba.segmentation.tesseract[d06cb14f-91e1-4327-8487-39928896b955]: Tesseract killed by signal: 11
[2015-10-30 06:50:49,496: ERROR/MainProcess] Task nidaba.segmentation.tesseract[d06cb14f-91e1-4327-8487-39928896b955] raised unexpected: NidabaTesseractException(u'Tesseract killed by signal: 11',)
Traceback (most recent call last):
  File "/cluster/home/mmunso01/envs/nidaba/lib/python2.7/site-packages/celery/app/trace.py", line 240, in trace_task
    R = retval = fun(*args, **kwargs)
  File "/cluster/home/mmunso01/envs/nidaba/lib/python2.7/site-packages/nidaba/tasks/helper.py", line 89, in __call__
    ret = super(NidabaTask, self).__call__(*args, **nkwargs)
  File "/cluster/home/mmunso01/envs/nidaba/lib/python2.7/site-packages/celery/app/trace.py", line 438, in __protected_call__
    return self.run(*args, **kwargs)
  File "/cluster/home/mmunso01/envs/nidaba/lib/python2.7/site-packages/nidaba/plugins/tesseract.py", line 251, in segmentation_tesseract
    raise NidabaTesseractException('Tesseract killed by signal: {0}'.format(os.WTERMSIG(status)))
NidabaTesseractException: Tesseract killed by signal: 11
[2015-10-30 07:09:07,444: WARNING/Worker-11] /cluster/home/mmunso01/envs/nidaba/lib/python2.7/site-packages/kraken/rpred.py:91: RuntimeWarning: invalid value encountered in true_divide
  temp = temp*1.0/np.amax(temp)
[2015-10-30 07:09:42,861: ERROR/Worker-8] nidaba.ocr.kraken[de1ae9b6-a48c-4ccf-af35-4ccdf01d9ba5]: float division by zero
[2015-10-30 07:09:44,126: ERROR/MainProcess] Task nidaba.ocr.kraken[de1ae9b6-a48c-4ccf-af35-4ccdf01d9ba5] raised unexpected: ZeroDivisionError('float division by zero',)
Traceback (most recent call last):
  File "/cluster/home/mmunso01/envs/nidaba/lib/python2.7/site-packages/celery/app/trace.py", line 240, in trace_task
    R = retval = fun(*args, **kwargs)
  File "/cluster/home/mmunso01/envs/nidaba/lib/python2.7/site-packages/nidaba/tasks/helper.py", line 89, in __call__
    ret = super(NidabaTask, self).__call__(*args, **nkwargs)
  File "/cluster/home/mmunso01/envs/nidaba/lib/python2.7/site-packages/celery/app/trace.py", line 438, in __protected_call__
    return self.run(*args, **kwargs)
  File "/cluster/home/mmunso01/envs/nidaba/lib/python2.7/site-packages/nidaba/plugins/kraken.py", line 155, in ocr_kraken
    for rec in rpred.rpred(rnn, img, [(int(x[0]), int(x[1]), int(x[2]), int(x[3])) for x in lines]):
  File "/cluster/home/mmunso01/envs/nidaba/lib/python2.7/site-packages/kraken/rpred.py", line 127, in rpred
    box = dewarp(lnorm, box)
  File "/cluster/home/mmunso01/envs/nidaba/lib/python2.7/site-packages/kraken/rpred.py", line 93, in dewarp
    line = normalizer.normalize(line, cval=np.amax(line))
  File "/cluster/home/mmunso01/envs/nidaba/lib/python2.7/site-packages/kraken/lib/lineest.py", line 60, in normalize
    dtype=dtype, cval=cval)
  File "/cluster/home/mmunso01/envs/nidaba/lib/python2.7/site-packages/kraken/lib/lineest.py", line 13, in scale_to_h
    scale = target_height*1.0/h
ZeroDivisionError: float division by zero
[2015-10-30 07:09:56,024: WARNING/Worker-25] /cluster/home/mmunso01/envs/nidaba/lib/python2.7/site-packages/kraken/rpred.py:91: RuntimeWarning: invalid value encountered in true_divide
  temp = temp*1.0/np.amax(temp)
[2015-10-30 07:10:17,264: WARNING/Worker-37] /cluster/home/mmunso01/envs/nidaba/lib/python2.7/site-packages/kraken/rpred.py:91: RuntimeWarning: invalid value encountered in true_divide
  temp = temp*1.0/np.amax(temp)
[2015-10-30 07:10:17,265: ERROR/Worker-37] nidaba.ocr.kraken[25112392-7267-4bbd-96be-ba0e4a7ddd9d]: float division by zero
[2015-10-30 07:10:21,746: ERROR/MainProcess] Task nidaba.ocr.kraken[25112392-7267-4bbd-96be-ba0e4a7ddd9d] raised unexpected: ZeroDivisionError('float division by zero',)
Traceback (most recent call last):
  File "/cluster/home/mmunso01/envs/nidaba/lib/python2.7/site-packages/celery/app/trace.py", line 240, in trace_task
    R = retval = fun(*args, **kwargs)
  File "/cluster/home/mmunso01/envs/nidaba/lib/python2.7/site-packages/nidaba/tasks/helper.py", line 89, in __call__
    ret = super(NidabaTask, self).__call__(*args, **nkwargs)
  File "/cluster/home/mmunso01/envs/nidaba/lib/python2.7/site-packages/celery/app/trace.py", line 438, in __protected_call__
    return self.run(*args, **kwargs)
  File "/cluster/home/mmunso01/envs/nidaba/lib/python2.7/site-packages/nidaba/plugins/kraken.py", line 155, in ocr_kraken
    for rec in rpred.rpred(rnn, img, [(int(x[0]), int(x[1]), int(x[2]), int(x[3])) for x in lines]):
  File "/cluster/home/mmunso01/envs/nidaba/lib/python2.7/site-packages/kraken/rpred.py", line 127, in rpred
    box = dewarp(lnorm, box)
  File "/cluster/home/mmunso01/envs/nidaba/lib/python2.7/site-packages/kraken/rpred.py", line 93, in dewarp
    line = normalizer.normalize(line, cval=np.amax(line))
  File "/cluster/home/mmunso01/envs/nidaba/lib/python2.7/site-packages/kraken/lib/lineest.py", line 60, in normalize
    dtype=dtype, cval=cval)
  File "/cluster/home/mmunso01/envs/nidaba/lib/python2.7/site-packages/kraken/lib/lineest.py", line 13, in scale_to_h
    scale = target_height*1.0/h
ZeroDivisionError: float division by zero
[2015-10-30 07:10:59,493: WARNING/Worker-35] /cluster/home/mmunso01/envs/nidaba/lib/python2.7/site-packages/kraken/rpred.py:91: RuntimeWarning: invalid value encountered in true_divide
  temp = temp*1.0/np.amax(temp)
[2015-10-30 07:11:24,100: WARNING/Worker-8] /cluster/home/mmunso01/envs/nidaba/lib/python2.7/site-packages/kraken/rpred.py:91: RuntimeWarning: invalid value encountered in true_divide
  temp = temp*1.0/np.amax(temp)
[2015-10-30 07:11:25,878: WARNING/Worker-3] /cluster/home/mmunso01/envs/nidaba/lib/python2.7/site-packages/kraken/rpred.py:91: RuntimeWarning: invalid value encountered in true_divide
  temp = temp*1.0/np.amax(temp)
[2015-10-30 07:11:25,883: WARNING/Worker-3] /cluster/home/mmunso01/envs/nidaba/lib/python2.7/site-packages/kraken/lib/lstm.py:48: RuntimeWarning: invalid value encountered in true_divide
  line = line * 1.0/np.amax(line)
[2015-10-30 07:11:25,927: ERROR/Worker-3] nidaba.ocr.kraken[6accf473-e351-4abc-af07-6dabc5790586]: 
[2015-10-30 07:11:53,324: ERROR/MainProcess] Task nidaba.ocr.kraken[6accf473-e351-4abc-af07-6dabc5790586] raised unexpected: AssertionError()
Traceback (most recent call last):
  File "/cluster/home/mmunso01/envs/nidaba/lib/python2.7/site-packages/celery/app/trace.py", line 240, in trace_task
    R = retval = fun(*args, **kwargs)
  File "/cluster/home/mmunso01/envs/nidaba/lib/python2.7/site-packages/nidaba/tasks/helper.py", line 89, in __call__
    ret = super(NidabaTask, self).__call__(*args, **nkwargs)
  File "/cluster/home/mmunso01/envs/nidaba/lib/python2.7/site-packages/celery/app/trace.py", line 438, in __protected_call__
    return self.run(*args, **kwargs)
  File "/cluster/home/mmunso01/envs/nidaba/lib/python2.7/site-packages/nidaba/plugins/kraken.py", line 155, in ocr_kraken
    for rec in rpred.rpred(rnn, img, [(int(x[0]), int(x[1]), int(x[2]), int(x[3])) for x in lines]):
  File "/cluster/home/mmunso01/envs/nidaba/lib/python2.7/site-packages/kraken/rpred.py", line 134, in rpred
    pred = network.predictString(line)
  File "/cluster/home/mmunso01/envs/nidaba/lib/python2.7/site-packages/kraken/lib/lstm.py", line 281, in predictString
    cs = self.predictSequence(xs)
  File "/cluster/home/mmunso01/envs/nidaba/lib/python2.7/site-packages/kraken/lib/lstm.py", line 273, in predictSequence
    self.outputs = np.array(self.lstm.forward(xs))
  File "/cluster/home/mmunso01/envs/nidaba/lib/python2.7/site-packages/kraken/lib/lstm.py", line 229, in forward
    xs = net.forward(xs)
  File "/cluster/home/mmunso01/envs/nidaba/lib/python2.7/site-packages/kraken/lib/lstm.py", line 244, in forward
    outputs = [net.forward(xs) for net in self.nets]
  File "/cluster/home/mmunso01/envs/nidaba/lib/python2.7/site-packages/kraken/lib/lstm.py", line 216, in forward
    assert not np.isnan(self.output[:n]).any()
AssertionError
[2015-10-30 07:11:54,784: WARNING/Worker-6] /cluster/home/mmunso01/envs/nidaba/lib/python2.7/site-packages/kraken/rpred.py:91: RuntimeWarning: invalid value encountered in true_divide
  temp = temp*1.0/np.amax(temp)
[2015-10-30 07:12:00,254: WARNING/Worker-27] /cluster/home/mmunso01/envs/nidaba/lib/python2.7/site-packages/kraken/rpred.py:91: RuntimeWarning: invalid value encountered in true_divide
  temp = temp*1.0/np.amax(temp)
[2015-10-30 07:12:00,257: WARNING/Worker-27] /cluster/home/mmunso01/envs/nidaba/lib/python2.7/site-packages/kraken/lib/lstm.py:48: RuntimeWarning: invalid value encountered in true_divide
  line = line * 1.0/np.amax(line)
[2015-10-30 07:12:00,297: ERROR/Worker-27] nidaba.ocr.kraken[376641f0-3a02-40f8-9ecb-7c33f9558433]: 
[2015-10-30 07:12:01,914: ERROR/MainProcess] Task nidaba.ocr.kraken[376641f0-3a02-40f8-9ecb-7c33f9558433] raised unexpected: AssertionError()
Traceback (most recent call last):
  File "/cluster/home/mmunso01/envs/nidaba/lib/python2.7/site-packages/celery/app/trace.py", line 240, in trace_task
    R = retval = fun(*args, **kwargs)
  File "/cluster/home/mmunso01/envs/nidaba/lib/python2.7/site-packages/nidaba/tasks/helper.py", line 89, in __call__
    ret = super(NidabaTask, self).__call__(*args, **nkwargs)
  File "/cluster/home/mmunso01/envs/nidaba/lib/python2.7/site-packages/celery/app/trace.py", line 438, in __protected_call__
    return self.run(*args, **kwargs)
  File "/cluster/home/mmunso01/envs/nidaba/lib/python2.7/site-packages/nidaba/plugins/kraken.py", line 155, in ocr_kraken
    for rec in rpred.rpred(rnn, img, [(int(x[0]), int(x[1]), int(x[2]), int(x[3])) for x in lines]):
  File "/cluster/home/mmunso01/envs/nidaba/lib/python2.7/site-packages/kraken/rpred.py", line 134, in rpred
    pred = network.predictString(line)
  File "/cluster/home/mmunso01/envs/nidaba/lib/python2.7/site-packages/kraken/lib/lstm.py", line 281, in predictString
    cs = self.predictSequence(xs)
  File "/cluster/home/mmunso01/envs/nidaba/lib/python2.7/site-packages/kraken/lib/lstm.py", line 273, in predictSequence
    self.outputs = np.array(self.lstm.forward(xs))
  File "/cluster/home/mmunso01/envs/nidaba/lib/python2.7/site-packages/kraken/lib/lstm.py", line 229, in forward
    xs = net.forward(xs)
  File "/cluster/home/mmunso01/envs/nidaba/lib/python2.7/site-packages/kraken/lib/lstm.py", line 244, in forward
    outputs = [net.forward(xs) for net in self.nets]
  File "/cluster/home/mmunso01/envs/nidaba/lib/python2.7/site-packages/kraken/lib/lstm.py", line 216, in forward
    assert not np.isnan(self.output[:n]).any()
AssertionError
[2015-10-30 07:12:24,842: ERROR/Worker-38] nidaba.ocr.kraken[f0b80e38-68e3-46e0-8c31-243441c97d06]: float division by zero
[2015-10-30 07:12:28,107: ERROR/Worker-31] nidaba.ocr.kraken[b22bfa14-739b-4246-adb1-0594163d4fbb]: tile cannot extend outside image
[2015-10-30 07:12:38,432: ERROR/MainProcess] Task nidaba.ocr.kraken[b22bfa14-739b-4246-adb1-0594163d4fbb] raised unexpected: SystemError('tile cannot extend outside image',)
Traceback (most recent call last):
  File "/cluster/home/mmunso01/envs/nidaba/lib/python2.7/site-packages/celery/app/trace.py", line 240, in trace_task
    R = retval = fun(*args, **kwargs)
  File "/cluster/home/mmunso01/envs/nidaba/lib/python2.7/site-packages/nidaba/tasks/helper.py", line 89, in __call__
    ret = super(NidabaTask, self).__call__(*args, **nkwargs)
  File "/cluster/home/mmunso01/envs/nidaba/lib/python2.7/site-packages/celery/app/trace.py", line 438, in __protected_call__
    return self.run(*args, **kwargs)
  File "/cluster/home/mmunso01/envs/nidaba/lib/python2.7/site-packages/nidaba/plugins/kraken.py", line 155, in ocr_kraken
    for rec in rpred.rpred(rnn, img, [(int(x[0]), int(x[1]), int(x[2]), int(x[3])) for x in lines]):
  File "/cluster/home/mmunso01/envs/nidaba/lib/python2.7/site-packages/kraken/rpred.py", line 127, in rpred
    box = dewarp(lnorm, box)
  File "/cluster/home/mmunso01/envs/nidaba/lib/python2.7/site-packages/kraken/rpred.py", line 89, in dewarp
    line = pil2array(im)
  File "/cluster/home/mmunso01/envs/nidaba/lib/python2.7/site-packages/kraken/lib/util.py", line 18, in pil2array
    a = np.fromstring(im.tobytes(), 'B')
  File "/cluster/home/mmunso01/envs/nidaba/lib/python2.7/site-packages/PIL/Image.py", line 669, in tobytes
    e.setimage(self.im)
SystemError: tile cannot extend outside image
[2015-10-30 07:12:45,156: ERROR/MainProcess] Task nidaba.ocr.kraken[f0b80e38-68e3-46e0-8c31-243441c97d06] raised unexpected: ZeroDivisionError('float division by zero',)
Traceback (most recent call last):
  File "/cluster/home/mmunso01/envs/nidaba/lib/python2.7/site-packages/celery/app/trace.py", line 240, in trace_task
    R = retval = fun(*args, **kwargs)
  File "/cluster/home/mmunso01/envs/nidaba/lib/python2.7/site-packages/nidaba/tasks/helper.py", line 89, in __call__
    ret = super(NidabaTask, self).__call__(*args, **nkwargs)
  File "/cluster/home/mmunso01/envs/nidaba/lib/python2.7/site-packages/celery/app/trace.py", line 438, in __protected_call__
    return self.run(*args, **kwargs)
  File "/cluster/home/mmunso01/envs/nidaba/lib/python2.7/site-packages/nidaba/plugins/kraken.py", line 155, in ocr_kraken
    for rec in rpred.rpred(rnn, img, [(int(x[0]), int(x[1]), int(x[2]), int(x[3])) for x in lines]):
  File "/cluster/home/mmunso01/envs/nidaba/lib/python2.7/site-packages/kraken/rpred.py", line 127, in rpred
    box = dewarp(lnorm, box)
  File "/cluster/home/mmunso01/envs/nidaba/lib/python2.7/site-packages/kraken/rpred.py", line 93, in dewarp
    line = normalizer.normalize(line, cval=np.amax(line))
  File "/cluster/home/mmunso01/envs/nidaba/lib/python2.7/site-packages/kraken/lib/lineest.py", line 60, in normalize
    dtype=dtype, cval=cval)
  File "/cluster/home/mmunso01/envs/nidaba/lib/python2.7/site-packages/kraken/lib/lineest.py", line 13, in scale_to_h
    scale = target_height*1.0/h
ZeroDivisionError: float division by zero
[2015-10-30 07:13:10,418: WARNING/Worker-9] /cluster/home/mmunso01/envs/nidaba/lib/python2.7/site-packages/kraken/rpred.py:91: RuntimeWarning: invalid value encountered in true_divide
  temp = temp*1.0/np.amax(temp)
[2015-10-30 07:13:19,614: ERROR/Worker-3] nidaba.ocr.kraken[a543f68b-8d39-4b5f-a9c0-ef9ff740fe87]: 
[2015-10-30 07:13:44,944: WARNING/Worker-15] /cluster/home/mmunso01/envs/nidaba/lib/python2.7/site-packages/kraken/rpred.py:91: RuntimeWarning: invalid value encountered in true_divide
  temp = temp*1.0/np.amax(temp)
[2015-10-30 07:13:44,957: WARNING/Worker-15] /cluster/home/mmunso01/envs/nidaba/lib/python2.7/site-packages/kraken/lib/lstm.py:48: RuntimeWarning: invalid value encountered in true_divide
  line = line * 1.0/np.amax(line)
[2015-10-30 07:13:44,990: ERROR/Worker-15] nidaba.ocr.kraken[ab1e47e3-c137-435f-9ca3-7552f3559bfa]: 
[2015-10-30 07:13:46,477: ERROR/MainProcess] Task nidaba.ocr.kraken[ab1e47e3-c137-435f-9ca3-7552f3559bfa] raised unexpected: AssertionError()
Traceback (most recent call last):
  File "/cluster/home/mmunso01/envs/nidaba/lib/python2.7/site-packages/celery/app/trace.py", line 240, in trace_task
    R = retval = fun(*args, **kwargs)
  File "/cluster/home/mmunso01/envs/nidaba/lib/python2.7/site-packages/nidaba/tasks/helper.py", line 89, in __call__
    ret = super(NidabaTask, self).__call__(*args, **nkwargs)
  File "/cluster/home/mmunso01/envs/nidaba/lib/python2.7/site-packages/celery/app/trace.py", line 438, in __protected_call__
    return self.run(*args, **kwargs)
  File "/cluster/home/mmunso01/envs/nidaba/lib/python2.7/site-packages/nidaba/plugins/kraken.py", line 155, in ocr_kraken
    for rec in rpred.rpred(rnn, img, [(int(x[0]), int(x[1]), int(x[2]), int(x[3])) for x in lines]):
  File "/cluster/home/mmunso01/envs/nidaba/lib/python2.7/site-packages/kraken/rpred.py", line 134, in rpred
    pred = network.predictString(line)
  File "/cluster/home/mmunso01/envs/nidaba/lib/python2.7/site-packages/kraken/lib/lstm.py", line 281, in predictString
    cs = self.predictSequence(xs)
  File "/cluster/home/mmunso01/envs/nidaba/lib/python2.7/site-packages/kraken/lib/lstm.py", line 273, in predictSequence
    self.outputs = np.array(self.lstm.forward(xs))
  File "/cluster/home/mmunso01/envs/nidaba/lib/python2.7/site-packages/kraken/lib/lstm.py", line 229, in forward
    xs = net.forward(xs)
  File "/cluster/home/mmunso01/envs/nidaba/lib/python2.7/site-packages/kraken/lib/lstm.py", line 244, in forward
    outputs = [net.forward(xs) for net in self.nets]
  File "/cluster/home/mmunso01/envs/nidaba/lib/python2.7/site-packages/kraken/lib/lstm.py", line 216, in forward
    assert not np.isnan(self.output[:n]).any()
AssertionError
[2015-10-30 07:14:14,161: ERROR/MainProcess] Task nidaba.ocr.kraken[a543f68b-8d39-4b5f-a9c0-ef9ff740fe87] raised unexpected: AssertionError()
Traceback (most recent call last):
  File "/cluster/home/mmunso01/envs/nidaba/lib/python2.7/site-packages/celery/app/trace.py", line 240, in trace_task
    R = retval = fun(*args, **kwargs)
  File "/cluster/home/mmunso01/envs/nidaba/lib/python2.7/site-packages/nidaba/tasks/helper.py", line 89, in __call__
    ret = super(NidabaTask, self).__call__(*args, **nkwargs)
  File "/cluster/home/mmunso01/envs/nidaba/lib/python2.7/site-packages/celery/app/trace.py", line 438, in __protected_call__
    return self.run(*args, **kwargs)
  File "/cluster/home/mmunso01/envs/nidaba/lib/python2.7/site-packages/nidaba/plugins/kraken.py", line 155, in ocr_kraken
    for rec in rpred.rpred(rnn, img, [(int(x[0]), int(x[1]), int(x[2]), int(x[3])) for x in lines]):
  File "/cluster/home/mmunso01/envs/nidaba/lib/python2.7/site-packages/kraken/rpred.py", line 134, in rpred
    pred = network.predictString(line)
  File "/cluster/home/mmunso01/envs/nidaba/lib/python2.7/site-packages/kraken/lib/lstm.py", line 281, in predictString
    cs = self.predictSequence(xs)
  File "/cluster/home/mmunso01/envs/nidaba/lib/python2.7/site-packages/kraken/lib/lstm.py", line 273, in predictSequence
    self.outputs = np.array(self.lstm.forward(xs))
  File "/cluster/home/mmunso01/envs/nidaba/lib/python2.7/site-packages/kraken/lib/lstm.py", line 229, in forward
    xs = net.forward(xs)
  File "/cluster/home/mmunso01/envs/nidaba/lib/python2.7/site-packages/kraken/lib/lstm.py", line 244, in forward
    outputs = [net.forward(xs) for net in self.nets]
  File "/cluster/home/mmunso01/envs/nidaba/lib/python2.7/site-packages/kraken/lib/lstm.py", line 216, in forward
    assert not np.isnan(self.output[:n]).any()
AssertionError
[2015-10-30 07:15:02,427: ERROR/Worker-3] nidaba.ocr.kraken[377d2886-97ec-4beb-9e79-2ca12587cf39]: 
[2015-10-30 07:15:05,384: WARNING/Worker-24] /cluster/home/mmunso01/envs/nidaba/lib/python2.7/site-packages/kraken/rpred.py:91: RuntimeWarning: invalid value encountered in true_divide
  temp = temp*1.0/np.amax(temp)
[2015-10-30 07:15:07,822: WARNING/Worker-9] /cluster/home/mmunso01/envs/nidaba/lib/python2.7/site-packages/kraken/lib/lstm.py:48: RuntimeWarning: invalid value encountered in true_divide
  line = line * 1.0/np.amax(line)
[2015-10-30 07:15:07,852: ERROR/Worker-9] nidaba.ocr.kraken[9b2ad6fa-e7ca-436e-a03a-a250da95cd58]: 
[2015-10-30 07:15:11,254: ERROR/MainProcess] Task nidaba.ocr.kraken[9b2ad6fa-e7ca-436e-a03a-a250da95cd58] raised unexpected: AssertionError()
Traceback (most recent call last):
  File "/cluster/home/mmunso01/envs/nidaba/lib/python2.7/site-packages/celery/app/trace.py", line 240, in trace_task
    R = retval = fun(*args, **kwargs)
  File "/cluster/home/mmunso01/envs/nidaba/lib/python2.7/site-packages/nidaba/tasks/helper.py", line 89, in __call__
    ret = super(NidabaTask, self).__call__(*args, **nkwargs)
  File "/cluster/home/mmunso01/envs/nidaba/lib/python2.7/site-packages/celery/app/trace.py", line 438, in __protected_call__
    return self.run(*args, **kwargs)
  File "/cluster/home/mmunso01/envs/nidaba/lib/python2.7/site-packages/nidaba/plugins/kraken.py", line 155, in ocr_kraken
    for rec in rpred.rpred(rnn, img, [(int(x[0]), int(x[1]), int(x[2]), int(x[3])) for x in lines]):
  File "/cluster/home/mmunso01/envs/nidaba/lib/python2.7/site-packages/kraken/rpred.py", line 134, in rpred
    pred = network.predictString(line)
  File "/cluster/home/mmunso01/envs/nidaba/lib/python2.7/site-packages/kraken/lib/lstm.py", line 281, in predictString
    cs = self.predictSequence(xs)
  File "/cluster/home/mmunso01/envs/nidaba/lib/python2.7/site-packages/kraken/lib/lstm.py", line 273, in predictSequence
    self.outputs = np.array(self.lstm.forward(xs))
  File "/cluster/home/mmunso01/envs/nidaba/lib/python2.7/site-packages/kraken/lib/lstm.py", line 229, in forward
    xs = net.forward(xs)
  File "/cluster/home/mmunso01/envs/nidaba/lib/python2.7/site-packages/kraken/lib/lstm.py", line 244, in forward
    outputs = [net.forward(xs) for net in self.nets]
  File "/cluster/home/mmunso01/envs/nidaba/lib/python2.7/site-packages/kraken/lib/lstm.py", line 216, in forward
    assert not np.isnan(self.output[:n]).any()
AssertionError
[2015-10-30 07:15:15,305: ERROR/MainProcess] Task nidaba.ocr.kraken[377d2886-97ec-4beb-9e79-2ca12587cf39] raised unexpected: AssertionError()
Traceback (most recent call last):
  File "/cluster/home/mmunso01/envs/nidaba/lib/python2.7/site-packages/celery/app/trace.py", line 240, in trace_task
    R = retval = fun(*args, **kwargs)
  File "/cluster/home/mmunso01/envs/nidaba/lib/python2.7/site-packages/nidaba/tasks/helper.py", line 89, in __call__
    ret = super(NidabaTask, self).__call__(*args, **nkwargs)
  File "/cluster/home/mmunso01/envs/nidaba/lib/python2.7/site-packages/celery/app/trace.py", line 438, in __protected_call__
    return self.run(*args, **kwargs)
  File "/cluster/home/mmunso01/envs/nidaba/lib/python2.7/site-packages/nidaba/plugins/kraken.py", line 155, in ocr_kraken
    for rec in rpred.rpred(rnn, img, [(int(x[0]), int(x[1]), int(x[2]), int(x[3])) for x in lines]):
  File "/cluster/home/mmunso01/envs/nidaba/lib/python2.7/site-packages/kraken/rpred.py", line 134, in rpred
    pred = network.predictString(line)
  File "/cluster/home/mmunso01/envs/nidaba/lib/python2.7/site-packages/kraken/lib/lstm.py", line 281, in predictString
    cs = self.predictSequence(xs)
  File "/cluster/home/mmunso01/envs/nidaba/lib/python2.7/site-packages/kraken/lib/lstm.py", line 273, in predictSequence
    self.outputs = np.array(self.lstm.forward(xs))
  File "/cluster/home/mmunso01/envs/nidaba/lib/python2.7/site-packages/kraken/lib/lstm.py", line 229, in forward
    xs = net.forward(xs)
  File "/cluster/home/mmunso01/envs/nidaba/lib/python2.7/site-packages/kraken/lib/lstm.py", line 244, in forward
    outputs = [net.forward(xs) for net in self.nets]
  File "/cluster/home/mmunso01/envs/nidaba/lib/python2.7/site-packages/kraken/lib/lstm.py", line 216, in forward
    assert not np.isnan(self.output[:n]).any()
AssertionError
[2015-10-30 07:15:38,263: ERROR/Worker-40] nidaba.ocr.kraken[b68e681f-b1c7-4a1b-987e-9caed75b3f1f]: index 5000 is out of bounds for axis 0 with size 5000
[2015-10-30 07:15:52,684: ERROR/MainProcess] Task nidaba.ocr.kraken[b68e681f-b1c7-4a1b-987e-9caed75b3f1f] raised unexpected: IndexError('index 5000 is out of bounds for axis 0 with size 5000',)
Traceback (most recent call last):
  File "/cluster/home/mmunso01/envs/nidaba/lib/python2.7/site-packages/celery/app/trace.py", line 240, in trace_task
    R = retval = fun(*args, **kwargs)
  File "/cluster/home/mmunso01/envs/nidaba/lib/python2.7/site-packages/nidaba/tasks/helper.py", line 89, in __call__
    ret = super(NidabaTask, self).__call__(*args, **nkwargs)
  File "/cluster/home/mmunso01/envs/nidaba/lib/python2.7/site-packages/celery/app/trace.py", line 438, in __protected_call__
    return self.run(*args, **kwargs)
  File "/cluster/home/mmunso01/envs/nidaba/lib/python2.7/site-packages/nidaba/plugins/kraken.py", line 155, in ocr_kraken
    for rec in rpred.rpred(rnn, img, [(int(x[0]), int(x[1]), int(x[2]), int(x[3])) for x in lines]):
  File "/cluster/home/mmunso01/envs/nidaba/lib/python2.7/site-packages/kraken/rpred.py", line 134, in rpred
    pred = network.predictString(line)
  File "/cluster/home/mmunso01/envs/nidaba/lib/python2.7/site-packages/kraken/lib/lstm.py", line 281, in predictString
    cs = self.predictSequence(xs)
  File "/cluster/home/mmunso01/envs/nidaba/lib/python2.7/site-packages/kraken/lib/lstm.py", line 273, in predictSequence
    self.outputs = np.array(self.lstm.forward(xs))
  File "/cluster/home/mmunso01/envs/nidaba/lib/python2.7/site-packages/kraken/lib/lstm.py", line 229, in forward
    xs = net.forward(xs)
  File "/cluster/home/mmunso01/envs/nidaba/lib/python2.7/site-packages/kraken/lib/lstm.py", line 244, in forward
    outputs = [net.forward(xs) for net in self.nets]
  File "/cluster/home/mmunso01/envs/nidaba/lib/python2.7/site-packages/kraken/lib/lstm.py", line 196, in forward
    self.source[t,0] = 1
IndexError: index 5000 is out of bounds for axis 0 with size 5000
[2015-10-30 07:16:10,404: WARNING/Worker-7] /cluster/home/mmunso01/envs/nidaba/lib/python2.7/site-packages/kraken/rpred.py:91: RuntimeWarning: invalid value encountered in true_divide
  temp = temp*1.0/np.amax(temp)
[2015-10-30 07:16:10,414: WARNING/Worker-7] /cluster/home/mmunso01/envs/nidaba/lib/python2.7/site-packages/kraken/lib/lstm.py:48: RuntimeWarning: invalid value encountered in true_divide
  line = line * 1.0/np.amax(line)
[2015-10-30 07:16:10,433: ERROR/Worker-7] nidaba.ocr.kraken[03c00619-e22e-4c22-a119-117bd3fea02d]: 
[2015-10-30 07:16:22,107: WARNING/Worker-1] /cluster/home/mmunso01/envs/nidaba/lib/python2.7/site-packages/kraken/rpred.py:91: RuntimeWarning: invalid value encountered in true_divide
  temp = temp*1.0/np.amax(temp)
[2015-10-30 07:16:22,134: WARNING/Worker-1] /cluster/home/mmunso01/envs/nidaba/lib/python2.7/site-packages/kraken/lib/lstm.py:48: RuntimeWarning: invalid value encountered in true_divide
  line = line * 1.0/np.amax(line)
[2015-10-30 07:16:22,439: ERROR/Worker-1] nidaba.ocr.kraken[a52a9753-7a0a-4cba-bd08-40fe1e5bea6a]: 
[2015-10-30 07:16:29,637: WARNING/Worker-32] /cluster/home/mmunso01/envs/nidaba/lib/python2.7/site-packages/kraken/rpred.py:91: RuntimeWarning: invalid value encountered in true_divide
  temp = temp*1.0/np.amax(temp)
[2015-10-30 07:16:29,644: WARNING/Worker-32] /cluster/home/mmunso01/envs/nidaba/lib/python2.7/site-packages/kraken/lib/lstm.py:48: RuntimeWarning: invalid value encountered in true_divide
  line = line * 1.0/np.amax(line)
[2015-10-30 07:16:29,688: ERROR/Worker-32] nidaba.ocr.kraken[7e083a33-11cb-4191-b624-9821ce547582]: 
[2015-10-30 07:16:43,416: ERROR/MainProcess] Task nidaba.ocr.kraken[7e083a33-11cb-4191-b624-9821ce547582] raised unexpected: AssertionError()
Traceback (most recent call last):
  File "/cluster/home/mmunso01/envs/nidaba/lib/python2.7/site-packages/celery/app/trace.py", line 240, in trace_task
    R = retval = fun(*args, **kwargs)
  File "/cluster/home/mmunso01/envs/nidaba/lib/python2.7/site-packages/nidaba/tasks/helper.py", line 89, in __call__
    ret = super(NidabaTask, self).__call__(*args, **nkwargs)
  File "/cluster/home/mmunso01/envs/nidaba/lib/python2.7/site-packages/celery/app/trace.py", line 438, in __protected_call__
    return self.run(*args, **kwargs)
  File "/cluster/home/mmunso01/envs/nidaba/lib/python2.7/site-packages/nidaba/plugins/kraken.py", line 155, in ocr_kraken
    for rec in rpred.rpred(rnn, img, [(int(x[0]), int(x[1]), int(x[2]), int(x[3])) for x in lines]):
  File "/cluster/home/mmunso01/envs/nidaba/lib/python2.7/site-packages/kraken/rpred.py", line 134, in rpred
    pred = network.predictString(line)
  File "/cluster/home/mmunso01/envs/nidaba/lib/python2.7/site-packages/kraken/lib/lstm.py", line 281, in predictString
    cs = self.predictSequence(xs)
  File "/cluster/home/mmunso01/envs/nidaba/lib/python2.7/site-packages/kraken/lib/lstm.py", line 273, in predictSequence
    self.outputs = np.array(self.lstm.forward(xs))
  File "/cluster/home/mmunso01/envs/nidaba/lib/python2.7/site-packages/kraken/lib/lstm.py", line 229, in forward
    xs = net.forward(xs)
  File "/cluster/home/mmunso01/envs/nidaba/lib/python2.7/site-packages/kraken/lib/lstm.py", line 244, in forward
    outputs = [net.forward(xs) for net in self.nets]
  File "/cluster/home/mmunso01/envs/nidaba/lib/python2.7/site-packages/kraken/lib/lstm.py", line 216, in forward
    assert not np.isnan(self.output[:n]).any()
AssertionError
[2015-10-30 07:17:08,846: ERROR/MainProcess] Task nidaba.ocr.kraken[03c00619-e22e-4c22-a119-117bd3fea02d] raised unexpected: AssertionError()
Traceback (most recent call last):
  File "/cluster/home/mmunso01/envs/nidaba/lib/python2.7/site-packages/celery/app/trace.py", line 240, in trace_task
    R = retval = fun(*args, **kwargs)
  File "/cluster/home/mmunso01/envs/nidaba/lib/python2.7/site-packages/nidaba/tasks/helper.py", line 89, in __call__
    ret = super(NidabaTask, self).__call__(*args, **nkwargs)
  File "/cluster/home/mmunso01/envs/nidaba/lib/python2.7/site-packages/celery/app/trace.py", line 438, in __protected_call__
    return self.run(*args, **kwargs)
  File "/cluster/home/mmunso01/envs/nidaba/lib/python2.7/site-packages/nidaba/plugins/kraken.py", line 155, in ocr_kraken
    for rec in rpred.rpred(rnn, img, [(int(x[0]), int(x[1]), int(x[2]), int(x[3])) for x in lines]):
  File "/cluster/home/mmunso01/envs/nidaba/lib/python2.7/site-packages/kraken/rpred.py", line 134, in rpred
    pred = network.predictString(line)
  File "/cluster/home/mmunso01/envs/nidaba/lib/python2.7/site-packages/kraken/lib/lstm.py", line 281, in predictString
    cs = self.predictSequence(xs)
  File "/cluster/home/mmunso01/envs/nidaba/lib/python2.7/site-packages/kraken/lib/lstm.py", line 273, in predictSequence
    self.outputs = np.array(self.lstm.forward(xs))
  File "/cluster/home/mmunso01/envs/nidaba/lib/python2.7/site-packages/kraken/lib/lstm.py", line 229, in forward
    xs = net.forward(xs)
  File "/cluster/home/mmunso01/envs/nidaba/lib/python2.7/site-packages/kraken/lib/lstm.py", line 244, in forward
    outputs = [net.forward(xs) for net in self.nets]
  File "/cluster/home/mmunso01/envs/nidaba/lib/python2.7/site-packages/kraken/lib/lstm.py", line 216, in forward
    assert not np.isnan(self.output[:n]).any()
AssertionError
[2015-10-30 07:17:22,636: ERROR/MainProcess] Task nidaba.ocr.kraken[a52a9753-7a0a-4cba-bd08-40fe1e5bea6a] raised unexpected: AssertionError()
Traceback (most recent call last):
  File "/cluster/home/mmunso01/envs/nidaba/lib/python2.7/site-packages/celery/app/trace.py", line 240, in trace_task
    R = retval = fun(*args, **kwargs)
  File "/cluster/home/mmunso01/envs/nidaba/lib/python2.7/site-packages/nidaba/tasks/helper.py", line 89, in __call__
    ret = super(NidabaTask, self).__call__(*args, **nkwargs)
  File "/cluster/home/mmunso01/envs/nidaba/lib/python2.7/site-packages/celery/app/trace.py", line 438, in __protected_call__
    return self.run(*args, **kwargs)
  File "/cluster/home/mmunso01/envs/nidaba/lib/python2.7/site-packages/nidaba/plugins/kraken.py", line 155, in ocr_kraken
    for rec in rpred.rpred(rnn, img, [(int(x[0]), int(x[1]), int(x[2]), int(x[3])) for x in lines]):
  File "/cluster/home/mmunso01/envs/nidaba/lib/python2.7/site-packages/kraken/rpred.py", line 134, in rpred
    pred = network.predictString(line)
  File "/cluster/home/mmunso01/envs/nidaba/lib/python2.7/site-packages/kraken/lib/lstm.py", line 281, in predictString
    cs = self.predictSequence(xs)
  File "/cluster/home/mmunso01/envs/nidaba/lib/python2.7/site-packages/kraken/lib/lstm.py", line 273, in predictSequence
    self.outputs = np.array(self.lstm.forward(xs))
  File "/cluster/home/mmunso01/envs/nidaba/lib/python2.7/site-packages/kraken/lib/lstm.py", line 229, in forward
    xs = net.forward(xs)
  File "/cluster/home/mmunso01/envs/nidaba/lib/python2.7/site-packages/kraken/lib/lstm.py", line 244, in forward
    outputs = [net.forward(xs) for net in self.nets]
  File "/cluster/home/mmunso01/envs/nidaba/lib/python2.7/site-packages/kraken/lib/lstm.py", line 216, in forward
    assert not np.isnan(self.output[:n]).any()
AssertionError
[2015-10-30 07:19:13,616: WARNING/Worker-40] /cluster/home/mmunso01/envs/nidaba/lib/python2.7/site-packages/kraken/rpred.py:91: RuntimeWarning: invalid value encountered in true_divide
  temp = temp*1.0/np.amax(temp)
[2015-10-30 07:19:13,629: WARNING/Worker-40] /cluster/home/mmunso01/envs/nidaba/lib/python2.7/site-packages/kraken/lib/lstm.py:48: RuntimeWarning: invalid value encountered in true_divide
  line = line * 1.0/np.amax(line)
[2015-10-30 07:19:13,660: ERROR/Worker-40] nidaba.ocr.kraken[845ca527-3df8-465a-af49-431b3548a212]: 
[2015-10-30 07:19:16,275: ERROR/Worker-30] nidaba.ocr.kraken[8b707608-37d0-4f3b-b9fa-674ea3062190]: float division by zero
[2015-10-30 07:19:17,180: ERROR/MainProcess] Task nidaba.ocr.kraken[8b707608-37d0-4f3b-b9fa-674ea3062190] raised unexpected: ZeroDivisionError('float division by zero',)
Traceback (most recent call last):
  File "/cluster/home/mmunso01/envs/nidaba/lib/python2.7/site-packages/celery/app/trace.py", line 240, in trace_task
    R = retval = fun(*args, **kwargs)
  File "/cluster/home/mmunso01/envs/nidaba/lib/python2.7/site-packages/nidaba/tasks/helper.py", line 89, in __call__
    ret = super(NidabaTask, self).__call__(*args, **nkwargs)
  File "/cluster/home/mmunso01/envs/nidaba/lib/python2.7/site-packages/celery/app/trace.py", line 438, in __protected_call__
    return self.run(*args, **kwargs)
  File "/cluster/home/mmunso01/envs/nidaba/lib/python2.7/site-packages/nidaba/plugins/kraken.py", line 155, in ocr_kraken
    for rec in rpred.rpred(rnn, img, [(int(x[0]), int(x[1]), int(x[2]), int(x[3])) for x in lines]):
  File "/cluster/home/mmunso01/envs/nidaba/lib/python2.7/site-packages/kraken/rpred.py", line 127, in rpred
    box = dewarp(lnorm, box)
  File "/cluster/home/mmunso01/envs/nidaba/lib/python2.7/site-packages/kraken/rpred.py", line 93, in dewarp
    line = normalizer.normalize(line, cval=np.amax(line))
  File "/cluster/home/mmunso01/envs/nidaba/lib/python2.7/site-packages/kraken/lib/lineest.py", line 60, in normalize
    dtype=dtype, cval=cval)
  File "/cluster/home/mmunso01/envs/nidaba/lib/python2.7/site-packages/kraken/lib/lineest.py", line 13, in scale_to_h
    scale = target_height*1.0/h
ZeroDivisionError: float division by zero
[2015-10-30 07:19:18,181: ERROR/MainProcess] Task nidaba.ocr.kraken[845ca527-3df8-465a-af49-431b3548a212] raised unexpected: AssertionError()
Traceback (most recent call last):
  File "/cluster/home/mmunso01/envs/nidaba/lib/python2.7/site-packages/celery/app/trace.py", line 240, in trace_task
    R = retval = fun(*args, **kwargs)
  File "/cluster/home/mmunso01/envs/nidaba/lib/python2.7/site-packages/nidaba/tasks/helper.py", line 89, in __call__
    ret = super(NidabaTask, self).__call__(*args, **nkwargs)
  File "/cluster/home/mmunso01/envs/nidaba/lib/python2.7/site-packages/celery/app/trace.py", line 438, in __protected_call__
    return self.run(*args, **kwargs)
  File "/cluster/home/mmunso01/envs/nidaba/lib/python2.7/site-packages/nidaba/plugins/kraken.py", line 155, in ocr_kraken
    for rec in rpred.rpred(rnn, img, [(int(x[0]), int(x[1]), int(x[2]), int(x[3])) for x in lines]):
  File "/cluster/home/mmunso01/envs/nidaba/lib/python2.7/site-packages/kraken/rpred.py", line 134, in rpred
    pred = network.predictString(line)
  File "/cluster/home/mmunso01/envs/nidaba/lib/python2.7/site-packages/kraken/lib/lstm.py", line 281, in predictString
    cs = self.predictSequence(xs)
  File "/cluster/home/mmunso01/envs/nidaba/lib/python2.7/site-packages/kraken/lib/lstm.py", line 273, in predictSequence
    self.outputs = np.array(self.lstm.forward(xs))
  File "/cluster/home/mmunso01/envs/nidaba/lib/python2.7/site-packages/kraken/lib/lstm.py", line 229, in forward
    xs = net.forward(xs)
  File "/cluster/home/mmunso01/envs/nidaba/lib/python2.7/site-packages/kraken/lib/lstm.py", line 244, in forward
    outputs = [net.forward(xs) for net in self.nets]
  File "/cluster/home/mmunso01/envs/nidaba/lib/python2.7/site-packages/kraken/lib/lstm.py", line 216, in forward
    assert not np.isnan(self.output[:n]).any()
AssertionError
[2015-10-30 07:20:13,287: WARNING/Worker-13] /cluster/home/mmunso01/envs/nidaba/lib/python2.7/site-packages/kraken/rpred.py:91: RuntimeWarning: invalid value encountered in true_divide
  temp = temp*1.0/np.amax(temp)
[2015-10-30 07:21:35,672: ERROR/Worker-17] nidaba.ocr.kraken[4116f5dc-3a76-424f-8551-862f051a850b]: float division by zero
[2015-10-30 07:21:41,706: ERROR/MainProcess] Task nidaba.ocr.kraken[4116f5dc-3a76-424f-8551-862f051a850b] raised unexpected: ZeroDivisionError('float division by zero',)
Traceback (most recent call last):
  File "/cluster/home/mmunso01/envs/nidaba/lib/python2.7/site-packages/celery/app/trace.py", line 240, in trace_task
    R = retval = fun(*args, **kwargs)
  File "/cluster/home/mmunso01/envs/nidaba/lib/python2.7/site-packages/nidaba/tasks/helper.py", line 89, in __call__
    ret = super(NidabaTask, self).__call__(*args, **nkwargs)
  File "/cluster/home/mmunso01/envs/nidaba/lib/python2.7/site-packages/celery/app/trace.py", line 438, in __protected_call__
    return self.run(*args, **kwargs)
  File "/cluster/home/mmunso01/envs/nidaba/lib/python2.7/site-packages/nidaba/plugins/kraken.py", line 155, in ocr_kraken
    for rec in rpred.rpred(rnn, img, [(int(x[0]), int(x[1]), int(x[2]), int(x[3])) for x in lines]):
  File "/cluster/home/mmunso01/envs/nidaba/lib/python2.7/site-packages/kraken/rpred.py", line 127, in rpred
    box = dewarp(lnorm, box)
  File "/cluster/home/mmunso01/envs/nidaba/lib/python2.7/site-packages/kraken/rpred.py", line 93, in dewarp
    line = normalizer.normalize(line, cval=np.amax(line))
  File "/cluster/home/mmunso01/envs/nidaba/lib/python2.7/site-packages/kraken/lib/lineest.py", line 60, in normalize
    dtype=dtype, cval=cval)
  File "/cluster/home/mmunso01/envs/nidaba/lib/python2.7/site-packages/kraken/lib/lineest.py", line 13, in scale_to_h
    scale = target_height*1.0/h
ZeroDivisionError: float division by zero
[2015-10-30 07:21:49,675: WARNING/Worker-23] /cluster/home/mmunso01/envs/nidaba/lib/python2.7/site-packages/kraken/rpred.py:91: RuntimeWarning: invalid value encountered in true_divide
  temp = temp*1.0/np.amax(temp)
[2015-10-30 07:22:12,683: WARNING/Worker-17] /cluster/home/mmunso01/envs/nidaba/lib/python2.7/site-packages/kraken/rpred.py:91: RuntimeWarning: invalid value encountered in true_divide
  temp = temp*1.0/np.amax(temp)
[2015-10-30 07:22:21,589: ERROR/Worker-1] nidaba.ocr.kraken[af64446c-46de-43f8-9eb7-fe688f44af07]: float division by zero
[2015-10-30 07:22:22,215: ERROR/Worker-17] nidaba.ocr.kraken[1a6f84dd-22af-4a43-9dd2-47b9fa089f1d]: float division by zero
[2015-10-30 07:22:25,480: ERROR/MainProcess] Task nidaba.ocr.kraken[af64446c-46de-43f8-9eb7-fe688f44af07] raised unexpected: ZeroDivisionError('float division by zero',)
Traceback (most recent call last):
  File "/cluster/home/mmunso01/envs/nidaba/lib/python2.7/site-packages/celery/app/trace.py", line 240, in trace_task
    R = retval = fun(*args, **kwargs)
  File "/cluster/home/mmunso01/envs/nidaba/lib/python2.7/site-packages/nidaba/tasks/helper.py", line 89, in __call__
    ret = super(NidabaTask, self).__call__(*args, **nkwargs)
  File "/cluster/home/mmunso01/envs/nidaba/lib/python2.7/site-packages/celery/app/trace.py", line 438, in __protected_call__
    return self.run(*args, **kwargs)
  File "/cluster/home/mmunso01/envs/nidaba/lib/python2.7/site-packages/nidaba/plugins/kraken.py", line 155, in ocr_kraken
    for rec in rpred.rpred(rnn, img, [(int(x[0]), int(x[1]), int(x[2]), int(x[3])) for x in lines]):
  File "/cluster/home/mmunso01/envs/nidaba/lib/python2.7/site-packages/kraken/rpred.py", line 127, in rpred
    box = dewarp(lnorm, box)
  File "/cluster/home/mmunso01/envs/nidaba/lib/python2.7/site-packages/kraken/rpred.py", line 93, in dewarp
    line = normalizer.normalize(line, cval=np.amax(line))
  File "/cluster/home/mmunso01/envs/nidaba/lib/python2.7/site-packages/kraken/lib/lineest.py", line 60, in normalize
    dtype=dtype, cval=cval)
  File "/cluster/home/mmunso01/envs/nidaba/lib/python2.7/site-packages/kraken/lib/lineest.py", line 13, in scale_to_h
    scale = target_height*1.0/h
ZeroDivisionError: float division by zero
[2015-10-30 07:22:36,850: ERROR/MainProcess] Task nidaba.ocr.kraken[1a6f84dd-22af-4a43-9dd2-47b9fa089f1d] raised unexpected: ZeroDivisionError('float division by zero',)
Traceback (most recent call last):
  File "/cluster/home/mmunso01/envs/nidaba/lib/python2.7/site-packages/celery/app/trace.py", line 240, in trace_task
    R = retval = fun(*args, **kwargs)
  File "/cluster/home/mmunso01/envs/nidaba/lib/python2.7/site-packages/nidaba/tasks/helper.py", line 89, in __call__
    ret = super(NidabaTask, self).__call__(*args, **nkwargs)
  File "/cluster/home/mmunso01/envs/nidaba/lib/python2.7/site-packages/celery/app/trace.py", line 438, in __protected_call__
    return self.run(*args, **kwargs)
  File "/cluster/home/mmunso01/envs/nidaba/lib/python2.7/site-packages/nidaba/plugins/kraken.py", line 155, in ocr_kraken
    for rec in rpred.rpred(rnn, img, [(int(x[0]), int(x[1]), int(x[2]), int(x[3])) for x in lines]):
  File "/cluster/home/mmunso01/envs/nidaba/lib/python2.7/site-packages/kraken/rpred.py", line 127, in rpred
    box = dewarp(lnorm, box)
  File "/cluster/home/mmunso01/envs/nidaba/lib/python2.7/site-packages/kraken/rpred.py", line 93, in dewarp
    line = normalizer.normalize(line, cval=np.amax(line))
  File "/cluster/home/mmunso01/envs/nidaba/lib/python2.7/site-packages/kraken/lib/lineest.py", line 60, in normalize
    dtype=dtype, cval=cval)
  File "/cluster/home/mmunso01/envs/nidaba/lib/python2.7/site-packages/kraken/lib/lineest.py", line 13, in scale_to_h
    scale = target_height*1.0/h
ZeroDivisionError: float division by zero
[2015-10-30 07:23:58,756: WARNING/Worker-33] /cluster/home/mmunso01/envs/nidaba/lib/python2.7/site-packages/kraken/rpred.py:91: RuntimeWarning: invalid value encountered in true_divide
  temp = temp*1.0/np.amax(temp)
[2015-10-30 07:23:58,764: WARNING/Worker-33] /cluster/home/mmunso01/envs/nidaba/lib/python2.7/site-packages/kraken/lib/lstm.py:48: RuntimeWarning: invalid value encountered in true_divide
  line = line * 1.0/np.amax(line)
[2015-10-30 07:23:58,794: ERROR/Worker-33] nidaba.ocr.kraken[bd3d7b1c-4bb3-47e5-94ed-daf227d8fcf4]: 
[2015-10-30 07:24:03,912: ERROR/MainProcess] Task nidaba.ocr.kraken[bd3d7b1c-4bb3-47e5-94ed-daf227d8fcf4] raised unexpected: AssertionError()
Traceback (most recent call last):
  File "/cluster/home/mmunso01/envs/nidaba/lib/python2.7/site-packages/celery/app/trace.py", line 240, in trace_task
    R = retval = fun(*args, **kwargs)
  File "/cluster/home/mmunso01/envs/nidaba/lib/python2.7/site-packages/nidaba/tasks/helper.py", line 89, in __call__
    ret = super(NidabaTask, self).__call__(*args, **nkwargs)
  File "/cluster/home/mmunso01/envs/nidaba/lib/python2.7/site-packages/celery/app/trace.py", line 438, in __protected_call__
    return self.run(*args, **kwargs)
  File "/cluster/home/mmunso01/envs/nidaba/lib/python2.7/site-packages/nidaba/plugins/kraken.py", line 155, in ocr_kraken
    for rec in rpred.rpred(rnn, img, [(int(x[0]), int(x[1]), int(x[2]), int(x[3])) for x in lines]):
  File "/cluster/home/mmunso01/envs/nidaba/lib/python2.7/site-packages/kraken/rpred.py", line 134, in rpred
    pred = network.predictString(line)
  File "/cluster/home/mmunso01/envs/nidaba/lib/python2.7/site-packages/kraken/lib/lstm.py", line 281, in predictString
    cs = self.predictSequence(xs)
  File "/cluster/home/mmunso01/envs/nidaba/lib/python2.7/site-packages/kraken/lib/lstm.py", line 273, in predictSequence
    self.outputs = np.array(self.lstm.forward(xs))
  File "/cluster/home/mmunso01/envs/nidaba/lib/python2.7/site-packages/kraken/lib/lstm.py", line 229, in forward
    xs = net.forward(xs)
  File "/cluster/home/mmunso01/envs/nidaba/lib/python2.7/site-packages/kraken/lib/lstm.py", line 244, in forward
    outputs = [net.forward(xs) for net in self.nets]
  File "/cluster/home/mmunso01/envs/nidaba/lib/python2.7/site-packages/kraken/lib/lstm.py", line 216, in forward
    assert not np.isnan(self.output[:n]).any()
AssertionError
[2015-10-30 07:24:30,520: WARNING/Worker-31] /cluster/home/mmunso01/envs/nidaba/lib/python2.7/site-packages/kraken/rpred.py:91: RuntimeWarning: invalid value encountered in true_divide
  temp = temp*1.0/np.amax(temp)
[2015-10-30 07:24:42,197: WARNING/Worker-17] /cluster/home/mmunso01/envs/nidaba/lib/python2.7/site-packages/kraken/lib/lstm.py:48: RuntimeWarning: invalid value encountered in true_divide
  line = line * 1.0/np.amax(line)
[2015-10-30 07:24:42,257: ERROR/Worker-17] nidaba.ocr.kraken[b87a29cc-15ac-4b50-9054-23896ac6189d]: 
[2015-10-30 07:24:43,776: ERROR/MainProcess] Task nidaba.ocr.kraken[b87a29cc-15ac-4b50-9054-23896ac6189d] raised unexpected: AssertionError()
Traceback (most recent call last):
  File "/cluster/home/mmunso01/envs/nidaba/lib/python2.7/site-packages/celery/app/trace.py", line 240, in trace_task
    R = retval = fun(*args, **kwargs)
  File "/cluster/home/mmunso01/envs/nidaba/lib/python2.7/site-packages/nidaba/tasks/helper.py", line 89, in __call__
    ret = super(NidabaTask, self).__call__(*args, **nkwargs)
  File "/cluster/home/mmunso01/envs/nidaba/lib/python2.7/site-packages/celery/app/trace.py", line 438, in __protected_call__
    return self.run(*args, **kwargs)
  File "/cluster/home/mmunso01/envs/nidaba/lib/python2.7/site-packages/nidaba/plugins/kraken.py", line 155, in ocr_kraken
    for rec in rpred.rpred(rnn, img, [(int(x[0]), int(x[1]), int(x[2]), int(x[3])) for x in lines]):
  File "/cluster/home/mmunso01/envs/nidaba/lib/python2.7/site-packages/kraken/rpred.py", line 134, in rpred
    pred = network.predictString(line)
  File "/cluster/home/mmunso01/envs/nidaba/lib/python2.7/site-packages/kraken/lib/lstm.py", line 281, in predictString
    cs = self.predictSequence(xs)
  File "/cluster/home/mmunso01/envs/nidaba/lib/python2.7/site-packages/kraken/lib/lstm.py", line 273, in predictSequence
    self.outputs = np.array(self.lstm.forward(xs))
  File "/cluster/home/mmunso01/envs/nidaba/lib/python2.7/site-packages/kraken/lib/lstm.py", line 229, in forward
    xs = net.forward(xs)
  File "/cluster/home/mmunso01/envs/nidaba/lib/python2.7/site-packages/kraken/lib/lstm.py", line 244, in forward
    outputs = [net.forward(xs) for net in self.nets]
  File "/cluster/home/mmunso01/envs/nidaba/lib/python2.7/site-packages/kraken/lib/lstm.py", line 216, in forward
    assert not np.isnan(self.output[:n]).any()
AssertionError
[2015-10-30 07:25:32,987: ERROR/Worker-2] nidaba.ocr.kraken[738d6c61-9c4e-4f15-afdc-5d476a3f901a]: index 5000 is out of bounds for axis 0 with size 5000
[2015-10-30 07:25:34,304: ERROR/MainProcess] Task nidaba.ocr.kraken[738d6c61-9c4e-4f15-afdc-5d476a3f901a] raised unexpected: IndexError('index 5000 is out of bounds for axis 0 with size 5000',)
Traceback (most recent call last):
  File "/cluster/home/mmunso01/envs/nidaba/lib/python2.7/site-packages/celery/app/trace.py", line 240, in trace_task
    R = retval = fun(*args, **kwargs)
  File "/cluster/home/mmunso01/envs/nidaba/lib/python2.7/site-packages/nidaba/tasks/helper.py", line 89, in __call__
    ret = super(NidabaTask, self).__call__(*args, **nkwargs)
  File "/cluster/home/mmunso01/envs/nidaba/lib/python2.7/site-packages/celery/app/trace.py", line 438, in __protected_call__
    return self.run(*args, **kwargs)
  File "/cluster/home/mmunso01/envs/nidaba/lib/python2.7/site-packages/nidaba/plugins/kraken.py", line 155, in ocr_kraken
    for rec in rpred.rpred(rnn, img, [(int(x[0]), int(x[1]), int(x[2]), int(x[3])) for x in lines]):
  File "/cluster/home/mmunso01/envs/nidaba/lib/python2.7/site-packages/kraken/rpred.py", line 134, in rpred
    pred = network.predictString(line)
  File "/cluster/home/mmunso01/envs/nidaba/lib/python2.7/site-packages/kraken/lib/lstm.py", line 281, in predictString
    cs = self.predictSequence(xs)
  File "/cluster/home/mmunso01/envs/nidaba/lib/python2.7/site-packages/kraken/lib/lstm.py", line 273, in predictSequence
    self.outputs = np.array(self.lstm.forward(xs))
  File "/cluster/home/mmunso01/envs/nidaba/lib/python2.7/site-packages/kraken/lib/lstm.py", line 229, in forward
    xs = net.forward(xs)
  File "/cluster/home/mmunso01/envs/nidaba/lib/python2.7/site-packages/kraken/lib/lstm.py", line 244, in forward
    outputs = [net.forward(xs) for net in self.nets]
  File "/cluster/home/mmunso01/envs/nidaba/lib/python2.7/site-packages/kraken/lib/lstm.py", line 196, in forward
    self.source[t,0] = 1
IndexError: index 5000 is out of bounds for axis 0 with size 5000
[2015-10-30 07:25:52,059: ERROR/Worker-40] nidaba.ocr.kraken[bbc4c481-8fdf-40ed-9be7-ae2cae48f597]: index 5000 is out of bounds for axis 0 with size 5000
[2015-10-30 07:25:53,057: ERROR/MainProcess] Task nidaba.ocr.kraken[bbc4c481-8fdf-40ed-9be7-ae2cae48f597] raised unexpected: IndexError('index 5000 is out of bounds for axis 0 with size 5000',)
Traceback (most recent call last):
  File "/cluster/home/mmunso01/envs/nidaba/lib/python2.7/site-packages/celery/app/trace.py", line 240, in trace_task
    R = retval = fun(*args, **kwargs)
  File "/cluster/home/mmunso01/envs/nidaba/lib/python2.7/site-packages/nidaba/tasks/helper.py", line 89, in __call__
    ret = super(NidabaTask, self).__call__(*args, **nkwargs)
  File "/cluster/home/mmunso01/envs/nidaba/lib/python2.7/site-packages/celery/app/trace.py", line 438, in __protected_call__
    return self.run(*args, **kwargs)
  File "/cluster/home/mmunso01/envs/nidaba/lib/python2.7/site-packages/nidaba/plugins/kraken.py", line 155, in ocr_kraken
    for rec in rpred.rpred(rnn, img, [(int(x[0]), int(x[1]), int(x[2]), int(x[3])) for x in lines]):
  File "/cluster/home/mmunso01/envs/nidaba/lib/python2.7/site-packages/kraken/rpred.py", line 134, in rpred
    pred = network.predictString(line)
  File "/cluster/home/mmunso01/envs/nidaba/lib/python2.7/site-packages/kraken/lib/lstm.py", line 281, in predictString
    cs = self.predictSequence(xs)
  File "/cluster/home/mmunso01/envs/nidaba/lib/python2.7/site-packages/kraken/lib/lstm.py", line 273, in predictSequence
    self.outputs = np.array(self.lstm.forward(xs))
  File "/cluster/home/mmunso01/envs/nidaba/lib/python2.7/site-packages/kraken/lib/lstm.py", line 229, in forward
    xs = net.forward(xs)
  File "/cluster/home/mmunso01/envs/nidaba/lib/python2.7/site-packages/kraken/lib/lstm.py", line 244, in forward
    outputs = [net.forward(xs) for net in self.nets]
  File "/cluster/home/mmunso01/envs/nidaba/lib/python2.7/site-packages/kraken/lib/lstm.py", line 196, in forward
    self.source[t,0] = 1
IndexError: index 5000 is out of bounds for axis 0 with size 5000
[2015-10-30 07:26:04,656: WARNING/Worker-14] /cluster/home/mmunso01/envs/nidaba/lib/python2.7/site-packages/kraken/rpred.py:91: RuntimeWarning: invalid value encountered in true_divide
  temp = temp*1.0/np.amax(temp)
[2015-10-30 07:26:13,628: WARNING/Worker-38] /cluster/home/mmunso01/envs/nidaba/lib/python2.7/site-packages/kraken/rpred.py:91: RuntimeWarning: invalid value encountered in true_divide
  temp = temp*1.0/np.amax(temp)
[2015-10-30 07:26:13,630: WARNING/Worker-38] /cluster/home/mmunso01/envs/nidaba/lib/python2.7/site-packages/kraken/lib/lstm.py:48: RuntimeWarning: invalid value encountered in true_divide
  line = line * 1.0/np.amax(line)
[2015-10-30 07:26:13,657: ERROR/Worker-38] nidaba.ocr.kraken[ec737dd7-72d5-44fa-a835-73a817f9ab3a]: 
[2015-10-30 07:26:14,978: ERROR/MainProcess] Task nidaba.ocr.kraken[ec737dd7-72d5-44fa-a835-73a817f9ab3a] raised unexpected: AssertionError()
Traceback (most recent call last):
  File "/cluster/home/mmunso01/envs/nidaba/lib/python2.7/site-packages/celery/app/trace.py", line 240, in trace_task
    R = retval = fun(*args, **kwargs)
  File "/cluster/home/mmunso01/envs/nidaba/lib/python2.7/site-packages/nidaba/tasks/helper.py", line 89, in __call__
    ret = super(NidabaTask, self).__call__(*args, **nkwargs)
  File "/cluster/home/mmunso01/envs/nidaba/lib/python2.7/site-packages/celery/app/trace.py", line 438, in __protected_call__
    return self.run(*args, **kwargs)
  File "/cluster/home/mmunso01/envs/nidaba/lib/python2.7/site-packages/nidaba/plugins/kraken.py", line 155, in ocr_kraken
    for rec in rpred.rpred(rnn, img, [(int(x[0]), int(x[1]), int(x[2]), int(x[3])) for x in lines]):
  File "/cluster/home/mmunso01/envs/nidaba/lib/python2.7/site-packages/kraken/rpred.py", line 134, in rpred
    pred = network.predictString(line)
  File "/cluster/home/mmunso01/envs/nidaba/lib/python2.7/site-packages/kraken/lib/lstm.py", line 281, in predictString
    cs = self.predictSequence(xs)
  File "/cluster/home/mmunso01/envs/nidaba/lib/python2.7/site-packages/kraken/lib/lstm.py", line 273, in predictSequence
    self.outputs = np.array(self.lstm.forward(xs))
  File "/cluster/home/mmunso01/envs/nidaba/lib/python2.7/site-packages/kraken/lib/lstm.py", line 229, in forward
    xs = net.forward(xs)
  File "/cluster/home/mmunso01/envs/nidaba/lib/python2.7/site-packages/kraken/lib/lstm.py", line 244, in forward
    outputs = [net.forward(xs) for net in self.nets]
  File "/cluster/home/mmunso01/envs/nidaba/lib/python2.7/site-packages/kraken/lib/lstm.py", line 216, in forward
    assert not np.isnan(self.output[:n]).any()
AssertionError
[2015-10-30 07:26:41,093: ERROR/Worker-29] nidaba.ocr.kraken[bdfb9d6e-ce3b-4671-8a73-5b9552953d89]: float division by zero
[2015-10-30 07:26:45,138: ERROR/Worker-15] nidaba.ocr.kraken[a7fc523e-f4cd-46b0-8013-970ce94d4e8d]: index 5000 is out of bounds for axis 0 with size 5000
[2015-10-30 07:26:46,511: ERROR/MainProcess] Task nidaba.ocr.kraken[a7fc523e-f4cd-46b0-8013-970ce94d4e8d] raised unexpected: IndexError('index 5000 is out of bounds for axis 0 with size 5000',)
Traceback (most recent call last):
  File "/cluster/home/mmunso01/envs/nidaba/lib/python2.7/site-packages/celery/app/trace.py", line 240, in trace_task
    R = retval = fun(*args, **kwargs)
  File "/cluster/home/mmunso01/envs/nidaba/lib/python2.7/site-packages/nidaba/tasks/helper.py", line 89, in __call__
    ret = super(NidabaTask, self).__call__(*args, **nkwargs)
  File "/cluster/home/mmunso01/envs/nidaba/lib/python2.7/site-packages/celery/app/trace.py", line 438, in __protected_call__
    return self.run(*args, **kwargs)
  File "/cluster/home/mmunso01/envs/nidaba/lib/python2.7/site-packages/nidaba/plugins/kraken.py", line 155, in ocr_kraken
    for rec in rpred.rpred(rnn, img, [(int(x[0]), int(x[1]), int(x[2]), int(x[3])) for x in lines]):
  File "/cluster/home/mmunso01/envs/nidaba/lib/python2.7/site-packages/kraken/rpred.py", line 134, in rpred
    pred = network.predictString(line)
  File "/cluster/home/mmunso01/envs/nidaba/lib/python2.7/site-packages/kraken/lib/lstm.py", line 281, in predictString
    cs = self.predictSequence(xs)
  File "/cluster/home/mmunso01/envs/nidaba/lib/python2.7/site-packages/kraken/lib/lstm.py", line 273, in predictSequence
    self.outputs = np.array(self.lstm.forward(xs))
  File "/cluster/home/mmunso01/envs/nidaba/lib/python2.7/site-packages/kraken/lib/lstm.py", line 229, in forward
    xs = net.forward(xs)
  File "/cluster/home/mmunso01/envs/nidaba/lib/python2.7/site-packages/kraken/lib/lstm.py", line 244, in forward
    outputs = [net.forward(xs) for net in self.nets]
  File "/cluster/home/mmunso01/envs/nidaba/lib/python2.7/site-packages/kraken/lib/lstm.py", line 196, in forward
    self.source[t,0] = 1
IndexError: index 5000 is out of bounds for axis 0 with size 5000
[2015-10-30 07:26:50,217: ERROR/MainProcess] Task nidaba.ocr.kraken[bdfb9d6e-ce3b-4671-8a73-5b9552953d89] raised unexpected: ZeroDivisionError('float division by zero',)
Traceback (most recent call last):
  File "/cluster/home/mmunso01/envs/nidaba/lib/python2.7/site-packages/celery/app/trace.py", line 240, in trace_task
    R = retval = fun(*args, **kwargs)
  File "/cluster/home/mmunso01/envs/nidaba/lib/python2.7/site-packages/nidaba/tasks/helper.py", line 89, in __call__
    ret = super(NidabaTask, self).__call__(*args, **nkwargs)
  File "/cluster/home/mmunso01/envs/nidaba/lib/python2.7/site-packages/celery/app/trace.py", line 438, in __protected_call__
    return self.run(*args, **kwargs)
  File "/cluster/home/mmunso01/envs/nidaba/lib/python2.7/site-packages/nidaba/plugins/kraken.py", line 155, in ocr_kraken
    for rec in rpred.rpred(rnn, img, [(int(x[0]), int(x[1]), int(x[2]), int(x[3])) for x in lines]):
  File "/cluster/home/mmunso01/envs/nidaba/lib/python2.7/site-packages/kraken/rpred.py", line 127, in rpred
    box = dewarp(lnorm, box)
  File "/cluster/home/mmunso01/envs/nidaba/lib/python2.7/site-packages/kraken/rpred.py", line 93, in dewarp
    line = normalizer.normalize(line, cval=np.amax(line))
  File "/cluster/home/mmunso01/envs/nidaba/lib/python2.7/site-packages/kraken/lib/lineest.py", line 60, in normalize
    dtype=dtype, cval=cval)
  File "/cluster/home/mmunso01/envs/nidaba/lib/python2.7/site-packages/kraken/lib/lineest.py", line 13, in scale_to_h
    scale = target_height*1.0/h
ZeroDivisionError: float division by zero
[2015-10-30 07:27:26,605: WARNING/Worker-21] /cluster/home/mmunso01/envs/nidaba/lib/python2.7/site-packages/kraken/rpred.py:91: RuntimeWarning: invalid value encountered in true_divide
  temp = temp*1.0/np.amax(temp)
[2015-10-30 07:27:26,607: ERROR/Worker-21] nidaba.ocr.kraken[992437fd-f5db-42df-acfc-0bad325cedc0]: float division by zero
[2015-10-30 07:27:27,687: ERROR/MainProcess] Task nidaba.ocr.kraken[992437fd-f5db-42df-acfc-0bad325cedc0] raised unexpected: ZeroDivisionError('float division by zero',)
Traceback (most recent call last):
  File "/cluster/home/mmunso01/envs/nidaba/lib/python2.7/site-packages/celery/app/trace.py", line 240, in trace_task
    R = retval = fun(*args, **kwargs)
  File "/cluster/home/mmunso01/envs/nidaba/lib/python2.7/site-packages/nidaba/tasks/helper.py", line 89, in __call__
    ret = super(NidabaTask, self).__call__(*args, **nkwargs)
  File "/cluster/home/mmunso01/envs/nidaba/lib/python2.7/site-packages/celery/app/trace.py", line 438, in __protected_call__
    return self.run(*args, **kwargs)
  File "/cluster/home/mmunso01/envs/nidaba/lib/python2.7/site-packages/nidaba/plugins/kraken.py", line 155, in ocr_kraken
    for rec in rpred.rpred(rnn, img, [(int(x[0]), int(x[1]), int(x[2]), int(x[3])) for x in lines]):
  File "/cluster/home/mmunso01/envs/nidaba/lib/python2.7/site-packages/kraken/rpred.py", line 127, in rpred
    box = dewarp(lnorm, box)
  File "/cluster/home/mmunso01/envs/nidaba/lib/python2.7/site-packages/kraken/rpred.py", line 93, in dewarp
    line = normalizer.normalize(line, cval=np.amax(line))
  File "/cluster/home/mmunso01/envs/nidaba/lib/python2.7/site-packages/kraken/lib/lineest.py", line 60, in normalize
    dtype=dtype, cval=cval)
  File "/cluster/home/mmunso01/envs/nidaba/lib/python2.7/site-packages/kraken/lib/lineest.py", line 13, in scale_to_h
    scale = target_height*1.0/h
ZeroDivisionError: float division by zero
[2015-10-30 07:28:25,064: ERROR/Worker-13] nidaba.ocr.kraken[63a74c0d-0cc4-437c-9361-940fee0cb349]: index 5000 is out of bounds for axis 0 with size 5000
[2015-10-30 07:28:27,371: ERROR/MainProcess] Task nidaba.ocr.kraken[63a74c0d-0cc4-437c-9361-940fee0cb349] raised unexpected: IndexError('index 5000 is out of bounds for axis 0 with size 5000',)
Traceback (most recent call last):
  File "/cluster/home/mmunso01/envs/nidaba/lib/python2.7/site-packages/celery/app/trace.py", line 240, in trace_task
    R = retval = fun(*args, **kwargs)
  File "/cluster/home/mmunso01/envs/nidaba/lib/python2.7/site-packages/nidaba/tasks/helper.py", line 89, in __call__
    ret = super(NidabaTask, self).__call__(*args, **nkwargs)
  File "/cluster/home/mmunso01/envs/nidaba/lib/python2.7/site-packages/celery/app/trace.py", line 438, in __protected_call__
    return self.run(*args, **kwargs)
  File "/cluster/home/mmunso01/envs/nidaba/lib/python2.7/site-packages/nidaba/plugins/kraken.py", line 155, in ocr_kraken
    for rec in rpred.rpred(rnn, img, [(int(x[0]), int(x[1]), int(x[2]), int(x[3])) for x in lines]):
  File "/cluster/home/mmunso01/envs/nidaba/lib/python2.7/site-packages/kraken/rpred.py", line 134, in rpred
    pred = network.predictString(line)
  File "/cluster/home/mmunso01/envs/nidaba/lib/python2.7/site-packages/kraken/lib/lstm.py", line 281, in predictString
    cs = self.predictSequence(xs)
  File "/cluster/home/mmunso01/envs/nidaba/lib/python2.7/site-packages/kraken/lib/lstm.py", line 273, in predictSequence
    self.outputs = np.array(self.lstm.forward(xs))
  File "/cluster/home/mmunso01/envs/nidaba/lib/python2.7/site-packages/kraken/lib/lstm.py", line 229, in forward
    xs = net.forward(xs)
  File "/cluster/home/mmunso01/envs/nidaba/lib/python2.7/site-packages/kraken/lib/lstm.py", line 244, in forward
    outputs = [net.forward(xs) for net in self.nets]
  File "/cluster/home/mmunso01/envs/nidaba/lib/python2.7/site-packages/kraken/lib/lstm.py", line 196, in forward
    self.source[t,0] = 1
IndexError: index 5000 is out of bounds for axis 0 with size 5000
[2015-10-30 07:29:55,581: WARNING/Worker-30] /cluster/home/mmunso01/envs/nidaba/lib/python2.7/site-packages/kraken/rpred.py:91: RuntimeWarning: invalid value encountered in true_divide
  temp = temp*1.0/np.amax(temp)
[2015-10-30 07:29:55,585: ERROR/Worker-30] nidaba.ocr.kraken[6af9aebb-544c-4e7e-934e-8a048824397e]: float division by zero
[2015-10-30 07:29:56,498: ERROR/MainProcess] Task nidaba.ocr.kraken[6af9aebb-544c-4e7e-934e-8a048824397e] raised unexpected: ZeroDivisionError('float division by zero',)
Traceback (most recent call last):
  File "/cluster/home/mmunso01/envs/nidaba/lib/python2.7/site-packages/celery/app/trace.py", line 240, in trace_task
    R = retval = fun(*args, **kwargs)
  File "/cluster/home/mmunso01/envs/nidaba/lib/python2.7/site-packages/nidaba/tasks/helper.py", line 89, in __call__
    ret = super(NidabaTask, self).__call__(*args, **nkwargs)
  File "/cluster/home/mmunso01/envs/nidaba/lib/python2.7/site-packages/celery/app/trace.py", line 438, in __protected_call__
    return self.run(*args, **kwargs)
  File "/cluster/home/mmunso01/envs/nidaba/lib/python2.7/site-packages/nidaba/plugins/kraken.py", line 155, in ocr_kraken
    for rec in rpred.rpred(rnn, img, [(int(x[0]), int(x[1]), int(x[2]), int(x[3])) for x in lines]):
  File "/cluster/home/mmunso01/envs/nidaba/lib/python2.7/site-packages/kraken/rpred.py", line 127, in rpred
    box = dewarp(lnorm, box)
  File "/cluster/home/mmunso01/envs/nidaba/lib/python2.7/site-packages/kraken/rpred.py", line 93, in dewarp
    line = normalizer.normalize(line, cval=np.amax(line))
  File "/cluster/home/mmunso01/envs/nidaba/lib/python2.7/site-packages/kraken/lib/lineest.py", line 60, in normalize
    dtype=dtype, cval=cval)
  File "/cluster/home/mmunso01/envs/nidaba/lib/python2.7/site-packages/kraken/lib/lineest.py", line 13, in scale_to_h
    scale = target_height*1.0/h
ZeroDivisionError: float division by zero
[2015-10-30 07:30:18,018: WARNING/Worker-29] /cluster/home/mmunso01/envs/nidaba/lib/python2.7/site-packages/kraken/rpred.py:91: RuntimeWarning: invalid value encountered in true_divide
  temp = temp*1.0/np.amax(temp)
[2015-10-30 07:30:25,200: ERROR/Worker-25] nidaba.ocr.kraken[876a0a9d-b7f7-4665-9d38-fd9d53e8c15a]: float division by zero
[2015-10-30 07:30:26,444: ERROR/MainProcess] Task nidaba.ocr.kraken[876a0a9d-b7f7-4665-9d38-fd9d53e8c15a] raised unexpected: ZeroDivisionError('float division by zero',)
Traceback (most recent call last):
  File "/cluster/home/mmunso01/envs/nidaba/lib/python2.7/site-packages/celery/app/trace.py", line 240, in trace_task
    R = retval = fun(*args, **kwargs)
  File "/cluster/home/mmunso01/envs/nidaba/lib/python2.7/site-packages/nidaba/tasks/helper.py", line 89, in __call__
    ret = super(NidabaTask, self).__call__(*args, **nkwargs)
  File "/cluster/home/mmunso01/envs/nidaba/lib/python2.7/site-packages/celery/app/trace.py", line 438, in __protected_call__
    return self.run(*args, **kwargs)
  File "/cluster/home/mmunso01/envs/nidaba/lib/python2.7/site-packages/nidaba/plugins/kraken.py", line 155, in ocr_kraken
    for rec in rpred.rpred(rnn, img, [(int(x[0]), int(x[1]), int(x[2]), int(x[3])) for x in lines]):
  File "/cluster/home/mmunso01/envs/nidaba/lib/python2.7/site-packages/kraken/rpred.py", line 127, in rpred
    box = dewarp(lnorm, box)
  File "/cluster/home/mmunso01/envs/nidaba/lib/python2.7/site-packages/kraken/rpred.py", line 93, in dewarp
    line = normalizer.normalize(line, cval=np.amax(line))
  File "/cluster/home/mmunso01/envs/nidaba/lib/python2.7/site-packages/kraken/lib/lineest.py", line 60, in normalize
    dtype=dtype, cval=cval)
  File "/cluster/home/mmunso01/envs/nidaba/lib/python2.7/site-packages/kraken/lib/lineest.py", line 13, in scale_to_h
    scale = target_height*1.0/h
ZeroDivisionError: float division by zero
[2015-10-30 07:31:07,496: WARNING/Worker-6] /cluster/home/mmunso01/envs/nidaba/lib/python2.7/site-packages/kraken/lib/lstm.py:48: RuntimeWarning: invalid value encountered in true_divide
  line = line * 1.0/np.amax(line)
[2015-10-30 07:31:07,529: ERROR/Worker-6] nidaba.ocr.kraken[d8eb3856-2e44-402a-869e-146c217bbea3]: 
[2015-10-30 07:31:08,934: ERROR/MainProcess] Task nidaba.ocr.kraken[d8eb3856-2e44-402a-869e-146c217bbea3] raised unexpected: AssertionError()
Traceback (most recent call last):
  File "/cluster/home/mmunso01/envs/nidaba/lib/python2.7/site-packages/celery/app/trace.py", line 240, in trace_task
    R = retval = fun(*args, **kwargs)
  File "/cluster/home/mmunso01/envs/nidaba/lib/python2.7/site-packages/nidaba/tasks/helper.py", line 89, in __call__
    ret = super(NidabaTask, self).__call__(*args, **nkwargs)
  File "/cluster/home/mmunso01/envs/nidaba/lib/python2.7/site-packages/celery/app/trace.py", line 438, in __protected_call__
    return self.run(*args, **kwargs)
  File "/cluster/home/mmunso01/envs/nidaba/lib/python2.7/site-packages/nidaba/plugins/kraken.py", line 155, in ocr_kraken
    for rec in rpred.rpred(rnn, img, [(int(x[0]), int(x[1]), int(x[2]), int(x[3])) for x in lines]):
  File "/cluster/home/mmunso01/envs/nidaba/lib/python2.7/site-packages/kraken/rpred.py", line 134, in rpred
    pred = network.predictString(line)
  File "/cluster/home/mmunso01/envs/nidaba/lib/python2.7/site-packages/kraken/lib/lstm.py", line 281, in predictString
    cs = self.predictSequence(xs)
  File "/cluster/home/mmunso01/envs/nidaba/lib/python2.7/site-packages/kraken/lib/lstm.py", line 273, in predictSequence
    self.outputs = np.array(self.lstm.forward(xs))
  File "/cluster/home/mmunso01/envs/nidaba/lib/python2.7/site-packages/kraken/lib/lstm.py", line 229, in forward
    xs = net.forward(xs)
  File "/cluster/home/mmunso01/envs/nidaba/lib/python2.7/site-packages/kraken/lib/lstm.py", line 244, in forward
    outputs = [net.forward(xs) for net in self.nets]
  File "/cluster/home/mmunso01/envs/nidaba/lib/python2.7/site-packages/kraken/lib/lstm.py", line 216, in forward
    assert not np.isnan(self.output[:n]).any()
AssertionError
[2015-10-30 07:31:13,229: ERROR/Worker-40] nidaba.ocr.kraken[682d63aa-7674-4c47-b748-69cd90dd00ab]: index 5000 is out of bounds for axis 0 with size 5000
[2015-10-30 07:31:14,376: ERROR/MainProcess] Task nidaba.ocr.kraken[682d63aa-7674-4c47-b748-69cd90dd00ab] raised unexpected: IndexError('index 5000 is out of bounds for axis 0 with size 5000',)
Traceback (most recent call last):
  File "/cluster/home/mmunso01/envs/nidaba/lib/python2.7/site-packages/celery/app/trace.py", line 240, in trace_task
    R = retval = fun(*args, **kwargs)
  File "/cluster/home/mmunso01/envs/nidaba/lib/python2.7/site-packages/nidaba/tasks/helper.py", line 89, in __call__
    ret = super(NidabaTask, self).__call__(*args, **nkwargs)
  File "/cluster/home/mmunso01/envs/nidaba/lib/python2.7/site-packages/celery/app/trace.py", line 438, in __protected_call__
    return self.run(*args, **kwargs)
  File "/cluster/home/mmunso01/envs/nidaba/lib/python2.7/site-packages/nidaba/plugins/kraken.py", line 155, in ocr_kraken
    for rec in rpred.rpred(rnn, img, [(int(x[0]), int(x[1]), int(x[2]), int(x[3])) for x in lines]):
  File "/cluster/home/mmunso01/envs/nidaba/lib/python2.7/site-packages/kraken/rpred.py", line 134, in rpred
    pred = network.predictString(line)
  File "/cluster/home/mmunso01/envs/nidaba/lib/python2.7/site-packages/kraken/lib/lstm.py", line 281, in predictString
    cs = self.predictSequence(xs)
  File "/cluster/home/mmunso01/envs/nidaba/lib/python2.7/site-packages/kraken/lib/lstm.py", line 273, in predictSequence
    self.outputs = np.array(self.lstm.forward(xs))
  File "/cluster/home/mmunso01/envs/nidaba/lib/python2.7/site-packages/kraken/lib/lstm.py", line 229, in forward
    xs = net.forward(xs)
  File "/cluster/home/mmunso01/envs/nidaba/lib/python2.7/site-packages/kraken/lib/lstm.py", line 244, in forward
    outputs = [net.forward(xs) for net in self.nets]
  File "/cluster/home/mmunso01/envs/nidaba/lib/python2.7/site-packages/kraken/lib/lstm.py", line 196, in forward
    self.source[t,0] = 1
IndexError: index 5000 is out of bounds for axis 0 with size 5000
[2015-10-30 07:31:25,201: ERROR/Worker-30] nidaba.ocr.kraken[1c92225a-ec37-40a2-be4b-281480a90cfc]: index 5000 is out of bounds for axis 0 with size 5000
[2015-10-30 07:31:26,196: ERROR/MainProcess] Task nidaba.ocr.kraken[1c92225a-ec37-40a2-be4b-281480a90cfc] raised unexpected: IndexError('index 5000 is out of bounds for axis 0 with size 5000',)
Traceback (most recent call last):
  File "/cluster/home/mmunso01/envs/nidaba/lib/python2.7/site-packages/celery/app/trace.py", line 240, in trace_task
    R = retval = fun(*args, **kwargs)
  File "/cluster/home/mmunso01/envs/nidaba/lib/python2.7/site-packages/nidaba/tasks/helper.py", line 89, in __call__
    ret = super(NidabaTask, self).__call__(*args, **nkwargs)
  File "/cluster/home/mmunso01/envs/nidaba/lib/python2.7/site-packages/celery/app/trace.py", line 438, in __protected_call__
    return self.run(*args, **kwargs)
  File "/cluster/home/mmunso01/envs/nidaba/lib/python2.7/site-packages/nidaba/plugins/kraken.py", line 155, in ocr_kraken
    for rec in rpred.rpred(rnn, img, [(int(x[0]), int(x[1]), int(x[2]), int(x[3])) for x in lines]):
  File "/cluster/home/mmunso01/envs/nidaba/lib/python2.7/site-packages/kraken/rpred.py", line 134, in rpred
    pred = network.predictString(line)
  File "/cluster/home/mmunso01/envs/nidaba/lib/python2.7/site-packages/kraken/lib/lstm.py", line 281, in predictString
    cs = self.predictSequence(xs)
  File "/cluster/home/mmunso01/envs/nidaba/lib/python2.7/site-packages/kraken/lib/lstm.py", line 273, in predictSequence
    self.outputs = np.array(self.lstm.forward(xs))
  File "/cluster/home/mmunso01/envs/nidaba/lib/python2.7/site-packages/kraken/lib/lstm.py", line 229, in forward
    xs = net.forward(xs)
  File "/cluster/home/mmunso01/envs/nidaba/lib/python2.7/site-packages/kraken/lib/lstm.py", line 244, in forward
    outputs = [net.forward(xs) for net in self.nets]
  File "/cluster/home/mmunso01/envs/nidaba/lib/python2.7/site-packages/kraken/lib/lstm.py", line 196, in forward
    self.source[t,0] = 1
IndexError: index 5000 is out of bounds for axis 0 with size 5000
[2015-10-30 07:33:03,394: ERROR/Worker-17] nidaba.ocr.kraken[614a6236-2b0e-4065-a25d-1bbd1471b978]: index 5000 is out of bounds for axis 0 with size 5000
[2015-10-30 07:33:04,537: ERROR/MainProcess] Task nidaba.ocr.kraken[614a6236-2b0e-4065-a25d-1bbd1471b978] raised unexpected: IndexError('index 5000 is out of bounds for axis 0 with size 5000',)
Traceback (most recent call last):
  File "/cluster/home/mmunso01/envs/nidaba/lib/python2.7/site-packages/celery/app/trace.py", line 240, in trace_task
    R = retval = fun(*args, **kwargs)
  File "/cluster/home/mmunso01/envs/nidaba/lib/python2.7/site-packages/nidaba/tasks/helper.py", line 89, in __call__
    ret = super(NidabaTask, self).__call__(*args, **nkwargs)
  File "/cluster/home/mmunso01/envs/nidaba/lib/python2.7/site-packages/celery/app/trace.py", line 438, in __protected_call__
    return self.run(*args, **kwargs)
  File "/cluster/home/mmunso01/envs/nidaba/lib/python2.7/site-packages/nidaba/plugins/kraken.py", line 155, in ocr_kraken
    for rec in rpred.rpred(rnn, img, [(int(x[0]), int(x[1]), int(x[2]), int(x[3])) for x in lines]):
  File "/cluster/home/mmunso01/envs/nidaba/lib/python2.7/site-packages/kraken/rpred.py", line 134, in rpred
    pred = network.predictString(line)
  File "/cluster/home/mmunso01/envs/nidaba/lib/python2.7/site-packages/kraken/lib/lstm.py", line 281, in predictString
    cs = self.predictSequence(xs)
  File "/cluster/home/mmunso01/envs/nidaba/lib/python2.7/site-packages/kraken/lib/lstm.py", line 273, in predictSequence
    self.outputs = np.array(self.lstm.forward(xs))
  File "/cluster/home/mmunso01/envs/nidaba/lib/python2.7/site-packages/kraken/lib/lstm.py", line 229, in forward
    xs = net.forward(xs)
  File "/cluster/home/mmunso01/envs/nidaba/lib/python2.7/site-packages/kraken/lib/lstm.py", line 244, in forward
    outputs = [net.forward(xs) for net in self.nets]
  File "/cluster/home/mmunso01/envs/nidaba/lib/python2.7/site-packages/kraken/lib/lstm.py", line 196, in forward
    self.source[t,0] = 1
IndexError: index 5000 is out of bounds for axis 0 with size 5000
[2015-10-30 07:34:38,688: ERROR/Worker-23] nidaba.ocr.kraken[a3526864-a5bc-45a4-9b95-487c54181b44]: index 5000 is out of bounds for axis 0 with size 5000
[2015-10-30 07:35:16,333: ERROR/MainProcess] Task nidaba.ocr.kraken[a3526864-a5bc-45a4-9b95-487c54181b44] raised unexpected: IndexError('index 5000 is out of bounds for axis 0 with size 5000',)
Traceback (most recent call last):
  File "/cluster/home/mmunso01/envs/nidaba/lib/python2.7/site-packages/celery/app/trace.py", line 240, in trace_task
    R = retval = fun(*args, **kwargs)
  File "/cluster/home/mmunso01/envs/nidaba/lib/python2.7/site-packages/nidaba/tasks/helper.py", line 89, in __call__
    ret = super(NidabaTask, self).__call__(*args, **nkwargs)
  File "/cluster/home/mmunso01/envs/nidaba/lib/python2.7/site-packages/celery/app/trace.py", line 438, in __protected_call__
    return self.run(*args, **kwargs)
  File "/cluster/home/mmunso01/envs/nidaba/lib/python2.7/site-packages/nidaba/plugins/kraken.py", line 155, in ocr_kraken
    for rec in rpred.rpred(rnn, img, [(int(x[0]), int(x[1]), int(x[2]), int(x[3])) for x in lines]):
  File "/cluster/home/mmunso01/envs/nidaba/lib/python2.7/site-packages/kraken/rpred.py", line 134, in rpred
    pred = network.predictString(line)
  File "/cluster/home/mmunso01/envs/nidaba/lib/python2.7/site-packages/kraken/lib/lstm.py", line 281, in predictString
    cs = self.predictSequence(xs)
  File "/cluster/home/mmunso01/envs/nidaba/lib/python2.7/site-packages/kraken/lib/lstm.py", line 273, in predictSequence
    self.outputs = np.array(self.lstm.forward(xs))
  File "/cluster/home/mmunso01/envs/nidaba/lib/python2.7/site-packages/kraken/lib/lstm.py", line 229, in forward
    xs = net.forward(xs)
  File "/cluster/home/mmunso01/envs/nidaba/lib/python2.7/site-packages/kraken/lib/lstm.py", line 244, in forward
    outputs = [net.forward(xs) for net in self.nets]
  File "/cluster/home/mmunso01/envs/nidaba/lib/python2.7/site-packages/kraken/lib/lstm.py", line 196, in forward
    self.source[t,0] = 1
IndexError: index 5000 is out of bounds for axis 0 with size 5000
[2015-10-30 07:38:55,479: ERROR/Worker-21] nidaba.ocr.kraken[fa3bb271-6be5-4a9d-834a-00aa3553461c]: index 5000 is out of bounds for axis 0 with size 5000
[2015-10-30 07:39:02,154: ERROR/MainProcess] Task nidaba.ocr.kraken[fa3bb271-6be5-4a9d-834a-00aa3553461c] raised unexpected: IndexError('index 5000 is out of bounds for axis 0 with size 5000',)
Traceback (most recent call last):
  File "/cluster/home/mmunso01/envs/nidaba/lib/python2.7/site-packages/celery/app/trace.py", line 240, in trace_task
    R = retval = fun(*args, **kwargs)
  File "/cluster/home/mmunso01/envs/nidaba/lib/python2.7/site-packages/nidaba/tasks/helper.py", line 89, in __call__
    ret = super(NidabaTask, self).__call__(*args, **nkwargs)
  File "/cluster/home/mmunso01/envs/nidaba/lib/python2.7/site-packages/celery/app/trace.py", line 438, in __protected_call__
    return self.run(*args, **kwargs)
  File "/cluster/home/mmunso01/envs/nidaba/lib/python2.7/site-packages/nidaba/plugins/kraken.py", line 155, in ocr_kraken
    for rec in rpred.rpred(rnn, img, [(int(x[0]), int(x[1]), int(x[2]), int(x[3])) for x in lines]):
  File "/cluster/home/mmunso01/envs/nidaba/lib/python2.7/site-packages/kraken/rpred.py", line 134, in rpred
    pred = network.predictString(line)
  File "/cluster/home/mmunso01/envs/nidaba/lib/python2.7/site-packages/kraken/lib/lstm.py", line 281, in predictString
    cs = self.predictSequence(xs)
  File "/cluster/home/mmunso01/envs/nidaba/lib/python2.7/site-packages/kraken/lib/lstm.py", line 273, in predictSequence
    self.outputs = np.array(self.lstm.forward(xs))
  File "/cluster/home/mmunso01/envs/nidaba/lib/python2.7/site-packages/kraken/lib/lstm.py", line 229, in forward
    xs = net.forward(xs)
  File "/cluster/home/mmunso01/envs/nidaba/lib/python2.7/site-packages/kraken/lib/lstm.py", line 244, in forward
    outputs = [net.forward(xs) for net in self.nets]
  File "/cluster/home/mmunso01/envs/nidaba/lib/python2.7/site-packages/kraken/lib/lstm.py", line 196, in forward
    self.source[t,0] = 1
IndexError: index 5000 is out of bounds for axis 0 with size 5000
[2015-10-30 07:48:38,229: ERROR/Worker-40] nidaba.ocr.kraken[f9d56103-2c4f-421f-9d76-a87a3573ec2f]: index 5000 is out of bounds for axis 0 with size 5000
[2015-10-30 07:48:50,208: ERROR/MainProcess] Task nidaba.ocr.kraken[f9d56103-2c4f-421f-9d76-a87a3573ec2f] raised unexpected: IndexError('index 5000 is out of bounds for axis 0 with size 5000',)
Traceback (most recent call last):
  File "/cluster/home/mmunso01/envs/nidaba/lib/python2.7/site-packages/celery/app/trace.py", line 240, in trace_task
    R = retval = fun(*args, **kwargs)
  File "/cluster/home/mmunso01/envs/nidaba/lib/python2.7/site-packages/nidaba/tasks/helper.py", line 89, in __call__
    ret = super(NidabaTask, self).__call__(*args, **nkwargs)
  File "/cluster/home/mmunso01/envs/nidaba/lib/python2.7/site-packages/celery/app/trace.py", line 438, in __protected_call__
    return self.run(*args, **kwargs)
  File "/cluster/home/mmunso01/envs/nidaba/lib/python2.7/site-packages/nidaba/plugins/kraken.py", line 155, in ocr_kraken
    for rec in rpred.rpred(rnn, img, [(int(x[0]), int(x[1]), int(x[2]), int(x[3])) for x in lines]):
  File "/cluster/home/mmunso01/envs/nidaba/lib/python2.7/site-packages/kraken/rpred.py", line 134, in rpred
    pred = network.predictString(line)
  File "/cluster/home/mmunso01/envs/nidaba/lib/python2.7/site-packages/kraken/lib/lstm.py", line 281, in predictString
    cs = self.predictSequence(xs)
  File "/cluster/home/mmunso01/envs/nidaba/lib/python2.7/site-packages/kraken/lib/lstm.py", line 273, in predictSequence
    self.outputs = np.array(self.lstm.forward(xs))
  File "/cluster/home/mmunso01/envs/nidaba/lib/python2.7/site-packages/kraken/lib/lstm.py", line 229, in forward
    xs = net.forward(xs)
  File "/cluster/home/mmunso01/envs/nidaba/lib/python2.7/site-packages/kraken/lib/lstm.py", line 244, in forward
    outputs = [net.forward(xs) for net in self.nets]
  File "/cluster/home/mmunso01/envs/nidaba/lib/python2.7/site-packages/kraken/lib/lstm.py", line 196, in forward
    self.source[t,0] = 1
IndexError: index 5000 is out of bounds for axis 0 with size 5000
[2015-10-30 07:52:06,573: ERROR/Worker-16] nidaba.ocr.kraken[4952ddd2-f577-4588-8b27-697c38c9a3a5]: index 5000 is out of bounds for axis 0 with size 5000
[2015-10-30 07:52:09,807: ERROR/MainProcess] Task nidaba.ocr.kraken[4952ddd2-f577-4588-8b27-697c38c9a3a5] raised unexpected: IndexError('index 5000 is out of bounds for axis 0 with size 5000',)
Traceback (most recent call last):
  File "/cluster/home/mmunso01/envs/nidaba/lib/python2.7/site-packages/celery/app/trace.py", line 240, in trace_task
    R = retval = fun(*args, **kwargs)
  File "/cluster/home/mmunso01/envs/nidaba/lib/python2.7/site-packages/nidaba/tasks/helper.py", line 89, in __call__
    ret = super(NidabaTask, self).__call__(*args, **nkwargs)
  File "/cluster/home/mmunso01/envs/nidaba/lib/python2.7/site-packages/celery/app/trace.py", line 438, in __protected_call__
    return self.run(*args, **kwargs)
  File "/cluster/home/mmunso01/envs/nidaba/lib/python2.7/site-packages/nidaba/plugins/kraken.py", line 155, in ocr_kraken
    for rec in rpred.rpred(rnn, img, [(int(x[0]), int(x[1]), int(x[2]), int(x[3])) for x in lines]):
  File "/cluster/home/mmunso01/envs/nidaba/lib/python2.7/site-packages/kraken/rpred.py", line 134, in rpred
    pred = network.predictString(line)
  File "/cluster/home/mmunso01/envs/nidaba/lib/python2.7/site-packages/kraken/lib/lstm.py", line 281, in predictString
    cs = self.predictSequence(xs)
  File "/cluster/home/mmunso01/envs/nidaba/lib/python2.7/site-packages/kraken/lib/lstm.py", line 273, in predictSequence
    self.outputs = np.array(self.lstm.forward(xs))
  File "/cluster/home/mmunso01/envs/nidaba/lib/python2.7/site-packages/kraken/lib/lstm.py", line 229, in forward
    xs = net.forward(xs)
  File "/cluster/home/mmunso01/envs/nidaba/lib/python2.7/site-packages/kraken/lib/lstm.py", line 244, in forward
    outputs = [net.forward(xs) for net in self.nets]
  File "/cluster/home/mmunso01/envs/nidaba/lib/python2.7/site-packages/kraken/lib/lstm.py", line 196, in forward
    self.source[t,0] = 1
IndexError: index 5000 is out of bounds for axis 0 with size 5000
[2015-10-30 07:52:22,037: ERROR/Worker-35] nidaba.ocr.kraken[fb811658-7c2e-4cc4-83e1-3b6f8dc4747e]: index 5000 is out of bounds for axis 0 with size 5000
[2015-10-30 07:52:25,642: ERROR/Worker-37] nidaba.ocr.kraken[8b65101d-2a67-483e-a2a6-d28ce2a77aff]: index 5000 is out of bounds for axis 0 with size 5000
[2015-10-30 07:52:31,530: ERROR/Worker-25] nidaba.ocr.kraken[f125d98e-acc5-4bc5-aaf1-54b73930a00b]: index 5000 is out of bounds for axis 0 with size 5000
[2015-10-30 07:52:34,514: ERROR/MainProcess] Task nidaba.ocr.kraken[8b65101d-2a67-483e-a2a6-d28ce2a77aff] raised unexpected: IndexError('index 5000 is out of bounds for axis 0 with size 5000',)
Traceback (most recent call last):
  File "/cluster/home/mmunso01/envs/nidaba/lib/python2.7/site-packages/celery/app/trace.py", line 240, in trace_task
    R = retval = fun(*args, **kwargs)
  File "/cluster/home/mmunso01/envs/nidaba/lib/python2.7/site-packages/nidaba/tasks/helper.py", line 89, in __call__
    ret = super(NidabaTask, self).__call__(*args, **nkwargs)
  File "/cluster/home/mmunso01/envs/nidaba/lib/python2.7/site-packages/celery/app/trace.py", line 438, in __protected_call__
    return self.run(*args, **kwargs)
  File "/cluster/home/mmunso01/envs/nidaba/lib/python2.7/site-packages/nidaba/plugins/kraken.py", line 155, in ocr_kraken
    for rec in rpred.rpred(rnn, img, [(int(x[0]), int(x[1]), int(x[2]), int(x[3])) for x in lines]):
  File "/cluster/home/mmunso01/envs/nidaba/lib/python2.7/site-packages/kraken/rpred.py", line 134, in rpred
    pred = network.predictString(line)
  File "/cluster/home/mmunso01/envs/nidaba/lib/python2.7/site-packages/kraken/lib/lstm.py", line 281, in predictString
    cs = self.predictSequence(xs)
  File "/cluster/home/mmunso01/envs/nidaba/lib/python2.7/site-packages/kraken/lib/lstm.py", line 273, in predictSequence
    self.outputs = np.array(self.lstm.forward(xs))
  File "/cluster/home/mmunso01/envs/nidaba/lib/python2.7/site-packages/kraken/lib/lstm.py", line 229, in forward
    xs = net.forward(xs)
  File "/cluster/home/mmunso01/envs/nidaba/lib/python2.7/site-packages/kraken/lib/lstm.py", line 244, in forward
    outputs = [net.forward(xs) for net in self.nets]
  File "/cluster/home/mmunso01/envs/nidaba/lib/python2.7/site-packages/kraken/lib/lstm.py", line 196, in forward
    self.source[t,0] = 1
IndexError: index 5000 is out of bounds for axis 0 with size 5000
[2015-10-30 07:52:34,585: ERROR/MainProcess] Task nidaba.ocr.kraken[fb811658-7c2e-4cc4-83e1-3b6f8dc4747e] raised unexpected: IndexError('index 5000 is out of bounds for axis 0 with size 5000',)
Traceback (most recent call last):
  File "/cluster/home/mmunso01/envs/nidaba/lib/python2.7/site-packages/celery/app/trace.py", line 240, in trace_task
    R = retval = fun(*args, **kwargs)
  File "/cluster/home/mmunso01/envs/nidaba/lib/python2.7/site-packages/nidaba/tasks/helper.py", line 89, in __call__
    ret = super(NidabaTask, self).__call__(*args, **nkwargs)
  File "/cluster/home/mmunso01/envs/nidaba/lib/python2.7/site-packages/celery/app/trace.py", line 438, in __protected_call__
    return self.run(*args, **kwargs)
  File "/cluster/home/mmunso01/envs/nidaba/lib/python2.7/site-packages/nidaba/plugins/kraken.py", line 155, in ocr_kraken
    for rec in rpred.rpred(rnn, img, [(int(x[0]), int(x[1]), int(x[2]), int(x[3])) for x in lines]):
  File "/cluster/home/mmunso01/envs/nidaba/lib/python2.7/site-packages/kraken/rpred.py", line 134, in rpred
    pred = network.predictString(line)
  File "/cluster/home/mmunso01/envs/nidaba/lib/python2.7/site-packages/kraken/lib/lstm.py", line 281, in predictString
    cs = self.predictSequence(xs)
  File "/cluster/home/mmunso01/envs/nidaba/lib/python2.7/site-packages/kraken/lib/lstm.py", line 273, in predictSequence
    self.outputs = np.array(self.lstm.forward(xs))
  File "/cluster/home/mmunso01/envs/nidaba/lib/python2.7/site-packages/kraken/lib/lstm.py", line 229, in forward
    xs = net.forward(xs)
  File "/cluster/home/mmunso01/envs/nidaba/lib/python2.7/site-packages/kraken/lib/lstm.py", line 244, in forward
    outputs = [net.forward(xs) for net in self.nets]
  File "/cluster/home/mmunso01/envs/nidaba/lib/python2.7/site-packages/kraken/lib/lstm.py", line 196, in forward
    self.source[t,0] = 1
IndexError: index 5000 is out of bounds for axis 0 with size 5000
[2015-10-30 07:52:37,289: ERROR/MainProcess] Task nidaba.ocr.kraken[f125d98e-acc5-4bc5-aaf1-54b73930a00b] raised unexpected: IndexError('index 5000 is out of bounds for axis 0 with size 5000',)
Traceback (most recent call last):
  File "/cluster/home/mmunso01/envs/nidaba/lib/python2.7/site-packages/celery/app/trace.py", line 240, in trace_task
    R = retval = fun(*args, **kwargs)
  File "/cluster/home/mmunso01/envs/nidaba/lib/python2.7/site-packages/nidaba/tasks/helper.py", line 89, in __call__
    ret = super(NidabaTask, self).__call__(*args, **nkwargs)
  File "/cluster/home/mmunso01/envs/nidaba/lib/python2.7/site-packages/celery/app/trace.py", line 438, in __protected_call__
    return self.run(*args, **kwargs)
  File "/cluster/home/mmunso01/envs/nidaba/lib/python2.7/site-packages/nidaba/plugins/kraken.py", line 155, in ocr_kraken
    for rec in rpred.rpred(rnn, img, [(int(x[0]), int(x[1]), int(x[2]), int(x[3])) for x in lines]):
  File "/cluster/home/mmunso01/envs/nidaba/lib/python2.7/site-packages/kraken/rpred.py", line 134, in rpred
    pred = network.predictString(line)
  File "/cluster/home/mmunso01/envs/nidaba/lib/python2.7/site-packages/kraken/lib/lstm.py", line 281, in predictString
    cs = self.predictSequence(xs)
  File "/cluster/home/mmunso01/envs/nidaba/lib/python2.7/site-packages/kraken/lib/lstm.py", line 273, in predictSequence
    self.outputs = np.array(self.lstm.forward(xs))
  File "/cluster/home/mmunso01/envs/nidaba/lib/python2.7/site-packages/kraken/lib/lstm.py", line 229, in forward
    xs = net.forward(xs)
  File "/cluster/home/mmunso01/envs/nidaba/lib/python2.7/site-packages/kraken/lib/lstm.py", line 244, in forward
    outputs = [net.forward(xs) for net in self.nets]
  File "/cluster/home/mmunso01/envs/nidaba/lib/python2.7/site-packages/kraken/lib/lstm.py", line 196, in forward
    self.source[t,0] = 1
IndexError: index 5000 is out of bounds for axis 0 with size 5000
[2015-10-30 07:53:46,216: ERROR/Worker-33] nidaba.ocr.kraken[87c1e069-027f-457a-b7e1-922161091c48]: index 5000 is out of bounds for axis 0 with size 5000
[2015-10-30 07:53:47,637: ERROR/MainProcess] Task nidaba.ocr.kraken[87c1e069-027f-457a-b7e1-922161091c48] raised unexpected: IndexError('index 5000 is out of bounds for axis 0 with size 5000',)
Traceback (most recent call last):
  File "/cluster/home/mmunso01/envs/nidaba/lib/python2.7/site-packages/celery/app/trace.py", line 240, in trace_task
    R = retval = fun(*args, **kwargs)
  File "/cluster/home/mmunso01/envs/nidaba/lib/python2.7/site-packages/nidaba/tasks/helper.py", line 89, in __call__
    ret = super(NidabaTask, self).__call__(*args, **nkwargs)
  File "/cluster/home/mmunso01/envs/nidaba/lib/python2.7/site-packages/celery/app/trace.py", line 438, in __protected_call__
    return self.run(*args, **kwargs)
  File "/cluster/home/mmunso01/envs/nidaba/lib/python2.7/site-packages/nidaba/plugins/kraken.py", line 155, in ocr_kraken
    for rec in rpred.rpred(rnn, img, [(int(x[0]), int(x[1]), int(x[2]), int(x[3])) for x in lines]):
  File "/cluster/home/mmunso01/envs/nidaba/lib/python2.7/site-packages/kraken/rpred.py", line 134, in rpred
    pred = network.predictString(line)
  File "/cluster/home/mmunso01/envs/nidaba/lib/python2.7/site-packages/kraken/lib/lstm.py", line 281, in predictString
    cs = self.predictSequence(xs)
  File "/cluster/home/mmunso01/envs/nidaba/lib/python2.7/site-packages/kraken/lib/lstm.py", line 273, in predictSequence
    self.outputs = np.array(self.lstm.forward(xs))
  File "/cluster/home/mmunso01/envs/nidaba/lib/python2.7/site-packages/kraken/lib/lstm.py", line 229, in forward
    xs = net.forward(xs)
  File "/cluster/home/mmunso01/envs/nidaba/lib/python2.7/site-packages/kraken/lib/lstm.py", line 244, in forward
    outputs = [net.forward(xs) for net in self.nets]
  File "/cluster/home/mmunso01/envs/nidaba/lib/python2.7/site-packages/kraken/lib/lstm.py", line 196, in forward
    self.source[t,0] = 1
IndexError: index 5000 is out of bounds for axis 0 with size 5000
[2015-10-30 07:58:37,460: ERROR/Worker-37] nidaba.ocr.kraken[ba6e6282-0175-4464-8958-b584ab97753b]: index 5000 is out of bounds for axis 0 with size 5000
[2015-10-30 07:58:40,410: ERROR/MainProcess] Task nidaba.ocr.kraken[ba6e6282-0175-4464-8958-b584ab97753b] raised unexpected: IndexError('index 5000 is out of bounds for axis 0 with size 5000',)
Traceback (most recent call last):
  File "/cluster/home/mmunso01/envs/nidaba/lib/python2.7/site-packages/celery/app/trace.py", line 240, in trace_task
    R = retval = fun(*args, **kwargs)
  File "/cluster/home/mmunso01/envs/nidaba/lib/python2.7/site-packages/nidaba/tasks/helper.py", line 89, in __call__
    ret = super(NidabaTask, self).__call__(*args, **nkwargs)
  File "/cluster/home/mmunso01/envs/nidaba/lib/python2.7/site-packages/celery/app/trace.py", line 438, in __protected_call__
    return self.run(*args, **kwargs)
  File "/cluster/home/mmunso01/envs/nidaba/lib/python2.7/site-packages/nidaba/plugins/kraken.py", line 155, in ocr_kraken
    for rec in rpred.rpred(rnn, img, [(int(x[0]), int(x[1]), int(x[2]), int(x[3])) for x in lines]):
  File "/cluster/home/mmunso01/envs/nidaba/lib/python2.7/site-packages/kraken/rpred.py", line 134, in rpred
    pred = network.predictString(line)
  File "/cluster/home/mmunso01/envs/nidaba/lib/python2.7/site-packages/kraken/lib/lstm.py", line 281, in predictString
    cs = self.predictSequence(xs)
  File "/cluster/home/mmunso01/envs/nidaba/lib/python2.7/site-packages/kraken/lib/lstm.py", line 273, in predictSequence
    self.outputs = np.array(self.lstm.forward(xs))
  File "/cluster/home/mmunso01/envs/nidaba/lib/python2.7/site-packages/kraken/lib/lstm.py", line 229, in forward
    xs = net.forward(xs)
  File "/cluster/home/mmunso01/envs/nidaba/lib/python2.7/site-packages/kraken/lib/lstm.py", line 244, in forward
    outputs = [net.forward(xs) for net in self.nets]
  File "/cluster/home/mmunso01/envs/nidaba/lib/python2.7/site-packages/kraken/lib/lstm.py", line 196, in forward
    self.source[t,0] = 1
IndexError: index 5000 is out of bounds for axis 0 with size 5000
