[2015-10-30 05:21:05,481: WARNING/MainProcess] worker@alpha024 ready.
[2015-10-30 05:32:19,284: WARNING/Worker-13] /cluster/home/mmunso01/envs/nidaba/lib/python2.7/site-packages/scipy/ndimage/interpolation.py:549: UserWarning: From scipy 0.13.0, the output shape of zoom() is calculated with round() instead of int() - for these inputs the size of the returned array has changed.
  "the returned array has changed.", UserWarning)
[2015-10-30 05:34:02,101: WARNING/Worker-26] /cluster/home/mmunso01/envs/nidaba/lib/python2.7/site-packages/scipy/ndimage/interpolation.py:549: UserWarning: From scipy 0.13.0, the output shape of zoom() is calculated with round() instead of int() - for these inputs the size of the returned array has changed.
  "the returned array has changed.", UserWarning)
[2015-10-30 05:40:26,752: WARNING/Worker-22] /cluster/home/mmunso01/envs/nidaba/lib/python2.7/site-packages/scipy/ndimage/interpolation.py:549: UserWarning: From scipy 0.13.0, the output shape of zoom() is calculated with round() instead of int() - for these inputs the size of the returned array has changed.
  "the returned array has changed.", UserWarning)
[2015-10-30 05:40:29,291: WARNING/Worker-34] /cluster/home/mmunso01/envs/nidaba/lib/python2.7/site-packages/scipy/ndimage/interpolation.py:549: UserWarning: From scipy 0.13.0, the output shape of zoom() is calculated with round() instead of int() - for these inputs the size of the returned array has changed.
  "the returned array has changed.", UserWarning)
[2015-10-30 05:40:30,154: WARNING/Worker-28] /cluster/home/mmunso01/envs/nidaba/lib/python2.7/site-packages/scipy/ndimage/interpolation.py:549: UserWarning: From scipy 0.13.0, the output shape of zoom() is calculated with round() instead of int() - for these inputs the size of the returned array has changed.
  "the returned array has changed.", UserWarning)
[2015-10-30 05:40:36,290: WARNING/Worker-11] /cluster/home/mmunso01/envs/nidaba/lib/python2.7/site-packages/scipy/ndimage/interpolation.py:549: UserWarning: From scipy 0.13.0, the output shape of zoom() is calculated with round() instead of int() - for these inputs the size of the returned array has changed.
  "the returned array has changed.", UserWarning)
[2015-10-30 05:40:36,810: WARNING/Worker-1] /cluster/home/mmunso01/envs/nidaba/lib/python2.7/site-packages/scipy/ndimage/interpolation.py:549: UserWarning: From scipy 0.13.0, the output shape of zoom() is calculated with round() instead of int() - for these inputs the size of the returned array has changed.
  "the returned array has changed.", UserWarning)
[2015-10-30 05:40:38,750: WARNING/Worker-18] /cluster/home/mmunso01/envs/nidaba/lib/python2.7/site-packages/scipy/ndimage/interpolation.py:549: UserWarning: From scipy 0.13.0, the output shape of zoom() is calculated with round() instead of int() - for these inputs the size of the returned array has changed.
  "the returned array has changed.", UserWarning)
[2015-10-30 05:40:40,610: WARNING/Worker-3] /cluster/home/mmunso01/envs/nidaba/lib/python2.7/site-packages/scipy/ndimage/interpolation.py:549: UserWarning: From scipy 0.13.0, the output shape of zoom() is calculated with round() instead of int() - for these inputs the size of the returned array has changed.
  "the returned array has changed.", UserWarning)
[2015-10-30 05:40:44,309: WARNING/Worker-24] /cluster/home/mmunso01/envs/nidaba/lib/python2.7/site-packages/scipy/ndimage/interpolation.py:549: UserWarning: From scipy 0.13.0, the output shape of zoom() is calculated with round() instead of int() - for these inputs the size of the returned array has changed.
  "the returned array has changed.", UserWarning)
[2015-10-30 05:40:45,531: WARNING/Worker-29] /cluster/home/mmunso01/envs/nidaba/lib/python2.7/site-packages/scipy/ndimage/interpolation.py:549: UserWarning: From scipy 0.13.0, the output shape of zoom() is calculated with round() instead of int() - for these inputs the size of the returned array has changed.
  "the returned array has changed.", UserWarning)
[2015-10-30 05:40:49,293: WARNING/Worker-23] /cluster/home/mmunso01/envs/nidaba/lib/python2.7/site-packages/scipy/ndimage/interpolation.py:549: UserWarning: From scipy 0.13.0, the output shape of zoom() is calculated with round() instead of int() - for these inputs the size of the returned array has changed.
  "the returned array has changed.", UserWarning)
[2015-10-30 05:40:53,690: WARNING/Worker-31] /cluster/home/mmunso01/envs/nidaba/lib/python2.7/site-packages/scipy/ndimage/interpolation.py:549: UserWarning: From scipy 0.13.0, the output shape of zoom() is calculated with round() instead of int() - for these inputs the size of the returned array has changed.
  "the returned array has changed.", UserWarning)
[2015-10-30 05:40:54,851: WARNING/Worker-21] /cluster/home/mmunso01/envs/nidaba/lib/python2.7/site-packages/scipy/ndimage/interpolation.py:549: UserWarning: From scipy 0.13.0, the output shape of zoom() is calculated with round() instead of int() - for these inputs the size of the returned array has changed.
  "the returned array has changed.", UserWarning)
[2015-10-30 05:40:56,900: WARNING/Worker-6] /cluster/home/mmunso01/envs/nidaba/lib/python2.7/site-packages/scipy/ndimage/interpolation.py:549: UserWarning: From scipy 0.13.0, the output shape of zoom() is calculated with round() instead of int() - for these inputs the size of the returned array has changed.
  "the returned array has changed.", UserWarning)
[2015-10-30 05:40:58,401: WARNING/Worker-40] /cluster/home/mmunso01/envs/nidaba/lib/python2.7/site-packages/scipy/ndimage/interpolation.py:549: UserWarning: From scipy 0.13.0, the output shape of zoom() is calculated with round() instead of int() - for these inputs the size of the returned array has changed.
  "the returned array has changed.", UserWarning)
[2015-10-30 05:41:03,585: WARNING/Worker-14] /cluster/home/mmunso01/envs/nidaba/lib/python2.7/site-packages/scipy/ndimage/interpolation.py:549: UserWarning: From scipy 0.13.0, the output shape of zoom() is calculated with round() instead of int() - for these inputs the size of the returned array has changed.
  "the returned array has changed.", UserWarning)
[2015-10-30 05:41:05,041: WARNING/Worker-15] /cluster/home/mmunso01/envs/nidaba/lib/python2.7/site-packages/scipy/ndimage/interpolation.py:549: UserWarning: From scipy 0.13.0, the output shape of zoom() is calculated with round() instead of int() - for these inputs the size of the returned array has changed.
  "the returned array has changed.", UserWarning)
[2015-10-30 05:41:05,370: WARNING/Worker-2] /cluster/home/mmunso01/envs/nidaba/lib/python2.7/site-packages/scipy/ndimage/interpolation.py:549: UserWarning: From scipy 0.13.0, the output shape of zoom() is calculated with round() instead of int() - for these inputs the size of the returned array has changed.
  "the returned array has changed.", UserWarning)
[2015-10-30 05:41:06,360: WARNING/Worker-37] /cluster/home/mmunso01/envs/nidaba/lib/python2.7/site-packages/scipy/ndimage/interpolation.py:549: UserWarning: From scipy 0.13.0, the output shape of zoom() is calculated with round() instead of int() - for these inputs the size of the returned array has changed.
  "the returned array has changed.", UserWarning)
[2015-10-30 05:41:09,465: WARNING/Worker-15] /cluster/home/mmunso01/envs/nidaba/lib/python2.7/site-packages/kraken/binarization.py:64: RuntimeWarning: divide by zero encountered in true_divide
  flat /= (hi-lo)
[2015-10-30 05:41:09,467: WARNING/Worker-15] /cluster/home/mmunso01/envs/nidaba/lib/python2.7/site-packages/kraken/binarization.py:64: RuntimeWarning: invalid value encountered in true_divide
  flat /= (hi-lo)
[2015-10-30 05:41:09,479: WARNING/Worker-15] /cluster/home/mmunso01/envs/nidaba/lib/python2.7/site-packages/kraken/binarization.py:66: RuntimeWarning: invalid value encountered in greater
  bin = np.array(255*(flat > threshold), 'B')
[2015-10-30 05:41:10,730: WARNING/Worker-27] /cluster/home/mmunso01/envs/nidaba/lib/python2.7/site-packages/scipy/ndimage/interpolation.py:549: UserWarning: From scipy 0.13.0, the output shape of zoom() is calculated with round() instead of int() - for these inputs the size of the returned array has changed.
  "the returned array has changed.", UserWarning)
[2015-10-30 05:41:11,530: WARNING/Worker-35] /cluster/home/mmunso01/envs/nidaba/lib/python2.7/site-packages/scipy/ndimage/interpolation.py:549: UserWarning: From scipy 0.13.0, the output shape of zoom() is calculated with round() instead of int() - for these inputs the size of the returned array has changed.
  "the returned array has changed.", UserWarning)
[2015-10-30 05:41:21,150: WARNING/Worker-5] /cluster/home/mmunso01/envs/nidaba/lib/python2.7/site-packages/scipy/ndimage/interpolation.py:549: UserWarning: From scipy 0.13.0, the output shape of zoom() is calculated with round() instead of int() - for these inputs the size of the returned array has changed.
  "the returned array has changed.", UserWarning)
[2015-10-30 05:41:24,380: WARNING/Worker-16] /cluster/home/mmunso01/envs/nidaba/lib/python2.7/site-packages/scipy/ndimage/interpolation.py:549: UserWarning: From scipy 0.13.0, the output shape of zoom() is calculated with round() instead of int() - for these inputs the size of the returned array has changed.
  "the returned array has changed.", UserWarning)
[2015-10-30 05:41:25,972: WARNING/Worker-9] /cluster/home/mmunso01/envs/nidaba/lib/python2.7/site-packages/scipy/ndimage/interpolation.py:549: UserWarning: From scipy 0.13.0, the output shape of zoom() is calculated with round() instead of int() - for these inputs the size of the returned array has changed.
  "the returned array has changed.", UserWarning)
[2015-10-30 05:41:30,155: WARNING/Worker-16] /cluster/home/mmunso01/envs/nidaba/lib/python2.7/site-packages/kraken/binarization.py:64: RuntimeWarning: divide by zero encountered in true_divide
  flat /= (hi-lo)
[2015-10-30 05:41:30,156: WARNING/Worker-16] /cluster/home/mmunso01/envs/nidaba/lib/python2.7/site-packages/kraken/binarization.py:64: RuntimeWarning: invalid value encountered in true_divide
  flat /= (hi-lo)
[2015-10-30 05:41:30,168: WARNING/Worker-16] /cluster/home/mmunso01/envs/nidaba/lib/python2.7/site-packages/kraken/binarization.py:66: RuntimeWarning: invalid value encountered in greater
  bin = np.array(255*(flat > threshold), 'B')
[2015-10-30 05:41:36,649: WARNING/Worker-4] /cluster/home/mmunso01/envs/nidaba/lib/python2.7/site-packages/scipy/ndimage/interpolation.py:549: UserWarning: From scipy 0.13.0, the output shape of zoom() is calculated with round() instead of int() - for these inputs the size of the returned array has changed.
  "the returned array has changed.", UserWarning)
[2015-10-30 05:41:42,611: WARNING/Worker-38] /cluster/home/mmunso01/envs/nidaba/lib/python2.7/site-packages/scipy/ndimage/interpolation.py:549: UserWarning: From scipy 0.13.0, the output shape of zoom() is calculated with round() instead of int() - for these inputs the size of the returned array has changed.
  "the returned array has changed.", UserWarning)
[2015-10-30 05:41:47,150: WARNING/Worker-30] /cluster/home/mmunso01/envs/nidaba/lib/python2.7/site-packages/scipy/ndimage/interpolation.py:549: UserWarning: From scipy 0.13.0, the output shape of zoom() is calculated with round() instead of int() - for these inputs the size of the returned array has changed.
  "the returned array has changed.", UserWarning)
[2015-10-30 05:42:04,390: WARNING/Worker-17] /cluster/home/mmunso01/envs/nidaba/lib/python2.7/site-packages/scipy/ndimage/interpolation.py:549: UserWarning: From scipy 0.13.0, the output shape of zoom() is calculated with round() instead of int() - for these inputs the size of the returned array has changed.
  "the returned array has changed.", UserWarning)
[2015-10-30 05:42:18,550: WARNING/Worker-39] /cluster/home/mmunso01/envs/nidaba/lib/python2.7/site-packages/scipy/ndimage/interpolation.py:549: UserWarning: From scipy 0.13.0, the output shape of zoom() is calculated with round() instead of int() - for these inputs the size of the returned array has changed.
  "the returned array has changed.", UserWarning)
[2015-10-30 05:42:21,565: WARNING/Worker-10] /cluster/home/mmunso01/envs/nidaba/lib/python2.7/site-packages/scipy/ndimage/interpolation.py:549: UserWarning: From scipy 0.13.0, the output shape of zoom() is calculated with round() instead of int() - for these inputs the size of the returned array has changed.
  "the returned array has changed.", UserWarning)
[2015-10-30 05:42:27,790: WARNING/Worker-32] /cluster/home/mmunso01/envs/nidaba/lib/python2.7/site-packages/scipy/ndimage/interpolation.py:549: UserWarning: From scipy 0.13.0, the output shape of zoom() is calculated with round() instead of int() - for these inputs the size of the returned array has changed.
  "the returned array has changed.", UserWarning)
[2015-10-30 05:42:30,150: WARNING/Worker-12] /cluster/home/mmunso01/envs/nidaba/lib/python2.7/site-packages/scipy/ndimage/interpolation.py:549: UserWarning: From scipy 0.13.0, the output shape of zoom() is calculated with round() instead of int() - for these inputs the size of the returned array has changed.
  "the returned array has changed.", UserWarning)
[2015-10-30 05:42:33,416: WARNING/Worker-36] /cluster/home/mmunso01/envs/nidaba/lib/python2.7/site-packages/scipy/ndimage/interpolation.py:549: UserWarning: From scipy 0.13.0, the output shape of zoom() is calculated with round() instead of int() - for these inputs the size of the returned array has changed.
  "the returned array has changed.", UserWarning)
[2015-10-30 05:42:34,492: WARNING/Worker-7] /cluster/home/mmunso01/envs/nidaba/lib/python2.7/site-packages/scipy/ndimage/interpolation.py:549: UserWarning: From scipy 0.13.0, the output shape of zoom() is calculated with round() instead of int() - for these inputs the size of the returned array has changed.
  "the returned array has changed.", UserWarning)
[2015-10-30 05:42:47,370: WARNING/Worker-8] /cluster/home/mmunso01/envs/nidaba/lib/python2.7/site-packages/scipy/ndimage/interpolation.py:549: UserWarning: From scipy 0.13.0, the output shape of zoom() is calculated with round() instead of int() - for these inputs the size of the returned array has changed.
  "the returned array has changed.", UserWarning)
[2015-10-30 05:42:51,340: WARNING/Worker-20] /cluster/home/mmunso01/envs/nidaba/lib/python2.7/site-packages/scipy/ndimage/interpolation.py:549: UserWarning: From scipy 0.13.0, the output shape of zoom() is calculated with round() instead of int() - for these inputs the size of the returned array has changed.
  "the returned array has changed.", UserWarning)
[2015-10-30 05:43:08,113: WARNING/Worker-25] /cluster/home/mmunso01/envs/nidaba/lib/python2.7/site-packages/scipy/ndimage/interpolation.py:549: UserWarning: From scipy 0.13.0, the output shape of zoom() is calculated with round() instead of int() - for these inputs the size of the returned array has changed.
  "the returned array has changed.", UserWarning)
[2015-10-30 05:43:12,918: WARNING/Worker-19] /cluster/home/mmunso01/envs/nidaba/lib/python2.7/site-packages/scipy/ndimage/interpolation.py:549: UserWarning: From scipy 0.13.0, the output shape of zoom() is calculated with round() instead of int() - for these inputs the size of the returned array has changed.
  "the returned array has changed.", UserWarning)
[2015-10-30 05:43:44,690: WARNING/Worker-33] /cluster/home/mmunso01/envs/nidaba/lib/python2.7/site-packages/scipy/ndimage/interpolation.py:549: UserWarning: From scipy 0.13.0, the output shape of zoom() is calculated with round() instead of int() - for these inputs the size of the returned array has changed.
  "the returned array has changed.", UserWarning)
[2015-10-30 05:57:53,834: ERROR/Worker-27] nidaba.segmentation.tesseract[07952cb4-bbf9-4c08-8e8e-0563ef5bb606]: Tesseract killed by signal: 11
[2015-10-30 05:58:17,226: ERROR/Worker-16] nidaba.segmentation.tesseract[48238337-f980-4dae-b65a-0962127d9afc]: Tesseract killed by signal: 11
[2015-10-30 05:58:36,540: ERROR/MainProcess] Task nidaba.segmentation.tesseract[48238337-f980-4dae-b65a-0962127d9afc] raised unexpected: NidabaTesseractException(u'Tesseract killed by signal: 11',)
Traceback (most recent call last):
  File "/cluster/home/mmunso01/envs/nidaba/lib/python2.7/site-packages/celery/app/trace.py", line 240, in trace_task
    R = retval = fun(*args, **kwargs)
  File "/cluster/home/mmunso01/envs/nidaba/lib/python2.7/site-packages/nidaba/tasks/helper.py", line 89, in __call__
    ret = super(NidabaTask, self).__call__(*args, **nkwargs)
  File "/cluster/home/mmunso01/envs/nidaba/lib/python2.7/site-packages/celery/app/trace.py", line 438, in __protected_call__
    return self.run(*args, **kwargs)
  File "/cluster/home/mmunso01/envs/nidaba/lib/python2.7/site-packages/nidaba/plugins/tesseract.py", line 251, in segmentation_tesseract
    raise NidabaTesseractException('Tesseract killed by signal: {0}'.format(os.WTERMSIG(status)))
NidabaTesseractException: Tesseract killed by signal: 11
[2015-10-30 05:58:43,321: ERROR/MainProcess] Task nidaba.segmentation.tesseract[07952cb4-bbf9-4c08-8e8e-0563ef5bb606] raised unexpected: NidabaTesseractException(u'Tesseract killed by signal: 11',)
Traceback (most recent call last):
  File "/cluster/home/mmunso01/envs/nidaba/lib/python2.7/site-packages/celery/app/trace.py", line 240, in trace_task
    R = retval = fun(*args, **kwargs)
  File "/cluster/home/mmunso01/envs/nidaba/lib/python2.7/site-packages/nidaba/tasks/helper.py", line 89, in __call__
    ret = super(NidabaTask, self).__call__(*args, **nkwargs)
  File "/cluster/home/mmunso01/envs/nidaba/lib/python2.7/site-packages/celery/app/trace.py", line 438, in __protected_call__
    return self.run(*args, **kwargs)
  File "/cluster/home/mmunso01/envs/nidaba/lib/python2.7/site-packages/nidaba/plugins/tesseract.py", line 251, in segmentation_tesseract
    raise NidabaTesseractException('Tesseract killed by signal: {0}'.format(os.WTERMSIG(status)))
NidabaTesseractException: Tesseract killed by signal: 11
[2015-10-30 05:59:20,057: ERROR/Worker-27] nidaba.segmentation.tesseract[e90c2a25-8354-47be-8f5f-8a46ec59b081]: Tesseract killed by signal: 11
[2015-10-30 05:59:22,792: ERROR/MainProcess] Task nidaba.segmentation.tesseract[e90c2a25-8354-47be-8f5f-8a46ec59b081] raised unexpected: NidabaTesseractException(u'Tesseract killed by signal: 11',)
Traceback (most recent call last):
  File "/cluster/home/mmunso01/envs/nidaba/lib/python2.7/site-packages/celery/app/trace.py", line 240, in trace_task
    R = retval = fun(*args, **kwargs)
  File "/cluster/home/mmunso01/envs/nidaba/lib/python2.7/site-packages/nidaba/tasks/helper.py", line 89, in __call__
    ret = super(NidabaTask, self).__call__(*args, **nkwargs)
  File "/cluster/home/mmunso01/envs/nidaba/lib/python2.7/site-packages/celery/app/trace.py", line 438, in __protected_call__
    return self.run(*args, **kwargs)
  File "/cluster/home/mmunso01/envs/nidaba/lib/python2.7/site-packages/nidaba/plugins/tesseract.py", line 251, in segmentation_tesseract
    raise NidabaTesseractException('Tesseract killed by signal: {0}'.format(os.WTERMSIG(status)))
NidabaTesseractException: Tesseract killed by signal: 11
[2015-10-30 06:16:48,420: WARNING/Worker-4] /cluster/home/mmunso01/envs/nidaba/lib/python2.7/site-packages/kraken/rpred.py:91: RuntimeWarning: invalid value encountered in true_divide
  temp = temp*1.0/np.amax(temp)
[2015-10-30 06:16:48,620: WARNING/Worker-4] /cluster/home/mmunso01/envs/nidaba/lib/python2.7/site-packages/kraken/lib/lstm.py:48: RuntimeWarning: invalid value encountered in true_divide
  line = line * 1.0/np.amax(line)
[2015-10-30 06:16:50,565: ERROR/Worker-4] nidaba.ocr.kraken[704361a9-9253-4260-b4a4-f22fd39af647]: index 5000 is out of bounds for axis 0 with size 5000
[2015-10-30 06:16:51,691: ERROR/MainProcess] Task nidaba.ocr.kraken[704361a9-9253-4260-b4a4-f22fd39af647] raised unexpected: IndexError('index 5000 is out of bounds for axis 0 with size 5000',)
Traceback (most recent call last):
  File "/cluster/home/mmunso01/envs/nidaba/lib/python2.7/site-packages/celery/app/trace.py", line 240, in trace_task
    R = retval = fun(*args, **kwargs)
  File "/cluster/home/mmunso01/envs/nidaba/lib/python2.7/site-packages/nidaba/tasks/helper.py", line 89, in __call__
    ret = super(NidabaTask, self).__call__(*args, **nkwargs)
  File "/cluster/home/mmunso01/envs/nidaba/lib/python2.7/site-packages/celery/app/trace.py", line 438, in __protected_call__
    return self.run(*args, **kwargs)
  File "/cluster/home/mmunso01/envs/nidaba/lib/python2.7/site-packages/nidaba/plugins/kraken.py", line 155, in ocr_kraken
    for rec in rpred.rpred(rnn, img, [(int(x[0]), int(x[1]), int(x[2]), int(x[3])) for x in lines]):
  File "/cluster/home/mmunso01/envs/nidaba/lib/python2.7/site-packages/kraken/rpred.py", line 134, in rpred
    pred = network.predictString(line)
  File "/cluster/home/mmunso01/envs/nidaba/lib/python2.7/site-packages/kraken/lib/lstm.py", line 281, in predictString
    cs = self.predictSequence(xs)
  File "/cluster/home/mmunso01/envs/nidaba/lib/python2.7/site-packages/kraken/lib/lstm.py", line 273, in predictSequence
    self.outputs = np.array(self.lstm.forward(xs))
  File "/cluster/home/mmunso01/envs/nidaba/lib/python2.7/site-packages/kraken/lib/lstm.py", line 229, in forward
    xs = net.forward(xs)
  File "/cluster/home/mmunso01/envs/nidaba/lib/python2.7/site-packages/kraken/lib/lstm.py", line 244, in forward
    outputs = [net.forward(xs) for net in self.nets]
  File "/cluster/home/mmunso01/envs/nidaba/lib/python2.7/site-packages/kraken/lib/lstm.py", line 196, in forward
    self.source[t,0] = 1
IndexError: index 5000 is out of bounds for axis 0 with size 5000
[2015-10-30 06:16:53,288: ERROR/Worker-4] nidaba.segmentation.tesseract[199c7df9-388b-4c02-be95-e1c8fd94764a]: Tesseract killed by signal: 11
[2015-10-30 06:16:58,171: ERROR/MainProcess] Task nidaba.segmentation.tesseract[199c7df9-388b-4c02-be95-e1c8fd94764a] raised unexpected: NidabaTesseractException(u'Tesseract killed by signal: 11',)
Traceback (most recent call last):
  File "/cluster/home/mmunso01/envs/nidaba/lib/python2.7/site-packages/celery/app/trace.py", line 240, in trace_task
    R = retval = fun(*args, **kwargs)
  File "/cluster/home/mmunso01/envs/nidaba/lib/python2.7/site-packages/nidaba/tasks/helper.py", line 89, in __call__
    ret = super(NidabaTask, self).__call__(*args, **nkwargs)
  File "/cluster/home/mmunso01/envs/nidaba/lib/python2.7/site-packages/celery/app/trace.py", line 438, in __protected_call__
    return self.run(*args, **kwargs)
  File "/cluster/home/mmunso01/envs/nidaba/lib/python2.7/site-packages/nidaba/plugins/tesseract.py", line 251, in segmentation_tesseract
    raise NidabaTesseractException('Tesseract killed by signal: {0}'.format(os.WTERMSIG(status)))
NidabaTesseractException: Tesseract killed by signal: 11
[2015-10-30 06:17:49,617: ERROR/Worker-15] nidaba.segmentation.tesseract[dece2a64-b9ea-4f36-b014-911cc5ba38e9]: Tesseract killed by signal: 11
[2015-10-30 06:17:51,874: ERROR/MainProcess] Task nidaba.segmentation.tesseract[dece2a64-b9ea-4f36-b014-911cc5ba38e9] raised unexpected: NidabaTesseractException(u'Tesseract killed by signal: 11',)
Traceback (most recent call last):
  File "/cluster/home/mmunso01/envs/nidaba/lib/python2.7/site-packages/celery/app/trace.py", line 240, in trace_task
    R = retval = fun(*args, **kwargs)
  File "/cluster/home/mmunso01/envs/nidaba/lib/python2.7/site-packages/nidaba/tasks/helper.py", line 89, in __call__
    ret = super(NidabaTask, self).__call__(*args, **nkwargs)
  File "/cluster/home/mmunso01/envs/nidaba/lib/python2.7/site-packages/celery/app/trace.py", line 438, in __protected_call__
    return self.run(*args, **kwargs)
  File "/cluster/home/mmunso01/envs/nidaba/lib/python2.7/site-packages/nidaba/plugins/tesseract.py", line 251, in segmentation_tesseract
    raise NidabaTesseractException('Tesseract killed by signal: {0}'.format(os.WTERMSIG(status)))
NidabaTesseractException: Tesseract killed by signal: 11
[2015-10-30 06:42:01,305: WARNING/Worker-12] /cluster/home/mmunso01/envs/nidaba/lib/python2.7/site-packages/kraken/rpred.py:91: RuntimeWarning: invalid value encountered in true_divide
  temp = temp*1.0/np.amax(temp)
[2015-10-30 06:42:01,309: WARNING/Worker-12] /cluster/home/mmunso01/envs/nidaba/lib/python2.7/site-packages/kraken/lib/lstm.py:48: RuntimeWarning: invalid value encountered in true_divide
  line = line * 1.0/np.amax(line)
[2015-10-30 06:42:01,358: ERROR/Worker-12] nidaba.ocr.kraken[f66bfd00-ef50-4a7c-bd85-b94410243aad]: 
[2015-10-30 06:42:06,447: ERROR/MainProcess] Task nidaba.ocr.kraken[f66bfd00-ef50-4a7c-bd85-b94410243aad] raised unexpected: AssertionError()
Traceback (most recent call last):
  File "/cluster/home/mmunso01/envs/nidaba/lib/python2.7/site-packages/celery/app/trace.py", line 240, in trace_task
    R = retval = fun(*args, **kwargs)
  File "/cluster/home/mmunso01/envs/nidaba/lib/python2.7/site-packages/nidaba/tasks/helper.py", line 89, in __call__
    ret = super(NidabaTask, self).__call__(*args, **nkwargs)
  File "/cluster/home/mmunso01/envs/nidaba/lib/python2.7/site-packages/celery/app/trace.py", line 438, in __protected_call__
    return self.run(*args, **kwargs)
  File "/cluster/home/mmunso01/envs/nidaba/lib/python2.7/site-packages/nidaba/plugins/kraken.py", line 155, in ocr_kraken
    for rec in rpred.rpred(rnn, img, [(int(x[0]), int(x[1]), int(x[2]), int(x[3])) for x in lines]):
  File "/cluster/home/mmunso01/envs/nidaba/lib/python2.7/site-packages/kraken/rpred.py", line 134, in rpred
    pred = network.predictString(line)
  File "/cluster/home/mmunso01/envs/nidaba/lib/python2.7/site-packages/kraken/lib/lstm.py", line 281, in predictString
    cs = self.predictSequence(xs)
  File "/cluster/home/mmunso01/envs/nidaba/lib/python2.7/site-packages/kraken/lib/lstm.py", line 273, in predictSequence
    self.outputs = np.array(self.lstm.forward(xs))
  File "/cluster/home/mmunso01/envs/nidaba/lib/python2.7/site-packages/kraken/lib/lstm.py", line 229, in forward
    xs = net.forward(xs)
  File "/cluster/home/mmunso01/envs/nidaba/lib/python2.7/site-packages/kraken/lib/lstm.py", line 244, in forward
    outputs = [net.forward(xs) for net in self.nets]
  File "/cluster/home/mmunso01/envs/nidaba/lib/python2.7/site-packages/kraken/lib/lstm.py", line 216, in forward
    assert not np.isnan(self.output[:n]).any()
AssertionError
[2015-10-30 06:48:47,460: WARNING/Worker-24] /cluster/home/mmunso01/envs/nidaba/lib/python2.7/site-packages/kraken/rpred.py:91: RuntimeWarning: invalid value encountered in true_divide
  temp = temp*1.0/np.amax(temp)
[2015-10-30 06:48:47,463: WARNING/Worker-24] /cluster/home/mmunso01/envs/nidaba/lib/python2.7/site-packages/kraken/lib/lstm.py:48: RuntimeWarning: invalid value encountered in true_divide
  line = line * 1.0/np.amax(line)
[2015-10-30 06:48:47,505: ERROR/Worker-24] nidaba.ocr.kraken[4dcd99c3-763b-49d2-a469-b3dbeb1b9a57]: 
[2015-10-30 06:48:50,502: ERROR/MainProcess] Task nidaba.ocr.kraken[4dcd99c3-763b-49d2-a469-b3dbeb1b9a57] raised unexpected: AssertionError()
Traceback (most recent call last):
  File "/cluster/home/mmunso01/envs/nidaba/lib/python2.7/site-packages/celery/app/trace.py", line 240, in trace_task
    R = retval = fun(*args, **kwargs)
  File "/cluster/home/mmunso01/envs/nidaba/lib/python2.7/site-packages/nidaba/tasks/helper.py", line 89, in __call__
    ret = super(NidabaTask, self).__call__(*args, **nkwargs)
  File "/cluster/home/mmunso01/envs/nidaba/lib/python2.7/site-packages/celery/app/trace.py", line 438, in __protected_call__
    return self.run(*args, **kwargs)
  File "/cluster/home/mmunso01/envs/nidaba/lib/python2.7/site-packages/nidaba/plugins/kraken.py", line 155, in ocr_kraken
    for rec in rpred.rpred(rnn, img, [(int(x[0]), int(x[1]), int(x[2]), int(x[3])) for x in lines]):
  File "/cluster/home/mmunso01/envs/nidaba/lib/python2.7/site-packages/kraken/rpred.py", line 134, in rpred
    pred = network.predictString(line)
  File "/cluster/home/mmunso01/envs/nidaba/lib/python2.7/site-packages/kraken/lib/lstm.py", line 281, in predictString
    cs = self.predictSequence(xs)
  File "/cluster/home/mmunso01/envs/nidaba/lib/python2.7/site-packages/kraken/lib/lstm.py", line 273, in predictSequence
    self.outputs = np.array(self.lstm.forward(xs))
  File "/cluster/home/mmunso01/envs/nidaba/lib/python2.7/site-packages/kraken/lib/lstm.py", line 229, in forward
    xs = net.forward(xs)
  File "/cluster/home/mmunso01/envs/nidaba/lib/python2.7/site-packages/kraken/lib/lstm.py", line 244, in forward
    outputs = [net.forward(xs) for net in self.nets]
  File "/cluster/home/mmunso01/envs/nidaba/lib/python2.7/site-packages/kraken/lib/lstm.py", line 216, in forward
    assert not np.isnan(self.output[:n]).any()
AssertionError
[2015-10-30 06:57:28,080: WARNING/Worker-2] /cluster/home/mmunso01/envs/nidaba/lib/python2.7/site-packages/kraken/rpred.py:91: RuntimeWarning: invalid value encountered in true_divide
  temp = temp*1.0/np.amax(temp)
[2015-10-30 06:57:28,090: WARNING/Worker-2] /cluster/home/mmunso01/envs/nidaba/lib/python2.7/site-packages/kraken/lib/lstm.py:48: RuntimeWarning: invalid value encountered in true_divide
  line = line * 1.0/np.amax(line)
[2015-10-30 06:57:28,120: ERROR/Worker-2] nidaba.ocr.kraken[ddae2911-3979-4f1d-83b4-70cba32349b1]: 
[2015-10-30 06:57:29,833: ERROR/MainProcess] Task nidaba.ocr.kraken[ddae2911-3979-4f1d-83b4-70cba32349b1] raised unexpected: AssertionError()
Traceback (most recent call last):
  File "/cluster/home/mmunso01/envs/nidaba/lib/python2.7/site-packages/celery/app/trace.py", line 240, in trace_task
    R = retval = fun(*args, **kwargs)
  File "/cluster/home/mmunso01/envs/nidaba/lib/python2.7/site-packages/nidaba/tasks/helper.py", line 89, in __call__
    ret = super(NidabaTask, self).__call__(*args, **nkwargs)
  File "/cluster/home/mmunso01/envs/nidaba/lib/python2.7/site-packages/celery/app/trace.py", line 438, in __protected_call__
    return self.run(*args, **kwargs)
  File "/cluster/home/mmunso01/envs/nidaba/lib/python2.7/site-packages/nidaba/plugins/kraken.py", line 155, in ocr_kraken
    for rec in rpred.rpred(rnn, img, [(int(x[0]), int(x[1]), int(x[2]), int(x[3])) for x in lines]):
  File "/cluster/home/mmunso01/envs/nidaba/lib/python2.7/site-packages/kraken/rpred.py", line 134, in rpred
    pred = network.predictString(line)
  File "/cluster/home/mmunso01/envs/nidaba/lib/python2.7/site-packages/kraken/lib/lstm.py", line 281, in predictString
    cs = self.predictSequence(xs)
  File "/cluster/home/mmunso01/envs/nidaba/lib/python2.7/site-packages/kraken/lib/lstm.py", line 273, in predictSequence
    self.outputs = np.array(self.lstm.forward(xs))
  File "/cluster/home/mmunso01/envs/nidaba/lib/python2.7/site-packages/kraken/lib/lstm.py", line 229, in forward
    xs = net.forward(xs)
  File "/cluster/home/mmunso01/envs/nidaba/lib/python2.7/site-packages/kraken/lib/lstm.py", line 244, in forward
    outputs = [net.forward(xs) for net in self.nets]
  File "/cluster/home/mmunso01/envs/nidaba/lib/python2.7/site-packages/kraken/lib/lstm.py", line 216, in forward
    assert not np.isnan(self.output[:n]).any()
AssertionError
[2015-10-30 06:58:04,158: ERROR/Worker-14] nidaba.ocr.kraken[451851bf-08d1-4b5e-a2f9-4e073fe74a06]: index 5000 is out of bounds for axis 0 with size 5000
[2015-10-30 06:58:06,512: ERROR/MainProcess] Task nidaba.ocr.kraken[451851bf-08d1-4b5e-a2f9-4e073fe74a06] raised unexpected: IndexError('index 5000 is out of bounds for axis 0 with size 5000',)
Traceback (most recent call last):
  File "/cluster/home/mmunso01/envs/nidaba/lib/python2.7/site-packages/celery/app/trace.py", line 240, in trace_task
    R = retval = fun(*args, **kwargs)
  File "/cluster/home/mmunso01/envs/nidaba/lib/python2.7/site-packages/nidaba/tasks/helper.py", line 89, in __call__
    ret = super(NidabaTask, self).__call__(*args, **nkwargs)
  File "/cluster/home/mmunso01/envs/nidaba/lib/python2.7/site-packages/celery/app/trace.py", line 438, in __protected_call__
    return self.run(*args, **kwargs)
  File "/cluster/home/mmunso01/envs/nidaba/lib/python2.7/site-packages/nidaba/plugins/kraken.py", line 155, in ocr_kraken
    for rec in rpred.rpred(rnn, img, [(int(x[0]), int(x[1]), int(x[2]), int(x[3])) for x in lines]):
  File "/cluster/home/mmunso01/envs/nidaba/lib/python2.7/site-packages/kraken/rpred.py", line 134, in rpred
    pred = network.predictString(line)
  File "/cluster/home/mmunso01/envs/nidaba/lib/python2.7/site-packages/kraken/lib/lstm.py", line 281, in predictString
    cs = self.predictSequence(xs)
  File "/cluster/home/mmunso01/envs/nidaba/lib/python2.7/site-packages/kraken/lib/lstm.py", line 273, in predictSequence
    self.outputs = np.array(self.lstm.forward(xs))
  File "/cluster/home/mmunso01/envs/nidaba/lib/python2.7/site-packages/kraken/lib/lstm.py", line 229, in forward
    xs = net.forward(xs)
  File "/cluster/home/mmunso01/envs/nidaba/lib/python2.7/site-packages/kraken/lib/lstm.py", line 244, in forward
    outputs = [net.forward(xs) for net in self.nets]
  File "/cluster/home/mmunso01/envs/nidaba/lib/python2.7/site-packages/kraken/lib/lstm.py", line 196, in forward
    self.source[t,0] = 1
IndexError: index 5000 is out of bounds for axis 0 with size 5000
[2015-10-30 07:00:06,890: ERROR/Worker-20] nidaba.ocr.kraken[2fbc7db0-2483-4f3d-888b-a8c01c97f87c]: index 5000 is out of bounds for axis 0 with size 5000
[2015-10-30 07:00:08,598: ERROR/MainProcess] Task nidaba.ocr.kraken[2fbc7db0-2483-4f3d-888b-a8c01c97f87c] raised unexpected: IndexError('index 5000 is out of bounds for axis 0 with size 5000',)
Traceback (most recent call last):
  File "/cluster/home/mmunso01/envs/nidaba/lib/python2.7/site-packages/celery/app/trace.py", line 240, in trace_task
    R = retval = fun(*args, **kwargs)
  File "/cluster/home/mmunso01/envs/nidaba/lib/python2.7/site-packages/nidaba/tasks/helper.py", line 89, in __call__
    ret = super(NidabaTask, self).__call__(*args, **nkwargs)
  File "/cluster/home/mmunso01/envs/nidaba/lib/python2.7/site-packages/celery/app/trace.py", line 438, in __protected_call__
    return self.run(*args, **kwargs)
  File "/cluster/home/mmunso01/envs/nidaba/lib/python2.7/site-packages/nidaba/plugins/kraken.py", line 155, in ocr_kraken
    for rec in rpred.rpred(rnn, img, [(int(x[0]), int(x[1]), int(x[2]), int(x[3])) for x in lines]):
  File "/cluster/home/mmunso01/envs/nidaba/lib/python2.7/site-packages/kraken/rpred.py", line 134, in rpred
    pred = network.predictString(line)
  File "/cluster/home/mmunso01/envs/nidaba/lib/python2.7/site-packages/kraken/lib/lstm.py", line 281, in predictString
    cs = self.predictSequence(xs)
  File "/cluster/home/mmunso01/envs/nidaba/lib/python2.7/site-packages/kraken/lib/lstm.py", line 273, in predictSequence
    self.outputs = np.array(self.lstm.forward(xs))
  File "/cluster/home/mmunso01/envs/nidaba/lib/python2.7/site-packages/kraken/lib/lstm.py", line 229, in forward
    xs = net.forward(xs)
  File "/cluster/home/mmunso01/envs/nidaba/lib/python2.7/site-packages/kraken/lib/lstm.py", line 244, in forward
    outputs = [net.forward(xs) for net in self.nets]
  File "/cluster/home/mmunso01/envs/nidaba/lib/python2.7/site-packages/kraken/lib/lstm.py", line 196, in forward
    self.source[t,0] = 1
IndexError: index 5000 is out of bounds for axis 0 with size 5000
[2015-10-30 07:00:32,988: ERROR/Worker-1] nidaba.ocr.kraken[7b16ffb3-a62f-4fcc-9d12-38853222fc68]: index 5000 is out of bounds for axis 0 with size 5000
[2015-10-30 07:00:34,629: ERROR/MainProcess] Task nidaba.ocr.kraken[7b16ffb3-a62f-4fcc-9d12-38853222fc68] raised unexpected: IndexError('index 5000 is out of bounds for axis 0 with size 5000',)
Traceback (most recent call last):
  File "/cluster/home/mmunso01/envs/nidaba/lib/python2.7/site-packages/celery/app/trace.py", line 240, in trace_task
    R = retval = fun(*args, **kwargs)
  File "/cluster/home/mmunso01/envs/nidaba/lib/python2.7/site-packages/nidaba/tasks/helper.py", line 89, in __call__
    ret = super(NidabaTask, self).__call__(*args, **nkwargs)
  File "/cluster/home/mmunso01/envs/nidaba/lib/python2.7/site-packages/celery/app/trace.py", line 438, in __protected_call__
    return self.run(*args, **kwargs)
  File "/cluster/home/mmunso01/envs/nidaba/lib/python2.7/site-packages/nidaba/plugins/kraken.py", line 155, in ocr_kraken
    for rec in rpred.rpred(rnn, img, [(int(x[0]), int(x[1]), int(x[2]), int(x[3])) for x in lines]):
  File "/cluster/home/mmunso01/envs/nidaba/lib/python2.7/site-packages/kraken/rpred.py", line 134, in rpred
    pred = network.predictString(line)
  File "/cluster/home/mmunso01/envs/nidaba/lib/python2.7/site-packages/kraken/lib/lstm.py", line 281, in predictString
    cs = self.predictSequence(xs)
  File "/cluster/home/mmunso01/envs/nidaba/lib/python2.7/site-packages/kraken/lib/lstm.py", line 273, in predictSequence
    self.outputs = np.array(self.lstm.forward(xs))
  File "/cluster/home/mmunso01/envs/nidaba/lib/python2.7/site-packages/kraken/lib/lstm.py", line 229, in forward
    xs = net.forward(xs)
  File "/cluster/home/mmunso01/envs/nidaba/lib/python2.7/site-packages/kraken/lib/lstm.py", line 244, in forward
    outputs = [net.forward(xs) for net in self.nets]
  File "/cluster/home/mmunso01/envs/nidaba/lib/python2.7/site-packages/kraken/lib/lstm.py", line 196, in forward
    self.source[t,0] = 1
IndexError: index 5000 is out of bounds for axis 0 with size 5000
[2015-10-30 07:00:51,130: ERROR/Worker-10] nidaba.ocr.kraken[80424231-ae48-494a-92e2-bfcdb5054e72]: index 5000 is out of bounds for axis 0 with size 5000
[2015-10-30 07:00:53,382: ERROR/MainProcess] Task nidaba.ocr.kraken[80424231-ae48-494a-92e2-bfcdb5054e72] raised unexpected: IndexError('index 5000 is out of bounds for axis 0 with size 5000',)
Traceback (most recent call last):
  File "/cluster/home/mmunso01/envs/nidaba/lib/python2.7/site-packages/celery/app/trace.py", line 240, in trace_task
    R = retval = fun(*args, **kwargs)
  File "/cluster/home/mmunso01/envs/nidaba/lib/python2.7/site-packages/nidaba/tasks/helper.py", line 89, in __call__
    ret = super(NidabaTask, self).__call__(*args, **nkwargs)
  File "/cluster/home/mmunso01/envs/nidaba/lib/python2.7/site-packages/celery/app/trace.py", line 438, in __protected_call__
    return self.run(*args, **kwargs)
  File "/cluster/home/mmunso01/envs/nidaba/lib/python2.7/site-packages/nidaba/plugins/kraken.py", line 155, in ocr_kraken
    for rec in rpred.rpred(rnn, img, [(int(x[0]), int(x[1]), int(x[2]), int(x[3])) for x in lines]):
  File "/cluster/home/mmunso01/envs/nidaba/lib/python2.7/site-packages/kraken/rpred.py", line 134, in rpred
    pred = network.predictString(line)
  File "/cluster/home/mmunso01/envs/nidaba/lib/python2.7/site-packages/kraken/lib/lstm.py", line 281, in predictString
    cs = self.predictSequence(xs)
  File "/cluster/home/mmunso01/envs/nidaba/lib/python2.7/site-packages/kraken/lib/lstm.py", line 273, in predictSequence
    self.outputs = np.array(self.lstm.forward(xs))
  File "/cluster/home/mmunso01/envs/nidaba/lib/python2.7/site-packages/kraken/lib/lstm.py", line 229, in forward
    xs = net.forward(xs)
  File "/cluster/home/mmunso01/envs/nidaba/lib/python2.7/site-packages/kraken/lib/lstm.py", line 244, in forward
    outputs = [net.forward(xs) for net in self.nets]
  File "/cluster/home/mmunso01/envs/nidaba/lib/python2.7/site-packages/kraken/lib/lstm.py", line 196, in forward
    self.source[t,0] = 1
IndexError: index 5000 is out of bounds for axis 0 with size 5000
[2015-10-30 07:02:35,436: ERROR/Worker-11] nidaba.ocr.kraken[10f6184e-b53f-4c38-b923-cdc5f1d09e1e]: index 5000 is out of bounds for axis 0 with size 5000
[2015-10-30 07:02:36,660: ERROR/MainProcess] Task nidaba.ocr.kraken[10f6184e-b53f-4c38-b923-cdc5f1d09e1e] raised unexpected: IndexError('index 5000 is out of bounds for axis 0 with size 5000',)
Traceback (most recent call last):
  File "/cluster/home/mmunso01/envs/nidaba/lib/python2.7/site-packages/celery/app/trace.py", line 240, in trace_task
    R = retval = fun(*args, **kwargs)
  File "/cluster/home/mmunso01/envs/nidaba/lib/python2.7/site-packages/nidaba/tasks/helper.py", line 89, in __call__
    ret = super(NidabaTask, self).__call__(*args, **nkwargs)
  File "/cluster/home/mmunso01/envs/nidaba/lib/python2.7/site-packages/celery/app/trace.py", line 438, in __protected_call__
    return self.run(*args, **kwargs)
  File "/cluster/home/mmunso01/envs/nidaba/lib/python2.7/site-packages/nidaba/plugins/kraken.py", line 155, in ocr_kraken
    for rec in rpred.rpred(rnn, img, [(int(x[0]), int(x[1]), int(x[2]), int(x[3])) for x in lines]):
  File "/cluster/home/mmunso01/envs/nidaba/lib/python2.7/site-packages/kraken/rpred.py", line 134, in rpred
    pred = network.predictString(line)
  File "/cluster/home/mmunso01/envs/nidaba/lib/python2.7/site-packages/kraken/lib/lstm.py", line 281, in predictString
    cs = self.predictSequence(xs)
  File "/cluster/home/mmunso01/envs/nidaba/lib/python2.7/site-packages/kraken/lib/lstm.py", line 273, in predictSequence
    self.outputs = np.array(self.lstm.forward(xs))
  File "/cluster/home/mmunso01/envs/nidaba/lib/python2.7/site-packages/kraken/lib/lstm.py", line 229, in forward
    xs = net.forward(xs)
  File "/cluster/home/mmunso01/envs/nidaba/lib/python2.7/site-packages/kraken/lib/lstm.py", line 244, in forward
    outputs = [net.forward(xs) for net in self.nets]
  File "/cluster/home/mmunso01/envs/nidaba/lib/python2.7/site-packages/kraken/lib/lstm.py", line 196, in forward
    self.source[t,0] = 1
IndexError: index 5000 is out of bounds for axis 0 with size 5000
[2015-10-30 07:02:44,377: ERROR/Worker-19] nidaba.ocr.kraken[fa84e623-04d3-41b5-989a-40ca72160990]: index 5000 is out of bounds for axis 0 with size 5000
[2015-10-30 07:02:46,152: ERROR/MainProcess] Task nidaba.ocr.kraken[fa84e623-04d3-41b5-989a-40ca72160990] raised unexpected: IndexError('index 5000 is out of bounds for axis 0 with size 5000',)
Traceback (most recent call last):
  File "/cluster/home/mmunso01/envs/nidaba/lib/python2.7/site-packages/celery/app/trace.py", line 240, in trace_task
    R = retval = fun(*args, **kwargs)
  File "/cluster/home/mmunso01/envs/nidaba/lib/python2.7/site-packages/nidaba/tasks/helper.py", line 89, in __call__
    ret = super(NidabaTask, self).__call__(*args, **nkwargs)
  File "/cluster/home/mmunso01/envs/nidaba/lib/python2.7/site-packages/celery/app/trace.py", line 438, in __protected_call__
    return self.run(*args, **kwargs)
  File "/cluster/home/mmunso01/envs/nidaba/lib/python2.7/site-packages/nidaba/plugins/kraken.py", line 155, in ocr_kraken
    for rec in rpred.rpred(rnn, img, [(int(x[0]), int(x[1]), int(x[2]), int(x[3])) for x in lines]):
  File "/cluster/home/mmunso01/envs/nidaba/lib/python2.7/site-packages/kraken/rpred.py", line 134, in rpred
    pred = network.predictString(line)
  File "/cluster/home/mmunso01/envs/nidaba/lib/python2.7/site-packages/kraken/lib/lstm.py", line 281, in predictString
    cs = self.predictSequence(xs)
  File "/cluster/home/mmunso01/envs/nidaba/lib/python2.7/site-packages/kraken/lib/lstm.py", line 273, in predictSequence
    self.outputs = np.array(self.lstm.forward(xs))
  File "/cluster/home/mmunso01/envs/nidaba/lib/python2.7/site-packages/kraken/lib/lstm.py", line 229, in forward
    xs = net.forward(xs)
  File "/cluster/home/mmunso01/envs/nidaba/lib/python2.7/site-packages/kraken/lib/lstm.py", line 244, in forward
    outputs = [net.forward(xs) for net in self.nets]
  File "/cluster/home/mmunso01/envs/nidaba/lib/python2.7/site-packages/kraken/lib/lstm.py", line 196, in forward
    self.source[t,0] = 1
IndexError: index 5000 is out of bounds for axis 0 with size 5000
[2015-10-30 07:02:57,021: ERROR/Worker-9] nidaba.ocr.kraken[8a5dec8b-c252-49b7-b7d2-30a287e3fc35]: index 5000 is out of bounds for axis 0 with size 5000
[2015-10-30 07:02:58,386: ERROR/MainProcess] Task nidaba.ocr.kraken[8a5dec8b-c252-49b7-b7d2-30a287e3fc35] raised unexpected: IndexError('index 5000 is out of bounds for axis 0 with size 5000',)
Traceback (most recent call last):
  File "/cluster/home/mmunso01/envs/nidaba/lib/python2.7/site-packages/celery/app/trace.py", line 240, in trace_task
    R = retval = fun(*args, **kwargs)
  File "/cluster/home/mmunso01/envs/nidaba/lib/python2.7/site-packages/nidaba/tasks/helper.py", line 89, in __call__
    ret = super(NidabaTask, self).__call__(*args, **nkwargs)
  File "/cluster/home/mmunso01/envs/nidaba/lib/python2.7/site-packages/celery/app/trace.py", line 438, in __protected_call__
    return self.run(*args, **kwargs)
  File "/cluster/home/mmunso01/envs/nidaba/lib/python2.7/site-packages/nidaba/plugins/kraken.py", line 155, in ocr_kraken
    for rec in rpred.rpred(rnn, img, [(int(x[0]), int(x[1]), int(x[2]), int(x[3])) for x in lines]):
  File "/cluster/home/mmunso01/envs/nidaba/lib/python2.7/site-packages/kraken/rpred.py", line 134, in rpred
    pred = network.predictString(line)
  File "/cluster/home/mmunso01/envs/nidaba/lib/python2.7/site-packages/kraken/lib/lstm.py", line 281, in predictString
    cs = self.predictSequence(xs)
  File "/cluster/home/mmunso01/envs/nidaba/lib/python2.7/site-packages/kraken/lib/lstm.py", line 273, in predictSequence
    self.outputs = np.array(self.lstm.forward(xs))
  File "/cluster/home/mmunso01/envs/nidaba/lib/python2.7/site-packages/kraken/lib/lstm.py", line 229, in forward
    xs = net.forward(xs)
  File "/cluster/home/mmunso01/envs/nidaba/lib/python2.7/site-packages/kraken/lib/lstm.py", line 244, in forward
    outputs = [net.forward(xs) for net in self.nets]
  File "/cluster/home/mmunso01/envs/nidaba/lib/python2.7/site-packages/kraken/lib/lstm.py", line 196, in forward
    self.source[t,0] = 1
IndexError: index 5000 is out of bounds for axis 0 with size 5000
[2015-10-30 07:03:00,238: ERROR/Worker-23] nidaba.ocr.kraken[530205d7-6ff9-4816-b0a9-09465c41bb69]: index 5000 is out of bounds for axis 0 with size 5000
[2015-10-30 07:03:03,812: ERROR/MainProcess] Task nidaba.ocr.kraken[530205d7-6ff9-4816-b0a9-09465c41bb69] raised unexpected: IndexError('index 5000 is out of bounds for axis 0 with size 5000',)
Traceback (most recent call last):
  File "/cluster/home/mmunso01/envs/nidaba/lib/python2.7/site-packages/celery/app/trace.py", line 240, in trace_task
    R = retval = fun(*args, **kwargs)
  File "/cluster/home/mmunso01/envs/nidaba/lib/python2.7/site-packages/nidaba/tasks/helper.py", line 89, in __call__
    ret = super(NidabaTask, self).__call__(*args, **nkwargs)
  File "/cluster/home/mmunso01/envs/nidaba/lib/python2.7/site-packages/celery/app/trace.py", line 438, in __protected_call__
    return self.run(*args, **kwargs)
  File "/cluster/home/mmunso01/envs/nidaba/lib/python2.7/site-packages/nidaba/plugins/kraken.py", line 155, in ocr_kraken
    for rec in rpred.rpred(rnn, img, [(int(x[0]), int(x[1]), int(x[2]), int(x[3])) for x in lines]):
  File "/cluster/home/mmunso01/envs/nidaba/lib/python2.7/site-packages/kraken/rpred.py", line 134, in rpred
    pred = network.predictString(line)
  File "/cluster/home/mmunso01/envs/nidaba/lib/python2.7/site-packages/kraken/lib/lstm.py", line 281, in predictString
    cs = self.predictSequence(xs)
  File "/cluster/home/mmunso01/envs/nidaba/lib/python2.7/site-packages/kraken/lib/lstm.py", line 273, in predictSequence
    self.outputs = np.array(self.lstm.forward(xs))
  File "/cluster/home/mmunso01/envs/nidaba/lib/python2.7/site-packages/kraken/lib/lstm.py", line 229, in forward
    xs = net.forward(xs)
  File "/cluster/home/mmunso01/envs/nidaba/lib/python2.7/site-packages/kraken/lib/lstm.py", line 244, in forward
    outputs = [net.forward(xs) for net in self.nets]
  File "/cluster/home/mmunso01/envs/nidaba/lib/python2.7/site-packages/kraken/lib/lstm.py", line 196, in forward
    self.source[t,0] = 1
IndexError: index 5000 is out of bounds for axis 0 with size 5000
[2015-10-30 07:03:03,986: ERROR/Worker-37] nidaba.ocr.kraken[8b6a0052-2277-406c-b0a4-7644c61d3c4b]: index 5000 is out of bounds for axis 0 with size 5000
[2015-10-30 07:03:06,092: ERROR/MainProcess] Task nidaba.ocr.kraken[8b6a0052-2277-406c-b0a4-7644c61d3c4b] raised unexpected: IndexError('index 5000 is out of bounds for axis 0 with size 5000',)
Traceback (most recent call last):
  File "/cluster/home/mmunso01/envs/nidaba/lib/python2.7/site-packages/celery/app/trace.py", line 240, in trace_task
    R = retval = fun(*args, **kwargs)
  File "/cluster/home/mmunso01/envs/nidaba/lib/python2.7/site-packages/nidaba/tasks/helper.py", line 89, in __call__
    ret = super(NidabaTask, self).__call__(*args, **nkwargs)
  File "/cluster/home/mmunso01/envs/nidaba/lib/python2.7/site-packages/celery/app/trace.py", line 438, in __protected_call__
    return self.run(*args, **kwargs)
  File "/cluster/home/mmunso01/envs/nidaba/lib/python2.7/site-packages/nidaba/plugins/kraken.py", line 155, in ocr_kraken
    for rec in rpred.rpred(rnn, img, [(int(x[0]), int(x[1]), int(x[2]), int(x[3])) for x in lines]):
  File "/cluster/home/mmunso01/envs/nidaba/lib/python2.7/site-packages/kraken/rpred.py", line 134, in rpred
    pred = network.predictString(line)
  File "/cluster/home/mmunso01/envs/nidaba/lib/python2.7/site-packages/kraken/lib/lstm.py", line 281, in predictString
    cs = self.predictSequence(xs)
  File "/cluster/home/mmunso01/envs/nidaba/lib/python2.7/site-packages/kraken/lib/lstm.py", line 273, in predictSequence
    self.outputs = np.array(self.lstm.forward(xs))
  File "/cluster/home/mmunso01/envs/nidaba/lib/python2.7/site-packages/kraken/lib/lstm.py", line 229, in forward
    xs = net.forward(xs)
  File "/cluster/home/mmunso01/envs/nidaba/lib/python2.7/site-packages/kraken/lib/lstm.py", line 244, in forward
    outputs = [net.forward(xs) for net in self.nets]
  File "/cluster/home/mmunso01/envs/nidaba/lib/python2.7/site-packages/kraken/lib/lstm.py", line 196, in forward
    self.source[t,0] = 1
IndexError: index 5000 is out of bounds for axis 0 with size 5000
[2015-10-30 07:03:13,633: ERROR/Worker-14] nidaba.ocr.kraken[23050035-3633-4e42-a988-51cdfb41973d]: index 5000 is out of bounds for axis 0 with size 5000
[2015-10-30 07:03:15,852: ERROR/MainProcess] Task nidaba.ocr.kraken[23050035-3633-4e42-a988-51cdfb41973d] raised unexpected: IndexError('index 5000 is out of bounds for axis 0 with size 5000',)
Traceback (most recent call last):
  File "/cluster/home/mmunso01/envs/nidaba/lib/python2.7/site-packages/celery/app/trace.py", line 240, in trace_task
    R = retval = fun(*args, **kwargs)
  File "/cluster/home/mmunso01/envs/nidaba/lib/python2.7/site-packages/nidaba/tasks/helper.py", line 89, in __call__
    ret = super(NidabaTask, self).__call__(*args, **nkwargs)
  File "/cluster/home/mmunso01/envs/nidaba/lib/python2.7/site-packages/celery/app/trace.py", line 438, in __protected_call__
    return self.run(*args, **kwargs)
  File "/cluster/home/mmunso01/envs/nidaba/lib/python2.7/site-packages/nidaba/plugins/kraken.py", line 155, in ocr_kraken
    for rec in rpred.rpred(rnn, img, [(int(x[0]), int(x[1]), int(x[2]), int(x[3])) for x in lines]):
  File "/cluster/home/mmunso01/envs/nidaba/lib/python2.7/site-packages/kraken/rpred.py", line 134, in rpred
    pred = network.predictString(line)
  File "/cluster/home/mmunso01/envs/nidaba/lib/python2.7/site-packages/kraken/lib/lstm.py", line 281, in predictString
    cs = self.predictSequence(xs)
  File "/cluster/home/mmunso01/envs/nidaba/lib/python2.7/site-packages/kraken/lib/lstm.py", line 273, in predictSequence
    self.outputs = np.array(self.lstm.forward(xs))
  File "/cluster/home/mmunso01/envs/nidaba/lib/python2.7/site-packages/kraken/lib/lstm.py", line 229, in forward
    xs = net.forward(xs)
  File "/cluster/home/mmunso01/envs/nidaba/lib/python2.7/site-packages/kraken/lib/lstm.py", line 244, in forward
    outputs = [net.forward(xs) for net in self.nets]
  File "/cluster/home/mmunso01/envs/nidaba/lib/python2.7/site-packages/kraken/lib/lstm.py", line 196, in forward
    self.source[t,0] = 1
IndexError: index 5000 is out of bounds for axis 0 with size 5000
[2015-10-30 07:03:27,692: ERROR/Worker-7] nidaba.ocr.kraken[3ea3af7e-d2e1-49a4-a9fb-15b7e04c4810]: index 5000 is out of bounds for axis 0 with size 5000
[2015-10-30 07:03:30,122: ERROR/MainProcess] Task nidaba.ocr.kraken[3ea3af7e-d2e1-49a4-a9fb-15b7e04c4810] raised unexpected: IndexError('index 5000 is out of bounds for axis 0 with size 5000',)
Traceback (most recent call last):
  File "/cluster/home/mmunso01/envs/nidaba/lib/python2.7/site-packages/celery/app/trace.py", line 240, in trace_task
    R = retval = fun(*args, **kwargs)
  File "/cluster/home/mmunso01/envs/nidaba/lib/python2.7/site-packages/nidaba/tasks/helper.py", line 89, in __call__
    ret = super(NidabaTask, self).__call__(*args, **nkwargs)
  File "/cluster/home/mmunso01/envs/nidaba/lib/python2.7/site-packages/celery/app/trace.py", line 438, in __protected_call__
    return self.run(*args, **kwargs)
  File "/cluster/home/mmunso01/envs/nidaba/lib/python2.7/site-packages/nidaba/plugins/kraken.py", line 155, in ocr_kraken
    for rec in rpred.rpred(rnn, img, [(int(x[0]), int(x[1]), int(x[2]), int(x[3])) for x in lines]):
  File "/cluster/home/mmunso01/envs/nidaba/lib/python2.7/site-packages/kraken/rpred.py", line 134, in rpred
    pred = network.predictString(line)
  File "/cluster/home/mmunso01/envs/nidaba/lib/python2.7/site-packages/kraken/lib/lstm.py", line 281, in predictString
    cs = self.predictSequence(xs)
  File "/cluster/home/mmunso01/envs/nidaba/lib/python2.7/site-packages/kraken/lib/lstm.py", line 273, in predictSequence
    self.outputs = np.array(self.lstm.forward(xs))
  File "/cluster/home/mmunso01/envs/nidaba/lib/python2.7/site-packages/kraken/lib/lstm.py", line 229, in forward
    xs = net.forward(xs)
  File "/cluster/home/mmunso01/envs/nidaba/lib/python2.7/site-packages/kraken/lib/lstm.py", line 244, in forward
    outputs = [net.forward(xs) for net in self.nets]
  File "/cluster/home/mmunso01/envs/nidaba/lib/python2.7/site-packages/kraken/lib/lstm.py", line 196, in forward
    self.source[t,0] = 1
IndexError: index 5000 is out of bounds for axis 0 with size 5000
[2015-10-30 07:03:43,127: ERROR/Worker-5] nidaba.ocr.kraken[12801f36-c4e0-4b57-b9cb-7a2395eb55b0]: index 5000 is out of bounds for axis 0 with size 5000
[2015-10-30 07:03:43,739: ERROR/Worker-38] nidaba.ocr.kraken[e581cd2b-66a9-465b-94d0-8b35161b160d]: index 5000 is out of bounds for axis 0 with size 5000
[2015-10-30 07:03:44,911: ERROR/MainProcess] Task nidaba.ocr.kraken[12801f36-c4e0-4b57-b9cb-7a2395eb55b0] raised unexpected: IndexError('index 5000 is out of bounds for axis 0 with size 5000',)
Traceback (most recent call last):
  File "/cluster/home/mmunso01/envs/nidaba/lib/python2.7/site-packages/celery/app/trace.py", line 240, in trace_task
    R = retval = fun(*args, **kwargs)
  File "/cluster/home/mmunso01/envs/nidaba/lib/python2.7/site-packages/nidaba/tasks/helper.py", line 89, in __call__
    ret = super(NidabaTask, self).__call__(*args, **nkwargs)
  File "/cluster/home/mmunso01/envs/nidaba/lib/python2.7/site-packages/celery/app/trace.py", line 438, in __protected_call__
    return self.run(*args, **kwargs)
  File "/cluster/home/mmunso01/envs/nidaba/lib/python2.7/site-packages/nidaba/plugins/kraken.py", line 155, in ocr_kraken
    for rec in rpred.rpred(rnn, img, [(int(x[0]), int(x[1]), int(x[2]), int(x[3])) for x in lines]):
  File "/cluster/home/mmunso01/envs/nidaba/lib/python2.7/site-packages/kraken/rpred.py", line 134, in rpred
    pred = network.predictString(line)
  File "/cluster/home/mmunso01/envs/nidaba/lib/python2.7/site-packages/kraken/lib/lstm.py", line 281, in predictString
    cs = self.predictSequence(xs)
  File "/cluster/home/mmunso01/envs/nidaba/lib/python2.7/site-packages/kraken/lib/lstm.py", line 273, in predictSequence
    self.outputs = np.array(self.lstm.forward(xs))
  File "/cluster/home/mmunso01/envs/nidaba/lib/python2.7/site-packages/kraken/lib/lstm.py", line 229, in forward
    xs = net.forward(xs)
  File "/cluster/home/mmunso01/envs/nidaba/lib/python2.7/site-packages/kraken/lib/lstm.py", line 244, in forward
    outputs = [net.forward(xs) for net in self.nets]
  File "/cluster/home/mmunso01/envs/nidaba/lib/python2.7/site-packages/kraken/lib/lstm.py", line 196, in forward
    self.source[t,0] = 1
IndexError: index 5000 is out of bounds for axis 0 with size 5000
[2015-10-30 07:03:46,113: ERROR/MainProcess] Task nidaba.ocr.kraken[e581cd2b-66a9-465b-94d0-8b35161b160d] raised unexpected: IndexError('index 5000 is out of bounds for axis 0 with size 5000',)
Traceback (most recent call last):
  File "/cluster/home/mmunso01/envs/nidaba/lib/python2.7/site-packages/celery/app/trace.py", line 240, in trace_task
    R = retval = fun(*args, **kwargs)
  File "/cluster/home/mmunso01/envs/nidaba/lib/python2.7/site-packages/nidaba/tasks/helper.py", line 89, in __call__
    ret = super(NidabaTask, self).__call__(*args, **nkwargs)
  File "/cluster/home/mmunso01/envs/nidaba/lib/python2.7/site-packages/celery/app/trace.py", line 438, in __protected_call__
    return self.run(*args, **kwargs)
  File "/cluster/home/mmunso01/envs/nidaba/lib/python2.7/site-packages/nidaba/plugins/kraken.py", line 155, in ocr_kraken
    for rec in rpred.rpred(rnn, img, [(int(x[0]), int(x[1]), int(x[2]), int(x[3])) for x in lines]):
  File "/cluster/home/mmunso01/envs/nidaba/lib/python2.7/site-packages/kraken/rpred.py", line 134, in rpred
    pred = network.predictString(line)
  File "/cluster/home/mmunso01/envs/nidaba/lib/python2.7/site-packages/kraken/lib/lstm.py", line 281, in predictString
    cs = self.predictSequence(xs)
  File "/cluster/home/mmunso01/envs/nidaba/lib/python2.7/site-packages/kraken/lib/lstm.py", line 273, in predictSequence
    self.outputs = np.array(self.lstm.forward(xs))
  File "/cluster/home/mmunso01/envs/nidaba/lib/python2.7/site-packages/kraken/lib/lstm.py", line 229, in forward
    xs = net.forward(xs)
  File "/cluster/home/mmunso01/envs/nidaba/lib/python2.7/site-packages/kraken/lib/lstm.py", line 244, in forward
    outputs = [net.forward(xs) for net in self.nets]
  File "/cluster/home/mmunso01/envs/nidaba/lib/python2.7/site-packages/kraken/lib/lstm.py", line 196, in forward
    self.source[t,0] = 1
IndexError: index 5000 is out of bounds for axis 0 with size 5000
[2015-10-30 07:03:56,604: ERROR/Worker-23] nidaba.ocr.kraken[caf2a2e4-3dbf-4647-ada6-1ac5e178ea46]: index 5000 is out of bounds for axis 0 with size 5000
[2015-10-30 07:03:59,609: ERROR/MainProcess] Task nidaba.ocr.kraken[caf2a2e4-3dbf-4647-ada6-1ac5e178ea46] raised unexpected: IndexError('index 5000 is out of bounds for axis 0 with size 5000',)
Traceback (most recent call last):
  File "/cluster/home/mmunso01/envs/nidaba/lib/python2.7/site-packages/celery/app/trace.py", line 240, in trace_task
    R = retval = fun(*args, **kwargs)
  File "/cluster/home/mmunso01/envs/nidaba/lib/python2.7/site-packages/nidaba/tasks/helper.py", line 89, in __call__
    ret = super(NidabaTask, self).__call__(*args, **nkwargs)
  File "/cluster/home/mmunso01/envs/nidaba/lib/python2.7/site-packages/celery/app/trace.py", line 438, in __protected_call__
    return self.run(*args, **kwargs)
  File "/cluster/home/mmunso01/envs/nidaba/lib/python2.7/site-packages/nidaba/plugins/kraken.py", line 155, in ocr_kraken
    for rec in rpred.rpred(rnn, img, [(int(x[0]), int(x[1]), int(x[2]), int(x[3])) for x in lines]):
  File "/cluster/home/mmunso01/envs/nidaba/lib/python2.7/site-packages/kraken/rpred.py", line 134, in rpred
    pred = network.predictString(line)
  File "/cluster/home/mmunso01/envs/nidaba/lib/python2.7/site-packages/kraken/lib/lstm.py", line 281, in predictString
    cs = self.predictSequence(xs)
  File "/cluster/home/mmunso01/envs/nidaba/lib/python2.7/site-packages/kraken/lib/lstm.py", line 273, in predictSequence
    self.outputs = np.array(self.lstm.forward(xs))
  File "/cluster/home/mmunso01/envs/nidaba/lib/python2.7/site-packages/kraken/lib/lstm.py", line 229, in forward
    xs = net.forward(xs)
  File "/cluster/home/mmunso01/envs/nidaba/lib/python2.7/site-packages/kraken/lib/lstm.py", line 244, in forward
    outputs = [net.forward(xs) for net in self.nets]
  File "/cluster/home/mmunso01/envs/nidaba/lib/python2.7/site-packages/kraken/lib/lstm.py", line 196, in forward
    self.source[t,0] = 1
IndexError: index 5000 is out of bounds for axis 0 with size 5000
[2015-10-30 07:04:23,903: ERROR/Worker-20] nidaba.ocr.kraken[e896dd4a-d788-4649-9e03-cbdd85fc4f5c]: index 5000 is out of bounds for axis 0 with size 5000
[2015-10-30 07:04:25,142: ERROR/MainProcess] Task nidaba.ocr.kraken[e896dd4a-d788-4649-9e03-cbdd85fc4f5c] raised unexpected: IndexError('index 5000 is out of bounds for axis 0 with size 5000',)
Traceback (most recent call last):
  File "/cluster/home/mmunso01/envs/nidaba/lib/python2.7/site-packages/celery/app/trace.py", line 240, in trace_task
    R = retval = fun(*args, **kwargs)
  File "/cluster/home/mmunso01/envs/nidaba/lib/python2.7/site-packages/nidaba/tasks/helper.py", line 89, in __call__
    ret = super(NidabaTask, self).__call__(*args, **nkwargs)
  File "/cluster/home/mmunso01/envs/nidaba/lib/python2.7/site-packages/celery/app/trace.py", line 438, in __protected_call__
    return self.run(*args, **kwargs)
  File "/cluster/home/mmunso01/envs/nidaba/lib/python2.7/site-packages/nidaba/plugins/kraken.py", line 155, in ocr_kraken
    for rec in rpred.rpred(rnn, img, [(int(x[0]), int(x[1]), int(x[2]), int(x[3])) for x in lines]):
  File "/cluster/home/mmunso01/envs/nidaba/lib/python2.7/site-packages/kraken/rpred.py", line 134, in rpred
    pred = network.predictString(line)
  File "/cluster/home/mmunso01/envs/nidaba/lib/python2.7/site-packages/kraken/lib/lstm.py", line 281, in predictString
    cs = self.predictSequence(xs)
  File "/cluster/home/mmunso01/envs/nidaba/lib/python2.7/site-packages/kraken/lib/lstm.py", line 273, in predictSequence
    self.outputs = np.array(self.lstm.forward(xs))
  File "/cluster/home/mmunso01/envs/nidaba/lib/python2.7/site-packages/kraken/lib/lstm.py", line 229, in forward
    xs = net.forward(xs)
  File "/cluster/home/mmunso01/envs/nidaba/lib/python2.7/site-packages/kraken/lib/lstm.py", line 244, in forward
    outputs = [net.forward(xs) for net in self.nets]
  File "/cluster/home/mmunso01/envs/nidaba/lib/python2.7/site-packages/kraken/lib/lstm.py", line 196, in forward
    self.source[t,0] = 1
IndexError: index 5000 is out of bounds for axis 0 with size 5000
[2015-10-30 07:04:26,232: ERROR/Worker-12] nidaba.ocr.kraken[5b6bb4a7-916a-435d-b27e-9624d37c2f01]: index 5000 is out of bounds for axis 0 with size 5000
[2015-10-30 07:04:28,964: ERROR/MainProcess] Task nidaba.ocr.kraken[5b6bb4a7-916a-435d-b27e-9624d37c2f01] raised unexpected: IndexError('index 5000 is out of bounds for axis 0 with size 5000',)
Traceback (most recent call last):
  File "/cluster/home/mmunso01/envs/nidaba/lib/python2.7/site-packages/celery/app/trace.py", line 240, in trace_task
    R = retval = fun(*args, **kwargs)
  File "/cluster/home/mmunso01/envs/nidaba/lib/python2.7/site-packages/nidaba/tasks/helper.py", line 89, in __call__
    ret = super(NidabaTask, self).__call__(*args, **nkwargs)
  File "/cluster/home/mmunso01/envs/nidaba/lib/python2.7/site-packages/celery/app/trace.py", line 438, in __protected_call__
    return self.run(*args, **kwargs)
  File "/cluster/home/mmunso01/envs/nidaba/lib/python2.7/site-packages/nidaba/plugins/kraken.py", line 155, in ocr_kraken
    for rec in rpred.rpred(rnn, img, [(int(x[0]), int(x[1]), int(x[2]), int(x[3])) for x in lines]):
  File "/cluster/home/mmunso01/envs/nidaba/lib/python2.7/site-packages/kraken/rpred.py", line 134, in rpred
    pred = network.predictString(line)
  File "/cluster/home/mmunso01/envs/nidaba/lib/python2.7/site-packages/kraken/lib/lstm.py", line 281, in predictString
    cs = self.predictSequence(xs)
  File "/cluster/home/mmunso01/envs/nidaba/lib/python2.7/site-packages/kraken/lib/lstm.py", line 273, in predictSequence
    self.outputs = np.array(self.lstm.forward(xs))
  File "/cluster/home/mmunso01/envs/nidaba/lib/python2.7/site-packages/kraken/lib/lstm.py", line 229, in forward
    xs = net.forward(xs)
  File "/cluster/home/mmunso01/envs/nidaba/lib/python2.7/site-packages/kraken/lib/lstm.py", line 244, in forward
    outputs = [net.forward(xs) for net in self.nets]
  File "/cluster/home/mmunso01/envs/nidaba/lib/python2.7/site-packages/kraken/lib/lstm.py", line 196, in forward
    self.source[t,0] = 1
IndexError: index 5000 is out of bounds for axis 0 with size 5000
[2015-10-30 07:04:30,522: ERROR/Worker-30] nidaba.ocr.kraken[66f2b863-3dab-4001-91b4-6da734e28437]: index 5000 is out of bounds for axis 0 with size 5000
[2015-10-30 07:04:32,336: ERROR/MainProcess] Task nidaba.ocr.kraken[66f2b863-3dab-4001-91b4-6da734e28437] raised unexpected: IndexError('index 5000 is out of bounds for axis 0 with size 5000',)
Traceback (most recent call last):
  File "/cluster/home/mmunso01/envs/nidaba/lib/python2.7/site-packages/celery/app/trace.py", line 240, in trace_task
    R = retval = fun(*args, **kwargs)
  File "/cluster/home/mmunso01/envs/nidaba/lib/python2.7/site-packages/nidaba/tasks/helper.py", line 89, in __call__
    ret = super(NidabaTask, self).__call__(*args, **nkwargs)
  File "/cluster/home/mmunso01/envs/nidaba/lib/python2.7/site-packages/celery/app/trace.py", line 438, in __protected_call__
    return self.run(*args, **kwargs)
  File "/cluster/home/mmunso01/envs/nidaba/lib/python2.7/site-packages/nidaba/plugins/kraken.py", line 155, in ocr_kraken
    for rec in rpred.rpred(rnn, img, [(int(x[0]), int(x[1]), int(x[2]), int(x[3])) for x in lines]):
  File "/cluster/home/mmunso01/envs/nidaba/lib/python2.7/site-packages/kraken/rpred.py", line 134, in rpred
    pred = network.predictString(line)
  File "/cluster/home/mmunso01/envs/nidaba/lib/python2.7/site-packages/kraken/lib/lstm.py", line 281, in predictString
    cs = self.predictSequence(xs)
  File "/cluster/home/mmunso01/envs/nidaba/lib/python2.7/site-packages/kraken/lib/lstm.py", line 273, in predictSequence
    self.outputs = np.array(self.lstm.forward(xs))
  File "/cluster/home/mmunso01/envs/nidaba/lib/python2.7/site-packages/kraken/lib/lstm.py", line 229, in forward
    xs = net.forward(xs)
  File "/cluster/home/mmunso01/envs/nidaba/lib/python2.7/site-packages/kraken/lib/lstm.py", line 244, in forward
    outputs = [net.forward(xs) for net in self.nets]
  File "/cluster/home/mmunso01/envs/nidaba/lib/python2.7/site-packages/kraken/lib/lstm.py", line 196, in forward
    self.source[t,0] = 1
IndexError: index 5000 is out of bounds for axis 0 with size 5000
[2015-10-30 07:04:39,801: ERROR/Worker-17] nidaba.ocr.kraken[d2f0037a-54f7-44c2-a5c8-b188425cb9c4]: index 5000 is out of bounds for axis 0 with size 5000
[2015-10-30 07:04:41,394: ERROR/MainProcess] Task nidaba.ocr.kraken[d2f0037a-54f7-44c2-a5c8-b188425cb9c4] raised unexpected: IndexError('index 5000 is out of bounds for axis 0 with size 5000',)
Traceback (most recent call last):
  File "/cluster/home/mmunso01/envs/nidaba/lib/python2.7/site-packages/celery/app/trace.py", line 240, in trace_task
    R = retval = fun(*args, **kwargs)
  File "/cluster/home/mmunso01/envs/nidaba/lib/python2.7/site-packages/nidaba/tasks/helper.py", line 89, in __call__
    ret = super(NidabaTask, self).__call__(*args, **nkwargs)
  File "/cluster/home/mmunso01/envs/nidaba/lib/python2.7/site-packages/celery/app/trace.py", line 438, in __protected_call__
    return self.run(*args, **kwargs)
  File "/cluster/home/mmunso01/envs/nidaba/lib/python2.7/site-packages/nidaba/plugins/kraken.py", line 155, in ocr_kraken
    for rec in rpred.rpred(rnn, img, [(int(x[0]), int(x[1]), int(x[2]), int(x[3])) for x in lines]):
  File "/cluster/home/mmunso01/envs/nidaba/lib/python2.7/site-packages/kraken/rpred.py", line 134, in rpred
    pred = network.predictString(line)
  File "/cluster/home/mmunso01/envs/nidaba/lib/python2.7/site-packages/kraken/lib/lstm.py", line 281, in predictString
    cs = self.predictSequence(xs)
  File "/cluster/home/mmunso01/envs/nidaba/lib/python2.7/site-packages/kraken/lib/lstm.py", line 273, in predictSequence
    self.outputs = np.array(self.lstm.forward(xs))
  File "/cluster/home/mmunso01/envs/nidaba/lib/python2.7/site-packages/kraken/lib/lstm.py", line 229, in forward
    xs = net.forward(xs)
  File "/cluster/home/mmunso01/envs/nidaba/lib/python2.7/site-packages/kraken/lib/lstm.py", line 244, in forward
    outputs = [net.forward(xs) for net in self.nets]
  File "/cluster/home/mmunso01/envs/nidaba/lib/python2.7/site-packages/kraken/lib/lstm.py", line 196, in forward
    self.source[t,0] = 1
IndexError: index 5000 is out of bounds for axis 0 with size 5000
[2015-10-30 07:05:30,222: ERROR/Worker-14] nidaba.ocr.kraken[cd41480e-ce29-4d13-9add-e198924fd8a4]: index 5000 is out of bounds for axis 0 with size 5000
[2015-10-30 07:05:31,994: ERROR/MainProcess] Task nidaba.ocr.kraken[cd41480e-ce29-4d13-9add-e198924fd8a4] raised unexpected: IndexError('index 5000 is out of bounds for axis 0 with size 5000',)
Traceback (most recent call last):
  File "/cluster/home/mmunso01/envs/nidaba/lib/python2.7/site-packages/celery/app/trace.py", line 240, in trace_task
    R = retval = fun(*args, **kwargs)
  File "/cluster/home/mmunso01/envs/nidaba/lib/python2.7/site-packages/nidaba/tasks/helper.py", line 89, in __call__
    ret = super(NidabaTask, self).__call__(*args, **nkwargs)
  File "/cluster/home/mmunso01/envs/nidaba/lib/python2.7/site-packages/celery/app/trace.py", line 438, in __protected_call__
    return self.run(*args, **kwargs)
  File "/cluster/home/mmunso01/envs/nidaba/lib/python2.7/site-packages/nidaba/plugins/kraken.py", line 155, in ocr_kraken
    for rec in rpred.rpred(rnn, img, [(int(x[0]), int(x[1]), int(x[2]), int(x[3])) for x in lines]):
  File "/cluster/home/mmunso01/envs/nidaba/lib/python2.7/site-packages/kraken/rpred.py", line 134, in rpred
    pred = network.predictString(line)
  File "/cluster/home/mmunso01/envs/nidaba/lib/python2.7/site-packages/kraken/lib/lstm.py", line 281, in predictString
    cs = self.predictSequence(xs)
  File "/cluster/home/mmunso01/envs/nidaba/lib/python2.7/site-packages/kraken/lib/lstm.py", line 273, in predictSequence
    self.outputs = np.array(self.lstm.forward(xs))
  File "/cluster/home/mmunso01/envs/nidaba/lib/python2.7/site-packages/kraken/lib/lstm.py", line 229, in forward
    xs = net.forward(xs)
  File "/cluster/home/mmunso01/envs/nidaba/lib/python2.7/site-packages/kraken/lib/lstm.py", line 244, in forward
    outputs = [net.forward(xs) for net in self.nets]
  File "/cluster/home/mmunso01/envs/nidaba/lib/python2.7/site-packages/kraken/lib/lstm.py", line 196, in forward
    self.source[t,0] = 1
IndexError: index 5000 is out of bounds for axis 0 with size 5000
[2015-10-30 07:05:49,122: ERROR/Worker-32] nidaba.ocr.kraken[7cb0d4ba-1a8d-4471-9a5d-db72c588bb5e]: index 5000 is out of bounds for axis 0 with size 5000
[2015-10-30 07:05:52,504: ERROR/MainProcess] Task nidaba.ocr.kraken[7cb0d4ba-1a8d-4471-9a5d-db72c588bb5e] raised unexpected: IndexError('index 5000 is out of bounds for axis 0 with size 5000',)
Traceback (most recent call last):
  File "/cluster/home/mmunso01/envs/nidaba/lib/python2.7/site-packages/celery/app/trace.py", line 240, in trace_task
    R = retval = fun(*args, **kwargs)
  File "/cluster/home/mmunso01/envs/nidaba/lib/python2.7/site-packages/nidaba/tasks/helper.py", line 89, in __call__
    ret = super(NidabaTask, self).__call__(*args, **nkwargs)
  File "/cluster/home/mmunso01/envs/nidaba/lib/python2.7/site-packages/celery/app/trace.py", line 438, in __protected_call__
    return self.run(*args, **kwargs)
  File "/cluster/home/mmunso01/envs/nidaba/lib/python2.7/site-packages/nidaba/plugins/kraken.py", line 155, in ocr_kraken
    for rec in rpred.rpred(rnn, img, [(int(x[0]), int(x[1]), int(x[2]), int(x[3])) for x in lines]):
  File "/cluster/home/mmunso01/envs/nidaba/lib/python2.7/site-packages/kraken/rpred.py", line 134, in rpred
    pred = network.predictString(line)
  File "/cluster/home/mmunso01/envs/nidaba/lib/python2.7/site-packages/kraken/lib/lstm.py", line 281, in predictString
    cs = self.predictSequence(xs)
  File "/cluster/home/mmunso01/envs/nidaba/lib/python2.7/site-packages/kraken/lib/lstm.py", line 273, in predictSequence
    self.outputs = np.array(self.lstm.forward(xs))
  File "/cluster/home/mmunso01/envs/nidaba/lib/python2.7/site-packages/kraken/lib/lstm.py", line 229, in forward
    xs = net.forward(xs)
  File "/cluster/home/mmunso01/envs/nidaba/lib/python2.7/site-packages/kraken/lib/lstm.py", line 244, in forward
    outputs = [net.forward(xs) for net in self.nets]
  File "/cluster/home/mmunso01/envs/nidaba/lib/python2.7/site-packages/kraken/lib/lstm.py", line 196, in forward
    self.source[t,0] = 1
IndexError: index 5000 is out of bounds for axis 0 with size 5000
[2015-10-30 07:05:53,844: ERROR/Worker-11] nidaba.ocr.kraken[2c2189ab-a386-48b8-9b74-ea71328a469c]: tile cannot extend outside image
[2015-10-30 07:05:55,011: ERROR/MainProcess] Task nidaba.ocr.kraken[2c2189ab-a386-48b8-9b74-ea71328a469c] raised unexpected: SystemError('tile cannot extend outside image',)
Traceback (most recent call last):
  File "/cluster/home/mmunso01/envs/nidaba/lib/python2.7/site-packages/celery/app/trace.py", line 240, in trace_task
    R = retval = fun(*args, **kwargs)
  File "/cluster/home/mmunso01/envs/nidaba/lib/python2.7/site-packages/nidaba/tasks/helper.py", line 89, in __call__
    ret = super(NidabaTask, self).__call__(*args, **nkwargs)
  File "/cluster/home/mmunso01/envs/nidaba/lib/python2.7/site-packages/celery/app/trace.py", line 438, in __protected_call__
    return self.run(*args, **kwargs)
  File "/cluster/home/mmunso01/envs/nidaba/lib/python2.7/site-packages/nidaba/plugins/kraken.py", line 155, in ocr_kraken
    for rec in rpred.rpred(rnn, img, [(int(x[0]), int(x[1]), int(x[2]), int(x[3])) for x in lines]):
  File "/cluster/home/mmunso01/envs/nidaba/lib/python2.7/site-packages/kraken/rpred.py", line 127, in rpred
    box = dewarp(lnorm, box)
  File "/cluster/home/mmunso01/envs/nidaba/lib/python2.7/site-packages/kraken/rpred.py", line 89, in dewarp
    line = pil2array(im)
  File "/cluster/home/mmunso01/envs/nidaba/lib/python2.7/site-packages/kraken/lib/util.py", line 18, in pil2array
    a = np.fromstring(im.tobytes(), 'B')
  File "/cluster/home/mmunso01/envs/nidaba/lib/python2.7/site-packages/PIL/Image.py", line 669, in tobytes
    e.setimage(self.im)
SystemError: tile cannot extend outside image
[2015-10-30 07:06:01,397: ERROR/Worker-27] nidaba.ocr.kraken[c73b7bc8-f5ba-4a34-ab4d-6be453dcfe86]: index 5000 is out of bounds for axis 0 with size 5000
[2015-10-30 07:06:02,137: ERROR/Worker-28] nidaba.ocr.kraken[52e8c4f4-a383-43d2-836c-daa48f565a89]: index 5000 is out of bounds for axis 0 with size 5000
[2015-10-30 07:06:03,132: ERROR/MainProcess] Task nidaba.ocr.kraken[52e8c4f4-a383-43d2-836c-daa48f565a89] raised unexpected: IndexError('index 5000 is out of bounds for axis 0 with size 5000',)
Traceback (most recent call last):
  File "/cluster/home/mmunso01/envs/nidaba/lib/python2.7/site-packages/celery/app/trace.py", line 240, in trace_task
    R = retval = fun(*args, **kwargs)
  File "/cluster/home/mmunso01/envs/nidaba/lib/python2.7/site-packages/nidaba/tasks/helper.py", line 89, in __call__
    ret = super(NidabaTask, self).__call__(*args, **nkwargs)
  File "/cluster/home/mmunso01/envs/nidaba/lib/python2.7/site-packages/celery/app/trace.py", line 438, in __protected_call__
    return self.run(*args, **kwargs)
  File "/cluster/home/mmunso01/envs/nidaba/lib/python2.7/site-packages/nidaba/plugins/kraken.py", line 155, in ocr_kraken
    for rec in rpred.rpred(rnn, img, [(int(x[0]), int(x[1]), int(x[2]), int(x[3])) for x in lines]):
  File "/cluster/home/mmunso01/envs/nidaba/lib/python2.7/site-packages/kraken/rpred.py", line 134, in rpred
    pred = network.predictString(line)
  File "/cluster/home/mmunso01/envs/nidaba/lib/python2.7/site-packages/kraken/lib/lstm.py", line 281, in predictString
    cs = self.predictSequence(xs)
  File "/cluster/home/mmunso01/envs/nidaba/lib/python2.7/site-packages/kraken/lib/lstm.py", line 273, in predictSequence
    self.outputs = np.array(self.lstm.forward(xs))
  File "/cluster/home/mmunso01/envs/nidaba/lib/python2.7/site-packages/kraken/lib/lstm.py", line 229, in forward
    xs = net.forward(xs)
  File "/cluster/home/mmunso01/envs/nidaba/lib/python2.7/site-packages/kraken/lib/lstm.py", line 244, in forward
    outputs = [net.forward(xs) for net in self.nets]
  File "/cluster/home/mmunso01/envs/nidaba/lib/python2.7/site-packages/kraken/lib/lstm.py", line 196, in forward
    self.source[t,0] = 1
IndexError: index 5000 is out of bounds for axis 0 with size 5000
[2015-10-30 07:06:05,062: ERROR/MainProcess] Task nidaba.ocr.kraken[c73b7bc8-f5ba-4a34-ab4d-6be453dcfe86] raised unexpected: IndexError('index 5000 is out of bounds for axis 0 with size 5000',)
Traceback (most recent call last):
  File "/cluster/home/mmunso01/envs/nidaba/lib/python2.7/site-packages/celery/app/trace.py", line 240, in trace_task
    R = retval = fun(*args, **kwargs)
  File "/cluster/home/mmunso01/envs/nidaba/lib/python2.7/site-packages/nidaba/tasks/helper.py", line 89, in __call__
    ret = super(NidabaTask, self).__call__(*args, **nkwargs)
  File "/cluster/home/mmunso01/envs/nidaba/lib/python2.7/site-packages/celery/app/trace.py", line 438, in __protected_call__
    return self.run(*args, **kwargs)
  File "/cluster/home/mmunso01/envs/nidaba/lib/python2.7/site-packages/nidaba/plugins/kraken.py", line 155, in ocr_kraken
    for rec in rpred.rpred(rnn, img, [(int(x[0]), int(x[1]), int(x[2]), int(x[3])) for x in lines]):
  File "/cluster/home/mmunso01/envs/nidaba/lib/python2.7/site-packages/kraken/rpred.py", line 134, in rpred
    pred = network.predictString(line)
  File "/cluster/home/mmunso01/envs/nidaba/lib/python2.7/site-packages/kraken/lib/lstm.py", line 281, in predictString
    cs = self.predictSequence(xs)
  File "/cluster/home/mmunso01/envs/nidaba/lib/python2.7/site-packages/kraken/lib/lstm.py", line 273, in predictSequence
    self.outputs = np.array(self.lstm.forward(xs))
  File "/cluster/home/mmunso01/envs/nidaba/lib/python2.7/site-packages/kraken/lib/lstm.py", line 229, in forward
    xs = net.forward(xs)
  File "/cluster/home/mmunso01/envs/nidaba/lib/python2.7/site-packages/kraken/lib/lstm.py", line 244, in forward
    outputs = [net.forward(xs) for net in self.nets]
  File "/cluster/home/mmunso01/envs/nidaba/lib/python2.7/site-packages/kraken/lib/lstm.py", line 196, in forward
    self.source[t,0] = 1
IndexError: index 5000 is out of bounds for axis 0 with size 5000
[2015-10-30 07:06:06,133: ERROR/Worker-12] nidaba.ocr.kraken[2327db71-428d-4f66-8f0f-21aa85b209d3]: index 5000 is out of bounds for axis 0 with size 5000
[2015-10-30 07:06:07,190: ERROR/MainProcess] Task nidaba.ocr.kraken[2327db71-428d-4f66-8f0f-21aa85b209d3] raised unexpected: IndexError('index 5000 is out of bounds for axis 0 with size 5000',)
Traceback (most recent call last):
  File "/cluster/home/mmunso01/envs/nidaba/lib/python2.7/site-packages/celery/app/trace.py", line 240, in trace_task
    R = retval = fun(*args, **kwargs)
  File "/cluster/home/mmunso01/envs/nidaba/lib/python2.7/site-packages/nidaba/tasks/helper.py", line 89, in __call__
    ret = super(NidabaTask, self).__call__(*args, **nkwargs)
  File "/cluster/home/mmunso01/envs/nidaba/lib/python2.7/site-packages/celery/app/trace.py", line 438, in __protected_call__
    return self.run(*args, **kwargs)
  File "/cluster/home/mmunso01/envs/nidaba/lib/python2.7/site-packages/nidaba/plugins/kraken.py", line 155, in ocr_kraken
    for rec in rpred.rpred(rnn, img, [(int(x[0]), int(x[1]), int(x[2]), int(x[3])) for x in lines]):
  File "/cluster/home/mmunso01/envs/nidaba/lib/python2.7/site-packages/kraken/rpred.py", line 134, in rpred
    pred = network.predictString(line)
  File "/cluster/home/mmunso01/envs/nidaba/lib/python2.7/site-packages/kraken/lib/lstm.py", line 281, in predictString
    cs = self.predictSequence(xs)
  File "/cluster/home/mmunso01/envs/nidaba/lib/python2.7/site-packages/kraken/lib/lstm.py", line 273, in predictSequence
    self.outputs = np.array(self.lstm.forward(xs))
  File "/cluster/home/mmunso01/envs/nidaba/lib/python2.7/site-packages/kraken/lib/lstm.py", line 229, in forward
    xs = net.forward(xs)
  File "/cluster/home/mmunso01/envs/nidaba/lib/python2.7/site-packages/kraken/lib/lstm.py", line 244, in forward
    outputs = [net.forward(xs) for net in self.nets]
  File "/cluster/home/mmunso01/envs/nidaba/lib/python2.7/site-packages/kraken/lib/lstm.py", line 196, in forward
    self.source[t,0] = 1
IndexError: index 5000 is out of bounds for axis 0 with size 5000
[2015-10-30 07:06:16,725: ERROR/Worker-18] nidaba.ocr.kraken[dece56aa-b01b-4145-8392-b8622cbed987]: index 5000 is out of bounds for axis 0 with size 5000
[2015-10-30 07:06:17,909: ERROR/MainProcess] Task nidaba.ocr.kraken[dece56aa-b01b-4145-8392-b8622cbed987] raised unexpected: IndexError('index 5000 is out of bounds for axis 0 with size 5000',)
Traceback (most recent call last):
  File "/cluster/home/mmunso01/envs/nidaba/lib/python2.7/site-packages/celery/app/trace.py", line 240, in trace_task
    R = retval = fun(*args, **kwargs)
  File "/cluster/home/mmunso01/envs/nidaba/lib/python2.7/site-packages/nidaba/tasks/helper.py", line 89, in __call__
    ret = super(NidabaTask, self).__call__(*args, **nkwargs)
  File "/cluster/home/mmunso01/envs/nidaba/lib/python2.7/site-packages/celery/app/trace.py", line 438, in __protected_call__
    return self.run(*args, **kwargs)
  File "/cluster/home/mmunso01/envs/nidaba/lib/python2.7/site-packages/nidaba/plugins/kraken.py", line 155, in ocr_kraken
    for rec in rpred.rpred(rnn, img, [(int(x[0]), int(x[1]), int(x[2]), int(x[3])) for x in lines]):
  File "/cluster/home/mmunso01/envs/nidaba/lib/python2.7/site-packages/kraken/rpred.py", line 134, in rpred
    pred = network.predictString(line)
  File "/cluster/home/mmunso01/envs/nidaba/lib/python2.7/site-packages/kraken/lib/lstm.py", line 281, in predictString
    cs = self.predictSequence(xs)
  File "/cluster/home/mmunso01/envs/nidaba/lib/python2.7/site-packages/kraken/lib/lstm.py", line 273, in predictSequence
    self.outputs = np.array(self.lstm.forward(xs))
  File "/cluster/home/mmunso01/envs/nidaba/lib/python2.7/site-packages/kraken/lib/lstm.py", line 229, in forward
    xs = net.forward(xs)
  File "/cluster/home/mmunso01/envs/nidaba/lib/python2.7/site-packages/kraken/lib/lstm.py", line 244, in forward
    outputs = [net.forward(xs) for net in self.nets]
  File "/cluster/home/mmunso01/envs/nidaba/lib/python2.7/site-packages/kraken/lib/lstm.py", line 196, in forward
    self.source[t,0] = 1
IndexError: index 5000 is out of bounds for axis 0 with size 5000
[2015-10-30 07:06:42,364: ERROR/Worker-3] nidaba.ocr.kraken[b6b38027-2bf0-4bf4-8581-d0b21dd10710]: index 5000 is out of bounds for axis 0 with size 5000
[2015-10-30 07:06:43,317: ERROR/MainProcess] Task nidaba.ocr.kraken[b6b38027-2bf0-4bf4-8581-d0b21dd10710] raised unexpected: IndexError('index 5000 is out of bounds for axis 0 with size 5000',)
Traceback (most recent call last):
  File "/cluster/home/mmunso01/envs/nidaba/lib/python2.7/site-packages/celery/app/trace.py", line 240, in trace_task
    R = retval = fun(*args, **kwargs)
  File "/cluster/home/mmunso01/envs/nidaba/lib/python2.7/site-packages/nidaba/tasks/helper.py", line 89, in __call__
    ret = super(NidabaTask, self).__call__(*args, **nkwargs)
  File "/cluster/home/mmunso01/envs/nidaba/lib/python2.7/site-packages/celery/app/trace.py", line 438, in __protected_call__
    return self.run(*args, **kwargs)
  File "/cluster/home/mmunso01/envs/nidaba/lib/python2.7/site-packages/nidaba/plugins/kraken.py", line 155, in ocr_kraken
    for rec in rpred.rpred(rnn, img, [(int(x[0]), int(x[1]), int(x[2]), int(x[3])) for x in lines]):
  File "/cluster/home/mmunso01/envs/nidaba/lib/python2.7/site-packages/kraken/rpred.py", line 134, in rpred
    pred = network.predictString(line)
  File "/cluster/home/mmunso01/envs/nidaba/lib/python2.7/site-packages/kraken/lib/lstm.py", line 281, in predictString
    cs = self.predictSequence(xs)
  File "/cluster/home/mmunso01/envs/nidaba/lib/python2.7/site-packages/kraken/lib/lstm.py", line 273, in predictSequence
    self.outputs = np.array(self.lstm.forward(xs))
  File "/cluster/home/mmunso01/envs/nidaba/lib/python2.7/site-packages/kraken/lib/lstm.py", line 229, in forward
    xs = net.forward(xs)
  File "/cluster/home/mmunso01/envs/nidaba/lib/python2.7/site-packages/kraken/lib/lstm.py", line 244, in forward
    outputs = [net.forward(xs) for net in self.nets]
  File "/cluster/home/mmunso01/envs/nidaba/lib/python2.7/site-packages/kraken/lib/lstm.py", line 196, in forward
    self.source[t,0] = 1
IndexError: index 5000 is out of bounds for axis 0 with size 5000
[2015-10-30 07:07:00,225: ERROR/Worker-20] nidaba.ocr.kraken[ca098644-6a68-4da5-b2a3-efd3c449feb8]: index 5000 is out of bounds for axis 0 with size 5000
[2015-10-30 07:07:00,644: ERROR/MainProcess] Task nidaba.ocr.kraken[ca098644-6a68-4da5-b2a3-efd3c449feb8] raised unexpected: IndexError('index 5000 is out of bounds for axis 0 with size 5000',)
Traceback (most recent call last):
  File "/cluster/home/mmunso01/envs/nidaba/lib/python2.7/site-packages/celery/app/trace.py", line 240, in trace_task
    R = retval = fun(*args, **kwargs)
  File "/cluster/home/mmunso01/envs/nidaba/lib/python2.7/site-packages/nidaba/tasks/helper.py", line 89, in __call__
    ret = super(NidabaTask, self).__call__(*args, **nkwargs)
  File "/cluster/home/mmunso01/envs/nidaba/lib/python2.7/site-packages/celery/app/trace.py", line 438, in __protected_call__
    return self.run(*args, **kwargs)
  File "/cluster/home/mmunso01/envs/nidaba/lib/python2.7/site-packages/nidaba/plugins/kraken.py", line 155, in ocr_kraken
    for rec in rpred.rpred(rnn, img, [(int(x[0]), int(x[1]), int(x[2]), int(x[3])) for x in lines]):
  File "/cluster/home/mmunso01/envs/nidaba/lib/python2.7/site-packages/kraken/rpred.py", line 134, in rpred
    pred = network.predictString(line)
  File "/cluster/home/mmunso01/envs/nidaba/lib/python2.7/site-packages/kraken/lib/lstm.py", line 281, in predictString
    cs = self.predictSequence(xs)
  File "/cluster/home/mmunso01/envs/nidaba/lib/python2.7/site-packages/kraken/lib/lstm.py", line 273, in predictSequence
    self.outputs = np.array(self.lstm.forward(xs))
  File "/cluster/home/mmunso01/envs/nidaba/lib/python2.7/site-packages/kraken/lib/lstm.py", line 229, in forward
    xs = net.forward(xs)
  File "/cluster/home/mmunso01/envs/nidaba/lib/python2.7/site-packages/kraken/lib/lstm.py", line 244, in forward
    outputs = [net.forward(xs) for net in self.nets]
  File "/cluster/home/mmunso01/envs/nidaba/lib/python2.7/site-packages/kraken/lib/lstm.py", line 196, in forward
    self.source[t,0] = 1
IndexError: index 5000 is out of bounds for axis 0 with size 5000
[2015-10-30 07:13:40,186: ERROR/Worker-28] nidaba.ocr.kraken[790bb4ed-f21c-4d8c-be3a-8e54ae75e415]: index 5000 is out of bounds for axis 0 with size 5000
[2015-10-30 07:13:40,514: ERROR/MainProcess] Task nidaba.ocr.kraken[790bb4ed-f21c-4d8c-be3a-8e54ae75e415] raised unexpected: IndexError('index 5000 is out of bounds for axis 0 with size 5000',)
Traceback (most recent call last):
  File "/cluster/home/mmunso01/envs/nidaba/lib/python2.7/site-packages/celery/app/trace.py", line 240, in trace_task
    R = retval = fun(*args, **kwargs)
  File "/cluster/home/mmunso01/envs/nidaba/lib/python2.7/site-packages/nidaba/tasks/helper.py", line 89, in __call__
    ret = super(NidabaTask, self).__call__(*args, **nkwargs)
  File "/cluster/home/mmunso01/envs/nidaba/lib/python2.7/site-packages/celery/app/trace.py", line 438, in __protected_call__
    return self.run(*args, **kwargs)
  File "/cluster/home/mmunso01/envs/nidaba/lib/python2.7/site-packages/nidaba/plugins/kraken.py", line 155, in ocr_kraken
    for rec in rpred.rpred(rnn, img, [(int(x[0]), int(x[1]), int(x[2]), int(x[3])) for x in lines]):
  File "/cluster/home/mmunso01/envs/nidaba/lib/python2.7/site-packages/kraken/rpred.py", line 134, in rpred
    pred = network.predictString(line)
  File "/cluster/home/mmunso01/envs/nidaba/lib/python2.7/site-packages/kraken/lib/lstm.py", line 281, in predictString
    cs = self.predictSequence(xs)
  File "/cluster/home/mmunso01/envs/nidaba/lib/python2.7/site-packages/kraken/lib/lstm.py", line 273, in predictSequence
    self.outputs = np.array(self.lstm.forward(xs))
  File "/cluster/home/mmunso01/envs/nidaba/lib/python2.7/site-packages/kraken/lib/lstm.py", line 229, in forward
    xs = net.forward(xs)
  File "/cluster/home/mmunso01/envs/nidaba/lib/python2.7/site-packages/kraken/lib/lstm.py", line 244, in forward
    outputs = [net.forward(xs) for net in self.nets]
  File "/cluster/home/mmunso01/envs/nidaba/lib/python2.7/site-packages/kraken/lib/lstm.py", line 196, in forward
    self.source[t,0] = 1
IndexError: index 5000 is out of bounds for axis 0 with size 5000
